Workbook

Sheet phauthuat
A1: BV TRƯỜNG ĐHYD CẦN THƠ
A2: KHOA NGOẠI CTCH - TK
A3: BẢNG KÊ TIỀN PHẪU THUẬT
A4: THÁNG 6/2026
A6: STT | B6: NGÀY | C6: Họ và tên bệnh nhân | D6: Tuổi | F6: Chẩn đoán và phương pháp phẫu thuật | G6: Loại phẫu thuật | H6: Số tiền thực tính thù lao cho khoa | I6: PTV chính | J6: Số tiền | K6: Phụ mổ 1 | L6: Số tiền | M6: Phụ mổ 2 | N6: Số tiền | O6: Phụ mổ 3 | P6: Số tiền | Q6: ĐD + HL | R6: Thực lãnh
A7: 1 | B7: 46163 | C7: Vũ Thành Đạt | D7: 71 | F7: Thay toàn bộ khớp háng | G7: Đặc biệt | H7: 3525500 | I7: HOAN | J7: =R7-L7-N7-P7-Q7 | K7: DUY | L7: =IF(K7="-",0,H7*0.03) | M7: BẢO | N7: =IF(M7="-",0,H7*0.02) | O7: G.TỬ | P7: =IF(O7="-",0,H7*0.01) | Q7: =H7*0.005 | R7: =IF(I7="V.Tân",H7*0.1375,IF(I7="nguyện",H7*0.1375,IF(I7="TOẢN",H7*0.1375,H7*0.17)))
A8: 2 | B8: 46164 | C8: Trần Văn Xiên | D8: 62 | F8: Cắt lọc hoại tử ổ loét vết thương mãn tính | G8: Loại 2 | H8: 2127400 | I8: TOẢN | J8: =R8-L8-N8-P8-Q8 | K8: V.HƯỞNG | L8: =IF(K8="-",0,H8*0.03) | M8: - | N8: =IF(M8="-",0,H8*0.02) | O8: - | P8: =IF(O8="-",0,H8*0.01) | Q8: =H8*0.005 | R8: =IF(I8="V.Tân",H8*0.1375,IF(I8="nguyện",H8*0.1375,IF(I8="TOẢN",H8*0.1375,H8*0.17)))
A9: 3 | B9: 46164 | C9: Nguyễn Thị Chuối | E9: 74 | F9: PTNS cắt hoạt mạc viêm gối | G9: Loại 1 | H9: 0 | I9: SƠN | J9: =R9-L9-N9-P9-Q9 | K9: BẢO | L9: =IF(K9="-",0,H9*0.03) | M9: V.HƯỞNG | N9: =IF(M9="-",0,H9*0.02) | O9: THUÝ | P9: =IF(O9="-",0,H9*0.01) | Q9: =H9*0.005 | R9: =IF(I9="V.Tân",H9*0.1375,IF(I9="nguyện",H9*0.1375,IF(I9="TOẢN",H9*0.1375,H9*0.17)))
A10: 4 | B10: 46164 | C10: Khuất Hùng | D10: 78 | F10: Cắt lọc hoại tử ổ loét vết thương mãn tính | G10: Loại 2 | H10: 2128200 | I10: DUY | J10: =R10-L10-N10-P10-Q10 | K10: V.HƯỞNG | L10: =IF(K10="-",0,H10*0.03) | M10: THUÝ | N10: =IF(M10="-",0,H10*0.02) | O10: - | P10: =IF(O10="-",0,H10*0.01) | Q10: =H10*0.005 | R10: =IF(I10="V.Tân",H10*0.1375,IF(I10="nguyện",H10*0.1375,IF(I10="TOẢN",H10*0.1375,H10*0.17)))
A11: 5 | B11: 46164 | C11: Nguyễn Thị bé Tư | E11: 59 | F11: Cố định cột sống và hàn khớp qua liên thân đốt cột sống thắt lưng cùng đường sau | G11: Đặc biệt | H11: 0 | I11: NGUYỆN | J11: =R11-L11-N11-P11-Q11 | K11: DUY | L11: =IF(K11="-",0,H11*0.03) | M11: KHANG | N11: =IF(M11="-",0,H11*0.02) | O11: - | P11: =IF(O11="-",0,H11*0.01) | Q11: =H11*0.005 | R11: =IF(I11="V.Tân",H11*0.1375,IF(I11="nguyện",H11*0.1375,IF(I11="TOẢN",H11*0.1375,H11*0.17)))
A12: 6 | B12: 46167 | C12: Huỳnh Thanh Hùng | D12: 81 | F12: Cắt lọc hoại tử ổ loét vết thương mãn tính | G12: Loại 2 | H12: 2127400 | I12: NGUYỆN | J12: =R12-L12-N12-P12-Q12 | K12: TOẢN | L12: =IF(K12="-",0,H12*0.03) | M12: THUÝ | N12: =IF(M12="-",0,H12*0.02) | O12: - | P12: =IF(O12="-",0,H12*0.01) | Q12: =H12*0.005 | R12: =IF(I12="V.Tân",H12*0.1375,IF(I12="nguyện",H12*0.1375,IF(I12="TOẢN",H12*0.1375,H12*0.17)))
A13: 7 | B13: 46167 | C13: Võ Văn Bé Ba | D13: 62 | F13: Cắt lọc hoại tử ổ loét vết thương mãn tính | G13: Loại 2 | H13: 2127400 | I13: HOAN | J13: =R13-L13-N13-P13-Q13 | K13: NGUYỆN | L13: =IF(K13="-",0,H13*0.03) | M13: TOẢN | N13: =IF(M13="-",0,H13*0.02) | O13: NHỊ | P13: =IF(O13="-",0,H13*0.01) | Q13: =H13*0.005 | R13: =IF(I13="V.Tân",H13*0.1375,IF(I13="nguyện",H13*0.1375,IF(I13="TOẢN",H13*0.1375,H13*0.17)))
A14: 8 | B14: 46167 | C14: Nguyễn Thị Lý | E14: 82 | F14: PT thay khớp háng bán phần | G14: Loại 1 | H14: 3897500 | I14: HOAN | J14: =R14-L14-N14-P14-Q14 | K14: NGUYỆN | L14: =IF(K14="-",0,H14*0.03) | M14: TOẢN | N14: =IF(M14="-",0,H14*0.02) | O14: - | P14: =IF(O14="-",0,H14*0.01) | Q14: =H14*0.005 | R14: =IF(I14="V.Tân",H14*0.1375,IF(I14="nguyện",H14*0.1375,IF(I14="TOẢN",H14*0.1375,H14*0.17)))
A15: 9 | B15: 46167 | C15: Kim Thanh Đạt | D15: 19 | F15: Cắt lọc hoại tử ổ loét vết thương mãn tính | G15: Loại 2 | H15: 2127400 | I15: ĐIỀN | J15: =R15-L15-N15-P15-Q15 | K15: KHANG | L15: =IF(K15="-",0,H15*0.03) | M15: THUÝ | N15: =IF(M15="-",0,H15*0.02) | O15: - | P15: =IF(O15="-",0,H15*0.01) | Q15: =H15*0.005 | R15: =IF(I15="V.Tân",H15*0.1375,IF(I15="nguyện",H15*0.1375,IF(I15="TOẢN",H15*0.1375,H15*0.17)))
A16: 10 | B16: 46168 | C16: Phan Thị Nỡ | E16: 69 | F16: Cắt lọc hoại tử ổ loét vết thương mạn tính | G16: Loại 2 | H16: 2128200 | I16: SƠN | J16: =R16-L16-N16-P16-Q16 | K16: LỘC | L16: =IF(K16="-",0,H16*0.03) | M16: - | N16: =IF(M16="-",0,H16*0.02) | O16: - | P16: =IF(O16="-",0,H16*0.01) | Q16: =H16*0.005 | R16: =IF(I16="V.Tân",H16*0.1375,IF(I16="nguyện",H16*0.1375,IF(I16="TOẢN",H16*0.1375,H16*0.17)))
A17: 11 | B17: 46168 | C17: Mai Thành Dương | D17: 62 | F17: Cắt lọc hoại tử ổ loét vết thương mạn tính | G17: Loại 2 | H17: 2127400 | I17: SƠN | J17: =R17-L17-N17-P17-Q17 | K17: LỘC | L17: =IF(K17="-",0,H17*0.03) | M17: - | N17: =IF(M17="-",0,H17*0.02) | O17: - | P17: =IF(O17="-",0,H17*0.01) | Q17: =H17*0.005 | R17: =IF(I17="V.Tân",H17*0.1375,IF(I17="nguyện",H17*0.1375,IF(I17="TOẢN",H17*0.1375,H17*0.17)))
A18: 12 | B18: 46168 | C18: Khuất Hùng | D18: 78 | F18: Cắt lọc hoại tử ổ loét vết thương mạn tính | G18: Loại 2 | H18: 2128200 | I18: DUY | J18: =R18-L18-N18-P18-Q18 | K18: LỘC | L18: =IF(K18="-",0,H18*0.03) | M18: - | N18: =IF(M18="-",0,H18*0.02) | O18: - | P18: =IF(O18="-",0,H18*0.01) | Q18: =H18*0.005 | R18: =IF(I18="V.Tân",H18*0.1375,IF(I18="nguyện",H18*0.1375,IF(I18="TOẢN",H18*0.1375,H18*0.17)))
A19: 13 | B19: 46168 | C19: Hồ Thanh Vũ | D19: 44 | F19: PTNS tái tạo dây chằng | G19: Đặc biệt | H19: 3405500 | I19: SƠN | J19: =R19-L19-N19-P19-Q19 | K19: V.HƯỞNG | L19: =IF(K19="-",0,H19*0.03) | M19: HẬU | N19: =IF(M19="-",0,H19*0.02) | O19: THUÝ | P19: =IF(O19="-",0,H19*0.01) | Q19: =H19*0.005 | R19: =IF(I19="V.Tân",H19*0.1375,IF(I19="nguyện",H19*0.1375,IF(I19="TOẢN",H19*0.1375,H19*0.17)))
A20: 14 | B20: 46168 | C20: Hồ Thanh Vũ | D20: 44 | F20: PTNS khâu sụn chêm (50%) | G20: Đặc biệt | H20: 0 | I20: SƠN | J20: =R20-L20-N20-P20-Q20 | K20: V.HƯỞNG | L20: =IF(K20="-",0,H20*0.03) | M20: HẬU | N20: =IF(M20="-",0,H20*0.02) | O20: THUÝ | P20: =IF(O20="-",0,H20*0.01) | Q20: =H20*0.005 | R20: =IF(I20="V.Tân",H20*0.1375,IF(I20="nguyện",H20*0.1375,IF(I20="TOẢN",H20*0.1375,H20*0.17)))
A21: 15 | B21: 46168 | C21: Nguyễn Thị Xua | E21: 88 | F21: PT KHX trên màn hình tăng sáng | G21: Đặc biệt | H21: 0 | I21: NGUYỆN | J21: =R21-L21-N21-P21-Q21 | K21: G.TỬ | L21: =IF(K21="-",0,H21*0.03) | M21: ĐIỀN | N21: =IF(M21="-",0,H21*0.02) | O21: - | P21: =IF(O21="-",0,H21*0.01) | Q21: =H21*0.005 | R21: =IF(I21="V.Tân",H21*0.1375,IF(I21="nguyện",H21*0.1375,IF(I21="TOẢN",H21*0.1375,H21*0.17)))
A22: 16 | B22: 46169 | C22: Nguyễn Văn Gập | D22: 74 | F22: Cố định cột sống và hàn khớp qua liên thân đốt cột sống thắt lưng cùng đường sau | G22: Đặc biệt | H22: 4201900 | I22: NGUYỆN | J22: =R22-L22-N22-P22-Q22 | K22: G.TỬ | L22: =IF(K22="-",0,H22*0.03) | M22: KHANG | N22: =IF(M22="-",0,H22*0.02) | O22: THUÝ | P22: =IF(O22="-",0,H22*0.01) | Q22: =H22*0.005 | R22: =IF(I22="V.Tân",H22*0.1375,IF(I22="nguyện",H22*0.1375,IF(I22="TOẢN",H22*0.1375,H22*0.17)))
A23: 17 | B23: 46169 | C23: Trần Ngọc Ánh | E23: 65 | F23: PT thay toàn bộ khớp gối | G23: Đặc biệt | H23: 3525500 | I23: TẤN | J23: =R23-L23-N23-P23-Q23 | K23: NGUYỆN | L23: =IF(K23="-",0,H23*0.03) | M23: G.TỬ | N23: =IF(M23="-",0,H23*0.02) | O23: KHANG | P23: =IF(O23="-",0,H23*0.01) | Q23: =H23*0.005 | R23: =IF(I23="V.Tân",H23*0.1375,IF(I23="nguyện",H23*0.1375,IF(I23="TOẢN",H23*0.1375,H23*0.17)))
A24: 18 | B24: 46169 | C24: Nguyễn Thị Hấn | E24: 67 | F24: PT thay toàn bộ khớp háng | G24: Đặc biệt | H24: 3525500 | I24: TẤN | J24: =R24-L24-N24-P24-Q24 | K24: BẢO | L24: =IF(K24="-",0,H24*0.03) | M24: G.TỬ | N24: =IF(M24="-",0,H24*0.02) | O24: KHANG | P24: =IF(O24="-",0,H24*0.01) | Q24: =H24*0.005 | R24: =IF(I24="V.Tân",H24*0.1375,IF(I24="nguyện",H24*0.1375,IF(I24="TOẢN",H24*0.1375,H24*0.17)))
A25: 19 | B25: 46169 | C25: Bùi Văn Long | D25: 65 | F25: KHX trên màn hình tăng sáng | G25: Đặc biệt | H25: 4497500 | I25: ĐIỀN | J25: =R25-L25-N25-P25-Q25 | K25: KHANG | L25: =IF(K25="-",0,H25*0.03) | M25: HẬU | N25: =IF(M25="-",0,H25*0.02) | O25: THUÝ | P25: =IF(O25="-",0,H25*0.01) | Q25: =H25*0.005 | R25: =IF(I25="V.Tân",H25*0.1375,IF(I25="nguyện",H25*0.1375,IF(I25="TOẢN",H25*0.1375,H25*0.17)))
A26: 20 | B26: 46169 | C26: Trần Văn Xiên | D26: 62 | F26: PT cắt cụt chi | G26: Loại 2 | H26: 0 | I26: TOẢN | J26: =R26-L26-N26-P26-Q26 | K26: - | L26: =IF(K26="-",0,H26*0.03) | M26: - | N26: =IF(M26="-",0,H26*0.02) | O26: - | P26: =IF(O26="-",0,H26*0.01) | Q26: =H26*0.005 | R26: =IF(I26="V.Tân",H26*0.1375,IF(I26="nguyện",H26*0.1375,IF(I26="TOẢN",H26*0.1375,H26*0.17)))
A27: 21 | B27: 46170 | C27: Huỳnh Thanh Hùng | D27: 81 | F27: Cắt lọc hoại tử ổ loét vết thương mạn tính | G27: Loại 2 | H27: 0 | I27: NGUYỆN | J27: =R27-L27-N27-P27-Q27 | K27: G.TỬ | L27: =IF(K27="-",0,H27*0.03) | M27: NGHĨA | N27: =IF(M27="-",0,H27*0.02) | O27: THUÝ | P27: =IF(O27="-",0,H27*0.01) | Q27: =H27*0.005 | R27: =IF(I27="V.Tân",H27*0.1375,IF(I27="nguyện",H27*0.1375,IF(I27="TOẢN",H27*0.1375,H27*0.17)))
A28: 22 | B28: 46170 | C28: Trương Bé Lài | E28: 40 | F28: PTNS tái tạo dây chằng bằng gân chân ngỗng | G28: Đặc biệt | H28: 3405500 | I28: TOẢN | J28: =R28-L28-N28-P28-Q28 | K28: NGHĨA | L28: =IF(K28="-",0,H28*0.03) | M28: THUÝ | N28: =IF(M28="-",0,H28*0.02) | O28: - | P28: =IF(O28="-",0,H28*0.01) | Q28: =H28*0.005 | R28: =IF(I28="V.Tân",H28*0.1375,IF(I28="nguyện",H28*0.1375,IF(I28="TOẢN",H28*0.1375,H28*0.17)))
A29: 23 | B29: 46170 | C29: Dương Văn Chiến | D29: 77 | F29: Cắt lọc hoại tử ổ loét vết thương mạn tính | G29: Loại 2 | H29: 2128200 | I29: BẢO | J29: =R29-L29-N29-P29-Q29 | K29: V.HƯỞNG | L29: =IF(K29="-",0,H29*0.03) | M29: LỘC | N29: =IF(M29="-",0,H29*0.02) | O29: - | P29: =IF(O29="-",0,H29*0.01) | Q29: =H29*0.005 | R29: =IF(I29="V.Tân",H29*0.1375,IF(I29="nguyện",H29*0.1375,IF(I29="TOẢN",H29*0.1375,H29*0.17)))
A30: 24 | B30: 46170 | C30: Tống Mỹ Dung | E30: 17 | F30: PTNS tái tạo nhiều dây chằng bằng gân đồng loại | G30: Đặc biệt | H30: 4405500 | I30: BẢO | J30: =R30-L30-N30-P30-Q30 | K30: SƠN | L30: =IF(K30="-",0,H30*0.03) | M30: TOẢN | N30: =IF(M30="-",0,H30*0.02) | O30: THUÝ | P30: =IF(O30="-",0,H30*0.01) | Q30: =H30*0.005 | R30: =IF(I30="V.Tân",H30*0.1375,IF(I30="nguyện",H30*0.1375,IF(I30="TOẢN",H30*0.1375,H30*0.17)))
A31: 25 | B31: 46170 | C31: Tống Mỹ Dung | E31: 17 | F31: PTNS tái tạo nhiều dây chằng bằng gân đồng loại (50%) | G31: Đặc biệt | H31: 2198750 | I31: BẢO | J31: =R31-L31-N31-P31-Q31 | K31: SƠN | L31: =IF(K31="-",0,H31*0.03) | M31: TOẢN | N31: =IF(M31="-",0,H31*0.02) | O31: THUÝ | P31: =IF(O31="-",0,H31*0.01) | Q31: =H31*0.005 | R31: =IF(I31="V.Tân",H31*0.1375,IF(I31="nguyện",H31*0.1375,IF(I31="TOẢN",H31*0.1375,H31*0.17)))
A32: 26 | B32: 46170 | C32: Lê Trọng Nghĩa | D32: 75 | F32: Cắt lọc hoại tử ổ loét vết thương mạn tính | G32: Loại 2 | H32: 2127400 | I32: BẢO | J32: =R32-L32-N32-P32-Q32 | K32: - | L32: =IF(K32="-",0,H32*0.03) | M32: - | N32: =IF(M32="-",0,H32*0.02) | O32: - | P32: =IF(O32="-",0,H32*0.01) | Q32: =H32*0.005 | R32: =IF(I32="V.Tân",H32*0.1375,IF(I32="nguyện",H32*0.1375,IF(I32="TOẢN",H32*0.1375,H32*0.17)))
A33: 27 | B33: 46171 | C33: Mai Thành Dương | D33: 62 | F33: Cắt lọc hoại tử ổ loét vết thương mạn tính | G33: Loại 2 | H33: 0 | I33: SƠN | J33: =R33-L33-N33-P33-Q33 | K33: KHANG | L33: =IF(K33="-",0,H33*0.03) | M33: LỘC | N33: =IF(M33="-",0,H33*0.02) | O33: - | P33: =IF(O33="-",0,H33*0.01) | Q33: =H33*0.005 | R33: =IF(I33="V.Tân",H33*0.1375,IF(I33="nguyện",H33*0.1375,IF(I33="TOẢN",H33*0.1375,H33*0.17)))
A34: 28 | B34: 46171 | C34: Khuất Hùng | D34: 78 | F34: Cắt lọc hoại tử ổ loét vết thương mạn tính | G34: Loại 2 | H34: 2128200 | I34: DUY | J34: =R34-L34-N34-P34-Q34 | K34: KHANG | L34: =IF(K34="-",0,H34*0.03) | M34: LỘC | N34: =IF(M34="-",0,H34*0.02) | O34: - | P34: =IF(O34="-",0,H34*0.01) | Q34: =H34*0.005 | R34: =IF(I34="V.Tân",H34*0.1375,IF(I34="nguyện",H34*0.1375,IF(I34="TOẢN",H34*0.1375,H34*0.17)))
A35: 29 | B35: 46171 | C35: Lê Tiến Đạt | D35: 22 | F35: PT KHX trên màn hình tăng sáng | G35: Đặc biệt | H35: 4497500 | I35: BẢO | J35: =R35-L35-N35-P35-Q35 | K35: DUY | L35: =IF(K35="-",0,H35*0.03) | M35: G.TỬ | N35: =IF(M35="-",0,H35*0.02) | O35: LỘC | P35: =IF(O35="-",0,H35*0.01) | Q35: =H35*0.005 | R35: =IF(I35="V.Tân",H35*0.1375,IF(I35="nguyện",H35*0.1375,IF(I35="TOẢN",H35*0.1375,H35*0.17)))
A36: 30 | B36: 46172 | C36: Trần Thị Quắn | E36: 92 | F36: PT thay khớp háng bán phần | G36: Loại 1 | H36: 3897500 | I36: TẤN | J36: =R36-L36-N36-P36-Q36 | K36: TOẢN | L36: =IF(K36="-",0,H36*0.03) | M36: G.TỬ | N36: =IF(M36="-",0,H36*0.02) | O36: KHANG | P36: =IF(O36="-",0,H36*0.01) | Q36: =H36*0.005 | R36: =IF(I36="V.Tân",H36*0.1375,IF(I36="nguyện",H36*0.1375,IF(I36="TOẢN",H36*0.1375,H36*0.17)))
A37: 31 | B37: 46172 | C37: Vũ Thị Thúy | E37: 61 | F37: PT lấy nhân đệm cột sống qua da | H37: 8993000 | I37: SƠN | J37: =R37-L37-N37-P37-Q37 | K37: NGUYỆN | L37: =IF(K37="-",0,H37*0.03) | M37: THUÝ | N37: =IF(M37="-",0,H37*0.02) | O37: - | P37: =IF(O37="-",0,H37*0.01) | Q37: =H37*0.005 | R37: =IF(I37="V.Tân",H37*0.1375,IF(I37="nguyện",H37*0.1375,IF(I37="TOẢN",H37*0.1375,H37*0.17)))
A38: 32 | B38: 46172 | C38: Nguyễn Minh Tuệ | E38: 24 | F38: PT KHX trên màn hình tăng sáng | G38: Đặc biệt | H38: 4497500 | I38: TOẢN | J38: =R38-L38-N38-P38-Q38 | K38: NGHĨA | L38: =IF(K38="-",0,H38*0.03) | M38: CHỈNH | N38: =IF(M38="-",0,H38*0.02) | O38: - | P38: =IF(O38="-",0,H38*0.01) | Q38: =H38*0.005 | R38: =IF(I38="V.Tân",H38*0.1375,IF(I38="nguyện",H38*0.1375,IF(I38="TOẢN",H38*0.1375,H38*0.17)))
A39: 33 | B39: 46174 | C39: Phan Tuấn Giới | D39: 61 | F39: PT KHX trên màn hình tăng sáng | G39: Đặc biệt | H39: 4497500 | I39: DUY | J39: =R39-L39-N39-P39-Q39 | K39: TOẢN | L39: =IF(K39="-",0,H39*0.03) | M39: CHỈNH | N39: =IF(M39="-",0,H39*0.02) | O39: NGHĨA | P39: =IF(O39="-",0,H39*0.01) | Q39: =H39*0.005 | R39: =IF(I39="V.Tân",H39*0.1375,IF(I39="nguyện",H39*0.1375,IF(I39="TOẢN",H39*0.1375,H39*0.17)))
A40: 34 | B40: 46174 | C40: Nguyễn Hoàng Việt Trinh | E40: 27 | F40: PT KHX trên màn hình tăng sáng | G40: Đặc biệt | H40: 4497500 | I40: TOẢN | J40: =R40-L40-N40-P40-Q40 | K40: NGHĨA | L40: =IF(K40="-",0,H40*0.03) | M40: CHỈNH | N40: =IF(M40="-",0,H40*0.02) | O40: - | P40: =IF(O40="-",0,H40*0.01) | Q40: =H40*0.005 | R40: =IF(I40="V.Tân",H40*0.1375,IF(I40="nguyện",H40*0.1375,IF(I40="TOẢN",H40*0.1375,H40*0.17)))
A41: 35 | B41: 46174 | C41: Phạm Thị Hồng Gấm | E41: 47 | F41: Cố định cột sống và hàn khớp qua liên thân đốt CSTL - cùng đường sau | G41: Đặc biệt | H41: 4201900 | I41: HOAN | J41: =R41-L41-N41-P41-Q41 | K41: NGUYỆN | L41: =IF(K41="-",0,H41*0.03) | M41: ĐIỀN | N41: =IF(M41="-",0,H41*0.02) | O41: G.TỬ | P41: =IF(O41="-",0,H41*0.01) | Q41: =H41*0.005 | R41: =IF(I41="V.Tân",H41*0.1375,IF(I41="nguyện",H41*0.1375,IF(I41="TOẢN",H41*0.1375,H41*0.17)))
...

Sheet thu thuat
A1: BV TRƯỜNG ĐHYD CẦN THƠ
A2: KHOA NGOẠI CTCH-TK
A3: BẢNG KÊ TIỀN TIỂU THỦ THUẬT
A4: =GB!A4
A5: STT | B5: Ngày | C5: Họ và tên | D5: Tuổi | E5: Tên CLS | F5: Số Lượng | G5: Thành tiền | H5: THỰC LÃNH
A6: 1 | B6: 2026/01/09 07:12 | C6: TRƯƠNG HUỲNH THÁI DUY | D6: 09/12/2007 | E6: Cắt chỉ sau phẫu thuật | F6: 1 | G6: 40300 | H6: =G6*25%*75%
A7: 2 | B7: 2026/04/22 14:06 | C7: LÊ KIỀU HÂN | D7: 24/11/2000 | E7: Nắn, bó bột gãy 1/3 trên hai xương cẳng tay [bột liền] | F7: 1 | G7: 372700 | H7: =G8*25%*75%
A8: 3 | B8: 2026/04/29 13:43 | C8: TRẦN HUỲNH BẢO TRÂN | D8: 27/07/1996 | E8: Thay băng, cắt chỉ vết mổ [chiều dài ≤ 15cm] | F8: 1 | G8: 64300 | H8: =G9*25%*75%
A9: 4 | B9: 2026/05/19 07:00 | C9: NGUYỄN THỊ ĐIỀN | D9: 01/01/1963 | E9: Thay băng, cắt chỉ vết mổ [chiều dài ≤ 15cm] | F9: 1 | G9: 100000 | H9: =G10*25%*75%
A10: 5 | B10: 2026/05/19 07:36 | C10: KHUẤT HÙNG | D10: 01/01/1948 | E10: Thay băng, cắt chỉ vết mổ [chiều dài ≤ 15cm] | F10: 1 | G10: 100000 | H10: =G11*25%*75%
A11: 6 | B11: 2026/05/20 05:00 | C11: KHUẤT HÙNG | D11: 01/01/1948 | E11: Thay băng, cắt chỉ vết mổ [chiều dài ≤ 15cm] | F11: 1 | G11: 100000 | H11: =G12*25%*75%
A12: 7 | B12: 2026/05/20 07:00 | C12: NGUYỄN THỊ ĐIỀN | D12: 01/01/1963 | E12: Thay băng, cắt chỉ vết mổ [chiều dài ≤ 15cm] | F12: 1 | G12: 100000 | H12: =G13*25%*75%
A13: 8 | B13: 2026/05/21 05:00 | C13: KHUẤT HÙNG | D13: 01/01/1948 | E13: Thay băng, cắt chỉ vết mổ [chiều dài ≤ 15cm] | F13: 1 | G13: 100000 | H13: =G14*25%*75%
A14: 9 | B14: 2026/05/21 07:00 | C14: NGUYỄN THỊ ĐIỀN | D14: 01/01/1963 | E14: Thay băng, cắt chỉ vết mổ [chiều dài ≤ 15cm] | F14: 1 | G14: 100000 | H14: =G15*25%*75%
A15: 10 | B15: 2026/05/21 07:00 | C15: TRẦN VĂN XIÊN | D15: 01/01/1964 | E15: Thay băng, cắt chỉ vết mổ [chiều dài ≤ 15cm] | F15: 1 | G15: 100000 | H15: =G16*25%*75%
A16: 11 | B16: 2026/05/21 07:00 | C16: VÕ VĂN BÉ BA | D16: 12/12/1964 | E16: Thay băng, cắt chỉ vết mổ [chiều dài ≤ 15cm] | F16: 1 | G16: 100000 | H16: =G17*25%*75%
A17: 12 | B17: 2026/05/22 05:00 | C17: KHUẤT HÙNG | D17: 01/01/1948 | E17: Thay băng, cắt chỉ vết mổ [chiều dài ≤ 15cm] | F17: 1 | G17: 100000 | H17: =G18*25%*75%
A18: 13 | B18: 2026/05/22 07:00 | C18: NGUYỄN THỊ ĐIỀN | D18: 01/01/1963 | E18: Thay băng, cắt chỉ vết mổ [chiều dài ≤ 15cm] | F18: 1 | G18: 100000 | H18: =G19*25%*75%
... A163: 158 | B163: 2026/06/01 08:00 | C163: NGUYỄN THỊ BÉ TƯ | D163: 01/01/1967 | E163: Thay băng, cắt chỉ vết mổ [chiều dài ≤ 15cm] | F163: 1 | G163: 100000 | H163: =G164*25%*75%
A164: 159 | B164: 2026/06/01 09:31 | C164: NGUYỄN THỊ THANH THỦY | D164: 27/04/1959 | E164: Điều trị thoái hóa khớp bằng huyết tương giàu tiểu cầu | F164: 1 | G164: 5500000 | H164: =G166*25%*75%
A165: 160 | B165: 2026/06/01 09:56 | C165: PHAN QUANG TINH | D165: 20/02/1999 | E165: Tháo bột (nhỏ) | F165: 1 | G165: 100000 | H165: =G167*25%*75%
A166: 161 | B166: 2026/06/01 10:35 | C166: NGUYỄN HUY HẠ | D166: 05/10/1968 | E166: Nắn, bó bột trật khớp cổ chân [bột liền] | F166: 1 | G166: 282000 | H166: =G168*25%*75%
A167: 162 | B167: 2026/06/01 11:03 | C167: NGUYỄN LONG VÂN KIỀU NGỌC LIÊN | D167: 24/12/1977 | E167: Tháo bột (nhỏ) | F167: 1 | G167: 100000 | H167: =G169*25%*75%
A168: 163 | B168: 2026/06/01 13:30 | C168: NGUYỄN THỊ HỒNG | D168: 01/01/1964 | E168: Thay băng, cắt chỉ vết mổ [chiều dài ≤ 15cm] | F168: 1 | G168: 100000 | H168: =G170*25%*75%
A169: 164 | B169: 2026/06/01 14:28 | C169: HUỲNH THỊ KIỀU TRANG | D169: 10/04/1983 | E169: Thay băng, cắt chỉ vết mổ [chiều dài ≤ 15cm] | F169: 1 | G169: 64300 | H169: =G171*25%*75%
A170: 165 | B170: 2026/06/01 15:31 | C170: LÂM VINH | D170: 17/08/1984 | E170: Tháo bột (trung bình) | F170: 1 | G170: 200000 | H170: =G173*25%*75%
A171: 166 | B171: 2026/06/01 15:45 | C171: NGUYỄN LONG VÂN KIỀU NGỌC LIÊN | D171: 24/12/1977 | E171: Nẹp bột các loại, không nắn (loại 2) | F171: 1 | G171: 300000 | H171: =G174*25%*75%
A172: 167 | B172: 2026/06/01 15:51 | C172: LÂM THANH HÙNG | D172: 01/01/1954 | E172: Tháo bột (nhỏ) | F172: 1 | G172: 100000 | H172: =G175*25%*75%
A173: 168 | B173: 2026/06/02 05:00 | C173: BÙI VĂN LONG | D173: 21/10/1961 | E173: Thay băng, cắt chỉ vết mổ [chiều dài ≤ 15cm] | F173: 1 | G173: 100000 | H173: =G177*25%*75%
A174: 169 | B174: 2026/06/02 05:00 | C174: DƯƠNG VĂN CHIẾN | D174: 01/01/1949 | E174: Thay băng, cắt chỉ vết mổ [chiều dài ≤ 15cm] | F174: 1 | G174: 100000 | H174: =G178*25%*75%
A175: 170 | B175: 2026/06/02 05:00 | C175: MAI THÀNH DƯƠNG | D175: 10/04/1964 | E175: Thay băng, cắt chỉ vết mổ [chiều dài ≤ 15cm] | F175: 1 | G175: 100000 | H175: =G179*25%*75%
A176: 171 | B176: 2026/06/02 05:00 | C176: NGUYỄN THỊ CHUỐI | D176: 06/08/1952 | E176: Thay băng, cắt chỉ vết mổ [chiều dài ≤ 15cm] | F176: 1 | G176: 100000 | H176: =G180*25%*75%
A177: 172 | B177: 2026/06/02 05:00 | C177: TRẦN VĂN XIÊN | D177: 01/01/1964 | E177: Thay băng, cắt chỉ vết mổ [chiều dài ≤ 15cm] | F177: 1 | G177: 100000 | H177: =G181*25%*75%
A178: 173 | B178: 2026/06/02 05:00 | C178: VŨ THÀNH ĐẠT | D178: 01/02/1955 | E178: Thay băng, cắt chỉ vết mổ [chiều dài ≤ 15cm] | F178: 1 | G178: 100000 | H178: =G182*25%*75%
A179: 174 | B179: 2026/06/02 06:20 | C179: PHẠM THỊ HỒNG GẤM | D179: 01/01/1979 | E179: Thay băng, cắt chỉ vết mổ [chiều dài ≤ 15cm] | F179: 1 | G179: 100000 | H179: =G183*25%*75%
A180: 175 | B180: 2026/06/02 07:00 | C180: KIM THANH ĐẠT | D180: 29/12/2007 | E180: Thay băng, cắt chỉ vết mổ [chiều dài ≤ 15cm] | F180: 1 | G180: 100000 | H180: =G184*25%*75%
A181: 176 | B181: 2026/06/02 07:00 | C181: NGUYỄN MINH TUỆ | D181: 20/05/2002 | E181: Thay băng, cắt chỉ vết mổ [chiều dài ≤ 15cm] | F181: 1 | G181: 100000 | H181: =G185*25%*75%
A182: 177 | B182: 2026/06/02 07:00 | C182: NGUYỄN THỊ HẤN | D182: 01/01/1959 | E182: Thay băng, cắt chỉ vết mổ [chiều dài ≤ 15cm] | F182: 1 | G182: 100000 | H182: =G186*25%*75%
A183: 178 | B183: 2026/06/02 07:00 | C183: NGUYỄN THỊ LÝ | D183: 01/01/1944 | E183: Thay băng, cắt chỉ vết mổ [chiều dài ≤ 15cm] | F183: 1 | G183: 100000 | H183: =G187*25%*75%
A184: 179 | B184: 2026/06/02 07:00 | C184: TRẦN THỊ QUẮN | D184: 01/01/1934 | E184: Thay băng, cắt chỉ vết mổ [chiều dài ≤ 15cm] | F184: 1 | G184: 100000 | H184: =G188*25%*75%
...

Sheet tieuphau
A1: BV TRƯỜNG ĐHYD CẦN THƠ
A2: KHOA NGOẠI CTCH - TK
A3: BẢNG KÊ TIỀN TIỂU PHẪU
A4: =phauthuat!A4
A6: STT | B6: Ngày | C6: Họ và tên | D6: Tuổi | E6: Tên CLS | F6: Số Lượng | G6: Thành tiền | H6: Bác Sĩ | I6: Số Tiền | J6: Điều Dưỡng | K6: Số Tiền | L6: Thực Lãnh
A7: 1 | B7: 2026/05/29 07:00 | C7: ÂU CẨM NHUNG | D7: 04/07/1974 | E7: Tạo hình và đổ xi măng cột sống (kyphoplasty) | F7: 1 | G7: 3418100 | H7: HOAN | I7: =L7-K7 | J7: ĐD | K7: =G7*0.05 | L7: =IF(H7="NGUYỆN",G7*25%*75%,IF(H7="TOẢN",G7*25%*75%,IF(H7="TÂN",G7*25%*75%,G7*0.25)))
A8: 2 | B8: 2026/06/01 15:10 | C8: TRẦN THỊ BA NHỎ | D8: 25/11/1957 | E8: Phẫu thuật giải ép thần kinh (ống cổ tay, Khuỷu…) | F8: 1 | G8: 5000000 | H8: BẢO | I8: =L8-K8 | J8: ĐD | K8: =G8*0.05 | L8: =IF(H8="NGUYỆN",G8*25%*75%,IF(H8="TOẢN",G8*25%*75%,IF(H8="TÂN",G8*25%*75%,G8*0.25)))
A9: 3 | B9: 2026/06/01 16:09 | C9: LÂM THỊ MỸ HOÀNG | D9: 01/01/1968 | E9: Phẫu thuật điều trị ngón tay cò súng (1 ngón) | F9: 1 | G9: 1000000 | H9: V.TÂN | I9: =L9-K9 | J9: ĐD | K9: =G9*0.05 | L9: =IF(H9="NGUYỆN",G9*25%*75%,IF(H9="TOẢN",G9*25%*75%,IF(H9="TÂN",G9*25%*75%,G9*0.25)))
A10: 4 | B10: 2026/06/02 13:16 | C10: NGŨ THỊ NGỌC BÍCH | D10: 01/01/1976 | E10: Phẫu thuật điều trị hội chứng ống cổ tay | F10: 1 | G10: 4000000 | H10: TOẢN | I10: =L10-K10 | J10: ĐD | K10: =G10*0.05 | L10: =IF(H10="NGUYỆN",G10*25%*75%,IF(H10="TOẢN",G10*25%*75%,IF(H10="TÂN",G10*25%*75%,G10*0.25)))
A11: 5 | B11: 2026/06/03 09:16 | C11: ĐẶNG BẠCH PHỤNG | D11: 05/07/1963 | E11: Phẫu thuật điều trị bệnh DE QUER VAIN và ngón tay cò súng [gây tê] | F11: 1 | G11: 3261000 | H11: TÚ | I11: =L11-K11 | J11: ĐD | K11: =G11*0.05 | L11: =IF(H11="NGUYỆN",G11*25%*75%,IF(H11="TOẢN",G11*25%*75%,IF(H11="TÂN",G11*25%*75%,G11*0.25)))
A12: 6 | B12: 2026/06/03 09:45 | C12: NGUYỄN NGỌC QUÝ | D12: 30/07/1975 | E12: Phẫu thuật điều trị ngón tay cò súng (1 ngón) | F12: 1 | G12: 1000000 | H12: TÚ | I12: =L12-K12 | J12: ĐD | K12: =G12*0.05 | L12: =IF(H12="NGUYỆN",G12*25%*75%,IF(H12="TOẢN",G12*25%*75%,IF(H12="TÂN",G12*25%*75%,G12*0.25)))
A13: 7 | B13: 2026/06/05 14:57 | C13: LÊ PHƯƠNG HỒNG | D13: 20/10/1972 | E13: Phẫu thuật điều trị bệnh DE QUER VAIN và ngón tay cò súng [gây tê] | F13: 1 | G13: 3261000 | H13: G.TỬ | I13: =L13-K13 | J13: ĐD | K13: =G13*0.05 | L13: =IF(H13="NGUYỆN",G13*25%*75%,IF(H13="TOẢN",G13*25%*75%,IF(H13="TÂN",G13*25%*75%,G13*0.25)))
A14: 8 | B14: 2026/06/07 21:33 | C14: VÕ KIM ANH | D14: 31/12/1939 | E14: Tạo hình và đổ xi măng cột sống (kyphoplasty) | F14: 1 | G14: 8548000 | H14: HOAN | I14: =L14-K14 | J14: ĐD | K14: =G14*0.05 | L14: =IF(H14="NGUYỆN",G14*25%*75%,IF(H14="TOẢN",G14*25%*75%,IF(H14="TÂN",G14*25%*75%,G14*0.25)))
A15: 9 | B15: 2026/06/08 13:15 | C15: NGUYỄN THÀNH ĐƯỢC | D15: 01/01/1961 | E15: Nắn, bó bột trật khớp háng [bột liền] | F15: 1 | G15: 749600 | H15: SƠN | I15: =L15-K15 | J15: ĐD | K15: =G15*0.05 | L15: =IF(H15="NGUYỆN",G15*25%*75%,IF(H15="TOẢN",G15*25%*75%,IF(H15="TÂN",G15*25%*75%,G15*0.25)))
A16: 10 | B16: 2026/06/09 08:52 | C16: HỒ THỊ LỰU | D16: 12/08/1979 | E16: Phẫu thuật điều trị hội chứng ống cổ tay | F16: 1 | G16: 4000000 | H16: V.TÂN | I16: =L16-K16 | J16: ĐD | K16: =G16*0.05 | L16: =IF(H16="NGUYỆN",G16*25%*75%,IF(H16="TOẢN",G16*25%*75%,IF(H16="TÂN",G16*25%*75%,G16*0.25)))
A17: 11 | B17: 2026/06/10 09:31 | C17: PHẠM THỊ NGUYỆT CHÂU | D17: 28/03/1961 | E17: Phẫu thuật điều trị hội chứng ống cổ tay | F17: 1 | G17: 4000000 | H17: TÚ | I17: =L17-K17 | J17: ĐD | K17: =G17*0.05 | L17: =IF(H17="NGUYỆN",G17*25%*75%,IF(H17="TOẢN",G17*25%*75%,IF(H17="TÂN",G17*25%*75%,G17*0.25)))
A18: 12 | B18: 2026/06/10 10:10 | C18: PHẠM THỊ LỆ | D18: 01/01/1969 | E18: Phẫu thuật điều trị ngón tay cò súng (1 ngón) | F18: 1 | G18: 1000000 | H18: TÚ | I18: =L18-K18 | J18: ĐD | K18: =G18*0.05 | L18: =IF(H18="NGUYỆN",G18*25%*75%,IF(H18="TOẢN",G18*25%*75%,IF(H18="TÂN",G18*25%*75%,G18*0.25)))
... A106: 100 | B106: 2026/06/30 13:52 | C106: TRẦN THỊ LIỆP | D106: 01/01/1954 | E106: Tiêm khớp gối | F106: 1 | G106: 384000 | H106: TOẢN | I106: =L106-K106 | J106: ĐD | K106: =G106*0.05 | L106: =IF(H106="NGUYỆN",G106*25%*75%,IF(H106="TOẢN",G106*25%*75%,IF(H106="TÂN",G106*25%*75%,G106*0.25)))
C107: Tổng Cộng | F107: =SUM(F7:F106) | G107: =SUM(G7:G106) | I107: =SUM(I7:I106) | K107: =SUM(K7:K106) | L107: =SUM(L7:L106)
H108: Cần Thơ, Ngày 31 tháng 5 năm 2026
A109: Lập bảng | H109: Trưởng khoa
G110: =+G107+'thu thuat'!G1336
A113: ĐD. Phan Văn Hiếu | H113: ThS. Bs. CKII. Nguyễn Lê Hoan

Sheet GB
A1: BỆNH VIỆN TRƯỜNG ĐH Y DƯỢC CẦN THƠ
A3: DANH SÁCH CHỈ ĐỊNH GIƯỜNG BỆNH
A4: =phauthuat!A4
F5: Số GB vượt >100% | G5: =IF((D7-D6)>0,D7-D6,0)
A6: Giường phân bổ: 40 GB Tổng Ngày giường Kế hoạch | D6: =40*30 | F6: Số GB vượt 80%-100% | G6: =IF(D7-D6*0.8>0,(D7-D6*0.8)-G5,0)
A7: Ngày giường thực hiện | D7: =F1203 | F7: Công suất GB: | G7: =D7/D6*100%
A8: STT | B8: Ngày | C8: Họ và tên | D8: Tuổi | E8: Tên CLS | F8: Số Lượng | G8: Thành tiền
A9: 1 | B9: 2026/05/16 00:42 | C9: VŨ THÀNH ĐẠT | D9: 01/02/1955 | E9: Giường Nội khoa loại 2 - Khoa Chấn thương chỉnh hình | F9: 1 | G9: 222300
A10: 2 | B10: 2026/05/17 00:00 | C10: VŨ THÀNH ĐẠT | D10: 01/02/1955 | E10: Giường Nội khoa loại 2 - Khoa Chấn thương chỉnh hình | F10: 1 | G10: 222300
A11: 3 | B11: 2026/05/17 22:39 | C11: KHUẤT HÙNG | D11: 01/01/1948 | E11: Giường Nội khoa loại 2 - Khoa Chấn thương chỉnh hình | F11: 1 | G11: 222300
A12: 4 | B12: 2026/05/18 00:00 | C12: VŨ THÀNH ĐẠT | D12: 01/02/1955 | E12: Giường Nội khoa loại 2 - Khoa Chấn thương chỉnh hình | F12: 1 | G12: 222300
A13: 5 | B13: 2026/05/18 14:40 | C13: VÕ VĂN BÉ BA | D13: 12/12/1964 | E13: Giường Nội khoa loại 2 - Khoa Chấn thương chỉnh hình | F13: 1 | G13: 222300
A14: 6 | B14: 2026/05/18 18:45 | C14: NGUYỄN THỊ ĐIỀN | D14: 01/01/1963 | E14: Giường Nội khoa loại 2 - Khoa Chấn thương chỉnh hình | F14: 1 | G14: 222300
A15: 7 | B15: 2026/05/18 20:50 | C15: KHUẤT HÙNG | D15: 01/01/1948 | E15: Giường Ngoại khoa loại 3 - Khoa Chấn thương chỉnh hình | F15: 1 | G15: 269200
A16: 8 | B16: 2026/05/19 00:00 | C16: VÕ VĂN BÉ BA | D16: 12/12/1964 | E16: Giường Nội khoa loại 2 - Khoa Chấn thương chỉnh hình | F16: 1 | G16: 222300
A17: 9 | B17: 2026/05/19 00:00 | C17: VŨ THÀNH ĐẠT | D17: 01/02/1955 | E17: Giường Nội khoa loại 2 - Khoa Chấn thương chỉnh hình | F17: 1 | G17: 222300
A18: 10 | B18: 2026/05/19 00:00 | C18: NGUYỄN THỊ ĐIỀN | D18: 01/01/1963 | E18: Giường Nội khoa loại 2 - Khoa Chấn thương chỉnh hình | F18: 3 | G18: 666900
A19: 11 | B19: 2026/05/19 08:16 | C19: BÙI VĂN LONG | D19: 21/10/1961 | E19: Giường Nội khoa loại 2 - Khoa Chấn thương chỉnh hình | F19: 1 | G19: 222300
A20: 12 | B20: 2026/05/19 17:11 | C20: NGUYỄN THỊ LÝ | D20: 01/01/1944 | E20: Giường Nội khoa loại 2 - Khoa Chấn thương chỉnh hình | F20: 1 | G20: 222300
... A1199: 1191 | B1199: 2026/06/29 00:00 | C1199: TRƯƠNG THỊ CẨM CHÂU | D1199: 09/10/1968 | E1199: Giường Ngoại khoa loại 3 - Khoa Chấn thương chỉnh hình | F1199: 1 | G1199: 269200
C1203: TỔNG CỘNG | F1203: =SUM(F9:F1202) | G1203: =SUM(G9:G1202)
B1205: Người lập | F1205: Trưởng Khoa

Sheet YCBS
A1: BV TRƯỜNG ĐHYD CẦN THƠ
A2: KHOA NGOẠI CTCH-TK
A3: BẢNG KÊ YÊU CẦU BÁC SĨ PHẨU THUẬT
A4: =GB!A4
A5: STT | B5: Ngày | C5: Họ và tên | D5: Tuổi | E5: Tên CLS | F5: Số Lượng | G5: Thành tiền
A6: 1 | B6: 2026/05/28 11:53 | C6: VŨ THỊ THÚY | D6: 02/08/1965 | E6: Chọn bác sĩ phẫu thuật theo yêu cầu | F6: 1 | G6: 1000000
A7: 2 | B7: 2026/05/29 15:00 | C7: VŨ THỊ THÚY | D7: 02/08/1965 | E7: Chọn bác sĩ phẫu thuật theo yêu cầu | F7: 1 | G7: 1000000
A8: 3 | B8: 2026/06/11 20:56 | C8: ĐẶNG KIM BÍCH | D8: 01/01/1972 | E8: Chọn bác sĩ phẫu thuật theo yêu cầu | F8: 1 | G8: 1000000
A9: 4 | B9: 2026/06/18 08:44 | C9: TRỊNH THÚY NGA | D9: 01/01/1965 | E9: Chọn bác sĩ phẫu thuật theo yêu cầu | F9: 1 | G9: 1000000
A10: 5 | B10: 2026/06/18 14:00 | C10: TRƯƠNG HOÀNG DIỄM THÚY | D10: 01/01/1985 | E10: Chọn bác sĩ phẫu thuật theo yêu cầu | F10: 1 | G10: 1000000
A11: 6 | B11: 2026/06/23 16:00 | C11: NGUYỄN ĐỨC THỊNH | D11: 16/12/1996 | E11: Chọn bác sĩ phẫu thuật theo yêu cầu | F11: 1 | G11: 1000000
C27: Tổng Cộng | F27: =SUM(F6:F26) | G27: =SUM(G6:G26)
F28: Cần Thơ, ngày 30 tháng 6 năm 2026
B29: Lập bảng | F29: Trưởng Khoa
B33: ĐD. Phan Văn Hiếu | F33: ThS. Bs. CKII. Nguyễn Lê Hoan
