Workbook

Sheet phauthuat
A1: BV TRƯỜNG ĐHYD CẦN THƠ
A2: KHOA NGOẠI CTCH - TK
A3: BẢNG KÊ TIỀN PHẪU THUẬT
A4: (THÁNG 9/2025)
A6: STT | B6: Ngày | C6: Họ Tên | D6: Nam | E6: Nữ | F6: Phương pháp phẫu thuật | G6: Loại PT | H6: Giá Phẫu thuật thực tính | I6: PTV chính | J6: Số tiền | K6: Phụ mổ 1 | L6: Số tiền | M6: Phụ mổ 2 | N6: Số tiền | O6: Phụ mổ 3 | P6: Số tiền | Q6: ĐD + HL | R6: Thực lãnh
A7: 1 | B7: 18/8/2025 | C7: Trần Văn Thậm | D7: 67 | F7: Cắt lọc, đặt VAC | G7: TT2 | H7: 2128200 | I7: ĐIỀN | J7: =R7-L7-N7-P7-Q7 -> 223461 | K7: HÀO | L7: =IF(K7="-",0,H7*0.03) -> 63846 | M7: PHONG | N7: =IF(M7="-",0,H7*0.02) -> 42564 | O7: KIỆT | P7: =IF(O7="-",0,H7*0.01) -> 21282 | Q7: =H7*0.005 -> 10641 | R7: =IF(I7="V.Tân",H7*0.1375,IF(I7="nguyện",H7*0.1375,IF(I7="TOẢN",H7*0.1375,H7*0.17))) -> 361794
A8: 2 | B8: 19/8/2025 | C8: Nguyễn Thị Nhung | E8: 52 | F8: Cắt lọc | G8: TT2 | H8: 2127400 | I8: ĐIỀN | J8: =R8-L8-N8-P8-Q8 -> 223377 | K8: LỢI | L8: =IF(K8="-",0,H8*0.03) -> 63822 | M8: HÀO | N8: =IF(M8="-",0,H8*0.02) -> 42548 | O8: VINH | P8: =IF(O8="-",0,H8*0.01) -> 21274 | Q8: =H8*0.005 -> 10637 | R8: =IF(I8="V.Tân",H8*0.1375,IF(I8="nguyện",H8*0.1375,IF(I8="TOẢN",H8*0.1375,H8*0.17))) -> 361658
A9: 3 | B9: 21/8/2025 | C9: Huỳnh Thị Mum | E9: 69 | F9: Cắt lọc hoại tử ổ loét vết thương mạn tính | G9: TT2 | H9: 2128200 | I9: ĐIỀN | J9: =R9-L9-N9-P9-Q9 -> 244743 | K9: Q.TẤN | L9: =IF(K9="-",0,H9*0.03) -> 63846 | M9: THANH | N9: =IF(M9="-",0,H9*0.02) -> 42564 | O9: - | P9: =IF(O9="-",0,H9*0.01) -> 0 | Q9: =H9*0.005 -> 10641 | R9: =IF(I9="V.Tân",H9*0.1375,IF(I9="nguyện",H9*0.1375,IF(I9="TOẢN",H9*0.1375,H9*0.17))) -> 361794
A10: 4 | B10: 22/8/2025 | C10: Trần Văn Thậm | D10: 67 | F10: Cắt lọc hoại tử ổ loét vết thương mạn tính | G10: TT2 | H10: 2128200 | I10: ĐIỀN | J10: =R10-L10-N10-P10-Q10 -> 223461 | K10: ĐAN | L10: =IF(K10="-",0,H10*0.03) -> 63846 | M10: KIỆT | N10: =IF(M10="-",0,H10*0.02) -> 42564 | O10: PHONG | P10: =IF(O10="-",0,H10*0.01) -> 21282 | Q10: =H10*0.005 -> 10641 | R10: =IF(I10="V.Tân",H10*0.1375,IF(I10="nguyện",H10*0.1375,IF(I10="TOẢN",H10*0.1375,H10*0.17))) -> 361794
A11: 5 | B11: 23/8/2024 | C11: Nguyễn Thành Trung | D11: 47 | F11: PT KHX mác đơn thuần | G11: TP | H11: 5000000 | I11: TOẢN | J11: =R11-L11-N11-P11-Q11 -> 362500 | K11: NGUYỆN | L11: =IF(K11="-",0,H11*0.03) -> 150000 | M11: KIỆT | N11: =IF(M11="-",0,H11*0.02) -> 100000 | O11: PHONG | P11: =IF(O11="-",0,H11*0.01) -> 50000 | Q11: =H11*0.005 -> 25000 | R11: =IF(I11="V.Tân",H11*0.1375,IF(I11="nguyện",H11*0.1375,IF(I11="TOẢN",H11*0.1375,H11*0.17))) -> 687500
A12: 6 | B12: 24/8/2025 | C12: Nguyễn Thị Nhung | E12: 52 | F12: Cắt lọc ổ loét, khâu kín | G12: TT2 | H12: 3128200 | I12: ĐIỀN | J12: =R12-L12-N12-P12-Q12 -> 328461 | K12: Q.TẤN | L12: =IF(K12="-",0,H12*0.03) -> 93846 | M12: THANH | N12: =IF(M12="-",0,H12*0.02) -> 62564 | O12: ĐAN | P12: =IF(O12="-",0,H12*0.01) -> 31282 | Q12: =H12*0.005 -> 15641 | R12: =IF(I12="V.Tân",H12*0.1375,IF(I12="nguyện",H12*0.1375,IF(I12="TOẢN",H12*0.1375,H12*0.17))) -> 531794
A13: 7 | B13: 25/8/2025 | C13: Huỳnh Thị Mum | E13: 69 | F13: Cắt lọc ổ loét, khâu kín | G13: TT2 | H13: 2127400 | I13: ĐIỀN | J13: =R13-L13-N13-P13-Q13 -> 244651 | K13: NGUYỆN | L13: =IF(K13="-",0,H13*0.03) -> 63822 | M13: KIỆT | N13: =IF(M13="-",0,H13*0.02) -> 42548 | O13: - | P13: =IF(O13="-",0,H13*0.01) -> 0 | Q13: =H13*0.005 -> 10637 | R13: =IF(I13="V.Tân",H13*0.1375,IF(I13="nguyện",H13*0.1375,IF(I13="TOẢN",H13*0.1375,H13*0.17))) -> 361658
A14: 8 | B14: 27/8/2025 | C14: Trần Văn Thậm | D14: 61 | F14: PT vá da diện tích >10cm | G14: TT1 | H14: 1300900 | I14: ĐIỀN | J14: =R14-L14-N14-P14-Q14 -> 136594.5 | K14: ĐAN | L14: =IF(K14="-",0,H14*0.03) -> 39027 | M14: LỢI | N14: =IF(M14="-",0,H14*0.02) -> 26018 | O14: KIỆT | P14: =IF(O14="-",0,H14*0.01) -> 13009 | Q14: =H14*0.005 -> 6504.5 | R14: =IF(I14="V.Tân",H14*0.1375,IF(I14="nguyện",H14*0.1375,IF(I14="TOẢN",H14*0.1375,H14*0.17))) -> 221153
A15: 9 | B15: 27/8/2025 | C15: Nguyễn Đình Long | D15: 70 | F15: Cố định cột sống | G15: TTDB | H15: 4201900 | I15: HOAN | J15: =R15-L15-N15-P15-Q15 -> 441199.5 | K15: NGUYỆN | L15: =IF(K15="-",0,H15*0.03) -> 126057 | M15: Q.TẤN | N15: =IF(M15="-",0,H15*0.02) -> 84038 | O15: KIỆT | P15: =IF(O15="-",0,H15*0.01) -> 42019 | Q15: =H15*0.005 -> 21009.5 | R15: =IF(I15="V.Tân",H15*0.1375,IF(I15="nguyện",H15*0.1375,IF(I15="TOẢN",H15*0.1375,H15*0.17))) -> 714323
A16: 10 | B16: 27/8/2025 | C16: Văng Tấn Hạnh | D16: 70 | F16: Cố định cột sống | G16: TTDB | H16: 4201900 | I16: HOAN | J16: =R16-L16-N16-P16-Q16 -> 483218.5 | K16: NGUYỆN | L16: =IF(K16="-",0,H16*0.03) -> 126057 | M16: ĐIỀN | N16: =IF(M16="-",0,H16*0.02) -> 84038 | O16: - | P16: =IF(O16="-",0,H16*0.01) -> 0 | Q16: =H16*0.005 -> 21009.5 | R16: =IF(I16="V.Tân",H16*0.1375,IF(I16="nguyện",H16*0.1375,IF(I16="TOẢN",H16*0.1375,H16*0.17))) -> 714323
A17: 11 | B17: 28/8/2025 | C17: Phùng Thế Thiện | D17: 31 | F17: KHX trên màn hình tăng sáng | G17: TP | H17: 9972000 | I17: NGUYỆN | J17: =R17-L17-N17-P17-Q17 -> 722970 | K17: ĐIỀN | L17: =IF(K17="-",0,H17*0.03) -> 299160 | M17: V.TÂN | N17: =IF(M17="-",0,H17*0.02) -> 199440 | O17: VINH | P17: =IF(O17="-",0,H17*0.01) -> 99720 | Q17: =H17*0.005 -> 49860 | R17: =IF(I17="V.Tân",H17*0.1375,IF(I17="nguyện",H17*0.1375,IF(I17="TOẢN",H17*0.1375,H17*0.17))) -> 1371150
A18: 12 | B18: 28/8/2025 | C18: Huỳnh Văn Nu | D18: 89 | F18: PT thay khớp háng bán phần | G18: TT1 | H18: 3897500 | I18: HOAN | J18: =R18-L18-N18-P18-Q18 -> 409237.5 | K18: V.TÂN | L18: =IF(K18="-",0,H18*0.03) -> 116925 | M18: VINH | N18: =IF(M18="-",0,H18*0.02) -> 77950 | O18: THANH | P18: =IF(O18="-",0,H18*0.01) -> 38975 | Q18: =H18*0.005 -> 19487.5 | R18: =IF(I18="V.Tân",H18*0.1375,IF(I18="nguyện",H18*0.1375,IF(I18="TOẢN",H18*0.1375,H18*0.17))) -> 662575
A19: 13 | B19: 29/8/2025 | C19: Lê Hồng Quang | D19: 76 | F19: PT làm mỏm cụt ngón và đốt bàn ngón | G19: TT2 | H19: 1773300 | I19: V.TÂN | J19: =R19-L19-N19-P19-Q19 -> 128564.25 | K19: HẬU | L19: =IF(K19="-",0,H19*0.03) -> 53199 | M19: PHONG | N19: =IF(M19="-",0,H19*0.02) -> 35466 | O19: NGUYÊN | P19: =IF(O19="-",0,H19*0.01) -> 17733 | Q19: =H19*0.005 -> 8866.5 | R19: =IF(I19="V.Tân",H19*0.1375,IF(I19="nguyện",H19*0.1375,IF(I19="TOẢN",H19*0.1375,H19*0.17))) -> 243828.75
A20: 14 | B20: 29/8/2025 | C20: Huỳnh Thị Mum | E20: 69 | F20: PT vá da diện tích >10cm | G20: TT1 | H20: 1300900 | I20: ĐIỀN | J20: =R20-L20-N20-P20-Q20 -> 149603.5 | K20: ĐAN | L20: =IF(K20="-",0,H20*0.03) -> 39027 | M20: KIỆT | N20: =IF(M20="-",0,H20*0.02) -> 26018 | O20: - | P20: =IF(O20="-",0,H20*0.01) -> 0 | Q20: =H20*0.005 -> 6504.5 | R20: =IF(I20="V.Tân",H20*0.1375,IF(I20="nguyện",H20*0.1375,IF(I20="TOẢN",H20*0.1375,H20*0.17))) -> 221153
A21: 15 | B21: 29/8/2025 | C21: Hun Rany | D21: 37 | F21: PT thoát vị đĩa đệm | G21: TP | H21: 7000000 | I21: HOAN | J21: =R21-L21-N21-P21-Q21 -> 735000 | K21: NGUYỆN | L21: =IF(K21="-",0,H21*0.03) -> 210000 | M21: NGUYÊN | N21: =IF(M21="-",0,H21*0.02) -> 140000 | O21: HẬU | P21: =IF(O21="-",0,H21*0.01) -> 70000 | Q21: =H21*0.005 -> 35000 | R21: =IF(I21="V.Tân",H21*0.1375,IF(I21="nguyện",H21*0.1375,IF(I21="TOẢN",H21*0.1375,H21*0.17))) -> 1190000
A22: 16 | B22: 29/8/2025 | C22: Nguyễn Thanh Giàu | D22: 40 | F22: Cắt lọc hoại tử ổ loét vết thương mạn tính | G22: TP | H22: 4221000 | I22: TOẢN | J22: =R22-L22-N22-P22-Q22 -> 348232.5 | K22: Q.TẤN | L22: =IF(K22="-",0,H22*0.03) -> 126630 | M22: THANH | N22: =IF(M22="-",0,H22*0.02) -> 84420 | O22: - | P22: =IF(O22="-",0,H22*0.01) -> 0 | Q22: =H22*0.005 -> 21105 | R22: =IF(I22="V.Tân",H22*0.1375,IF(I22="nguyện",H22*0.1375,IF(I22="TOẢN",H22*0.1375,H22*0.17))) -> 580387.5
A23: 17 | B23: 30/8/2025 | C23: Trần Thị Ánh | E23: 74 | F23: KHX trên màn hình tăng sáng | G23: TTDB | H23: 4497500 | I23: V.TÂN | J23: =R23-L23-N23-P23-Q23 -> 326068.75 | K23: NGUYÊN | L23: =IF(K23="-",0,H23*0.03) -> 134925 | M23: HẬU | N23: =IF(M23="-",0,H23*0.02) -> 89950 | O23: PHONG | P23: =IF(O23="-",0,H23*0.01) -> 44975 | Q23: =H23*0.005 -> 22487.5 | R23: =IF(I23="V.Tân",H23*0.1375,IF(I23="nguyện",H23*0.1375,IF(I23="TOẢN",H23*0.1375,H23*0.17))) -> 618406.25
A24: 18 | B24: 02/9/2025 | C24: Nguyễn Văn Đức | D24: 35 | F24: PT vết thương phần mềm đơn giản | G24: TT2 | H24: 1233000 | I24: TOẢN | J24: =R24-L24-N24-P24-Q24 -> 89392.5 | K24: VINH | L24: =IF(K24="-",0,H24*0.03) -> 36990 | M24: HÀO | N24: =IF(M24="-",0,H24*0.02) -> 24660 | O24: LỢI | P24: =IF(O24="-",0,H24*0.01) -> 12330 | Q24: =H24*0.005 -> 6165 | R24: =IF(I24="V.Tân",H24*0.1375,IF(I24="nguyện",H24*0.1375,IF(I24="TOẢN",H24*0.1375,H24*0.17))) -> 169537.5
A25: 19 | B25: 03/9/2025 | C25: Võ Thành Nguyên | D25: 75 | F25: KHX trên màn hình tăng sáng | G25: TTDB | H25: 4497500 | I25: NGUYỆN | J25: =R25-L25-N25-P25-Q25 -> 326068.75 | K25: TOẢN | L25: =IF(K25="-",0,H25*0.03) -> 134925 | M25: ĐIỀN | N25: =IF(M25="-",0,H25*0.02) -> 89950 | O25: Q.TẤN | P25: =IF(O25="-",0,H25*0.01) -> 44975 | Q25: =H25*0.005 -> 22487.5 | R25: =IF(I25="V.Tân",H25*0.1375,IF(I25="nguyện",H25*0.1375,IF(I25="TOẢN",H25*0.1375,H25*0.17))) -> 618406.25
A26: 20 | B26: 05/9/2025 | C26: Trịnh Văn Đủ | D26: 68 | F26: Cắt lọc hoại tử ổ loét vết thương mạn tính | G26: TT2 | H26: 2128200 | I26: V.TÂN | J26: =R26-L26-N26-P26-Q26 -> 154294.5 | K26: TOẢN | L26: =IF(K26="-",0,H26*0.03) -> 63846 | M26: HÀO | N26: =IF(M26="-",0,H26*0.02) -> 42564 | O26: VINH | P26: =IF(O26="-",0,H26*0.01) -> 21282 | Q26: =H26*0.005 -> 10641 | R26: =IF(I26="V.Tân",H26*0.1375,IF(I26="nguyện",H26*0.1375,IF(I26="TOẢN",H26*0.1375,H26*0.17))) -> 292627.5
A27: 21 | B27: 05/9/2025 | C27: Trần Văn Đức | D27: 46 | F27: Cắt lọc hoại tử ổ loét vết thương mạn tính | G27: TT2 | H27: 2128200 | I27: TOẢN | J27: =R27-L27-N27-P27-Q27 -> 154294.5 | K27: HẬU | L27: =IF(K27="-",0,H27*0.03) -> 63846 | M27: LỢI | N27: =IF(M27="-",0,H27*0.02) -> 42564 | O27: HÀO | P27: =IF(O27="-",0,H27*0.01) -> 21282 | Q27: =H27*0.005 -> 10641 | R27: =IF(I27="V.Tân",H27*0.1375,IF(I27="nguyện",H27*0.1375,IF(I27="TOẢN",H27*0.1375,H27*0.17))) -> 292627.5
A28: 22 | B28: 05/9/2025 | C28: Huỳnh Mỹ Huệ | E28: 68 | F28: PT giải phóng chèn ép thần kinh ngoại biên | G28: TT1 | H28: 2301200 | I28: TOẢN | J28: =R28-L28-N28-P28-Q28 -> 166837 | K28: VINH | L28: =IF(K28="-",0,H28*0.03) -> 69036 | M28: HẬU | N28: =IF(M28="-",0,H28*0.02) -> 46024 | O28: LỢI | P28: =IF(O28="-",0,H28*0.01) -> 23012 | Q28: =H28*0.005 -> 11506 | R28: =IF(I28="V.Tân",H28*0.1375,IF(I28="nguyện",H28*0.1375,IF(I28="TOẢN",H28*0.1375,H28*0.17))) -> 316415
A29: 23 | B29: 05/9/2025 | C29: Phan Thị Bê | E29: 85 | F29: PT thay khớp háng bán phần | G29: TT1 | H29: 3897500 | I29: NGUYỆN | J29: =R29-L29-N29-P29-Q29 -> 282568.75 | K29: TOẢN | L29: =IF(K29="-",0,H29*0.03) -> 116925 | M29: VINH | N29: =IF(M29="-",0,H29*0.02) -> 77950 | O29: LỢI | P29: =IF(O29="-",0,H29*0.01) -> 38975 | Q29: =H29*0.005 -> 19487.5 | R29: =IF(I29="V.Tân",H29*0.1375,IF(I29="nguyện",H29*0.1375,IF(I29="TOẢN",H29*0.1375,H29*0.17))) -> 535906.25
A30: 24 | B30: 05/9/2025 | C30: Nguyễn Kim Hoàng | E30: 70 | F30: Thay toàn bộ khớp háng | G30: TTDB | H30: 3525500 | I30: NGUYỆN | J30: =R30-L30-N30-P30-Q30 -> 255598.75 | K30: TOẢN | L30: =IF(K30="-",0,H30*0.03) -> 105765 | M30: VINH | N30: =IF(M30="-",0,H30*0.02) -> 70510 | O30: HÀO | P30: =IF(O30="-",0,H30*0.01) -> 35255 | Q30: =H30*0.005 -> 17627.5 | R30: =IF(I30="V.Tân",H30*0.1375,IF(I30="nguyện",H30*0.1375,IF(I30="TOẢN",H30*0.1375,H30*0.17))) -> 484756.25
A31: 25 | B31: 07/9/2025 | C31: Hồ Nguyễn Tâm Anh | E31: 19 | F31: PT vết thương phần mềm đơn giản | G31: TT2 | H31: 1233000 | I31: V.TÂN | J31: =R31-L31-N31-P31-Q31 -> 126382.5 | K31: THANH | L31: =IF(K31="-",0,H31*0.03) -> 36990 | M31: - | N31: =IF(M31="-",0,H31*0.02) -> 0 | O31: - | P31: =IF(O31="-",0,H31*0.01) -> 0 | Q31: =H31*0.005 -> 6165 | R31: =IF(I31="V.Tân",H31*0.1375,IF(I31="nguyện",H31*0.1375,IF(I31="TOẢN",H31*0.1375,H31*0.17))) -> 169537.5
A32: 26 | B32: 08/9/2025 | C32: Lê Diễm Phương | E32: 32 | F32: KHX trên màn hình tăng sáng | G32: TTDB | H32: 4497500 | I32: NGUYỆN | J32: =R32-L32-N32-P32-Q32 -> 326068.75 | K32: Q.TẤN | L32: =IF(K32="-",0,H32*0.03) -> 134925 | M32: NGUYÊN | N32: =IF(M32="-",0,H32*0.02) -> 89950 | O32: PHONG | P32: =IF(O32="-",0,H32*0.01) -> 44975 | Q32: =H32*0.005 -> 22487.5 | R32: =IF(I32="V.Tân",H32*0.1375,IF(I32="nguyện",H32*0.1375,IF(I32="TOẢN",H32*0.1375,H32*0.17))) -> 618406.25
A33: 27 | B33: 08/9/2025 | C33: Nguyễn Thanh Giàu | D33: 40 | F33: PT vá da diện tích > 10cm2 | G33: TP | H33: 5265000 | I33: TOẢN | J33: =R33-L33-N33-P33-Q33 -> 381712.5 | K33: LỢI | L33: =IF(K33="-",0,H33*0.03) -> 157950 | M33: VINH | N33: =IF(M33="-",0,H33*0.02) -> 105300 | O33: HÀO | P33: =IF(O33="-",0,H33*0.01) -> 52650 | Q33: =H33*0.005 -> 26325 | R33: =IF(I33="V.Tân",H33*0.1375,IF(I33="nguyện",H33*0.1375,IF(I33="TOẢN",H33*0.1375,H33*0.17))) -> 723937.5
A34: 28 | B34: 08/9/2025 | C34: Nguyễn Ái Duy | D34: 22 | F34: KHX trên màn hình tăng sáng | G34: TTDB | H34: 4497500 | I34: HOAN | J34: =R34-L34-N34-P34-Q34 -> 472237.5 | K34: NGUYỆN | L34: =IF(K34="-",0,H34*0.03) -> 134925 | M34: VINH | N34: =IF(M34="-",0,H34*0.02) -> 89950 | O34: HÀO | P34: =IF(O34="-",0,H34*0.01) -> 44975 | Q34: =H34*0.005 -> 22487.5 | R34: =IF(I34="V.Tân",H34*0.1375,IF(I34="nguyện",H34*0.1375,IF(I34="TOẢN",H34*0.1375,H34*0.17))) -> 764575
A35: 29 | B35: 09/9/2025 | C35: Phạm Thị Tuyết Trinh | E35: 30 | F35: PT đóng cứng khớp cổ chân | G35: TT1 | H35: 4724100 | I35: HOAN | J35: =R35-L35-N35-P35-Q35 -> 496030.5 | K35: TOẢN | L35: =IF(K35="-",0,H35*0.03) -> 141723 | M35: HÀO | N35: =IF(M35="-",0,H35*0.02) -> 94482 | O35: VINH | P35: =IF(O35="-",0,H35*0.01) -> 47241 | Q35: =H35*0.005 -> 23620.5 | R35: =IF(I35="V.Tân",H35*0.1375,IF(I35="nguyện",H35*0.1375,IF(I35="TOẢN",H35*0.1375,H35*0.17))) -> 803097
A36: 30 | B36: 09/9/2025 | C36: Lâm Văn Hùng | D36: 55 | F36: Thay toàn bộ khớp háng | G36: TTDB | H36: 3525500 | I36: TRIỀU | J36: =R36-L36-N36-P36-Q36 -> 370177.5 | K36: HOAN | L36: =IF(K36="-",0,H36*0.03) -> 105765 | M36: V.TÂN | N36: =IF(M36="-",0,H36*0.02) -> 70510 | O36: VINH | P36: =IF(O36="-",0,H36*0.01) -> 35255 | Q36: =H36*0.005 -> 17627.5 | R36: =IF(I36="V.Tân",H36*0.1375,IF(I36="nguyện",H36*0.1375,IF(I36="TOẢN",H36*0.1375,H36*0.17))) -> 599335
A37: 31 | B37: 09/9/2025 | C37: Nguyễn Văn Trường | D37: 68 | F37: Cố định cột sống | G37: TTDB | H37: 4201900 | I37: HOAN | J37: =R37-L37-N37-P37-Q37 -> 441199.5 | K37: NGUYỆN | L37: =IF(K37="-",0,H37*0.03) -> 126057 | M37: ĐIỀN | N37: =IF(M37="-",0,H37*0.02) -> 84038 | O37: HÀO | P37: =IF(O37="-",0,H37*0.01) -> 42019 | Q37: =H37*0.005 -> 21009.5 | R37: =IF(I37="V.Tân",H37*0.1375,IF(I37="nguyện",H37*0.1375,IF(I37="TOẢN",H37*0.1375,H37*0.17))) -> 714323
A38: 32 | B38: 09/9/2025 | C38: Âu Văn Hòa | D38: 47 | F38: Cắt u lành >10cm | G38: TT1 | H38: 1859300 | I38: V.TÂN | J38: =R38-L38-N38-P38-Q38 -> 153392.25 | K38: HẬU | L38: =IF(K38="-",0,H38*0.03) -> 55779 | M38: THANH | N38: =IF(M38="-",0,H38*0.02) -> 37186 | O38: - | P38: =IF(O38="-",0,H38*0.01) -> 0 | Q38: =H38*0.005 -> 9296.5 | R38: =IF(I38="V.Tân",H38*0.1375,IF(I38="nguyện",H38*0.1375,IF(I38="TOẢN",H38*0.1375,H38*0.17))) -> 255653.75
A39: 33 | B39: 09/9/2025 | C39: Lê Thị Luyến | E39: 33 | F39: Cắt u lành < 10cm | G39: TP | H39: 3000000 | I39: V.TÂN | J39: =R39-L39-N39-P39-Q39 -> 397500 | K39: - | L39: =IF(K39="-",0,H39*0.03) -> 0 | M39: - | N39: =IF(M39="-",0,H39*0.02) -> 0 | O39: - | P39: =IF(O39="-",0,H39*0.01) -> 0 | Q39: =H39*0.005 -> 15000 | R39: =IF(I39="V.Tân",H39*0.1375,IF(I39="nguyện",H39*0.1375,IF(I39="TOẢN",H39*0.1375,H39*0.17))) -> 412500
A40: 34 | B40: 10/9/2025 | C40: Nguyễn Hoàng mậu | D40: 64 | F40: PT tổn thương gân Achille | G40: TT1 | H40: 2697300 | I40: NGUYỆN | J40: =R40-L40-N40-P40-Q40 -> 195554.25 | K40: TOẢN | L40: =IF(K40="-",0,H40*0.03) -> 80919 | M40: NGUYÊN | N40: =IF(M40="-",0,H40*0.02) -> 53946 | O40: HẬU | P40: =IF(O40="-",0,H40*0.01) -> 26973 | Q40: =H40*0.005 -> 13486.5 | R40: =IF(I40="V.Tân",H40*0.1375,IF(I40="nguyện",H40*0.1375,IF(I40="TOẢN",H40*0.1375,H40*0.17))) -> 370878.75
A41: 35 | B41: 10/9/2025 | C41: Lâm Văn Thử | D41: 57 | F41: PT làm mỏm cụt ngón và đốt bàn ngón | G41: TT2 | H41: 1773300 | I41: TOẢN | J41: =R41-L41-N41-P41-Q41 -> 128564.25 | K41: VINH | L41: =IF(K41="-",0,H41*0.03) -> 53199 | M41: HÀO | N41: =IF(M41="-",0,H41*0.02) -> 35466 | O41: LỢI | P41: =IF(O41="-",0,H41*0.01) -> 17733 | Q41: =H41*0.005 -> 8866.5 | R41: =IF(I41="V.Tân",H41*0.1375,IF(I41="nguyện",H41*0.1375,IF(I41="TOẢN",H41*0.1375,H41*0.17))) -> 243828.75
...

Sheet lanh tien PT
A1: BV TRƯỜNG ĐHYD CẦN THƠ
A2: KHOA NGOẠI CTCH-TK
B3: DANH SÁCH LÃNH TIỀN THÙ LAO THÁNG 9/2025
C4: (Phẫu thuật)
A6: STT | B6: HỌ TÊN | C6: chức vụ | D6: SỐ TIỀN | E6: KÝ NHẬN
A7: 1 | B7: Phạm Việt Triều | C7: Bác sĩ | D7: =SUM(SUMIF(phauthuat!$I$7:$I$85,"TRIỀU",phauthuat!$J$7:$J$85),SUMIF(phauthuat!$K$7:$K$85,"TRIỀU",phauthuat!$L$7:$L$85),SUMIF(phauthuat!$M$7:$M$85,"TRIỀU",phauthuat!$N$7:$N$85),SUMIF(phauthuat!$O$7:$O$85,"TRIỀU",phauthuat!$P$7:$P$85)) -> 740355
A8: 2 | B8: Nguyễn Thành Tấn | C8: Bác sĩ | D8: =SUM(SUMIF(phauthuat!$I$7:$I$85,"TẤN",phauthuat!$J$7:$J$85),SUMIF(phauthuat!$K$7:$K$85,"TẤN",phauthuat!$L$7:$L$85),SUMIF(phauthuat!$M$7:$M$85,"TẤN",phauthuat!$N$7:$N$85),SUMIF(phauthuat!$O$7:$O$85,"TẤN",phauthuat!$P$7:$P$85)) -> 405432.5
A9: 3 | B9: Nguyễn Lê Hoan | C9: Bác sĩ | D9: =SUM(SUMIF(phauthuat!$I$7:$I$85,"HOAN",phauthuat!$J$7:$J$85),SUMIF(phauthuat!$K$7:$K$85,"HOAN",phauthuat!$L$7:$L$85),SUMIF(phauthuat!$M$7:$M$85,"HOAN",phauthuat!$N$7:$N$85),SUMIF(phauthuat!$O$7:$O$85,"Hoan",phauthuat!$P$7:$P$85)) -> 9599324.5
A10: 4 | B10: Nguyễn Chí Nguyện | C10: Bác sĩ | D10: =SUM(SUMIF(phauthuat!$I$7:$I$85,"NGUYỆN",phauthuat!$J$7:$J$85),SUMIF(phauthuat!$K$7:$K$85,"NGUYỆN",phauthuat!$L$7:$L$85),SUMIF(phauthuat!$M$7:$M$85,"NGUYỆN",phauthuat!$N$7:$N$85),SUMIF(phauthuat!$O$7:$O$85,"NGUYỆN",phauthuat!$P$7:$P$85)) -> 5824000.8
A11: 5 | B11: Hồ Điền | C11: Bác sĩ | D11: =SUM(SUMIF(phauthuat!$I$7:$I$85,"ĐIỀN",phauthuat!$J$7:$J$85),SUMIF(phauthuat!$K$7:$K$85,"ĐIỀN",phauthuat!$L$7:$L$85),SUMIF(phauthuat!$M$7:$M$85,"ĐIỀN",phauthuat!$N$7:$N$85),SUMIF(phauthuat!$O$7:$O$85,"ĐIỀN",phauthuat!$P$7:$P$85)) -> 3988549.5
A12: 6 | B12: Trần Quốc Toản | C12: Bác sĩ | D12: =SUM(SUMIF(phauthuat!$I$7:$I$85,"TOẢN",phauthuat!$J$7:$J$85),SUMIF(phauthuat!$K$7:$K$85,"TOẢN",phauthuat!$L$7:$L$85),SUMIF(phauthuat!$M$7:$M$85,"TOẢN",phauthuat!$N$7:$N$85),SUMIF(phauthuat!$O$7:$O$85,"TOẢN",phauthuat!$P$7:$P$85)) -> 5156874.5
A13: 7 | B13: Phạm Việt Tân | C13: Bác sĩ | D13: =SUM(SUMIF(phauthuat!$I$7:$I$85,"V.TÂN",phauthuat!$J$7:$J$85),SUMIF(phauthuat!$K$7:$K$85,"V.TÂN",phauthuat!$L$7:$L$85),SUMIF(phauthuat!$M$7:$M$85,"V.TÂN",phauthuat!$N$7:$N$85),SUMIF(phauthuat!$O$7:$O$85,"V.TÂN",phauthuat!$P$7:$P$85)) -> 4553340.8
A14: 8 | B14: Phan Văn Tuấn | C14: Bác sĩ | D14: =SUM(SUMIF(phauthuat!$I$7:$I$85,"TUẤN",phauthuat!$J$7:$J$85),SUMIF(phauthuat!$K$7:$K$85,"TUẤN",phauthuat!$L$7:$L$85),SUMIF(phauthuat!$M$7:$M$85,"TUẤN",phauthuat!$N$7:$N$85),SUMIF(phauthuat!$O$7:$O$85,"TUẤN",phauthuat!$P$7:$P$85)) -> 1652944
A15: 9 | B15: Nguyễn Hữu Thuyết | C15: Bác sĩ | D15: =SUM(SUMIF(phauthuat!$I$7:$I$85,"thuyết",phauthuat!$J$7:$J$85),SUMIF(phauthuat!$K$7:$K$85,"thuyết",phauthuat!$L$7:$L$85),SUMIF(phauthuat!$M$7:$M$85,"thuyết",phauthuat!$N$7:$N$85),SUMIF(phauthuat!$O$7:$O$85,"thuyết",phauthuat!$P$7:$P$85)) -> 1483845
A16: 10 | B16: Điều Tấn Kiệt | C16: Bác sĩ (nt) | D16: =SUM(SUMIF(phauthuat!$I$7:$I$85,"kiệt",phauthuat!$J$7:$J$85),SUMIF(phauthuat!$K$7:$K$85,"kiệt",phauthuat!$L$7:$L$85),SUMIF(phauthuat!$M$7:$M$85,"kiệt",phauthuat!$N$7:$N$85),SUMIF(phauthuat!$O$7:$O$85,"kiệt",phauthuat!$P$7:$P$85)) -> 703381
A17: 11 | B17: Nguyễn Lê Duy Phong | C17: Bác sĩ (nt) | D17: =SUM(SUMIF(phauthuat!$I$7:$I$85,"phong",phauthuat!$J$7:$J$85),SUMIF(phauthuat!$K$7:$K$85,"phong",phauthuat!$L$7:$L$85),SUMIF(phauthuat!$M$7:$M$85,"phong",phauthuat!$N$7:$N$85),SUMIF(phauthuat!$O$7:$O$85,"phong",phauthuat!$P$7:$P$85)) -> 763480
A18: 12 | B18: Trương Đại Lợi | C18: Bác sĩ (nt) | D18: =SUM(SUMIF(phauthuat!$I$7:$I$85,"lợi",phauthuat!$J$7:$J$85),SUMIF(phauthuat!$K$7:$K$85,"lợi",phauthuat!$L$7:$L$85),SUMIF(phauthuat!$M$7:$M$85,"lợi",phauthuat!$N$7:$N$85),SUMIF(phauthuat!$O$7:$O$85,"lợi",phauthuat!$P$7:$P$85)) -> 724109
A19: 13 | B19: Nguyễn Chí Thanh | C19: Bác sĩ (nt) | D19: =SUM(SUMIF(phauthuat!$I$7:$I$85,"thanh",phauthuat!$J$7:$J$85),SUMIF(phauthuat!$K$7:$K$85,"thanh",phauthuat!$L$7:$L$85),SUMIF(phauthuat!$M$7:$M$85,"thanh",phauthuat!$N$7:$N$85),SUMIF(phauthuat!$O$7:$O$85,"thanh",phauthuat!$P$7:$P$85)) -> 500360
A20: 14 | B20: Nguyễn Trần Khánh Đan | C20: Bác sĩ (nt) | D20: =SUM(SUMIF(phauthuat!$I$7:$I$85,"ĐAN",phauthuat!$J$7:$J$85),SUMIF(phauthuat!$K$7:$K$85,"ĐAN",phauthuat!$L$7:$L$85),SUMIF(phauthuat!$M$7:$M$85,"ĐAN",phauthuat!$N$7:$N$85),SUMIF(phauthuat!$O$7:$O$85,"ĐAN",phauthuat!$P$7:$P$85)) -> 173182
A21: 15 | B21: Phạm Công Hậu | C21: Bác sĩ (nt) | D21: =SUM(SUMIF(phauthuat!$I$7:$I$85,"HẬU",phauthuat!$J$7:$J$85),SUMIF(phauthuat!$K$7:$K$85,"HẬU",phauthuat!$L$7:$L$85),SUMIF(phauthuat!$M$7:$M$85,"HẬU",phauthuat!$N$7:$N$85),SUMIF(phauthuat!$O$7:$O$85,"HẬU",phauthuat!$P$7:$P$85)) -> 495721
A22: 16 | B22: Trang Gia Vinh | C22: Bác sĩ (nt) | D22: =SUM(SUMIF(phauthuat!$I$7:$I$85,"VINH",phauthuat!$J$7:$J$85),SUMIF(phauthuat!$K$7:$K$85,"VINH",phauthuat!$L$7:$L$85),SUMIF(phauthuat!$M$7:$M$85,"VINH",phauthuat!$N$7:$N$85),SUMIF(phauthuat!$O$7:$O$85,"VINH",phauthuat!$P$7:$P$85)) -> 1189077
A23: 17 | B23: Bùi Quan Tấn | C23: Bác sĩ (nt) | D23: =SUM(SUMIF(phauthuat!$I$7:$I$85,"Q.TẤN",phauthuat!$J$7:$J$85),SUMIF(phauthuat!$K$7:$K$85,"Q.TẤN",phauthuat!$L$7:$L$85),SUMIF(phauthuat!$M$7:$M$85,"Q.TẤN",phauthuat!$N$7:$N$85),SUMIF(phauthuat!$O$7:$O$85,"Q.TẤN",phauthuat!$P$7:$P$85)) -> 929210
A24: 18 | B24: Tào Nhật Hào | C24: Bác sĩ (nt) | D24: =SUM(SUMIF(phauthuat!$I$7:$I$85,"HÀO",phauthuat!$J$7:$J$85),SUMIF(phauthuat!$K$7:$K$85,"HÀO",phauthuat!$L$7:$L$85),SUMIF(phauthuat!$M$7:$M$85,"HÀO",phauthuat!$N$7:$N$85),SUMIF(phauthuat!$O$7:$O$85,"HÀO",phauthuat!$P$7:$P$85)) -> 678160
A25: 19 | B25: Huỳnh Phúc Nguyên | C25: Bác sĩ (nt) | D25: =SUM(SUMIF(phauthuat!$I$7:$I$85,"NGUYÊN",phauthuat!$J$7:$J$85),SUMIF(phauthuat!$K$7:$K$85,"NGUYÊN",phauthuat!$L$7:$L$85),SUMIF(phauthuat!$M$7:$M$85,"NGUYÊN",phauthuat!$N$7:$N$85),SUMIF(phauthuat!$O$7:$O$85,"NGUYÊN",phauthuat!$P$7:$P$85)) -> 545980
A26: 20 | B26: Nguyễn Văn Nghiêm | C26: Bác sĩ (nt) | D26: =SUM(SUMIF(phauthuat!$I$7:$I$85,"NGHIÊM",phauthuat!$J$7:$J$85),SUMIF(phauthuat!$K$7:$K$85,"NGHIÊM",phauthuat!$L$7:$L$85),SUMIF(phauthuat!$M$7:$M$85,"NGHIÊM",phauthuat!$N$7:$N$85),SUMIF(phauthuat!$O$7:$O$85,"NGHIÊM",phauthuat!$P$7:$P$85)) -> 242797
A27: 21 | B27: Đỗ Thành Công | C27: Bác sĩ (nt) | D27: =SUM(SUMIF(phauthuat!$I$7:$I$85,"CÔNG",phauthuat!$J$7:$J$85),SUMIF(phauthuat!$K$7:$K$85,"CÔNG",phauthuat!$L$7:$L$85),SUMIF(phauthuat!$M$7:$M$85,"CÔNG",phauthuat!$N$7:$N$85),SUMIF(phauthuat!$O$7:$O$85,"CÔNG",phauthuat!$P$7:$P$85)) -> 315393
A28: 22 | B28: Võ Ngọc Thiện | C28: Bác sĩ (nt) | D28: =SUM(SUMIF(phauthuat!$I$7:$I$85,"THIỆN",phauthuat!$J$7:$J$85),SUMIF(phauthuat!$K$7:$K$85,"THIỆN",phauthuat!$L$7:$L$85),SUMIF(phauthuat!$M$7:$M$85,"THIỆN",phauthuat!$N$7:$N$85),SUMIF(phauthuat!$O$7:$O$85,"THIỆN",phauthuat!$P$7:$P$85)) -> 468412
A29: 23 | B29: Nguyễn Hoài Linh | C29: Bác sĩ (nt) | D29: =SUM(SUMIF(phauthuat!$I$7:$I$85,"LINH",phauthuat!$J$7:$J$85),SUMIF(phauthuat!$K$7:$K$85,"LINH",phauthuat!$L$7:$L$85),SUMIF(phauthuat!$M$7:$M$85,"LINH",phauthuat!$N$7:$N$85),SUMIF(phauthuat!$O$7:$O$85,"LINH",phauthuat!$P$7:$P$85)) -> 343929
A30: 24 | B30: Nguyễn Hoài Đức | C30: Bác sĩ (nt) | D30: =SUM(SUMIF(phauthuat!$I$7:$I$85,"ĐỨC",phauthuat!$J$7:$J$85),SUMIF(phauthuat!$K$7:$K$85,"ĐỨC",phauthuat!$L$7:$L$85),SUMIF(phauthuat!$M$7:$M$85,"ĐỨC",phauthuat!$N$7:$N$85),SUMIF(phauthuat!$O$7:$O$85,"ĐỨC",phauthuat!$P$7:$P$85)) -> 378420
A31: 25 | B31: Phan Văn Hiếu | C31: Điều dưỡng | D31: =phauthuat!Q83/9 -> 156834.61
A32: 26 | B32: Võ Thị Yến Nhi | C32: Điều dưỡng | D32: =D31 -> 156834.61
A33: 27 | B33: Võ Phương Duy | C33: Điều dưỡng | D33: =D32 -> 156834.61
A34: 28 | B34: Nguyễn Kim Ngân | C34: Điều dưỡng | D34: =D33 -> 156834.61
A35: 29 | B35: Lê Ngọc Diệu | C35: Điều dưỡng | D35: =D34 -> 156834.61
A36: 30 | B36: Trần Quỳnh Minh Thư | C36: Điều dưỡng | D36: =D35 -> 156834.61
A37: 31 | B37: Lê Thị Tuyết Đoan | C37: Điều dưỡng | D37: -
A38: 32 | B38: Thạch Thị Thúy Đa | C38: Điều dưỡng | D38: =D36 -> 156834.61
A39: 33 | B39: Lê Kim Hoàn | C39: Điều dưỡng | D39: =D38 -> 156834.61
A40: 34 | B40: Nguyễn Lê Duy Anh | C40: Điều dưỡng | D40: =D39 -> 156834.61
B41: TỔNG CỘNG | D41: =SUM(D7:D40) -> 43267789
...

Sheet phauthuat_BHYT
A1: BV TRƯỜNG ĐHYD CẦN THƠ
A2: KHOA NGOẠI CTCH-TK
B3: BẢNG KÊ TIỀN PHẪU THUẬT BHYT
A4: (THÁNG 9/2025)
A7: STT | B7: Ngày | C7: Họ và tên | D7: Nam | E7: Nữ | F7: Phương pháp phẫu thuật | G7: loại pt - đối tượng | H7: PTV chính | I7: Số tiền | J7: Phụ mổ 1 | K7: Số tiền | L7: Phụ mổ 2 | M7: Số tiền | N7: Tổng số tiền được lãnh sau trừ khấu hao
A8: 1 | B8: 27/8/2025 | C8: Trần Văn Thậm | D8: 61 | F8: PT vá da diện tích >10cm | G8: TT1 | H8: ĐIỀN | I8: =IF(G8="DTDB",420000,IF(G8="TTDB",420000,IF(G8="DT1",187500,IF(G8="TT1",187500,IF(G8="DT2",97500,IF(G8="TT2",97500,IF(G8="DT3",75000,75000))))))) -> 187500 | J8: ĐAN | K8: =IF(G8="DTDB",300000,IF(G8="TTDB",300000,IF(G8="DT1",135000,IF(G8="TT1",135000,IF(G8="DT2",75000,IF(G8="TT2",75000,IF(G8="DT3",45000,45000))))))) -> 135000 | L8: LỢI | M8: =IF(L8="-",0,IF(G8="DTDB",300000,IF(G8="TTDB",300000,IF(G8="DT1",135000,IF(G8="TT1",135000,IF(G8="DT2",75000,IF(G8="TT2",75000,IF(G8="DT3",45000,45000)))))))) -> 135000 | N8: =I8+K8+M8 -> 457500
A9: 2 | B9: 27/8/2025 | C9: Nguyễn Đình Long | D9: 70 | F9: Cố định cột sống | G9: TTDB | H9: HOAN | I9: =IF(G9="DTDB",420000,IF(G9="TTDB",420000,IF(G9="DT1",187500,IF(G9="TT1",187500,IF(G9="DT2",97500,IF(G9="TT2",97500,IF(G9="DT3",75000,75000))))))) -> 420000 | J9: NGUYỆN | K9: =IF(G9="DTDB",300000,IF(G9="TTDB",300000,IF(G9="DT1",135000,IF(G9="TT1",135000,IF(G9="DT2",75000,IF(G9="TT2",75000,IF(G9="DT3",45000,45000))))))) -> 300000 | L9: Q.TẤN | M9: =IF(L9="-",0,IF(G9="DTDB",300000,IF(G9="TTDB",300000,IF(G9="DT1",135000,IF(G9="TT1",135000,IF(G9="DT2",75000,IF(G9="TT2",75000,IF(G9="DT3",45000,45000)))))))) -> 300000 | N9: =I9+K9+M9 -> 1020000
A10: 3 | B10: 27/8/2025 | C10: Văng Tấn Hạnh | D10: 70 | F10: Cố định cột sống | G10: TTDB | H10: HOAN | I10: =IF(G10="DTDB",420000,IF(G10="TTDB",420000,IF(G10="DT1",187500,IF(G10="TT1",187500,IF(G10="DT2",97500,IF(G10="TT2",97500,IF(G10="DT3",75000,75000))))))) -> 420000 | J10: NGUYỆN | K10: =IF(G10="DTDB",300000,IF(G10="TTDB",300000,IF(G10="DT1",135000,IF(G10="TT1",135000,IF(G10="DT2",75000,IF(G10="TT2",75000,IF(G10="DT3",45000,45000))))))) -> 300000 | L10: ĐIỀN | M10: =IF(L10="-",0,IF(G10="DTDB",300000,IF(G10="TTDB",300000,IF(G10="DT1",135000,IF(G10="TT1",135000,IF(G10="DT2",75000,IF(G10="TT2",75000,IF(G10="DT3",45000,45000)))))))) -> 300000 | N10: =I10+K10+M10 -> 1020000
A11: 4 | B11: 28/8/2025 | C11: Huỳnh Văn Nu | D11: 89 | F11: PT thay khớp háng bán phần | G11: TT1 | H11: HOAN | I11: =IF(G11="DTDB",420000,IF(G11="TTDB",420000,IF(G11="DT1",187500,IF(G11="TT1",187500,IF(G11="DT2",97500,IF(G11="TT2",97500,IF(G11="DT3",75000,75000))))))) -> 187500 | J11: V.TÂN | K11: =IF(G11="DTDB",300000,IF(G11="TTDB",300000,IF(G11="DT1",135000,IF(G11="TT1",135000,IF(G11="DT2",75000,IF(G11="TT2",75000,IF(G11="DT3",45000,45000))))))) -> 135000 | L11: VINH | M11: =IF(L11="-",0,IF(G11="DTDB",300000,IF(G11="TTDB",300000,IF(G11="DT1",135000,IF(G11="TT1",135000,IF(G11="DT2",75000,IF(G11="TT2",75000,IF(G11="DT3",45000,45000)))))))) -> 135000 | N11: =I11+K11+M11 -> 457500
A12: 5 | B12: 28/8/2025 | C12: Ung Văn Đúa | D12: 69 | F12: KHX trên màn hình tăng sáng | G12: DTDB | H12: TOẢN | I12: =IF(G12="DTDB",420000,IF(G12="TTDB",420000,IF(G12="DT1",187500,IF(G12="TT1",187500,IF(G12="DT2",97500,IF(G12="TT2",97500,IF(G12="DT3",75000,75000))))))) -> 420000 | J12: ĐAN | K12: =IF(G12="DTDB",300000,IF(G12="TTDB",300000,IF(G12="DT1",135000,IF(G12="TT1",135000,IF(G12="DT2",75000,IF(G12="TT2",75000,IF(G12="DT3",45000,45000))))))) -> 300000 | L12: KIỆT | M12: =IF(L12="-",0,IF(G12="DTDB",300000,IF(G12="TTDB",300000,IF(G12="DT1",135000,IF(G12="TT1",135000,IF(G12="DT2",75000,IF(G12="TT2",75000,IF(G12="DT3",45000,45000)))))))) -> 300000 | N12: =I12+K12+M12 -> 1020000
A13: 6 | B13: 29/8/2025 | C13: Huỳnh Thị Mum | E13: 69 | F13: PT vá da diện tích >10cm | G13: TT1 | H13: ĐIỀN | I13: =IF(G13="DTDB",420000,IF(G13="TTDB",420000,IF(G13="DT1",187500,IF(G13="TT1",187500,IF(G13="DT2",97500,IF(G13="TT2",97500,IF(G13="DT3",75000,75000))))))) -> 187500 | J13: ĐAN | K13: =IF(G13="DTDB",300000,IF(G13="TTDB",300000,IF(G13="DT1",135000,IF(G13="TT1",135000,IF(G13="DT2",75000,IF(G13="TT2",75000,IF(G13="DT3",45000,45000))))))) -> 135000 | L13: KIỆT | M13: =IF(L13="-",0,IF(G13="DTDB",300000,IF(G13="TTDB",300000,IF(G13="DT1",135000,IF(G13="TT1",135000,IF(G13="DT2",75000,IF(G13="TT2",75000,IF(G13="DT3",45000,45000)))))))) -> 135000 | N13: =I13+K13+M13 -> 457500
A14: 7 | B14: 30/8/2025 | C14: Trần Thị Ánh | E14: 74 | F14: KHX trên màn hình tăng sáng | G14: TTDB | H14: V.TÂN | I14: =IF(G14="DTDB",420000,IF(G14="TTDB",420000,IF(G14="DT1",187500,IF(G14="TT1",187500,IF(G14="DT2",97500,IF(G14="TT2",97500,IF(G14="DT3",75000,75000))))))) -> 420000 | J14: NGUYÊN | K14: =IF(G14="DTDB",300000,IF(G14="TTDB",300000,IF(G14="DT1",135000,IF(G14="TT1",135000,IF(G14="DT2",75000,IF(G14="TT2",75000,IF(G14="DT3",45000,45000))))))) -> 300000 | L14: HẬU | M14: =IF(L14="-",0,IF(G14="DTDB",300000,IF(G14="TTDB",300000,IF(G14="DT1",135000,IF(G14="TT1",135000,IF(G14="DT2",75000,IF(G14="TT2",75000,IF(G14="DT3",45000,45000)))))))) -> 300000 | N14: =I14+K14+M14 -> 1020000
A15: 8 | B15: 01/9/2025 | C15: Nguyễn Văn Thạnh | D15: 95 | F15: KHX trên màn hình tăng sáng | G15: DTDB | H15: ĐIỀN | I15: =IF(G15="DTDB",420000,IF(G15="TTDB",420000,IF(G15="DT1",187500,IF(G15="TT1",187500,IF(G15="DT2",97500,IF(G15="TT2",97500,IF(G15="DT3",75000,75000))))))) -> 420000 | J15: NGUYỆN | K15: =IF(G15="DTDB",300000,IF(G15="TTDB",300000,IF(G15="DT1",135000,IF(G15="TT1",135000,IF(G15="DT2",75000,IF(G15="TT2",75000,IF(G15="DT3",45000,45000))))))) -> 300000 | L15: ĐAN | M15: =IF(L15="-",0,IF(G15="DTDB",300000,IF(G15="TTDB",300000,IF(G15="DT1",135000,IF(G15="TT1",135000,IF(G15="DT2",75000,IF(G15="TT2",75000,IF(G15="DT3",45000,45000)))))))) -> 300000 | N15: =I15+K15+M15 -> 1020000
A16: 9 | B16: 03/9/2025 | C16: Võ Thành Nguyên | D16: 75 | F16: KHX trên màn hình tăng sáng | G16: TTDB | H16: NGUYỆN | I16: =IF(G16="DTDB",420000,IF(G16="TTDB",420000,IF(G16="DT1",187500,IF(G16="TT1",187500,IF(G16="DT2",97500,IF(G16="TT2",97500,IF(G16="DT3",75000,75000))))))) -> 420000 | J16: TOẢN | K16: =IF(G16="DTDB",300000,IF(G16="TTDB",300000,IF(G16="DT1",135000,IF(G16="TT1",135000,IF(G16="DT2",75000,IF(G16="TT2",75000,IF(G16="DT3",45000,45000))))))) -> 300000 | L16: ĐIỀN | M16: =IF(L16="-",0,IF(G16="DTDB",300000,IF(G16="TTDB",300000,IF(G16="DT1",135000,IF(G16="TT1",135000,IF(G16="DT2",75000,IF(G16="TT2",75000,IF(G16="DT3",45000,45000)))))))) -> 300000 | N16: =I16+K16+M16 -> 1020000
A17: 10 | B17: 05/9/2025 | C17: Huỳnh Mỹ Huệ | E17: 68 | F17: PT giải phóng chèn ép thần kinh ngoại biên | G17: TT1 | H17: TOẢN | I17: =IF(G17="DTDB",420000,IF(G17="TTDB",420000,IF(G17="DT1",187500,IF(G17="TT1",187500,IF(G17="DT2",97500,IF(G17="TT2",97500,IF(G17="DT3",75000,75000))))))) -> 187500 | J17: VINH | K17: =IF(G17="DTDB",300000,IF(G17="TTDB",300000,IF(G17="DT1",135000,IF(G17="TT1",135000,IF(G17="DT2",75000,IF(G17="TT2",75000,IF(G17="DT3",45000,45000))))))) -> 135000 | L17: HẬU | M17: =IF(L17="-",0,IF(G17="DTDB",300000,IF(G17="TTDB",300000,IF(G17="DT1",135000,IF(G17="TT1",135000,IF(G17="DT2",75000,IF(G17="TT2",75000,IF(G17="DT3",45000,45000)))))))) -> 135000 | N17: =I17+K17+M17 -> 457500
A18: 11 | B18: 05/9/2025 | C18: Phan Thị Bê | E18: 85 | F18: PT thay khớp háng bán phần | G18: TT1 | H18: NGUYỆN | I18: =IF(G18="DTDB",420000,IF(G18="TTDB",420000,IF(G18="DT1",187500,IF(G18="TT1",187500,IF(G18="DT2",97500,IF(G18="TT2",97500,IF(G18="DT3",75000,75000))))))) -> 187500 | J18: TOẢN | K18: =IF(G18="DTDB",300000,IF(G18="TTDB",300000,IF(G18="DT1",135000,IF(G18="TT1",135000,IF(G18="DT2",75000,IF(G18="TT2",75000,IF(G18="DT3",45000,45000))))))) -> 135000 | L18: VINH | M18: =IF(L18="-",0,IF(G18="DTDB",300000,IF(G18="TTDB",300000,IF(G18="DT1",135000,IF(G18="TT1",135000,IF(G18="DT2",75000,IF(G18="TT2",75000,IF(G18="DT3",45000,45000)))))))) -> 135000 | N18: =I18+K18+M18 -> 457500
A19: 12 | B19: 05/9/2025 | C19: Nguyễn Kim Hoàng | E19: 70 | F19: Thay toàn bộ khớp háng | G19: TTDB | H19: NGUYỆN | I19: =IF(G19="DTDB",420000,IF(G19="TTDB",420000,IF(G19="DT1",187500,IF(G19="TT1",187500,IF(G19="DT2",97500,IF(G19="TT2",97500,IF(G19="DT3",75000,75000))))))) -> 420000 | J19: TOẢN | K19: =IF(G19="DTDB",300000,IF(G19="TTDB",300000,IF(G19="DT1",135000,IF(G19="TT1",135000,IF(G19="DT2",75000,IF(G19="TT2",75000,IF(G19="DT3",45000,45000))))))) -> 300000 | L19: VINH | M19: =IF(L19="-",0,IF(G19="DTDB",300000,IF(G19="TTDB",300000,IF(G19="DT1",135000,IF(G19="TT1",135000,IF(G19="DT2",75000,IF(G19="TT2",75000,IF(G19="DT3",45000,45000)))))))) -> 300000 | N19: =I19+K19+M19 -> 1020000
A20: 13 | B20: 08/9/2025 | C20: Lê Diễm Phương | E20: 32 | F20: KHX trên màn hình tăng sáng | G20: TTDB | H20: NGUYỆN | I20: =IF(G20="DTDB",420000,IF(G20="TTDB",420000,IF(G20="DT1",187500,IF(G20="TT1",187500,IF(G20="DT2",97500,IF(G20="TT2",97500,IF(G20="DT3",75000,75000))))))) -> 420000 | J20: Q.TẤN | K20: =IF(G20="DTDB",300000,IF(G20="TTDB",300000,IF(G20="DT1",135000,IF(G20="TT1",135000,IF(G20="DT2",75000,IF(G20="TT2",75000,IF(G20="DT3",45000,45000))))))) -> 300000 | L20: NGUYÊN | M20: =IF(L20="-",0,IF(G20="DTDB",300000,IF(G20="TTDB",300000,IF(G20="DT1",135000,IF(G20="TT1",135000,IF(G20="DT2",75000,IF(G20="TT2",75000,IF(G20="DT3",45000,45000)))))))) -> 300000 | N20: =I20+K20+M20 -> 1020000
A21: 14 | B21: 08/9/2025 | C21: Nguyễn Ái Duy | D21: 22 | F21: KHX trên màn hình tăng sáng | G21: TTDB | H21: HOAN | I21: =IF(G21="DTDB",420000,IF(G21="TTDB",420000,IF(G21="DT1",187500,IF(G21="TT1",187500,IF(G21="DT2",97500,IF(G21="TT2",97500,IF(G21="DT3",75000,75000))))))) -> 420000 | J21: NGUYỆN | K21: =IF(G21="DTDB",300000,IF(G21="TTDB",300000,IF(G21="DT1",135000,IF(G21="TT1",135000,IF(G21="DT2",75000,IF(G21="TT2",75000,IF(G21="DT3",45000,45000))))))) -> 300000 | L21: VINH | M21: =IF(L21="-",0,IF(G21="DTDB",300000,IF(G21="TTDB",300000,IF(G21="DT1",135000,IF(G21="TT1",135000,IF(G21="DT2",75000,IF(G21="TT2",75000,IF(G21="DT3",45000,45000)))))))) -> 300000 | N21: =I21+K21+M21 -> 1020000
A22: 15 | B22: 09/9/2025 | C22: Phạm Thị Tuyết Trinh | E22: 30 | F22: PT đóng cứng khớp cổ chân | G22: TT1 | H22: HOAN | I22: =IF(G22="DTDB",420000,IF(G22="TTDB",420000,IF(G22="DT1",187500,IF(G22="TT1",187500,IF(G22="DT2",97500,IF(G22="TT2",97500,IF(G22="DT3",75000,75000))))))) -> 187500 | J22: TOẢN | K22: =IF(G22="DTDB",300000,IF(G22="TTDB",300000,IF(G22="DT1",135000,IF(G22="TT1",135000,IF(G22="DT2",75000,IF(G22="TT2",75000,IF(G22="DT3",45000,45000))))))) -> 135000 | L22: HÀO | M22: =IF(L22="-",0,IF(G22="DTDB",300000,IF(G22="TTDB",300000,IF(G22="DT1",135000,IF(G22="TT1",135000,IF(G22="DT2",75000,IF(G22="TT2",75000,IF(G22="DT3",45000,45000)))))))) -> 135000 | N22: =I22+K22+M22 -> 457500
A23: 16 | B23: 09/9/2025 | C23: Lâm Văn Hùng | D23: 55 | F23: Thay toàn bộ khớp háng | G23: TTDB | H23: TRIỀU | I23: =IF(G23="DTDB",420000,IF(G23="TTDB",420000,IF(G23="DT1",187500,IF(G23="TT1",187500,IF(G23="DT2",97500,IF(G23="TT2",97500,IF(G23="DT3",75000,75000))))))) -> 420000 | J23: HOAN | K23: =IF(G23="DTDB",300000,IF(G23="TTDB",300000,IF(G23="DT1",135000,IF(G23="TT1",135000,IF(G23="DT2",75000,IF(G23="TT2",75000,IF(G23="DT3",45000,45000))))))) -> 300000 | L23: V.TÂN | M23: =IF(L23="-",0,IF(G23="DTDB",300000,IF(G23="TTDB",300000,IF(G23="DT1",135000,IF(G23="TT1",135000,IF(G23="DT2",75000,IF(G23="TT2",75000,IF(G23="DT3",45000,45000)))))))) -> 300000 | N23: =I23+K23+M23 -> 1020000
A24: 17 | B24: 09/9/2025 | C24: Nguyễn Văn Trường | D24: 68 | F24: Cố định cột sống | G24: TTDB | H24: HOAN | I24: =IF(G24="DTDB",420000,IF(G24="TTDB",420000,IF(G24="DT1",187500,IF(G24="TT1",187500,IF(G24="DT2",97500,IF(G24="TT2",97500,IF(G24="DT3",75000,75000))))))) -> 420000 | J24: NGUYỆN | K24: =IF(G24="DTDB",300000,IF(G24="TTDB",300000,IF(G24="DT1",135000,IF(G24="TT1",135000,IF(G24="DT2",75000,IF(G24="TT2",75000,IF(G24="DT3",45000,45000))))))) -> 300000 | L24: ĐIỀN | M24: =IF(L24="-",0,IF(G24="DTDB",300000,IF(G24="TTDB",300000,IF(G24="DT1",135000,IF(G24="TT1",135000,IF(G24="DT2",75000,IF(G24="TT2",75000,IF(G24="DT3",45000,45000)))))))) -> 300000 | N24: =I24+K24+M24 -> 1020000
A25: 18 | B25: 09/9/2025 | C25: Âu Văn Hòa | D25: 47 | F25: Cắt u lành >10cm | G25: TT1 | H25: V.TÂN | I25: =IF(G25="DTDB",420000,IF(G25="TTDB",420000,IF(G25="DT1",187500,IF(G25="TT1",187500,IF(G25="DT2",97500,IF(G25="TT2",97500,IF(G25="DT3",75000,75000))))))) -> 187500 | J25: HẬU | K25: =IF(G25="DTDB",300000,IF(G25="TTDB",300000,IF(G25="DT1",135000,IF(G25="TT1",135000,IF(G25="DT2",75000,IF(G25="TT2",75000,IF(G25="DT3",45000,45000))))))) -> 135000 | L25: THANH | M25: =IF(L25="-",0,IF(G25="DTDB",300000,IF(G25="TTDB",300000,IF(G25="DT1",135000,IF(G25="TT1",135000,IF(G25="DT2",75000,IF(G25="TT2",75000,IF(G25="DT3",45000,45000)))))))) -> 135000 | N25: =I25+K25+M25 -> 457500
A26: 19 | B26: 10/9/2025 | C26: Nguyễn Hoàng mậu | D26: 64 | F26: PT tổn thương gân Achille | G26: TT1 | H26: NGUYỆN | I26: =IF(G26="DTDB",420000,IF(G26="TTDB",420000,IF(G26="DT1",187500,IF(G26="TT1",187500,IF(G26="DT2",97500,IF(G26="TT2",97500,IF(G26="DT3",75000,75000))))))) -> 187500 | J26: TOẢN | K26: =IF(G26="DTDB",300000,IF(G26="TTDB",300000,IF(G26="DT1",135000,IF(G26="TT1",135000,IF(G26="DT2",75000,IF(G26="TT2",75000,IF(G26="DT3",45000,45000))))))) -> 135000 | L26: NGUYÊN | M26: =IF(L26="-",0,IF(G26="DTDB",300000,IF(G26="TTDB",300000,IF(G26="DT1",135000,IF(G26="TT1",135000,IF(G26="DT2",75000,IF(G26="TT2",75000,IF(G26="DT3",45000,45000)))))))) -> 135000 | N26: =I26+K26+M26 -> 457500
A27: 20 | B27: 10/9/2025 | C27: Võ Thanh Hải | D27: 22 | F27: PTNS tái tạo dây chằng | G27: DTDB | H27: TOẢN | I27: =IF(G27="DTDB",420000,IF(G27="TTDB",420000,IF(G27="DT1",187500,IF(G27="TT1",187500,IF(G27="DT2",97500,IF(G27="TT2",97500,IF(G27="DT3",75000,75000))))))) -> 420000 | J27: HẬU | K27: =IF(G27="DTDB",300000,IF(G27="TTDB",300000,IF(G27="DT1",135000,IF(G27="TT1",135000,IF(G27="DT2",75000,IF(G27="TT2",75000,IF(G27="DT3",45000,45000))))))) -> 300000 | L27: NGUYÊN | M27: =IF(L27="-",0,IF(G27="DTDB",300000,IF(G27="TTDB",300000,IF(G27="DT1",135000,IF(G27="TT1",135000,IF(G27="DT2",75000,IF(G27="TT2",75000,IF(G27="DT3",45000,45000)))))))) -> 300000 | N27: =I27+K27+M27 -> 1020000
A28: 21 | B28: 11/9/2025 | C28: Phan Văn Duyên | D28: 100 | F28: KHX trên màn hình tăng sáng | G28: TTDB | H28: HOAN | I28: =IF(G28="DTDB",420000,IF(G28="TTDB",420000,IF(G28="DT1",187500,IF(G28="TT1",187500,IF(G28="DT2",97500,IF(G28="TT2",97500,IF(G28="DT3",75000,75000))))))) -> 420000 | J28: V.TÂN | K28: =IF(G28="DTDB",300000,IF(G28="TTDB",300000,IF(G28="DT1",135000,IF(G28="TT1",135000,IF(G28="DT2",75000,IF(G28="TT2",75000,IF(G28="DT3",45000,45000))))))) -> 300000 | L28: NGUYÊN | M28: =IF(L28="-",0,IF(G28="DTDB",300000,IF(G28="TTDB",300000,IF(G28="DT1",135000,IF(G28="TT1",135000,IF(G28="DT2",75000,IF(G28="TT2",75000,IF(G28="DT3",45000,45000)))))))) -> 300000 | N28: =I28+K28+M28 -> 1020000
A29: 22 | B29: 11/9/2025 | C29: Nguyễn Thị Tuyết Mai | E29: 70 | F29: KHX trên màn hình tăng sáng | G29: TTDB | H29: V.TÂN | I29: =IF(G29="DTDB",420000,IF(G29="TTDB",420000,IF(G29="DT1",187500,IF(G29="TT1",187500,IF(G29="DT2",97500,IF(G29="TT2",97500,IF(G29="DT3",75000,75000))))))) -> 420000 | J29: TUẤN | K29: =IF(G29="DTDB",300000,IF(G29="TTDB",300000,IF(G29="DT1",135000,IF(G29="TT1",135000,IF(G29="DT2",75000,IF(G29="TT2",75000,IF(G29="DT3",45000,45000))))))) -> 300000 | L29: HẬU | M29: =IF(L29="-",0,IF(G29="DTDB",300000,IF(G29="TTDB",300000,IF(G29="DT1",135000,IF(G29="TT1",135000,IF(G29="DT2",75000,IF(G29="TT2",75000,IF(G29="DT3",45000,45000)))))))) -> 300000 | N29: =I29+K29+M29 -> 1020000
A30: 23 | B30: 11/9/2025 | C30: Trần Hoàng Thanh | D30: 34 | F30: KHX trên màn hình tăng sáng | G30: TTDB | H30: NGUYỆN | I30: =IF(G30="DTDB",420000,IF(G30="TTDB",420000,IF(G30="DT1",187500,IF(G30="TT1",187500,IF(G30="DT2",97500,IF(G30="TT2",97500,IF(G30="DT3",75000,75000))))))) -> 420000 | J30: TOẢN | K30: =IF(G30="DTDB",300000,IF(G30="TTDB",300000,IF(G30="DT1",135000,IF(G30="TT1",135000,IF(G30="DT2",75000,IF(G30="TT2",75000,IF(G30="DT3",45000,45000))))))) -> 300000 | L30: Q.TẤN | M30: =IF(L30="-",0,IF(G30="DTDB",300000,IF(G30="TTDB",300000,IF(G30="DT1",135000,IF(G30="TT1",135000,IF(G30="DT2",75000,IF(G30="TT2",75000,IF(G30="DT3",45000,45000)))))))) -> 300000 | N30: =I30+K30+M30 -> 1020000
A31: 24 | B31: 12/9/2025 | C31: Lê Thị Sáu | E31: 72 | F31: Tạo hình thân đốt sống bằng bơm cement sinh học có bóng | G31: TTDB | H31: NGUYỆN | I31: =IF(G31="DTDB",420000,IF(G31="TTDB",420000,IF(G31="DT1",187500,IF(G31="TT1",187500,IF(G31="DT2",97500,IF(G31="TT2",97500,IF(G31="DT3",75000,75000))))))) -> 420000 | J31: TOẢN | K31: =IF(G31="DTDB",300000,IF(G31="TTDB",300000,IF(G31="DT1",135000,IF(G31="TT1",135000,IF(G31="DT2",75000,IF(G31="TT2",75000,IF(G31="DT3",45000,45000))))))) -> 300000 | L31: Q.TẤN | M31: =IF(L31="-",0,IF(G31="DTDB",300000,IF(G31="TTDB",300000,IF(G31="DT1",135000,IF(G31="TT1",135000,IF(G31="DT2",75000,IF(G31="TT2",75000,IF(G31="DT3",45000,45000)))))))) -> 300000 | N31: =I31+K31+M31 -> 1020000
A32: 25 | B32: 12/9/2025 | C32: Lê Minh Thùy Trang | E32: 44 | F32: PTNS cắt sụn chêm | G32: TT1 | H32: TOẢN | I32: =IF(G32="DTDB",420000,IF(G32="TTDB",420000,IF(G32="DT1",187500,IF(G32="TT1",187500,IF(G32="DT2",97500,IF(G32="TT2",97500,IF(G32="DT3",75000,75000))))))) -> 187500 | J32: TUẤN | K32: =IF(G32="DTDB",300000,IF(G32="TTDB",300000,IF(G32="DT1",135000,IF(G32="TT1",135000,IF(G32="DT2",75000,IF(G32="TT2",75000,IF(G32="DT3",45000,45000))))))) -> 135000 | L32: KIỆT | M32: =IF(L32="-",0,IF(G32="DTDB",300000,IF(G32="TTDB",300000,IF(G32="DT1",135000,IF(G32="TT1",135000,IF(G32="DT2",75000,IF(G32="TT2",75000,IF(G32="DT3",45000,45000)))))))) -> 135000 | N32: =I32+K32+M32 -> 457500
A33: 26 | B33: 12/9/2025 | C33: Trần Hữu Nghị | D33: 40 | F33: PTNS khâu chóp xoay | G33: TTDB | H33: TOẢN | I33: =IF(G33="DTDB",420000,IF(G33="TTDB",420000,IF(G33="DT1",187500,IF(G33="TT1",187500,IF(G33="DT2",97500,IF(G33="TT2",97500,IF(G33="DT3",75000,75000))))))) -> 420000 | J33: VINH | K33: =IF(G33="DTDB",300000,IF(G33="TTDB",300000,IF(G33="DT1",135000,IF(G33="TT1",135000,IF(G33="DT2",75000,IF(G33="TT2",75000,IF(G33="DT3",45000,45000))))))) -> 300000 | L33: LỢI | M33: =IF(L33="-",0,IF(G33="DTDB",300000,IF(G33="TTDB",300000,IF(G33="DT1",135000,IF(G33="TT1",135000,IF(G33="DT2",75000,IF(G33="TT2",75000,IF(G33="DT3",45000,45000)))))))) -> 300000 | N33: =I33+K33+M33 -> 1020000
A34: 27 | B34: 13/9/2025 | C34: Nguyễn Thị Yến | E34: 72 | F34: PT thay toàn bộ khớp háng | G34: TTDB | H34: HOAN | I34: =IF(G34="DTDB",420000,IF(G34="TTDB",420000,IF(G34="DT1",187500,IF(G34="TT1",187500,IF(G34="DT2",97500,IF(G34="TT2",97500,IF(G34="DT3",75000,75000))))))) -> 420000 | J34: ĐIỀN | K34: =IF(G34="DTDB",300000,IF(G34="TTDB",300000,IF(G34="DT1",135000,IF(G34="TT1",135000,IF(G34="DT2",75000,IF(G34="TT2",75000,IF(G34="DT3",45000,45000))))))) -> 300000 | L34: LỢI | M34: =IF(L34="-",0,IF(G34="DTDB",300000,IF(G34="TTDB",300000,IF(G34="DT1",135000,IF(G34="TT1",135000,IF(G34="DT2",75000,IF(G34="TT2",75000,IF(G34="DT3",45000,45000)))))))) -> 300000 | N34: =I34+K34+M34 -> 1020000
A35: 28 | B35: 13/9/2025 | C35: Nguyễn Thị Yến | E35: 72 | F35: KHX trên màn hình tăng sáng (50%) | G35: DTDB | H35: HOAN | I35: =IF(G35="DTDB",420000,IF(G35="TTDB",420000,IF(G35="DT1",187500,IF(G35="TT1",187500,IF(G35="DT2",97500,IF(G35="TT2",97500,IF(G35="DT3",75000,75000))))))) -> 420000 | J35: ĐIỀN | K35: =IF(G35="DTDB",300000,IF(G35="TTDB",300000,IF(G35="DT1",135000,IF(G35="TT1",135000,IF(G35="DT2",75000,IF(G35="TT2",75000,IF(G35="DT3",45000,45000))))))) -> 300000 | L35: THANH | M35: =IF(L35="-",0,IF(G35="DTDB",300000,IF(G35="TTDB",300000,IF(G35="DT1",135000,IF(G35="TT1",135000,IF(G35="DT2",75000,IF(G35="TT2",75000,IF(G35="DT3",45000,45000)))))))) -> 300000 | N35: =I35+K35+M35 -> 1020000
A36: 29 | B36: 15/9/2025 | C36: Trần Văn Cáo | D36: 63 | F36: Cố định cột sống | G36: TTDB | H36: HOAN | I36: =IF(G36="DTDB",420000,IF(G36="TTDB",420000,IF(G36="DT1",187500,IF(G36="TT1",187500,IF(G36="DT2",97500,IF(G36="TT2",97500,IF(G36="DT3",75000,75000))))))) -> 420000 | J36: NGUYỆN | K36: =IF(G36="DTDB",300000,IF(G36="TTDB",300000,IF(G36="DT1",135000,IF(G36="TT1",135000,IF(G36="DT2",75000,IF(G36="TT2",75000,IF(G36="DT3",45000,45000))))))) -> 300000 | L36: TUẤN | M36: =IF(L36="-",0,IF(G36="DTDB",300000,IF(G36="TTDB",300000,IF(G36="DT1",135000,IF(G36="TT1",135000,IF(G36="DT2",75000,IF(G36="TT2",75000,IF(G36="DT3",45000,45000)))))))) -> 300000 | N36: =I36+K36+M36 -> 1020000
A37: 30 | B37: 15/9/2025 | C37: Nguyễn Thị Xương | E37: 60 | F37: Cố định cột sống | G37: TTDB | H37: HOAN | I37: =IF(G37="DTDB",420000,IF(G37="TTDB",420000,IF(G37="DT1",187500,IF(G37="TT1",187500,IF(G37="DT2",97500,IF(G37="TT2",97500,IF(G37="DT3",75000,75000))))))) -> 420000 | J37: NGUYỆN | K37: =IF(G37="DTDB",300000,IF(G37="TTDB",300000,IF(G37="DT1",135000,IF(G37="TT1",135000,IF(G37="DT2",75000,IF(G37="TT2",75000,IF(G37="DT3",45000,45000))))))) -> 300000 | L37: TUẤN | M37: =IF(L37="-",0,IF(G37="DTDB",300000,IF(G37="TTDB",300000,IF(G37="DT1",135000,IF(G37="TT1",135000,IF(G37="DT2",75000,IF(G37="TT2",75000,IF(G37="DT3",45000,45000)))))))) -> 300000 | N37: =I37+K37+M37 -> 1020000
A38: 31 | B38: 16/9/2025 | C38: Nguyễn Thị Bé | E38: 84 | F38: Thay khớp háng bán phần | G38: TT1 | H38: NGUYỆN | I38: =IF(G38="DTDB",420000,IF(G38="TTDB",420000,IF(G38="DT1",187500,IF(G38="TT1",187500,IF(G38="DT2",97500,IF(G38="TT2",97500,IF(G38="DT3",75000,75000))))))) -> 187500 | J38: TOẢN | K38: =IF(G38="DTDB",300000,IF(G38="TTDB",300000,IF(G38="DT1",135000,IF(G38="TT1",135000,IF(G38="DT2",75000,IF(G38="TT2",75000,IF(G38="DT3",45000,45000))))))) -> 135000 | L38: TUẤN | M38: =IF(L38="-",0,IF(G38="DTDB",300000,IF(G38="TTDB",300000,IF(G38="DT1",135000,IF(G38="TT1",135000,IF(G38="DT2",75000,IF(G38="TT2",75000,IF(G38="DT3",45000,45000)))))))) -> 135000 | N38: =I38+K38+M38 -> 457500
A39: 32 | B39: 17/9/2025 | C39: Nguyễn Văn Tấn | D39: 59 | F39: PT thay toàn bộ khớp háng | G39: TTDB | H39: TRIỀU | I39: =IF(G39="DTDB",420000,IF(G39="TTDB",420000,IF(G39="DT1",187500,IF(G39="TT1",187500,IF(G39="DT2",97500,IF(G39="TT2",97500,IF(G39="DT3",75000,75000))))))) -> 420000 | J39: HOAN | K39: =IF(G39="DTDB",300000,IF(G39="TTDB",300000,IF(G39="DT1",135000,IF(G39="TT1",135000,IF(G39="DT2",75000,IF(G39="TT2",75000,IF(G39="DT3",45000,45000))))))) -> 300000 | L39: ĐỨC | M39: =IF(L39="-",0,IF(G39="DTDB",300000,IF(G39="TTDB",300000,IF(G39="DT1",135000,IF(G39="TT1",135000,IF(G39="DT2",75000,IF(G39="TT2",75000,IF(G39="DT3",45000,45000)))))))) -> 300000 | N39: =I39+K39+M39 -> 1020000
A40: 33 | B40: 17/9/2025 | C40: Lương Thu Vân | E40: 74 | F40: PT thay toàn bộ khớp gối | G40: TTDB | H40: TẤN | I40: =IF(G40="DTDB",420000,IF(G40="TTDB",420000,IF(G40="DT1",187500,IF(G40="TT1",187500,IF(G40="DT2",97500,IF(G40="TT2",97500,IF(G40="DT3",75000,75000))))))) -> 420000 | J40: HOAN | K40: =IF(G40="DTDB",300000,IF(G40="TTDB",300000,IF(G40="DT1",135000,IF(G40="TT1",135000,IF(G40="DT2",75000,IF(G40="TT2",75000,IF(G40="DT3",45000,45000))))))) -> 300000 | L40: NGUYỆN | M40: =IF(L40="-",0,IF(G40="DTDB",300000,IF(G40="TTDB",300000,IF(G40="DT1",135000,IF(G40="TT1",135000,IF(G40="DT2",75000,IF(G40="TT2",75000,IF(G40="DT3",45000,45000)))))))) -> 300000 | N40: =I40+K40+M40 -> 1020000
A41: 34 | B41: 17/9/2025 | C41: Nguyễn Thị Dân | E41: 77 | F41: PT KHX trên màn hình tăng sáng | G41: DTDB | H41: NGUYỆN | I41: =IF(G41="DTDB",420000,IF(G41="TTDB",420000,IF(G41="DT1",187500,IF(G41="TT1",187500,IF(G41="DT2",97500,IF(G41="TT2",97500,IF(G41="DT3",75000,75000))))))) -> 420000 | J41: ĐỨC | K41: =IF(G41="DTDB",300000,IF(G41="TTDB",300000,IF(G41="DT1",135000,IF(G41="TT1",135000,IF(G41="DT2",75000,IF(G41="TT2",75000,IF(G41="DT3",45000,45000))))))) -> 300000 | L41: THANH | M41: =IF(L41="-",0,IF(G41="DTDB",300000,IF(G41="TTDB",300000,IF(G41="DT1",135000,IF(G41="TT1",135000,IF(G41="DT2",75000,IF(G41="TT2",75000,IF(G41="DT3",45000,45000)))))))) -> 300000 | N41: =I41+K41+M41 -> 1020000
A42: 35 | B42: 18/9/2025 | C42: Phạm Thanh Hùng | D42: 47 | F42: KHX trên màn hình tăng sáng | G42: DTDB | H42: NGUYỆN | I42: =IF(G42="DTDB",420000,IF(G42="TTDB",420000,IF(G42="DT1",187500,IF(G42="TT1",187500,IF(G42="DT2",97500,IF(G42="TT2",97500,IF(G42="DT3",75000,75000))))))) -> 420000 | J42: TUẤN | K42: =IF(G42="DTDB",300000,IF(G42="TTDB",300000,IF(G42="DT1",135000,IF(G42="TT1",135000,IF(G42="DT2",75000,IF(G42="TT2",75000,IF(G42="DT3",45000,45000))))))) -> 300000 | L42: ĐỨC | M42: =IF(L42="-",0,IF(G42="DTDB",300000,IF(G42="TTDB",300000,IF(G42="DT1",135000,IF(G42="TT1",135000,IF(G42="DT2",75000,IF(G42="TT2",75000,IF(G42="DT3",45000,45000)))))))) -> 300000 | N42: =I42+K42+M42 -> 1020000
...

Sheet lanh tien PT_BHYT
A1: BV TRƯỜNG ĐHYD CẦN THƠ
A2: KHOA NGOẠI CTCH-TK
A3: DANH SÁCH LÃNH TIỀN THÙ LAO THÁNG 9/2025
A4: (BHYT)
A6: STT | B6: HỌ TÊN | C6: CHỨC VỤ | D6: SỐ TÀI KHOẢN | E6: SỐ TIỀN | F6: Thuế 10%
A7: 1 | B7: Phạm Việt Triều | C7: Bác sĩ | D7: 102006610216 | E7: =SUM(SUMIF(phauthuat_BHYT!$H$8:$H$93,"TRIỀU",phauthuat_BHYT!$I$8:$I$93),SUMIF(phauthuat_BHYT!$J$8:$J$93,"TRIỀU",phauthuat_BHYT!$K$8:$K$93),SUMIF(phauthuat_BHYT!$L$8:$L$93,"TRIỀU",phauthuat_BHYT!$M$8:$M$93)) -> 840000
A8: 2 | B8: Nguyễn Thành Tấn | C8: Bác sĩ | D8: 103006610215 | E8: =SUM(SUMIF(phauthuat_BHYT!$H$8:$H$93,"TẤN",phauthuat_BHYT!$I$8:$I$93),SUMIF(phauthuat_BHYT!$J$8:$J$93,"TẤN",phauthuat_BHYT!$K$8:$K$93),SUMIF(phauthuat_BHYT!$L$8:$L$93,"TẤN",phauthuat_BHYT!$M$8:$M$93)) -> 420000
A9: 3 | B9: Nguyễn Lê Hoan | C9: Bác sĩ | D9: 100006610218 | E9: =SUM(SUMIF(phauthuat_BHYT!$H$8:$H$93,"HOAN",phauthuat_BHYT!$I$8:$I$93),SUMIF(phauthuat_BHYT!$J$8:$J$93,"HOAN",phauthuat_BHYT!$K$8:$K$93),SUMIF(phauthuat_BHYT!$L$8:$L$93,"HOAN",phauthuat_BHYT!$M$8:$M$93)) -> 7860000
A10: 4 | B10: Nguyễn Chí Nguyện | C10: Bác sĩ | D10: 105001159195 | E10: =SUM(SUMIF(phauthuat_BHYT!$H$8:$H$93,"NGUYỆN",phauthuat_BHYT!$I$8:$I$93),SUMIF(phauthuat_BHYT!$J$8:$J$93,"NGUYỆN",phauthuat_BHYT!$K$8:$K$93),SUMIF(phauthuat_BHYT!$L$8:$L$93,"NGUYỆN",phauthuat_BHYT!$M$8:$M$93)) -> 9390000
A11: 5 | B11: Hồ Điền | C11: Bác sĩ | D11: 105001225232 | E11: =SUM(SUMIF(phauthuat_BHYT!$H$8:$H$93,"ĐIỀN",phauthuat_BHYT!$I$8:$I$93),SUMIF(phauthuat_BHYT!$J$8:$J$93,"ĐIỀN",phauthuat_BHYT!$K$8:$K$93),SUMIF(phauthuat_BHYT!$L$8:$L$93,"ĐIỀN",phauthuat_BHYT!$M$8:$M$93)) -> 4507500
A12: 6 | B12: Trần Quốc Toản | C12: Bác sĩ | D12: 107868829237 | E12: =SUM(SUMIF(phauthuat_BHYT!$H$8:$H$93,"TOẢN",phauthuat_BHYT!$I$8:$I$93),SUMIF(phauthuat_BHYT!$J$8:$J$93,"TOẢN",phauthuat_BHYT!$K$8:$K$93),SUMIF(phauthuat_BHYT!$L$8:$L$93,"TOẢN",phauthuat_BHYT!$M$8:$M$93)) -> 5415000
A13: 7 | B13: Phạm Việt Tân | C13: Bác sĩ | D13: 104000362303 | E13: =SUM(SUMIF(phauthuat_BHYT!$H$8:$H$93,"v.tân",phauthuat_BHYT!$I$8:$I$93),SUMIF(phauthuat_BHYT!$J$8:$J$93,"v.tân",phauthuat_BHYT!$K$8:$K$93),SUMIF(phauthuat_BHYT!$L$8:$L$93,"v.tân",phauthuat_BHYT!$M$8:$M$93)) -> 3855000
A14: 8 | B14: Phan Văn Tuấn | C14: Bác sĩ | D14: 105872433048 | E14: =SUM(SUMIF(phauthuat_BHYT!$H$8:$H$93,"TUẤN",phauthuat_BHYT!$I$8:$I$93),SUMIF(phauthuat_BHYT!$J$8:$J$93,"TUẤN",phauthuat_BHYT!$K$8:$K$93),SUMIF(phauthuat_BHYT!$L$8:$L$93,"TUẤN",phauthuat_BHYT!$M$8:$M$93)) -> 5355000
A15: 9 | B15: Trần Quang Sơn | C15: Bác sĩ | D15: 107004193662 | E15: =SUM(SUMIF(phauthuat_BHYT!$H$8:$H$93,"sơn",phauthuat_BHYT!$I$8:$I$93),SUMIF(phauthuat_BHYT!$J$8:$J$93,"sơn",phauthuat_BHYT!$K$8:$K$93),SUMIF(phauthuat_BHYT!$L$8:$L$93,"sơn",phauthuat_BHYT!$M$8:$M$93)) -> 0
A16: 10 | B16: Điều Tấn Kiệt | C16: Bác sĩ (nt) | D16: 105883051352 | E16: =SUM(SUMIF(phauthuat_BHYT!$H$8:$H$93,"kiệt",phauthuat_BHYT!$I$8:$I$93),SUMIF(phauthuat_BHYT!$J$8:$J$93,"kiệt",phauthuat_BHYT!$K$8:$K$93),SUMIF(phauthuat_BHYT!$L$8:$L$93,"kiệt",phauthuat_BHYT!$M$8:$M$93)) -> 1080000
A17: 11 | B17: Nguyễn Lê Duy Phong | C17: Bác sĩ (nt) | E17: =SUM(SUMIF(phauthuat_BHYT!$H$8:$H$93,"phong",phauthuat_BHYT!$I$8:$I$93),SUMIF(phauthuat_BHYT!$J$8:$J$93,"phong",phauthuat_BHYT!$K$8:$K$93),SUMIF(phauthuat_BHYT!$L$8:$L$93,"phong",phauthuat_BHYT!$M$8:$M$93)) -> 300000
A18: 12 | B18: Trương Đại Lợi | C18: Bác sĩ (nt) | E18: =SUM(SUMIF(phauthuat_BHYT!$H$8:$H$93,"lợi",phauthuat_BHYT!$I$8:$I$93),SUMIF(phauthuat_BHYT!$J$8:$J$93,"lợi",phauthuat_BHYT!$K$8:$K$93),SUMIF(phauthuat_BHYT!$L$8:$L$93,"lợi",phauthuat_BHYT!$M$8:$M$93)) -> 810000
A19: 13 | B19: Nguyễn Chí Thanh | C19: Bác sĩ (nt) | E19: =SUM(SUMIF(phauthuat_BHYT!$H$8:$H$93,"thanh",phauthuat_BHYT!$I$8:$I$93),SUMIF(phauthuat_BHYT!$J$8:$J$93,"thanh",phauthuat_BHYT!$K$8:$K$93),SUMIF(phauthuat_BHYT!$L$8:$L$93,"thanh",phauthuat_BHYT!$M$8:$M$93)) -> 1020000
A20: 14 | B20: Nguyễn Trần Khánh Đan | C20: Bác sĩ (nt) | D20: 105880975165 | E20: =SUM(SUMIF(phauthuat_BHYT!$H$8:$H$93,"ĐAN",phauthuat_BHYT!$I$8:$I$93),SUMIF(phauthuat_BHYT!$J$8:$J$93,"ĐAN",phauthuat_BHYT!$K$8:$K$93),SUMIF(phauthuat_BHYT!$L$8:$L$93,"ĐAN",phauthuat_BHYT!$M$8:$M$93)) -> 945000
A21: 15 | B21: Phạm Công Hậu | C21: Bác sĩ (nt) | D21: 102879258199 | E21: =SUM(SUMIF(phauthuat_BHYT!$H$8:$H$93,"HẬU",phauthuat_BHYT!$I$8:$I$93),SUMIF(phauthuat_BHYT!$J$8:$J$93,"HẬU",phauthuat_BHYT!$K$8:$K$93),SUMIF(phauthuat_BHYT!$L$8:$L$93,"HẬU",phauthuat_BHYT!$M$8:$M$93)) -> 1320000
A22: 16 | B22: Trang Gia Vinh | C22: Bác sĩ (nt) | D22: 109880991105 | E22: =SUM(SUMIF(phauthuat_BHYT!$H$8:$H$93,"VINH",phauthuat_BHYT!$I$8:$I$93),SUMIF(phauthuat_BHYT!$J$8:$J$93,"VINH",phauthuat_BHYT!$K$8:$K$93),SUMIF(phauthuat_BHYT!$L$8:$L$93,"VINH",phauthuat_BHYT!$M$8:$M$93)) -> 1530000
A23: 17 | B23: Bùi Quan Tấn | C23: Bác sĩ (nt) | D23: 109881014321 | E23: =SUM(SUMIF(phauthuat_BHYT!$H$8:$H$93,"Q.TẤN",phauthuat_BHYT!$I$8:$I$93),SUMIF(phauthuat_BHYT!$J$8:$J$93,"Q.TẤN",phauthuat_BHYT!$K$8:$K$93),SUMIF(phauthuat_BHYT!$L$8:$L$93,"Q.TẤN",phauthuat_BHYT!$M$8:$M$93)) -> 1425000
A24: 18 | B24: Tào Nhật Hào | C24: Bác sĩ (nt) | D24: 102880994246 | E24: =SUM(SUMIF(phauthuat_BHYT!$H$8:$H$93,"HÀO",phauthuat_BHYT!$I$8:$I$93),SUMIF(phauthuat_BHYT!$J$8:$J$93,"HÀO",phauthuat_BHYT!$K$8:$K$93),SUMIF(phauthuat_BHYT!$L$8:$L$93,"HÀO",phauthuat_BHYT!$M$8:$M$93)) -> 360000
A25: 19 | B25: Huỳnh Phúc Nguyên | C25: Bác sĩ (nt) | D25: 100881016109 | E25: =SUM(SUMIF(phauthuat_BHYT!$H$8:$H$93,"NGUYÊN",phauthuat_BHYT!$I$8:$I$93),SUMIF(phauthuat_BHYT!$J$8:$J$93,"NGUYÊN",phauthuat_BHYT!$K$8:$K$93),SUMIF(phauthuat_BHYT!$L$8:$L$93,"NGUYÊN",phauthuat_BHYT!$M$8:$M$93)) -> 1335000
A26: 20 | B26: Nguyễn Văn Nghiêm | C26: Bác sĩ (nt) | D26: 108883113558 | E26: =SUM(SUMIF(phauthuat_BHYT!$H$8:$H$93,"NGHIÊM",phauthuat_BHYT!$I$8:$I$93),SUMIF(phauthuat_BHYT!$J$8:$J$93,"NGHIÊM",phauthuat_BHYT!$K$8:$K$93),SUMIF(phauthuat_BHYT!$L$8:$L$93,"NGHIÊM",phauthuat_BHYT!$M$8:$M$93)) -> 375000
A27: 21 | B27: Đỗ Thành Công | C27: Bác sĩ (nt) | D27: 109881609351 | E27: =SUM(SUMIF(phauthuat_BHYT!$H$8:$H$93,"CÔNG",phauthuat_BHYT!$I$8:$I$93),SUMIF(phauthuat_BHYT!$J$8:$J$93,"CÔNG",phauthuat_BHYT!$K$8:$K$93),SUMIF(phauthuat_BHYT!$L$8:$L$93,"CÔNG",phauthuat_BHYT!$M$8:$M$93)) -> 150000
A28: 22 | B28: Võ Ngọc Thiện | C28: Bác sĩ (nt) | D28: 102885267089 | E28: =SUM(SUMIF(phauthuat_BHYT!$H$8:$H$93,"THIỆN",phauthuat_BHYT!$I$8:$I$93),SUMIF(phauthuat_BHYT!$J$8:$J$93,"THIỆN",phauthuat_BHYT!$K$8:$K$93),SUMIF(phauthuat_BHYT!$L$8:$L$93,"THIỆN",phauthuat_BHYT!$M$8:$M$93)) -> 1425000
A29: 23 | B29: Nguyễn Hoài Linh | C29: Bác sĩ (nt) | E29: =SUM(SUMIF(phauthuat_BHYT!$H$8:$H$93,"LINH",phauthuat_BHYT!$I$8:$I$93),SUMIF(phauthuat_BHYT!$J$8:$J$93,"LINH",phauthuat_BHYT!$K$8:$K$93),SUMIF(phauthuat_BHYT!$L$8:$L$93,"LINH",phauthuat_BHYT!$M$8:$M$93)) -> 300000
A30: 24 | B30: Nguyễn Hoài Đức | C30: Bác sĩ (nt) | D30: 101883256042 | E30: =SUM(SUMIF(phauthuat_BHYT!$H$8:$H$93,"ĐỨC",phauthuat_BHYT!$I$8:$I$93),SUMIF(phauthuat_BHYT!$J$8:$J$93,"ĐỨC",phauthuat_BHYT!$K$8:$K$93),SUMIF(phauthuat_BHYT!$L$8:$L$93,"ĐỨC",phauthuat_BHYT!$M$8:$M$93)) -> 2235000
B31: TỔNG CỘNG | E31: =SUM(E7:E30) -> 52252500
D33: Cần Thơ, ngày 21 tháng 10 năm 2025
A34: Người lập bảng | D34: Trưởng khoa
A38: ĐD. Phan Văn Hiếu | D38: ThS.Bs.CKII. Nguyễn Lê Hoan

Sheet Thực lãnh
A1: BV TRƯỜNG ĐHYD CẦN THƠ
A2: KHOA NGOẠI CTCH-TK
A3: DANH SÁCH LÃNH TIỀN THÙ LAO THÁNG 9/2025
A4: (BHYT)
A6: STT | B6: HỌ TÊN | C6: CHỨC VỤ | D6: SỐ TÀI KHOẢN | E6: SỐ TIỀN | F6: SỐ TIỀN | G6: KÝ NHẬN
A7: 1 | B7: Phạm Việt Triều | C7: Bác sĩ | D7: 102006610216 | E7: =SUM(SUMIF(phauthuat_BHYT!$H$8:$H$93,"TRIỀU",phauthuat_BHYT!$I$8:$I$93),SUMIF(phauthuat_BHYT!$J$8:$J$93,"TRIỀU",phauthuat_BHYT!$K$8:$K$93),SUMIF(phauthuat_BHYT!$L$8:$L$93,"TRIỀU",phauthuat_BHYT!$M$8:$M$93)) -> 840000 | F7: =E7 -> 840000
A8: 2 | B8: Nguyễn Thành Tấn | C8: Bác sĩ | D8: 103006610215 | E8: =SUM(SUMIF(phauthuat_BHYT!$H$8:$H$93,"TẤN",phauthuat_BHYT!$I$8:$I$93),SUMIF(phauthuat_BHYT!$J$8:$J$93,"TẤN",phauthuat_BHYT!$K$8:$K$93),SUMIF(phauthuat_BHYT!$L$8:$L$93,"TẤN",phauthuat_BHYT!$M$8:$M$93)) -> 420000 | F8: =E8 -> 420000
A9: 3 | B9: Nguyễn Lê Hoan | C9: Bác sĩ | D9: 100006610218 | E9: =SUM(SUMIF(phauthuat_BHYT!$H$8:$H$93,"HOAN",phauthuat_BHYT!$I$8:$I$93),SUMIF(phauthuat_BHYT!$J$8:$J$93,"HOAN",phauthuat_BHYT!$K$8:$K$93),SUMIF(phauthuat_BHYT!$L$8:$L$93,"HOAN",phauthuat_BHYT!$M$8:$M$93)) -> 7860000 | F9: =E9+I27 -> 14460000
A10: 4 | B10: Nguyễn Chí Nguyện | C10: Bác sĩ | D10: 105001159195 | E10: =SUM(SUMIF(phauthuat_BHYT!$H$8:$H$93,"NGUYỆN",phauthuat_BHYT!$I$8:$I$93),SUMIF(phauthuat_BHYT!$J$8:$J$93,"NGUYỆN",phauthuat_BHYT!$K$8:$K$93),SUMIF(phauthuat_BHYT!$L$8:$L$93,"NGUYỆN",phauthuat_BHYT!$M$8:$M$93)) -> 9390000 | F10: =E10 -> 9390000
A11: 5 | B11: Hồ Điền | C11: Bác sĩ | D11: 105001225232 | E11: =SUM(SUMIF(phauthuat_BHYT!$H$8:$H$93,"ĐIỀN",phauthuat_BHYT!$I$8:$I$93),SUMIF(phauthuat_BHYT!$J$8:$J$93,"ĐIỀN",phauthuat_BHYT!$K$8:$K$93),SUMIF(phauthuat_BHYT!$L$8:$L$93,"ĐIỀN",phauthuat_BHYT!$M$8:$M$93)) -> 4507500 | F11: =E11+I17 -> 9982500
A12: 6 | B12: Trần Quốc Toản | C12: Bác sĩ | D12: 107868829237 | E12: =SUM(SUMIF(phauthuat_BHYT!$H$8:$H$93,"TOẢN",phauthuat_BHYT!$I$8:$I$93),SUMIF(phauthuat_BHYT!$J$8:$J$93,"TOẢN",phauthuat_BHYT!$K$8:$K$93),SUMIF(phauthuat_BHYT!$L$8:$L$93,"TOẢN",phauthuat_BHYT!$M$8:$M$93)) -> 5415000 | F12: =E12 -> 5415000
A13: 7 | B13: Đặng Phước Giàu | C13: Bác sĩ | D13: 105867664283 | E13: =SUM(SUMIF(phauthuat_BHYT!$H$8:$H$93,"giàu",phauthuat_BHYT!$I$8:$I$93),SUMIF(phauthuat_BHYT!$J$8:$J$93,"giàu",phauthuat_BHYT!$K$8:$K$93),SUMIF(phauthuat_BHYT!$L$8:$L$93,"giàu",phauthuat_BHYT!$M$8:$M$93)) -> 0 | F13: =E13+I22 -> 0
A14: 8 | B14: Phạm Việt Tân | C14: Bác sĩ | D14: 104000362303 | F14: ='lanh tien PT_BHYT'!E13+I29 -> 6390000
A15: 10 | B15: Phan Văn Tuấn | C15: Bác sĩ | D15: 105872433048 | F15: ='lanh tien PT_BHYT'!E14 -> 5355000
A16: 11 | B16: Trần Quang Sơn | C16: Bác sĩ | D16: 107004193662 | F16: ='lanh tien PT_BHYT'!E15 -> 0
A17: 12 | B17: Võ Dương Thành Thái | C17: Bác sĩ (nt) | H17: BS.ĐIỀN | I17: =SUM('lanh tien PT_BHYT'!E16:E21) -> 5475000
A18: 13 | B18: Văn Minh Khén | C18: Bác sĩ (nt)
A19: 14 | B19: Nguyễn Đông Khang | C19: Bác sĩ (nt)
A20: 15 | B20: Nguyễn Đình Luật | C20: Bác sĩ (nt)
A21: 16 | B21: Lê Nhỉ Khang | C21: Bác sĩ (nt)
A22: 17 | B22: Phạm Văn Hưởng | C22: Bác sĩ (nt)
A23: 18 | B23: Trần Trung Nghĩa | C23: Bác sĩ (nt)
A24: 19 | B24: Nguyễn Trung Nhị | C24: Bác sĩ (nt)
A25: 20 | B25: Nguyễn Trần Khánh Đan | C25: Bác sĩ (nt)
A26: 21 | B26: Phạm Công Hậu | C26: Bác sĩ (nt)
A27: 22 | B27: Trang Gia Vinh | C27: Bác sĩ (nt) | H27: BS.HOAN | I27: =SUM('lanh tien PT_BHYT'!E22:E28) -> 6600000
A28: 23 | B28: Bùi Quan Tấn | C28: Bác sĩ (nt)
A29: 24 | B29: Tào Nhật Hào | C29: Bác sĩ (nt) | H29: BS.TÂN | I29: =SUM('lanh tien PT_BHYT'!E29:E30) -> 2535000
A30: 25 | B30: Huỳnh Phúc Nguyên | C30: Bác sĩ (nt)
B31: TỔNG CỘNG | E31: =SUM(E7:E15) -> 28432500 | F31: =SUM(F7:F22) -> 52252500
