Workbook

Sheet phauthuat
A1: BV TRƯỜNG ĐHYD CẦN THƠ
A2: KHOA NGOẠI CTCH - TK
A3: BẢNG KÊ TIỀN PHẪU THUẬT
A4: (THÁNG 1/2025)
A6: STT | B6: Ngày | C6: Họ Tên | D6: Nam | E6: Nữ | F6: Phương pháp phẫu thuật | G6: Loại PT | H6: Giá Phẫu thuật thực tính | I6: PTV chính | J6: Số tiền | K6: Phụ mổ 1 | L6: Số tiền | M6: Phụ mổ 2 | N6: Số tiền | O6: Phụ mổ 3 | P6: Số tiền | Q6: ĐD + HL | R6: Thực lãnh
A7: 1 | B7: 11/12/2024 | C7: Thái Duyệt Hiền | E7: 42 | F7: Cắt lọc hoại tử ổ loét vết thương mãn tính | G7: TT2 | H7: 2128200 | I7: V.TÂN | J7: =R7-L7-N7-P7-Q7 -> 175576.5 | K7: TUẤN | L7: =IF(K7="-",0,H7*0.03) -> 63846 | M7: KHÁNH | N7: =IF(M7="-",0,H7*0.02) -> 42564 | O7: - | P7: =IF(O7="-",0,H7*0.01) -> 0 | Q7: =H7*0.005 -> 10641 | R7: =IF(I7="V.Tân",H7*0.1375,IF(I7="nguyện",H7*0.1375,IF(I7="TOẢN",H7*0.1375,H7*0.17))) -> 292627.5
A8: 2 | B8: 24/12/2024 | C8: Nguyễn Văn Thoàng | D8: 63 | F8: Cắt lọc hoại tử ổ loét vết thương mãn tính | G8: TT2 | H8: 2127400 | I8: V.TÂN | J8: =R8-L8-N8-P8-Q8 -> 154236.5 | K8: TUẤN | L8: =IF(K8="-",0,H8*0.03) -> 63822 | M8: LUẬN | N8: =IF(M8="-",0,H8*0.02) -> 42548 | O8: THẠNH | P8: =IF(O8="-",0,H8*0.01) -> 21274 | Q8: =H8*0.005 -> 10637 | R8: =IF(I8="V.Tân",H8*0.1375,IF(I8="nguyện",H8*0.1375,IF(I8="TOẢN",H8*0.1375,H8*0.17))) -> 292517.5
A9: 3 | B9: 24/12/2024 | C9: Thạch Thị Phẹnh | E9: 61 | F9: Cắt lọc hoại tử ổ loét vết thương mãn tính | G9: TT2 | H9: 2128200 | I9: GIÀU | J9: =R9-L9-N9-P9-Q9 -> 223461 | K9: TOÀN | L9: =IF(K9="-",0,H9*0.03) -> 63846 | M9: DƯƠNG | N9: =IF(M9="-",0,H9*0.02) -> 42564 | O9: ẨN | P9: =IF(O9="-",0,H9*0.01) -> 21282 | Q9: =H9*0.005 -> 10641 | R9: =IF(I9="V.Tân",H9*0.1375,IF(I9="nguyện",H9*0.1375,IF(I9="TOẢN",H9*0.1375,H9*0.17))) -> 361794
A10: 4 | B10: 25/12/2024 | C10: Nguyễn Hoàng Du | D10: 42 | F10: Cắt lọc ổ loét mạn | G10: TT2 | H10: 2128200 | I10: V.TÂN | J10: =R10-L10-N10-P10-Q10 -> 154294.5 | K10: TUẤN | L10: =IF(K10="-",0,H10*0.03) -> 63846 | M10: HƯỞNG | N10: =IF(M10="-",0,H10*0.02) -> 42564 | O10: TÙNG | P10: =IF(O10="-",0,H10*0.01) -> 21282 | Q10: =H10*0.005 -> 10641 | R10: =IF(I10="V.Tân",H10*0.1375,IF(I10="nguyện",H10*0.1375,IF(I10="TOẢN",H10*0.1375,H10*0.17))) -> 292627.5
A11: 5 | B11: 25/12/2024 | C11: Mã Nguyên Sang | D11: 43 | F11: PTNS tái tạo dây chằng chéo sau | G11: TTDB | H11: 3405500 | I11: TRIỀU | J11: =R11-L11-N11-P11-Q11 -> 357577.5 | K11: TOẢN | L11: =IF(K11="-",0,H11*0.03) -> 102165 | M11: LUẬN | N11: =IF(M11="-",0,H11*0.02) -> 68110 | O11: KHANG | P11: =IF(O11="-",0,H11*0.01) -> 34055 | Q11: =H11*0.005 -> 17027.5 | R11: =IF(I11="V.Tân",H11*0.1375,IF(I11="nguyện",H11*0.1375,IF(I11="TOẢN",H11*0.1375,H11*0.17))) -> 578935
A12: 6 | B12: 27/12/2024 | C12: TRẦN VĂN PHỤNG | D12: 54 | F12: Thay khớp háng toàn phần | G12: TTDB | H12: 3525500 | I12: HOAN | J12: =R12-L12-N12-P12-Q12 -> 370177.5 | K12: NGUYỆN | L12: =IF(K12="-",0,H12*0.03) -> 105765 | M12: TUẤN | N12: =IF(M12="-",0,H12*0.02) -> 70510 | O12: TOÀN | P12: =IF(O12="-",0,H12*0.01) -> 35255 | Q12: =H12*0.005 -> 17627.5 | R12: =IF(I12="V.Tân",H12*0.1375,IF(I12="nguyện",H12*0.1375,IF(I12="TOẢN",H12*0.1375,H12*0.17))) -> 599335
A13: 7 | B13: 27/12/2024 | C13: Nguyễn Văn Chính | D13: 55 | F13: Thay khớp háng toàn phần | G13: TTDB | H13: 3525500 | I13: HOAN | J13: =R13-L13-N13-P13-Q13 -> 370177.5 | K13: NGUYỆN | L13: =IF(K13="-",0,H13*0.03) -> 105765 | M13: TUẤN | N13: =IF(M13="-",0,H13*0.02) -> 70510 | O13: TOÀN | P13: =IF(O13="-",0,H13*0.01) -> 35255 | Q13: =H13*0.005 -> 17627.5 | R13: =IF(I13="V.Tân",H13*0.1375,IF(I13="nguyện",H13*0.1375,IF(I13="TOẢN",H13*0.1375,H13*0.17))) -> 599335
A14: 8 | B14: 27/12/2024 | C14: Trần Chí Nguyện | D14: 54 | F14: Thay khớp háng toàn phần | G14: TTDB | H14: 3525500 | I14: HOAN | J14: =R14-L14-N14-P14-Q14 -> 370177.5 | K14: NGUYỆN | L14: =IF(K14="-",0,H14*0.03) -> 105765 | M14: TUẤN | N14: =IF(M14="-",0,H14*0.02) -> 70510 | O14: TOÀN | P14: =IF(O14="-",0,H14*0.01) -> 35255 | Q14: =H14*0.005 -> 17627.5 | R14: =IF(I14="V.Tân",H14*0.1375,IF(I14="nguyện",H14*0.1375,IF(I14="TOẢN",H14*0.1375,H14*0.17))) -> 599335
A15: 9 | B15: 30/12/2024 | C15: Lê Văn Đồng | D15: 77 | F15: PT thay khớp háng bán phần | G15: TT1 | H15: 3897500 | I15: NGUYỆN | J15: =R15-L15-N15-P15-Q15 -> 282568.75 | K15: ĐIỀN | L15: =IF(K15="-",0,H15*0.03) -> 116925 | M15: TOẢN | N15: =IF(M15="-",0,H15*0.02) -> 77950 | O15: HƯNG | P15: =IF(O15="-",0,H15*0.01) -> 38975 | Q15: =H15*0.005 -> 19487.5 | R15: =IF(I15="V.Tân",H15*0.1375,IF(I15="nguyện",H15*0.1375,IF(I15="TOẢN",H15*0.1375,H15*0.17))) -> 535906.25
A16: 10 | B16: 30/12/2024 | C16: La Quang Đạo | D16: 38 | F16: PT KHX trên màn hình tăng sáng | G16: TP | H16: 9972000 | I16: TOẢN | J16: =R16-L16-N16-P16-Q16 -> 722970 | K16: NGUYỆN | L16: =IF(K16="-",0,H16*0.03) -> 299160 | M16: LUẬN | N16: =IF(M16="-",0,H16*0.02) -> 199440 | O16: HƯỞNG | P16: =IF(O16="-",0,H16*0.01) -> 99720 | Q16: =H16*0.005 -> 49860 | R16: =IF(I16="V.Tân",H16*0.1375,IF(I16="nguyện",H16*0.1375,IF(I16="TOẢN",H16*0.1375,H16*0.17))) -> 1371150
A17: 11 | B17: 30/12/2024 | C17: Võ Thị Lòng | E17: 78 | F17: Cắt lọc hoại tử ổ loét vết thương mãn tính | G17: TT2 | H17: 2127400 | I17: NGUYỆN | J17: =R17-L17-N17-P17-Q17 -> 154236.5 | K17: ĐIỀN | L17: =IF(K17="-",0,H17*0.03) -> 63822 | M17: THÁI | N17: =IF(M17="-",0,H17*0.02) -> 42548 | O17: KHÉN | P17: =IF(O17="-",0,H17*0.01) -> 21274 | Q17: =H17*0.005 -> 10637 | R17: =IF(I17="V.Tân",H17*0.1375,IF(I17="nguyện",H17*0.1375,IF(I17="TOẢN",H17*0.1375,H17*0.17))) -> 292517.5
A18: 12 | B18: 30/12/2024 | C18: Nguyễn Lê Vũ Luân | D18: 22 | F18: Cắt u xương sụn | G18: TT2 | H18: 2496100 | I18: NGUYỆN | J18: =R18-L18-N18-P18-Q18 -> 180967.25 | K18: HƯNG | L18: =IF(K18="-",0,H18*0.03) -> 74883 | M18: TÙNG | N18: =IF(M18="-",0,H18*0.02) -> 49922 | O18: LUẬT | P18: =IF(O18="-",0,H18*0.01) -> 24961 | Q18: =H18*0.005 -> 12480.5 | R18: =IF(I18="V.Tân",H18*0.1375,IF(I18="nguyện",H18*0.1375,IF(I18="TOẢN",H18*0.1375,H18*0.17))) -> 343213.75
A19: 13 | B19: 31/12/2024 | C19: Cao Minh Lý | D19: 62 | F19: Lấy DC KHX | G19: TT2 | H19: 2559100 | I19: V.TÂN | J19: =R19-L19-N19-P19-Q19 -> 185534.75 | K19: HƯNG | L19: =IF(K19="-",0,H19*0.03) -> 76773 | M19: KHÉN | N19: =IF(M19="-",0,H19*0.02) -> 51182 | O19: LUẬT | P19: =IF(O19="-",0,H19*0.01) -> 25591 | Q19: =H19*0.005 -> 12795.5 | R19: =IF(I19="V.Tân",H19*0.1375,IF(I19="nguyện",H19*0.1375,IF(I19="TOẢN",H19*0.1375,H19*0.17))) -> 351876.25
A20: 14 | B20: 01/01/2025 | C20: Giáp Thành Trung | D20: 50 | F20: Khâu gân duỗi | G20: TP | H20: 5302000 | I20: TOẢN | J20: =R20-L20-N20-P20-Q20 -> 384395 | K20: LUẬN | L20: =IF(K20="-",0,H20*0.03) -> 159060 | M20: KHANG | N20: =IF(M20="-",0,H20*0.02) -> 106040 | O20: ẨN | P20: =IF(O20="-",0,H20*0.01) -> 53020 | Q20: =H20*0.005 -> 26510 | R20: =IF(I20="V.Tân",H20*0.1375,IF(I20="nguyện",H20*0.1375,IF(I20="TOẢN",H20*0.1375,H20*0.17))) -> 729025
A21: 15 | B21: 02/01/2025 | C21: Đặng Thị Ra | E21: 69 | F21: KHX trên màn hình tăng sáng | G21: TTDB | H21: 4497500 | I21: NGUYỆN | J21: =R21-L21-N21-P21-Q21 -> 326068.75 | K21: TOẢN | L21: =IF(K21="-",0,H21*0.03) -> 134925 | M21: TUẤN | N21: =IF(M21="-",0,H21*0.02) -> 89950 | O21: TOÀN | P21: =IF(O21="-",0,H21*0.01) -> 44975 | Q21: =H21*0.005 -> 22487.5 | R21: =IF(I21="V.Tân",H21*0.1375,IF(I21="nguyện",H21*0.1375,IF(I21="TOẢN",H21*0.1375,H21*0.17))) -> 618406.25
A22: 16 | B22: 03/01/2025 | C22: Đỗ Văn Pheo | D22: 63 | F22: PT KHX tăng sáng | G22: TTDB | H22: 4497500 | I22: V.TÂN | J22: =R22-L22-N22-P22-Q22 -> 326068.75 | K22: TUẤN | L22: =IF(K22="-",0,H22*0.03) -> 134925 | M22: TOÀN | N22: =IF(M22="-",0,H22*0.02) -> 89950 | O22: HƯỞNG | P22: =IF(O22="-",0,H22*0.01) -> 44975 | Q22: =H22*0.005 -> 22487.5 | R22: =IF(I22="V.Tân",H22*0.1375,IF(I22="nguyện",H22*0.1375,IF(I22="TOẢN",H22*0.1375,H22*0.17))) -> 618406.25
A23: 17 | B23: 03/01/2025 | C23: Lê Trung Vinh | D23: 26 | F23: PT KHX gãy đài quay | G23: TT2 | H23: 2897500 | I23: NGUYỆN | J23: =R23-L23-N23-P23-Q23 -> 210068.75 | K23: TUẤN | L23: =IF(K23="-",0,H23*0.03) -> 86925 | M23: TOÀN | N23: =IF(M23="-",0,H23*0.02) -> 57950 | O23: KHANG | P23: =IF(O23="-",0,H23*0.01) -> 28975 | Q23: =H23*0.005 -> 14487.5 | R23: =IF(I23="V.Tân",H23*0.1375,IF(I23="nguyện",H23*0.1375,IF(I23="TOẢN",H23*0.1375,H23*0.17))) -> 398406.25
A24: 18 | B24: 03/01/2025 | C24: Hà Minh Huy | D24: 61 | F24: KHX trên màn hình tăng sáng | G24: TTDB | H24: 4497500 | I24: HOAN | J24: =R24-L24-N24-P24-Q24 -> 472237.5 | K24: TOẢN | L24: =IF(K24="-",0,H24*0.03) -> 134925 | M24: TUẤN | N24: =IF(M24="-",0,H24*0.02) -> 89950 | O24: TOÀN | P24: =IF(O24="-",0,H24*0.01) -> 44975 | Q24: =H24*0.005 -> 22487.5 | R24: =IF(I24="V.Tân",H24*0.1375,IF(I24="nguyện",H24*0.1375,IF(I24="TOẢN",H24*0.1375,H24*0.17))) -> 764575
A25: 19 | B25: 03/01/2025 | C25: Đỗ Văn Hiền | D25: 72 | F25: Cắt lọc hoại tử ổ loét vết thương mạn tính | G25: TT2 | H25: 2128200 | I25: ĐIỀN | J25: =R25-L25-N25-P25-Q25 -> 223461 | K25: LUẬN | L25: =IF(K25="-",0,H25*0.03) -> 63846 | M25: KHÉN | N25: =IF(M25="-",0,H25*0.02) -> 42564 | O25: TÙNG | P25: =IF(O25="-",0,H25*0.01) -> 21282 | Q25: =H25*0.005 -> 10641 | R25: =IF(I25="V.Tân",H25*0.1375,IF(I25="nguyện",H25*0.1375,IF(I25="TOẢN",H25*0.1375,H25*0.17))) -> 361794
A26: 20 | B26: 03/01/2025 | C26: Thạch Thị Phẹnh | E26: 62 | F26: Cắt lọc hoại tử ổ loét vết thương mạn tính | G26: TT2 | H26: 2128200 | I26: ĐIỀN | J26: =R26-L26-N26-P26-Q26 -> 223461 | K26: LUẬN | L26: =IF(K26="-",0,H26*0.03) -> 63846 | M26: KHÉN | N26: =IF(M26="-",0,H26*0.02) -> 42564 | O26: TÙNG | P26: =IF(O26="-",0,H26*0.01) -> 21282 | Q26: =H26*0.005 -> 10641 | R26: =IF(I26="V.Tân",H26*0.1375,IF(I26="nguyện",H26*0.1375,IF(I26="TOẢN",H26*0.1375,H26*0.17))) -> 361794
A27: 21 | B27: 03/01/2025 | C27: Nguyễn Thị Trinh | E27: 40 | F27: PTNS cắt hoạt mạc viêm khớp gối | G27: TT1 | H27: 3397500 | I27: HOAN | J27: =R27-L27-N27-P27-Q27 -> 356737.5 | K27: TOẢN | L27: =IF(K27="-",0,H27*0.03) -> 101925 | M27: TUẤN | N27: =IF(M27="-",0,H27*0.02) -> 67950 | O27: TOÀN | P27: =IF(O27="-",0,H27*0.01) -> 33975 | Q27: =H27*0.005 -> 16987.5 | R27: =IF(I27="V.Tân",H27*0.1375,IF(I27="nguyện",H27*0.1375,IF(I27="TOẢN",H27*0.1375,H27*0.17))) -> 577575
A28: 22 | B28: 04/01/2025 | C28: Mã Thanh Xà | E28: 88 | F28: PT thay khớp háng bán phần | G28: TT1 | H28: 3897500 | I28: HOAN | J28: =R28-L28-N28-P28-Q28 -> 409237.5 | K28: NGUYỆN | L28: =IF(K28="-",0,H28*0.03) -> 116925 | M28: ĐIỀN | N28: =IF(M28="-",0,H28*0.02) -> 77950 | O28: TUẤN | P28: =IF(O28="-",0,H28*0.01) -> 38975 | Q28: =H28*0.005 -> 19487.5 | R28: =IF(I28="V.Tân",H28*0.1375,IF(I28="nguyện",H28*0.1375,IF(I28="TOẢN",H28*0.1375,H28*0.17))) -> 662575
A29: 23 | B29: 04/01/2025 | C29: Nguyễn Văn Đời | D29: 84 | F29: PT vết thương phần mềm phức tạp | G29: TT1 | H29: 796000 | I29: ĐIỀN | J29: =R29-L29-N29-P29-Q29 -> 91540 | K29: TUẤN | L29: =IF(K29="-",0,H29*0.03) -> 23880 | M29: KHÁNH | N29: =IF(M29="-",0,H29*0.02) -> 15920 | O29: - | P29: =IF(O29="-",0,H29*0.01) -> 0 | Q29: =H29*0.005 -> 3980 | R29: =IF(I29="V.Tân",H29*0.1375,IF(I29="nguyện",H29*0.1375,IF(I29="TOẢN",H29*0.1375,H29*0.17))) -> 135320
A30: 24 | B30: 06/01/2025 | C30: Thái Thị Thanh Trúc | E30: 28 | F30: Lấy DC KHX | G30: TT2 | H30: 2559100 | I30: V.TÂN | J30: =R30-L30-N30-P30-Q30 -> 211125.75 | K30: HƯNG | L30: =IF(K30="-",0,H30*0.03) -> 76773 | M30: KHANG | N30: =IF(M30="-",0,H30*0.02) -> 51182 | O30: - | P30: =IF(O30="-",0,H30*0.01) -> 0 | Q30: =H30*0.005 -> 12795.5 | R30: =IF(I30="V.Tân",H30*0.1375,IF(I30="nguyện",H30*0.1375,IF(I30="TOẢN",H30*0.1375,H30*0.17))) -> 351876.25
A31: 25 | B31: 07/01/2025 | C31: Võ Thị Lòng | E31: 78 | F31: PT cắt đáy ổ loét mạn tính khâu kín | G31: TT2 | H31: 3127400 | I31: ĐIỀN | J31: =R31-L31-N31-P31-Q31 -> 359651 | K31: LUẬN | L31: =IF(K31="-",0,H31*0.03) -> 93822 | M31: KHÉN | N31: =IF(M31="-",0,H31*0.02) -> 62548 | O31: - | P31: =IF(O31="-",0,H31*0.01) -> 0 | Q31: =H31*0.005 -> 15637 | R31: =IF(I31="V.Tân",H31*0.1375,IF(I31="nguyện",H31*0.1375,IF(I31="TOẢN",H31*0.1375,H31*0.17))) -> 531658
A32: 26 | B32: 07/01/2025 | C32: Nguyễn Văn Sáu | D32: 61 | F32: KHX trên màn hình tăng sáng | G32: TTDB | H32: 4497500 | I32: GIÀU | J32: =R32-L32-N32-P32-Q32 -> 472237.5 | K32: TUẤN | L32: =IF(K32="-",0,H32*0.03) -> 134925 | M32: HƯNG | N32: =IF(M32="-",0,H32*0.02) -> 89950 | O32: KHÉN | P32: =IF(O32="-",0,H32*0.01) -> 44975 | Q32: =H32*0.005 -> 22487.5 | R32: =IF(I32="V.Tân",H32*0.1375,IF(I32="nguyện",H32*0.1375,IF(I32="TOẢN",H32*0.1375,H32*0.17))) -> 764575
A33: 27 | B33: 07/01/2025 | C33: Trần Huệ Mẫn | E33: 17 | F33: KHX trên màn hình tăng sáng | G33: TTDB | H33: 4497500 | I33: NGUYỆN | J33: =R33-L33-N33-P33-Q33 -> 326068.75 | K33: TUẤN | L33: =IF(K33="-",0,H33*0.03) -> 134925 | M33: HƯNG | N33: =IF(M33="-",0,H33*0.02) -> 89950 | O33: KHÉN | P33: =IF(O33="-",0,H33*0.01) -> 44975 | Q33: =H33*0.005 -> 22487.5 | R33: =IF(I33="V.Tân",H33*0.1375,IF(I33="nguyện",H33*0.1375,IF(I33="TOẢN",H33*0.1375,H33*0.17))) -> 618406.25
A34: 28 | B34: 07/01/2025 | C34: Phó Châu Tuyền | D34: 30 | F34: KHX trên màn hình tăng sáng | G34: TP | H34: 9972000 | I34: HOAN | J34: =R34-L34-N34-P34-Q34 -> 1047060 | K34: TUẤN | L34: =IF(K34="-",0,H34*0.03) -> 299160 | M34: TOÀN | N34: =IF(M34="-",0,H34*0.02) -> 199440 | O34: KHANG | P34: =IF(O34="-",0,H34*0.01) -> 99720 | Q34: =H34*0.005 -> 49860 | R34: =IF(I34="V.Tân",H34*0.1375,IF(I34="nguyện",H34*0.1375,IF(I34="TOẢN",H34*0.1375,H34*0.17))) -> 1695240
A35: 29 | B35: 08/01/2025 | C35: Huỳnh Thị Yến | E35: 74 | F35: PT thay khớp háng toàn bộ | G35: TTDB | H35: 3525500 | I35: HOAN | J35: =R35-L35-N35-P35-Q35 -> 370177.5 | K35: V.TÂN | L35: =IF(K35="-",0,H35*0.03) -> 105765 | M35: TUẤN | N35: =IF(M35="-",0,H35*0.02) -> 70510 | O35: HƯNG | P35: =IF(O35="-",0,H35*0.01) -> 35255 | Q35: =H35*0.005 -> 17627.5 | R35: =IF(I35="V.Tân",H35*0.1375,IF(I35="nguyện",H35*0.1375,IF(I35="TOẢN",H35*0.1375,H35*0.17))) -> 599335
A36: 30 | B36: 08/01/2025 | C36: Lê Văn Đạt | D36: 84 | F36: PT khớp háng bán phần | G36: TT1 | H36: 3897500 | I36: HOAN | J36: =R36-L36-N36-P36-Q36 -> 409237.5 | K36: TUẤN | L36: =IF(K36="-",0,H36*0.03) -> 116925 | M36: HƯNG | N36: =IF(M36="-",0,H36*0.02) -> 77950 | O36: KHÉN | P36: =IF(O36="-",0,H36*0.01) -> 38975 | Q36: =H36*0.005 -> 19487.5 | R36: =IF(I36="V.Tân",H36*0.1375,IF(I36="nguyện",H36*0.1375,IF(I36="TOẢN",H36*0.1375,H36*0.17))) -> 662575
A37: 31 | B37: 08/01/2025 | C37: Lâm Hó Văn | D37: 87 | F37: PT thay khớp háng bán phần | G37: TP | H37: 8000000 | I37: NGUYỆN | J37: =R37-L37-N37-P37-Q37 -> 580000 | K37: TOẢN | L37: =IF(K37="-",0,H37*0.03) -> 240000 | M37: TUẤN | N37: =IF(M37="-",0,H37*0.02) -> 160000 | O37: TOÀN | P37: =IF(O37="-",0,H37*0.01) -> 80000 | Q37: =H37*0.005 -> 40000 | R37: =IF(I37="V.Tân",H37*0.1375,IF(I37="nguyện",H37*0.1375,IF(I37="TOẢN",H37*0.1375,H37*0.17))) -> 1100000
A38: 32 | B38: 08/01/2025 | C38: Nguyễn Duy | D38: 42 | F38: Lấy dụng cụ KHX | G38: TT2 | H38: 2559100 | I38: NGUYỆN | J38: =R38-L38-N38-P38-Q38 -> 185534.75 | K38: TUẤN | L38: =IF(K38="-",0,H38*0.03) -> 76773 | M38: LUẬN | N38: =IF(M38="-",0,H38*0.02) -> 51182 | O38: HƯỞNG | P38: =IF(O38="-",0,H38*0.01) -> 25591 | Q38: =H38*0.005 -> 12795.5 | R38: =IF(I38="V.Tân",H38*0.1375,IF(I38="nguyện",H38*0.1375,IF(I38="TOẢN",H38*0.1375,H38*0.17))) -> 351876.25
A39: 33 | B39: 08/01/2025 | C39: Hoàng Thị Thanh Thúy | E39: 22 | F39: PTNS tái tạo dây chằng | G39: TTDB | H39: 3405500 | I39: GIÀU | J39: =R39-L39-N39-P39-Q39 -> 357577.5 | K39: TOẢN | L39: =IF(K39="-",0,H39*0.03) -> 102165 | M39: HƯNG | N39: =IF(M39="-",0,H39*0.02) -> 68110 | O39: KHANG | P39: =IF(O39="-",0,H39*0.01) -> 34055 | Q39: =H39*0.005 -> 17027.5 | R39: =IF(I39="V.Tân",H39*0.1375,IF(I39="nguyện",H39*0.1375,IF(I39="TOẢN",H39*0.1375,H39*0.17))) -> 578935
A40: 34 | B40: 09/01/2025 | C40: Nguyễn Thị Khéo | E40: 75 | F40: KHX trên màn hình tăng sáng | G40: TTDB | H40: 4497500 | I40: NGUYỆN | J40: =R40-L40-N40-P40-Q40 -> 326068.75 | K40: TOẢN | L40: =IF(K40="-",0,H40*0.03) -> 134925 | M40: TUẤN | N40: =IF(M40="-",0,H40*0.02) -> 89950 | O40: TÙNG | P40: =IF(O40="-",0,H40*0.01) -> 44975 | Q40: =H40*0.005 -> 22487.5 | R40: =IF(I40="V.Tân",H40*0.1375,IF(I40="nguyện",H40*0.1375,IF(I40="TOẢN",H40*0.1375,H40*0.17))) -> 618406.25
A41: 35 | B41: 10/01/2025 | C41: Trần Thị Tư | E41: 80 | F41: PT thay khớp háng bán phần | G41: TT1 | H41: 3897500 | I41: HOAN | J41: =R41-L41-N41-P41-Q41 -> 409237.5 | K41: NGUYỆN | L41: =IF(K41="-",0,H41*0.03) -> 116925 | M41: ĐIỀN | N41: =IF(M41="-",0,H41*0.02) -> 77950 | O41: TUẤN | P41: =IF(O41="-",0,H41*0.01) -> 38975 | Q41: =H41*0.005 -> 19487.5 | R41: =IF(I41="V.Tân",H41*0.1375,IF(I41="nguyện",H41*0.1375,IF(I41="TOẢN",H41*0.1375,H41*0.17))) -> 662575
...

Sheet lanh tien PT
A1: BV TRƯỜNG ĐHYD CẦN THƠ
A2: KHOA NGOẠI CTCH-TK
B3: DANH SÁCH LÃNH TIỀN THÙ LAO THÁNG 1/2025
C4: (Phẫu thuật)
A6: STT | B6: HỌ TÊN | C6: chức vụ | D6: SỐ TIỀN | E6: KÝ NHẬN
A7: 1 | B7: Phạm Việt Triều | C7: Bác sĩ | D7: =SUM(SUMIF(phauthuat!$I$7:$I$73,"TRIỀU",phauthuat!$J$7:$J$73),SUMIF(phauthuat!$K$7:$K$73,"TRIỀU",phauthuat!$L$7:$L$73),SUMIF(phauthuat!$M$7:$M$73,"TRIỀU",phauthuat!$N$7:$N$73),SUMIF(phauthuat!$O$7:$O$73,"TRIỀU",phauthuat!$P$7:$P$73)) -> 357577.5
A8: 2 | B8: Nguyễn Thành Tấn | C8: Bác sĩ | D8: =SUM(SUMIF(phauthuat!$I$7:$I$73,"TẤN",phauthuat!$J$7:$J$73),SUMIF(phauthuat!$K$7:$K$73,"TẤN",phauthuat!$L$7:$L$73),SUMIF(phauthuat!$M$7:$M$73,"TẤN",phauthuat!$N$7:$N$73),SUMIF(phauthuat!$O$7:$O$73,"TẤN",phauthuat!$P$7:$P$73)) -> 626283
A9: 3 | B9: Nguyễn Lê Hoan | C9: Bác sĩ | D9: =SUM(SUMIF(phauthuat!$I$7:$I$73,"HOAN",phauthuat!$J$7:$J$73),SUMIF(phauthuat!$K$7:$K$73,"HOAN",phauthuat!$L$7:$L$73),SUMIF(phauthuat!$M$7:$M$73,"HOAN",phauthuat!$N$7:$N$73),SUMIF(phauthuat!$O$7:$O$73,"TẤN",phauthuat!$P$7:$P$73)) -> 5465932.5
A10: 4 | B10: Nguyễn Chí Nguyện | C10: Bác sĩ | D10: =SUM(SUMIF(phauthuat!$I$7:$I$73,"NGUYỆN",phauthuat!$J$7:$J$73),SUMIF(phauthuat!$K$7:$K$73,"NGUYỆN",phauthuat!$L$7:$L$73),SUMIF(phauthuat!$M$7:$M$73,"NGUYỆN",phauthuat!$N$7:$N$73),SUMIF(phauthuat!$O$7:$O$73,"NGUYỆN",phauthuat!$P$7:$P$73)) -> 5855972
A11: 5 | B11: Đặng Phước Giàu | C11: Bác sĩ | D11: =SUM(SUMIF(phauthuat!$I$7:$I$73,"GIÀU",phauthuat!$J$7:$J$73),SUMIF(phauthuat!$K$7:$K$73,"GIÀU",phauthuat!$L$7:$L$73),SUMIF(phauthuat!$M$7:$M$73,"GIÀU",phauthuat!$N$7:$N$73),SUMIF(phauthuat!$O$7:$O$73,"GIÀU",phauthuat!$P$7:$P$73)) -> 3180691.5
A12: 6 | B12: Hồ Điền | C12: Bác sĩ | D12: =SUM(SUMIF(phauthuat!$I$7:$I$73,"ĐIỀN",phauthuat!$J$7:$J$73),SUMIF(phauthuat!$K$7:$K$73,"ĐIỀN",phauthuat!$L$7:$L$73),SUMIF(phauthuat!$M$7:$M$73,"ĐIỀN",phauthuat!$N$7:$N$73),SUMIF(phauthuat!$O$7:$O$73,"ĐIỀN",phauthuat!$P$7:$P$73)) -> 2660833.5
A13: 7 | B13: Trần Quốc Toản | C13: Bác sĩ | D13: =SUM(SUMIF(phauthuat!$I$7:$I$73,"TOẢN",phauthuat!$J$7:$J$73),SUMIF(phauthuat!$K$7:$K$73,"TOẢN",phauthuat!$L$7:$L$73),SUMIF(phauthuat!$M$7:$M$73,"TOẢN",phauthuat!$N$7:$N$73),SUMIF(phauthuat!$O$7:$O$73,"TOẢN",phauthuat!$P$7:$P$73)) -> 4653294.2
A14: 8 | B14: Phạm Việt Tân | C14: Bác sĩ | D14: =SUM(SUMIF(phauthuat!$I$7:$I$73,"V.TÂN",phauthuat!$J$7:$J$73),SUMIF(phauthuat!$K$7:$K$73,"V.TÂN",phauthuat!$L$7:$L$73),SUMIF(phauthuat!$M$7:$M$73,"V.TÂN",phauthuat!$N$7:$N$73),SUMIF(phauthuat!$O$7:$O$73,"V.TÂN",phauthuat!$P$7:$P$73)) -> 1758221.1
A15: 9 | B15: Bùi Công Minh | C15: Bác sĩ | D15: =SUM(SUMIF(phauthuat!$I$7:$I$73,"MINH",phauthuat!$J$7:$J$73),SUMIF(phauthuat!$K$7:$K$73,"MINH",phauthuat!$L$7:$L$73),SUMIF(phauthuat!$M$7:$M$73,"MINH",phauthuat!$N$7:$N$73),SUMIF(phauthuat!$O$7:$O$73,"MINH",phauthuat!$P$7:$P$73)) -> 881443.5
A16: 10 | B16: Phan Văn Tuấn | C16: Bác sĩ | D16: =SUM(SUMIF(phauthuat!$I$7:$I$73,"TUẤN",phauthuat!$J$7:$J$73),SUMIF(phauthuat!$K$7:$K$73,"Tuấn",phauthuat!$L$7:$L$73),SUMIF(phauthuat!$M$7:$M$73,"TUẤN",phauthuat!$N$7:$N$73),SUMIF(phauthuat!$O$7:$O$73,"TUẤN",phauthuat!$P$7:$P$73)) -> 3615463
A17: 11 | B17: Huỳnh Quốc Hưng | C17: Bác sĩ (nt) | D17: =SUM(SUMIF(phauthuat!$I$7:$I$73,"hưng",phauthuat!$J$7:$J$73),SUMIF(phauthuat!$K$7:$K$73,"hưng",phauthuat!$L$7:$L$73),SUMIF(phauthuat!$M$7:$M$73,"hưng",phauthuat!$N$7:$N$73),SUMIF(phauthuat!$O$7:$O$73,"hưng",phauthuat!$P$7:$P$73)) -> 1126579
A18: 12 | B18: Võ Văn Phúc Toàn | C18: Bác sĩ (nt) | D18: =SUM(SUMIF(phauthuat!$I$7:$I$73,"toàn",phauthuat!$J$7:$J$73),SUMIF(phauthuat!$K$7:$K$73,"toàn",phauthuat!$L$7:$L$73),SUMIF(phauthuat!$M$7:$M$73,"toàn",phauthuat!$N$7:$N$73),SUMIF(phauthuat!$O$7:$O$73,"toàn",phauthuat!$P$7:$P$73)) -> 1053571
A19: 13 | B19: Võ Minh Luận | C19: Bác sĩ (nt) | D19: =SUM(SUMIF(phauthuat!$I$7:$I$73,"luận",phauthuat!$J$7:$J$73),SUMIF(phauthuat!$K$7:$K$73,"luận",phauthuat!$L$7:$L$73),SUMIF(phauthuat!$M$7:$M$73,"luận",phauthuat!$N$7:$N$73),SUMIF(phauthuat!$O$7:$O$73,"luận",phauthuat!$P$7:$P$73)) -> 876779
A20: 14 | B20: Võ Dương Thành Thái | C20: Bác sĩ (nt) | D20: =SUM(SUMIF(phauthuat!$I$7:$I$73,"thái",phauthuat!$J$7:$J$73),SUMIF(phauthuat!$K$7:$K$73,"thái",phauthuat!$L$7:$L$73),SUMIF(phauthuat!$M$7:$M$73,"thái",phauthuat!$N$7:$N$73),SUMIF(phauthuat!$O$7:$O$73,"thái",phauthuat!$P$7:$P$73)) -> 305383
A21: 15 | B21: Lê Đình Tùng | C21: Bác sĩ (nt) | D21: =SUM(SUMIF(phauthuat!$I$7:$I$73,"tùng",phauthuat!$J$7:$J$73),SUMIF(phauthuat!$K$7:$K$73,"tùng",phauthuat!$L$7:$L$73),SUMIF(phauthuat!$M$7:$M$73,"tùng",phauthuat!$N$7:$N$73),SUMIF(phauthuat!$O$7:$O$73,"tùng",phauthuat!$P$7:$P$73)) -> 1026382
A22: 16 | B22: Văn Minh Khén | C22: Bác sĩ (nt) | D22: =SUM(SUMIF(phauthuat!$I$7:$I$73,"khén",phauthuat!$J$7:$J$73),SUMIF(phauthuat!$K$7:$K$73,"khén",phauthuat!$L$7:$L$73),SUMIF(phauthuat!$M$7:$M$73,"khén",phauthuat!$N$7:$N$73),SUMIF(phauthuat!$O$7:$O$73,"khén",phauthuat!$P$7:$P$73)) -> 782506
A23: 17 | B23: Phạm Tấn Hưởng | C23: Bác sĩ (nt) | D23: =SUM(SUMIF(phauthuat!$I$7:$I$73,"hưởng",phauthuat!$J$7:$J$73),SUMIF(phauthuat!$K$7:$K$73,"hưởng",phauthuat!$L$7:$L$73),SUMIF(phauthuat!$M$7:$M$73,"hưởng",phauthuat!$N$7:$N$73),SUMIF(phauthuat!$O$7:$O$73,"hưởng",phauthuat!$P$7:$P$73)) -> 212850
A24: 18 | B24: Nguyễn Đông Khang | C24: Bác sĩ (nt) | D24: =SUM(SUMIF(phauthuat!$I$7:$I$73,"khang",phauthuat!$J$7:$J$73),SUMIF(phauthuat!$K$7:$K$73,"khang",phauthuat!$L$7:$L$73),SUMIF(phauthuat!$M$7:$M$73,"khang",phauthuat!$N$7:$N$73),SUMIF(phauthuat!$O$7:$O$73,"khang",phauthuat!$P$7:$P$73)) -> 651965
A25: 19 | B25: Nguyễn Đình Luật | C25: Bác sĩ (nt) | D25: =SUM(SUMIF(phauthuat!$I$7:$I$73,"luật",phauthuat!$J$7:$J$73),SUMIF(phauthuat!$K$7:$K$73,"luật",phauthuat!$L$7:$L$73),SUMIF(phauthuat!$M$7:$M$73,"luật",phauthuat!$N$7:$N$73),SUMIF(phauthuat!$O$7:$O$73,"luật",phauthuat!$P$7:$P$73)) -> 341159.5
A26: 20 | B26: Võ Long Ẩn | C26: Bác sĩ (nt) | D26: =SUM(SUMIF(phauthuat!$I$7:$I$73,"ẩn",phauthuat!$J$7:$J$73),SUMIF(phauthuat!$K$7:$K$73,"ẩn",phauthuat!$L$7:$L$73),SUMIF(phauthuat!$M$7:$M$73,"ẩn",phauthuat!$N$7:$N$73),SUMIF(phauthuat!$O$7:$O$73,"ẩn",phauthuat!$P$7:$P$73)) -> 410344
A27: 21 | B27: Nguyễn Xuân Bình | C27: Bác sĩ (nt) | D27: =SUM(SUMIF(phauthuat!$I$7:$I$73,"bình",phauthuat!$J$7:$J$73),SUMIF(phauthuat!$K$7:$K$73,"bình",phauthuat!$L$7:$L$73),SUMIF(phauthuat!$M$7:$M$73,"bình",phauthuat!$N$7:$N$73),SUMIF(phauthuat!$O$7:$O$73,"bình",phauthuat!$P$7:$P$73)) -> 26971
A28: 22 | B28: Phan Doãn Đại Dương | C28: Bác sĩ (nt) | D28: =SUM(SUMIF(phauthuat!$I$7:$I$73,"dương",phauthuat!$J$7:$J$73),SUMIF(phauthuat!$K$7:$K$73,"dương",phauthuat!$L$7:$L$73),SUMIF(phauthuat!$M$7:$M$73,"dương",phauthuat!$N$7:$N$73),SUMIF(phauthuat!$O$7:$O$73,"dương",phauthuat!$P$7:$P$73)) -> 50524
A29: 23 | B29: Lê Quốc Khánh | C29: Bác sĩ (nt) | D29: =SUM(SUMIF(phauthuat!$I$7:$I$73,"khánh",phauthuat!$J$7:$J$73),SUMIF(phauthuat!$K$7:$K$73,"khánh",phauthuat!$L$7:$L$73),SUMIF(phauthuat!$M$7:$M$73,"khánh",phauthuat!$N$7:$N$73),SUMIF(phauthuat!$O$7:$O$73,"khánh",phauthuat!$P$7:$P$73)) -> 237968
A30: 24 | B30: Lê Cường Thạnh | C30: Bác sĩ (nt) | D30: =SUM(SUMIF(phauthuat!$I$7:$I$73,"thạnh",phauthuat!$J$7:$J$73),SUMIF(phauthuat!$K$7:$K$73,"thạnh",phauthuat!$L$7:$L$73),SUMIF(phauthuat!$M$7:$M$73,"thạnh",phauthuat!$N$7:$N$73),SUMIF(phauthuat!$O$7:$O$73,"thạnh",phauthuat!$P$7:$P$73)) -> 128954
A31: 25 | B31: Phan Văn Hiếu | C31: Điều dưỡng | D31: =phauthuat!Q71/8 -> 152918.16
A32: 26 | B32: Võ Thị Yến Nhi | C32: Điều dưỡng | D32: =D31 -> 152918.16
A33: 27 | B33: Võ Phương Duy | C33: Điều dưỡng | D33: =D32 -> 152918.16
A34: 28 | B34: Nguyễn Kim Ngân | C34: Điều dưỡng | D34: =D33 -> 152918.16
A35: 29 | B35: Lê Ngọc Diệu | C35: Điều dưỡng | D35: =D34 -> 152918.16
A36: 30 | B36: Trần Quỳnh Minh Thư | C36: Điều dưỡng | D36: =D35 -> 152918.16
A37: 31 | B37: Lê Thị Tuyết Đoan | C37: Điều dưỡng | D37: =D36 -> 152918.16
A38: 32 | B38: Thạch Thị Thúy Đa | C38: Điều dưỡng | D38: =D37 -> 152918.16
B39: TỔNG CỘNG | D39: =SUM(D7:D38) -> 37510993
D41: Cần Thơ, ngày 18 tháng 2 năm 2025
A42: Người lập bảng | D42: Trưởng khoa

Sheet Bác sĩ điều trị
A1: BV TRƯỜNG ĐHYD CẦN THƠ
A2: KHOA NGOẠI CTCH-TK
A3: DANH SÁCH LÃNH TIỀN THÙ LAO THÁNG 1/2025
A4: (BÁC SĨ ĐIỀU TRỊ)
A6: STT | B6: HỌ TÊN | C6: chức vụ | D6: SỐ TIỀN | E6: KÝ NHẬN
A7: 1 | B7: Phạm Việt Triều | C7: Bác sĩ | D7: -
A8: 2 | B8: Nguyễn Thành Tấn | C8: Bác sĩ | D8: -
A9: 3 | B9: Nguyễn Lê Hoan | C9: Bác sĩ | D9: =10800000*0.25 -> 2700000
A10: 4 | B10: Trần Quang Sơn | C10: Bác sĩ | D10: -
A11: 5 | B11: Nguyễn Chí Nguyện | C11: Bác sĩ | D11: -
A12: 6 | B12: Bùi Công Minh | C12: Bác sĩ | D12: -
A13: 7 | B13: Hồ Điền | C13: Bác sĩ | D13: =10800000*0.25 -> 2700000
A14: 8 | B14: Phạm Việt Tân | C14: Bác sĩ | D14: =10800000*0.0625 -> 675000
A15: 9 | B15: Đặng Phước Giàu | C15: Bác sĩ | D15: =10800000*0.125 -> 1350000
A16: 10 | B16: Trần Quốc Toản | C16: Bác sĩ | D16: =10800000*0.0625 -> 675000
A17: 11 | B17: Nguyễn Hữu Đạt | C17: Bác sĩ | D17: =10800000*0.125 -> 1350000
A18: 12 | B18: Nguyễn Giang Tử | C18: Bác sĩ | D18: =10800000*0.125 -> 1350000
B19: TỔNG CỘNG | D19: =SUM(D7:D18) -> 10800000
D21: Cần Thơ, ngày 22 tháng 02 năm 2024
A22: Người lập bảng | D22: Trưởng khoa

Sheet lanh tien PT1
A1: BV TRƯỜNG ĐHYD CẦN THƠ
A2: KHOA NGOẠI CTCH-TK
B3: DANH SÁCH LÃNH TIỀN THÙ LAO THÁNG 1/2025
C4: (Phẫu thuật)
A6: STT | B6: HỌ TÊN | C6: chức vụ | D6: SỐ TIỀN | E6: KÝ NHẬN
A7: 1 | B7: Phạm Việt Triều | C7: Bác sĩ | D7: -
A8: 2 | B8: Nguyễn Thành Tấn | C8: Bác sĩ | D8: -
A9: 3 | B9: Lê Dũng | C9: Bác sĩ | D9: -
A10: 4 | B10: Nguyễn Lê Hoan | C10: Bác sĩ | D10: -
A11: 5 | B11: Nguyễn Tâm Từ | C11: Bác sĩ | D11: -
A12: 6 | B12: Hoàng Minh Tú | C12: Bác sĩ | D12: -
A13: 7 | B13: Nguyễn Hữu Thuyết | C13: Bác sĩ | D13: -
A14: 8 | B14: Nguyễn Thanh Huy | C14: Bác sĩ | D14: -
A15: 9 | B15: Trần Mạnh Dũng | C15: Bác sĩ | D15: -
A16: 10 | B16: Trần Quang Sơn | C16: Bác sĩ (nt) | D16: -
A17: 11 | B17: Lê Thế Hiển | C17: Bác sĩ (nt) | D17: -
A18: 12 | B18: Lê Minh Dương | C18: Bác sĩ (nt) | D18: -
G19: =2630565+152918+296444 -> 3079927
A20: 1 | B20: Phan Văn Hiếu | C20: Điều dưỡng | D20: =G22 -> 2898754.8 | G20: =G19*8 -> 24639416
A21: 2 | B21: Võ Thị Yến Nhi | C21: Điều dưỡng | D21: =G22 -> 2898754.8 | G21: =G20/17 -> 1449377.4
A22: 3 | B22: Nguyễn Kim Ngân | C22: Điều dưỡng | D22: =G22 -> 2898754.8 | G22: =G21*2 -> 2898754.8
A23: 4 | B23: Võ Phương Duy | C23: Điều dưỡng | D23: =G22 -> 2898754.8
A24: 5 | B24: Lê Ngọc Diệu | C24: Điều dưỡng | D24: =D22 -> 2898754.8
A25: 6 | B25: Trần Quỳnh Minh Thư | C25: Điều dưỡng | D25: =G22 -> 2898754.8
A26: 7 | B26: Lê Thị Tuyết Đoan | C26: Điều dưỡng | D26: =D25 -> 2898754.8
A27: 8 | B27: Thạch Thị Thúy Đa | C27: Điều dưỡng | D27: =D26 -> 2898754.8
A28: 9 | B28: Nguyễn Thị Như Ý | C28: Hộ Lí | D28: =G21+7+98951 -> 1548335.4
B29: TỔNG CỘNG | D29: =SUM(D20:D28) -> 24738374
D32: Cần Thơ, ngày 25 tháng 09 năm 2017
A33: Người lập bảng | D33: Trưởng khoa

Sheet phauthuat_BHYT
A1: BV TRƯỜNG ĐHYD CẦN THƠ
A2: KHOA NGOẠI CTCH-TK
B3: BẢNG KÊ TIỀN PHẪU THUẬT BHYT
A4: (THÁNG 1/2025)
A7: STT | B7: Ngày | C7: Họ và tên | D7: Nam | E7: Nữ | F7: Phương pháp phẫu thuật | G7: loại pt - đối tượng | H7: PTV chính | I7: Số tiền | J7: Phụ mổ 1 | K7: Số tiền | L7: Phụ mổ 2 | M7: Số tiền | N7: Tổng số tiền được lãnh sau trừ khấu hao
A8: 1 | B8: 25/12/2024 | C8: Mã Nguyên Sang | D8: 43 | F8: PTNS tái tạo dây chằng chéo sau | G8: TTDB | H8: TRIỀU | I8: =IF(G8="DTDB",420000,IF(G8="TTDB",420000,IF(G8="DT1",187500,IF(G8="TT1",187500,IF(G8="DT2",97500,IF(G8="TT2",97500,IF(G8="DT3",75000,75000))))))) -> 420000 | J8: TOẢN | K8: =IF(G8="DTDB",300000,IF(G8="TTDB",300000,IF(G8="DT1",135000,IF(G8="TT1",135000,IF(G8="DT2",75000,IF(G8="TT2",75000,IF(G8="DT3",45000,45000))))))) -> 300000 | L8: LUẬN | M8: =IF(L8="-",0,IF(G8="DTDB",300000,IF(G8="TTDB",300000,IF(G8="DT1",135000,IF(G8="TT1",135000,IF(G8="DT2",75000,IF(G8="TT2",75000,IF(G8="DT3",45000,45000)))))))) -> 300000 | N8: =I8+K8+M8 -> 1020000
A9: 2 | B9: 27/12/2024 | C9: TRẦN VĂN PHỤNG | D9: 54 | F9: Thay khớp háng toàn phần | G9: TTDB | H9: HOAN | I9: =IF(G9="DTDB",420000,IF(G9="TTDB",420000,IF(G9="DT1",187500,IF(G9="TT1",187500,IF(G9="DT2",97500,IF(G9="TT2",97500,IF(G9="DT3",75000,75000))))))) -> 420000 | J9: NGUYỆN | K9: =IF(G9="DTDB",300000,IF(G9="TTDB",300000,IF(G9="DT1",135000,IF(G9="TT1",135000,IF(G9="DT2",75000,IF(G9="TT2",75000,IF(G9="DT3",45000,45000))))))) -> 300000 | L9: TUẤN | M9: =IF(L9="-",0,IF(G9="DTDB",300000,IF(G9="TTDB",300000,IF(G9="DT1",135000,IF(G9="TT1",135000,IF(G9="DT2",75000,IF(G9="TT2",75000,IF(G9="DT3",45000,45000)))))))) -> 300000 | N9: =I9+K9+M9 -> 1020000
A10: 3 | B10: 27/12/2024 | C10: Nguyễn Văn Chính | D10: 55 | F10: Thay khớp háng toàn phần | G10: TTDB | H10: HOAN | I10: =IF(G10="DTDB",420000,IF(G10="TTDB",420000,IF(G10="DT1",187500,IF(G10="TT1",187500,IF(G10="DT2",97500,IF(G10="TT2",97500,IF(G10="DT3",75000,75000))))))) -> 420000 | J10: NGUYỆN | K10: =IF(G10="DTDB",300000,IF(G10="TTDB",300000,IF(G10="DT1",135000,IF(G10="TT1",135000,IF(G10="DT2",75000,IF(G10="TT2",75000,IF(G10="DT3",45000,45000))))))) -> 300000 | L10: TUẤN | M10: =IF(L10="-",0,IF(G10="DTDB",300000,IF(G10="TTDB",300000,IF(G10="DT1",135000,IF(G10="TT1",135000,IF(G10="DT2",75000,IF(G10="TT2",75000,IF(G10="DT3",45000,45000)))))))) -> 300000 | N10: =I10+K10+M10 -> 1020000
A11: 4 | B11: 27/12/2024 | C11: Trần Chí Nguyện | D11: 54 | F11: Thay khớp háng toàn phần | G11: TTDB | H11: HOAN | I11: =IF(G11="DTDB",420000,IF(G11="TTDB",420000,IF(G11="DT1",187500,IF(G11="TT1",187500,IF(G11="DT2",97500,IF(G11="TT2",97500,IF(G11="DT3",75000,75000))))))) -> 420000 | J11: NGUYỆN | K11: =IF(G11="DTDB",300000,IF(G11="TTDB",300000,IF(G11="DT1",135000,IF(G11="TT1",135000,IF(G11="DT2",75000,IF(G11="TT2",75000,IF(G11="DT3",45000,45000))))))) -> 300000 | L11: TUẤN | M11: =IF(L11="-",0,IF(G11="DTDB",300000,IF(G11="TTDB",300000,IF(G11="DT1",135000,IF(G11="TT1",135000,IF(G11="DT2",75000,IF(G11="TT2",75000,IF(G11="DT3",45000,45000)))))))) -> 300000 | N11: =I11+K11+M11 -> 1020000
A12: 5 | B12: 28/12/2024 | C12: Nguyễn Văn Trung | D12: 20 | F12: PT vết thương phần mềm phức tạp | G12: DT1 | H12: NGUYỆN | I12: =IF(G12="DTDB",420000,IF(G12="TTDB",420000,IF(G12="DT1",187500,IF(G12="TT1",187500,IF(G12="DT2",97500,IF(G12="TT2",97500,IF(G12="DT3",75000,75000))))))) -> 187500 | J12: TUẤN | K12: =IF(G12="DTDB",300000,IF(G12="TTDB",300000,IF(G12="DT1",135000,IF(G12="TT1",135000,IF(G12="DT2",75000,IF(G12="TT2",75000,IF(G12="DT3",45000,45000))))))) -> 135000 | L12: THÁI | M12: =IF(L12="-",0,IF(G12="DTDB",300000,IF(G12="TTDB",300000,IF(G12="DT1",135000,IF(G12="TT1",135000,IF(G12="DT2",75000,IF(G12="TT2",75000,IF(G12="DT3",45000,45000)))))))) -> 135000 | N12: =I12+K12+M12 -> 457500
A13: 6 | B13: 30/12/2024 | C13: Lê Văn Đồng | D13: 77 | F13: PT thay khớp háng bán phần | G13: TT1 | H13: NGUYỆN | I13: =IF(G13="DTDB",420000,IF(G13="TTDB",420000,IF(G13="DT1",187500,IF(G13="TT1",187500,IF(G13="DT2",97500,IF(G13="TT2",97500,IF(G13="DT3",75000,75000))))))) -> 187500 | J13: ĐIỀN | K13: =IF(G13="DTDB",300000,IF(G13="TTDB",300000,IF(G13="DT1",135000,IF(G13="TT1",135000,IF(G13="DT2",75000,IF(G13="TT2",75000,IF(G13="DT3",45000,45000))))))) -> 135000 | L13: TOẢN | M13: =IF(L13="-",0,IF(G13="DTDB",300000,IF(G13="TTDB",300000,IF(G13="DT1",135000,IF(G13="TT1",135000,IF(G13="DT2",75000,IF(G13="TT2",75000,IF(G13="DT3",45000,45000)))))))) -> 135000 | N13: =I13+K13+M13 -> 457500
A14: 7 | B14: 30/12/2024 | C14: Nguyễn Văn Thoàng | D14: 63 | F14: Ghép da tự thân dưới 10% diện tích cơ thể | G14: DT1 | H14: V.TÂN | I14: =IF(G14="DTDB",420000,IF(G14="TTDB",420000,IF(G14="DT1",187500,IF(G14="TT1",187500,IF(G14="DT2",97500,IF(G14="TT2",97500,IF(G14="DT3",75000,75000))))))) -> 187500 | J14: KHÉN | K14: =IF(G14="DTDB",300000,IF(G14="TTDB",300000,IF(G14="DT1",135000,IF(G14="TT1",135000,IF(G14="DT2",75000,IF(G14="TT2",75000,IF(G14="DT3",45000,45000))))))) -> 135000 | L14: KHANG | M14: =IF(L14="-",0,IF(G14="DTDB",300000,IF(G14="TTDB",300000,IF(G14="DT1",135000,IF(G14="TT1",135000,IF(G14="DT2",75000,IF(G14="TT2",75000,IF(G14="DT3",45000,45000)))))))) -> 135000 | N14: =I14+K14+M14 -> 457500
A15: 8 | B15: 31/12/2024 | C15: Mã Nguyên Sang | D15: 43 | F15: PTNS cắt hoạt mạc viêm khớp gối | G15: DT1 | H15: HOAN | I15: =IF(G15="DTDB",420000,IF(G15="TTDB",420000,IF(G15="DT1",187500,IF(G15="TT1",187500,IF(G15="DT2",97500,IF(G15="TT2",97500,IF(G15="DT3",75000,75000))))))) -> 187500 | J15: TOẢN | K15: =IF(G15="DTDB",300000,IF(G15="TTDB",300000,IF(G15="DT1",135000,IF(G15="TT1",135000,IF(G15="DT2",75000,IF(G15="TT2",75000,IF(G15="DT3",45000,45000))))))) -> 135000 | L15: LUẬN | M15: =IF(L15="-",0,IF(G15="DTDB",300000,IF(G15="TTDB",300000,IF(G15="DT1",135000,IF(G15="TT1",135000,IF(G15="DT2",75000,IF(G15="TT2",75000,IF(G15="DT3",45000,45000)))))))) -> 135000 | N15: =I15+K15+M15 -> 457500
A16: 9 | B16: 02/01/2025 | C16: Đặng Thị Ra | E16: 69 | F16: KHX trên màn hình tăng sáng | G16: TTDB | H16: NGUYỆN | I16: =IF(G16="DTDB",420000,IF(G16="TTDB",420000,IF(G16="DT1",187500,IF(G16="TT1",187500,IF(G16="DT2",97500,IF(G16="TT2",97500,IF(G16="DT3",75000,75000))))))) -> 420000 | J16: TOẢN | K16: =IF(G16="DTDB",300000,IF(G16="TTDB",300000,IF(G16="DT1",135000,IF(G16="TT1",135000,IF(G16="DT2",75000,IF(G16="TT2",75000,IF(G16="DT3",45000,45000))))))) -> 300000 | L16: TUẤN | M16: =IF(L16="-",0,IF(G16="DTDB",300000,IF(G16="TTDB",300000,IF(G16="DT1",135000,IF(G16="TT1",135000,IF(G16="DT2",75000,IF(G16="TT2",75000,IF(G16="DT3",45000,45000)))))))) -> 300000 | N16: =I16+K16+M16 -> 1020000
A17: 10 | B17: 03/01/2025 | C17: Đỗ Văn Pheo | D17: 63 | F17: PT KHX tăng sáng | G17: TTDB | H17: V.TÂN | I17: =IF(G17="DTDB",420000,IF(G17="TTDB",420000,IF(G17="DT1",187500,IF(G17="TT1",187500,IF(G17="DT2",97500,IF(G17="TT2",97500,IF(G17="DT3",75000,75000))))))) -> 420000 | J17: TUẤN | K17: =IF(G17="DTDB",300000,IF(G17="TTDB",300000,IF(G17="DT1",135000,IF(G17="TT1",135000,IF(G17="DT2",75000,IF(G17="TT2",75000,IF(G17="DT3",45000,45000))))))) -> 300000 | L17: TOÀN | M17: =IF(L17="-",0,IF(G17="DTDB",300000,IF(G17="TTDB",300000,IF(G17="DT1",135000,IF(G17="TT1",135000,IF(G17="DT2",75000,IF(G17="TT2",75000,IF(G17="DT3",45000,45000)))))))) -> 300000 | N17: =I17+K17+M17 -> 1020000
A18: 11 | B18: 03/01/2025 | C18: Hà Minh Huy | D18: 61 | F18: KHX trên màn hình tăng sáng | G18: TTDB | H18: HOAN | I18: =IF(G18="DTDB",420000,IF(G18="TTDB",420000,IF(G18="DT1",187500,IF(G18="TT1",187500,IF(G18="DT2",97500,IF(G18="TT2",97500,IF(G18="DT3",75000,75000))))))) -> 420000 | J18: TOẢN | K18: =IF(G18="DTDB",300000,IF(G18="TTDB",300000,IF(G18="DT1",135000,IF(G18="TT1",135000,IF(G18="DT2",75000,IF(G18="TT2",75000,IF(G18="DT3",45000,45000))))))) -> 300000 | L18: TUẤN | M18: =IF(L18="-",0,IF(G18="DTDB",300000,IF(G18="TTDB",300000,IF(G18="DT1",135000,IF(G18="TT1",135000,IF(G18="DT2",75000,IF(G18="TT2",75000,IF(G18="DT3",45000,45000)))))))) -> 300000 | N18: =I18+K18+M18 -> 1020000
A19: 12 | B19: 03/01/2025 | C19: Lê Nguyễn Minh Long | D19: 25 | F19: PT vết thương phần mềm phức tạp | G19: DT1 | H19: ĐIỀN | I19: =IF(G19="DTDB",420000,IF(G19="TTDB",420000,IF(G19="DT1",187500,IF(G19="TT1",187500,IF(G19="DT2",97500,IF(G19="TT2",97500,IF(G19="DT3",75000,75000))))))) -> 187500 | J19: LUẬN | K19: =IF(G19="DTDB",300000,IF(G19="TTDB",300000,IF(G19="DT1",135000,IF(G19="TT1",135000,IF(G19="DT2",75000,IF(G19="TT2",75000,IF(G19="DT3",45000,45000))))))) -> 135000 | L19: KHÉN | M19: =IF(L19="-",0,IF(G19="DTDB",300000,IF(G19="TTDB",300000,IF(G19="DT1",135000,IF(G19="TT1",135000,IF(G19="DT2",75000,IF(G19="TT2",75000,IF(G19="DT3",45000,45000)))))))) -> 135000 | N19: =I19+K19+M19 -> 457500
A20: 13 | B20: 03/01/2025 | C20: Nguyễn Thị Trinh | E20: 40 | F20: PTNS cắt hoạt mạc viêm khớp gối | G20: TT1 | H20: HOAN | I20: =IF(G20="DTDB",420000,IF(G20="TTDB",420000,IF(G20="DT1",187500,IF(G20="TT1",187500,IF(G20="DT2",97500,IF(G20="TT2",97500,IF(G20="DT3",75000,75000))))))) -> 187500 | J20: TOẢN | K20: =IF(G20="DTDB",300000,IF(G20="TTDB",300000,IF(G20="DT1",135000,IF(G20="TT1",135000,IF(G20="DT2",75000,IF(G20="TT2",75000,IF(G20="DT3",45000,45000))))))) -> 135000 | L20: TUẤN | M20: =IF(L20="-",0,IF(G20="DTDB",300000,IF(G20="TTDB",300000,IF(G20="DT1",135000,IF(G20="TT1",135000,IF(G20="DT2",75000,IF(G20="TT2",75000,IF(G20="DT3",45000,45000)))))))) -> 135000 | N20: =I20+K20+M20 -> 457500
A21: 14 | B21: 04/01/2025 | C21: Mã Thanh Xà | E21: 88 | F21: PT thay khớp háng bán phần | G21: TT1 | H21: HOAN | I21: =IF(G21="DTDB",420000,IF(G21="TTDB",420000,IF(G21="DT1",187500,IF(G21="TT1",187500,IF(G21="DT2",97500,IF(G21="TT2",97500,IF(G21="DT3",75000,75000))))))) -> 187500 | J21: NGUYỆN | K21: =IF(G21="DTDB",300000,IF(G21="TTDB",300000,IF(G21="DT1",135000,IF(G21="TT1",135000,IF(G21="DT2",75000,IF(G21="TT2",75000,IF(G21="DT3",45000,45000))))))) -> 135000 | L21: ĐIỀN | M21: =IF(L21="-",0,IF(G21="DTDB",300000,IF(G21="TTDB",300000,IF(G21="DT1",135000,IF(G21="TT1",135000,IF(G21="DT2",75000,IF(G21="TT2",75000,IF(G21="DT3",45000,45000)))))))) -> 135000 | N21: =I21+K21+M21 -> 457500
A22: 15 | B22: 04/01/2025 | C22: Nguyễn Văn Đời | D22: 84 | F22: PT vết thương phần mềm phức tạp | G22: TT1 | H22: ĐIỀN | I22: =IF(G22="DTDB",420000,IF(G22="TTDB",420000,IF(G22="DT1",187500,IF(G22="TT1",187500,IF(G22="DT2",97500,IF(G22="TT2",97500,IF(G22="DT3",75000,75000))))))) -> 187500 | J22: TUẤN | K22: =IF(G22="DTDB",300000,IF(G22="TTDB",300000,IF(G22="DT1",135000,IF(G22="TT1",135000,IF(G22="DT2",75000,IF(G22="TT2",75000,IF(G22="DT3",45000,45000))))))) -> 135000 | L22: KHÁNH | M22: =IF(L22="-",0,IF(G22="DTDB",300000,IF(G22="TTDB",300000,IF(G22="DT1",135000,IF(G22="TT1",135000,IF(G22="DT2",75000,IF(G22="TT2",75000,IF(G22="DT3",45000,45000)))))))) -> 135000 | N22: =I22+K22+M22 -> 457500
A23: 16 | B23: 06/01/2025 | C23: Nguyễn Thị Ngọc Ánh | E23: 68 | F23: KHX trên màn hình tăng sáng | G23: DTDB | H23: TOẢN | I23: =IF(G23="DTDB",420000,IF(G23="TTDB",420000,IF(G23="DT1",187500,IF(G23="TT1",187500,IF(G23="DT2",97500,IF(G23="TT2",97500,IF(G23="DT3",75000,75000))))))) -> 420000 | J23: TUẤN | K23: =IF(G23="DTDB",300000,IF(G23="TTDB",300000,IF(G23="DT1",135000,IF(G23="TT1",135000,IF(G23="DT2",75000,IF(G23="TT2",75000,IF(G23="DT3",45000,45000))))))) -> 300000 | L23: LUẬN | M23: =IF(L23="-",0,IF(G23="DTDB",300000,IF(G23="TTDB",300000,IF(G23="DT1",135000,IF(G23="TT1",135000,IF(G23="DT2",75000,IF(G23="TT2",75000,IF(G23="DT3",45000,45000)))))))) -> 300000 | N23: =I23+K23+M23 -> 1020000
A24: 17 | B24: 07/01/2025 | C24: Nguyễn Văn Sáu | D24: 61 | F24: KHX trên màn hình tăng sáng | G24: TTDB | H24: GIÀU | I24: =IF(G24="DTDB",420000,IF(G24="TTDB",420000,IF(G24="DT1",187500,IF(G24="TT1",187500,IF(G24="DT2",97500,IF(G24="TT2",97500,IF(G24="DT3",75000,75000))))))) -> 420000 | J24: TUẤN | K24: =IF(G24="DTDB",300000,IF(G24="TTDB",300000,IF(G24="DT1",135000,IF(G24="TT1",135000,IF(G24="DT2",75000,IF(G24="TT2",75000,IF(G24="DT3",45000,45000))))))) -> 300000 | L24: HƯNG | M24: =IF(L24="-",0,IF(G24="DTDB",300000,IF(G24="TTDB",300000,IF(G24="DT1",135000,IF(G24="TT1",135000,IF(G24="DT2",75000,IF(G24="TT2",75000,IF(G24="DT3",45000,45000)))))))) -> 300000 | N24: =I24+K24+M24 -> 1020000
A25: 18 | B25: 07/01/2025 | C25: Trần Huệ Mẫn | E25: 17 | F25: KHX trên màn hình tăng sáng | G25: TTDB | H25: NGUYỆN | I25: =IF(G25="DTDB",420000,IF(G25="TTDB",420000,IF(G25="DT1",187500,IF(G25="TT1",187500,IF(G25="DT2",97500,IF(G25="TT2",97500,IF(G25="DT3",75000,75000))))))) -> 420000 | J25: TUẤN | K25: =IF(G25="DTDB",300000,IF(G25="TTDB",300000,IF(G25="DT1",135000,IF(G25="TT1",135000,IF(G25="DT2",75000,IF(G25="TT2",75000,IF(G25="DT3",45000,45000))))))) -> 300000 | L25: HƯNG | M25: =IF(L25="-",0,IF(G25="DTDB",300000,IF(G25="TTDB",300000,IF(G25="DT1",135000,IF(G25="TT1",135000,IF(G25="DT2",75000,IF(G25="TT2",75000,IF(G25="DT3",45000,45000)))))))) -> 300000 | N25: =I25+K25+M25 -> 1020000
A26: 19 | B26: 08/01/2025 | C26: Huỳnh Thị Yến | E26: 74 | F26: PT thay khớp háng toàn bộ | G26: TTDB | H26: HOAN | I26: =IF(G26="DTDB",420000,IF(G26="TTDB",420000,IF(G26="DT1",187500,IF(G26="TT1",187500,IF(G26="DT2",97500,IF(G26="TT2",97500,IF(G26="DT3",75000,75000))))))) -> 420000 | J26: V.TÂN | K26: =IF(G26="DTDB",300000,IF(G26="TTDB",300000,IF(G26="DT1",135000,IF(G26="TT1",135000,IF(G26="DT2",75000,IF(G26="TT2",75000,IF(G26="DT3",45000,45000))))))) -> 300000 | L26: TUẤN | M26: =IF(L26="-",0,IF(G26="DTDB",300000,IF(G26="TTDB",300000,IF(G26="DT1",135000,IF(G26="TT1",135000,IF(G26="DT2",75000,IF(G26="TT2",75000,IF(G26="DT3",45000,45000)))))))) -> 300000 | N26: =I26+K26+M26 -> 1020000
A27: 20 | B27: 08/01/2025 | C27: Lê Văn Đạt | D27: 84 | F27: PT khớp háng bán phần | G27: TT1 | H27: HOAN | I27: =IF(G27="DTDB",420000,IF(G27="TTDB",420000,IF(G27="DT1",187500,IF(G27="TT1",187500,IF(G27="DT2",97500,IF(G27="TT2",97500,IF(G27="DT3",75000,75000))))))) -> 187500 | J27: TUẤN | K27: =IF(G27="DTDB",300000,IF(G27="TTDB",300000,IF(G27="DT1",135000,IF(G27="TT1",135000,IF(G27="DT2",75000,IF(G27="TT2",75000,IF(G27="DT3",45000,45000))))))) -> 135000 | L27: HƯNG | M27: =IF(L27="-",0,IF(G27="DTDB",300000,IF(G27="TTDB",300000,IF(G27="DT1",135000,IF(G27="TT1",135000,IF(G27="DT2",75000,IF(G27="TT2",75000,IF(G27="DT3",45000,45000)))))))) -> 135000 | N27: =I27+K27+M27 -> 457500
A28: 21 | B28: 08/01/2025 | C28: Hoàng Thị Thanh Thúy | E28: 22 | F28: PTNS tái tạo dây chằng | G28: TTDB | H28: GIÀU | I28: =IF(G28="DTDB",420000,IF(G28="TTDB",420000,IF(G28="DT1",187500,IF(G28="TT1",187500,IF(G28="DT2",97500,IF(G28="TT2",97500,IF(G28="DT3",75000,75000))))))) -> 420000 | J28: TOẢN | K28: =IF(G28="DTDB",300000,IF(G28="TTDB",300000,IF(G28="DT1",135000,IF(G28="TT1",135000,IF(G28="DT2",75000,IF(G28="TT2",75000,IF(G28="DT3",45000,45000))))))) -> 300000 | L28: HƯNG | M28: =IF(L28="-",0,IF(G28="DTDB",300000,IF(G28="TTDB",300000,IF(G28="DT1",135000,IF(G28="TT1",135000,IF(G28="DT2",75000,IF(G28="TT2",75000,IF(G28="DT3",45000,45000)))))))) -> 300000 | N28: =I28+K28+M28 -> 1020000
A29: 22 | B29: 09/01/2025 | C29: Nguyễn Thị Khéo | E29: 75 | F29: KHX trên màn hình tăng sáng | G29: TTDB | H29: NGUYỆN | I29: =IF(G29="DTDB",420000,IF(G29="TTDB",420000,IF(G29="DT1",187500,IF(G29="TT1",187500,IF(G29="DT2",97500,IF(G29="TT2",97500,IF(G29="DT3",75000,75000))))))) -> 420000 | J29: TOẢN | K29: =IF(G29="DTDB",300000,IF(G29="TTDB",300000,IF(G29="DT1",135000,IF(G29="TT1",135000,IF(G29="DT2",75000,IF(G29="TT2",75000,IF(G29="DT3",45000,45000))))))) -> 300000 | L29: TUẤN | M29: =IF(L29="-",0,IF(G29="DTDB",300000,IF(G29="TTDB",300000,IF(G29="DT1",135000,IF(G29="TT1",135000,IF(G29="DT2",75000,IF(G29="TT2",75000,IF(G29="DT3",45000,45000)))))))) -> 300000 | N29: =I29+K29+M29 -> 1020000
A30: 23 | B30: 10/01/2025 | C30: Trần Thị Tư | E30: 80 | F30: PT thay khớp háng bán phần | G30: TT1 | H30: HOAN | I30: =IF(G30="DTDB",420000,IF(G30="TTDB",420000,IF(G30="DT1",187500,IF(G30="TT1",187500,IF(G30="DT2",97500,IF(G30="TT2",97500,IF(G30="DT3",75000,75000))))))) -> 187500 | J30: NGUYỆN | K30: =IF(G30="DTDB",300000,IF(G30="TTDB",300000,IF(G30="DT1",135000,IF(G30="TT1",135000,IF(G30="DT2",75000,IF(G30="TT2",75000,IF(G30="DT3",45000,45000))))))) -> 135000 | L30: ĐIỀN | M30: =IF(L30="-",0,IF(G30="DTDB",300000,IF(G30="TTDB",300000,IF(G30="DT1",135000,IF(G30="TT1",135000,IF(G30="DT2",75000,IF(G30="TT2",75000,IF(G30="DT3",45000,45000)))))))) -> 135000 | N30: =I30+K30+M30 -> 457500
A31: 24 | B31: 10/01/2025 | C31: Võ Văn Ngẫu | D31: 97 | F31: PT thay khớp háng bán phần | G31: TT1 | H31: HOAN | I31: =IF(G31="DTDB",420000,IF(G31="TTDB",420000,IF(G31="DT1",187500,IF(G31="TT1",187500,IF(G31="DT2",97500,IF(G31="TT2",97500,IF(G31="DT3",75000,75000))))))) -> 187500 | J31: NGUYỆN | K31: =IF(G31="DTDB",300000,IF(G31="TTDB",300000,IF(G31="DT1",135000,IF(G31="TT1",135000,IF(G31="DT2",75000,IF(G31="TT2",75000,IF(G31="DT3",45000,45000))))))) -> 135000 | L31: ĐIỀN | M31: =IF(L31="-",0,IF(G31="DTDB",300000,IF(G31="TTDB",300000,IF(G31="DT1",135000,IF(G31="TT1",135000,IF(G31="DT2",75000,IF(G31="TT2",75000,IF(G31="DT3",45000,45000)))))))) -> 135000 | N31: =I31+K31+M31 -> 457500
A32: 25 | B32: 10/01/2025 | C32: LÊ VĂN THƯỜNG | E32: 38 | F32: PT thay khớp háng bán phần | G32: TT1 | H32: NGUYỆN | I32: =IF(G32="DTDB",420000,IF(G32="TTDB",420000,IF(G32="DT1",187500,IF(G32="TT1",187500,IF(G32="DT2",97500,IF(G32="TT2",97500,IF(G32="DT3",75000,75000))))))) -> 187500 | J32: ĐIỀN | K32: =IF(G32="DTDB",300000,IF(G32="TTDB",300000,IF(G32="DT1",135000,IF(G32="TT1",135000,IF(G32="DT2",75000,IF(G32="TT2",75000,IF(G32="DT3",45000,45000))))))) -> 135000 | L32: TUẤN | M32: =IF(L32="-",0,IF(G32="DTDB",300000,IF(G32="TTDB",300000,IF(G32="DT1",135000,IF(G32="TT1",135000,IF(G32="DT2",75000,IF(G32="TT2",75000,IF(G32="DT3",45000,45000)))))))) -> 135000 | N32: =I32+K32+M32 -> 457500
A33: 26 | B33: 10/01/2025 | C33: Lý Thị Tuyết Nga | E33: 49 | F33: Khâu phục hồi tổn thương gân duỗi | G33: TT1 | H33: GIÀU | I33: =IF(G33="DTDB",420000,IF(G33="TTDB",420000,IF(G33="DT1",187500,IF(G33="TT1",187500,IF(G33="DT2",97500,IF(G33="TT2",97500,IF(G33="DT3",75000,75000))))))) -> 187500 | J33: TOÀN | K33: =IF(G33="DTDB",300000,IF(G33="TTDB",300000,IF(G33="DT1",135000,IF(G33="TT1",135000,IF(G33="DT2",75000,IF(G33="TT2",75000,IF(G33="DT3",45000,45000))))))) -> 135000 | L33: LUẬT | M33: =IF(L33="-",0,IF(G33="DTDB",300000,IF(G33="TTDB",300000,IF(G33="DT1",135000,IF(G33="TT1",135000,IF(G33="DT2",75000,IF(G33="TT2",75000,IF(G33="DT3",45000,45000)))))))) -> 135000 | N33: =I33+K33+M33 -> 457500
A34: 27 | B34: 13/01/2025 | C34: Đoàn Thiện Thái | D34: 38 | F34: PT KHX tăng sáng | G34: TTDB | H34: TOẢN | I34: =IF(G34="DTDB",420000,IF(G34="TTDB",420000,IF(G34="DT1",187500,IF(G34="TT1",187500,IF(G34="DT2",97500,IF(G34="TT2",97500,IF(G34="DT3",75000,75000))))))) -> 420000 | J34: TUẤN | K34: =IF(G34="DTDB",300000,IF(G34="TTDB",300000,IF(G34="DT1",135000,IF(G34="TT1",135000,IF(G34="DT2",75000,IF(G34="TT2",75000,IF(G34="DT3",45000,45000))))))) -> 300000 | L34: THÁI | M34: =IF(L34="-",0,IF(G34="DTDB",300000,IF(G34="TTDB",300000,IF(G34="DT1",135000,IF(G34="TT1",135000,IF(G34="DT2",75000,IF(G34="TT2",75000,IF(G34="DT3",45000,45000)))))))) -> 300000 | N34: =I34+K34+M34 -> 1020000
A35: 28 | B35: 13/01/2025 | C35: Trần Văn Mỹ | D35: 100 | F35: PT vết thương phần mềm phức tạp | G35: TT1 | H35: MINH | I35: =IF(G35="DTDB",420000,IF(G35="TTDB",420000,IF(G35="DT1",187500,IF(G35="TT1",187500,IF(G35="DT2",97500,IF(G35="TT2",97500,IF(G35="DT3",75000,75000))))))) -> 187500 | J35: KHANG | K35: =IF(G35="DTDB",300000,IF(G35="TTDB",300000,IF(G35="DT1",135000,IF(G35="TT1",135000,IF(G35="DT2",75000,IF(G35="TT2",75000,IF(G35="DT3",45000,45000))))))) -> 135000 | L35: LUẬT | M35: =IF(L35="-",0,IF(G35="DTDB",300000,IF(G35="TTDB",300000,IF(G35="DT1",135000,IF(G35="TT1",135000,IF(G35="DT2",75000,IF(G35="TT2",75000,IF(G35="DT3",45000,45000)))))))) -> 135000 | N35: =I35+K35+M35 -> 457500
A36: 29 | B36: 14/01/2025 | C36: Trần Thị Ánh Vân | E36: 49 | F36: KHX trên màn hình tăng sáng | G36: TTDB | H36: ĐIỀN | I36: =IF(G36="DTDB",420000,IF(G36="TTDB",420000,IF(G36="DT1",187500,IF(G36="TT1",187500,IF(G36="DT2",97500,IF(G36="TT2",97500,IF(G36="DT3",75000,75000))))))) -> 420000 | J36: LUẬN | K36: =IF(G36="DTDB",300000,IF(G36="TTDB",300000,IF(G36="DT1",135000,IF(G36="TT1",135000,IF(G36="DT2",75000,IF(G36="TT2",75000,IF(G36="DT3",45000,45000))))))) -> 300000 | L36: KHÉN | M36: =IF(L36="-",0,IF(G36="DTDB",300000,IF(G36="TTDB",300000,IF(G36="DT1",135000,IF(G36="TT1",135000,IF(G36="DT2",75000,IF(G36="TT2",75000,IF(G36="DT3",45000,45000)))))))) -> 300000 | N36: =I36+K36+M36 -> 1020000
A37: 30 | B37: 14/01/2025 | C37: Nguyễn Văn Hưng | D37: 42 | F37: PTNS tái tạo dây chằng | G37: TTDB | H37: TOẢN | I37: =IF(G37="DTDB",420000,IF(G37="TTDB",420000,IF(G37="DT1",187500,IF(G37="TT1",187500,IF(G37="DT2",97500,IF(G37="TT2",97500,IF(G37="DT3",75000,75000))))))) -> 420000 | J37: MINH | K37: =IF(G37="DTDB",300000,IF(G37="TTDB",300000,IF(G37="DT1",135000,IF(G37="TT1",135000,IF(G37="DT2",75000,IF(G37="TT2",75000,IF(G37="DT3",45000,45000))))))) -> 300000 | L37: HƯNG | M37: =IF(L37="-",0,IF(G37="DTDB",300000,IF(G37="TTDB",300000,IF(G37="DT1",135000,IF(G37="TT1",135000,IF(G37="DT2",75000,IF(G37="TT2",75000,IF(G37="DT3",45000,45000)))))))) -> 300000 | N37: =I37+K37+M37 -> 1020000
A38: 31 | B38: 15/01/2025 | C38: Nguyễn Văn Mát | D38: 55 | F38: PT KHX tăng sáng | G38: DTDB | H38: GIÀU | I38: =IF(G38="DTDB",420000,IF(G38="TTDB",420000,IF(G38="DT1",187500,IF(G38="TT1",187500,IF(G38="DT2",97500,IF(G38="TT2",97500,IF(G38="DT3",75000,75000))))))) -> 420000 | J38: TUẤN | K38: =IF(G38="DTDB",300000,IF(G38="TTDB",300000,IF(G38="DT1",135000,IF(G38="TT1",135000,IF(G38="DT2",75000,IF(G38="TT2",75000,IF(G38="DT3",45000,45000))))))) -> 300000 | L38: KHÉN | M38: =IF(L38="-",0,IF(G38="DTDB",300000,IF(G38="TTDB",300000,IF(G38="DT1",135000,IF(G38="TT1",135000,IF(G38="DT2",75000,IF(G38="TT2",75000,IF(G38="DT3",45000,45000)))))))) -> 300000 | N38: =I38+K38+M38 -> 1020000
A39: 32 | B39: 16/01/2025 | C39: Võ Hoàng Dư | D39: 37 | F39: Cắt u lành >10cm | G39: TT1 | H39: NGUYỆN | I39: =IF(G39="DTDB",420000,IF(G39="TTDB",420000,IF(G39="DT1",187500,IF(G39="TT1",187500,IF(G39="DT2",97500,IF(G39="TT2",97500,IF(G39="DT3",75000,75000))))))) -> 187500 | J39: TUẤN | K39: =IF(G39="DTDB",300000,IF(G39="TTDB",300000,IF(G39="DT1",135000,IF(G39="TT1",135000,IF(G39="DT2",75000,IF(G39="TT2",75000,IF(G39="DT3",45000,45000))))))) -> 135000 | L39: TOÀN | M39: =IF(L39="-",0,IF(G39="DTDB",300000,IF(G39="TTDB",300000,IF(G39="DT1",135000,IF(G39="TT1",135000,IF(G39="DT2",75000,IF(G39="TT2",75000,IF(G39="DT3",45000,45000)))))))) -> 135000 | N39: =I39+K39+M39 -> 457500
A40: 33 | B40: 16/01/2025 | C40: Trần Thị Út | E40: 52 | F40: Lấy nhân đệm | G40: TT1 | H40: GIÀU | I40: =IF(G40="DTDB",420000,IF(G40="TTDB",420000,IF(G40="DT1",187500,IF(G40="TT1",187500,IF(G40="DT2",97500,IF(G40="TT2",97500,IF(G40="DT3",75000,75000))))))) -> 187500 | J40: TÙNG | K40: =IF(G40="DTDB",300000,IF(G40="TTDB",300000,IF(G40="DT1",135000,IF(G40="TT1",135000,IF(G40="DT2",75000,IF(G40="TT2",75000,IF(G40="DT3",45000,45000))))))) -> 135000 | L40: TOÀN | M40: =IF(L40="-",0,IF(G40="DTDB",300000,IF(G40="TTDB",300000,IF(G40="DT1",135000,IF(G40="TT1",135000,IF(G40="DT2",75000,IF(G40="TT2",75000,IF(G40="DT3",45000,45000)))))))) -> 135000 | N40: =I40+K40+M40 -> 457500
A41: 34 | B41: 16/01/2025 | C41: Nguyễn Tấn Đăng Quang | D41: 37 | F41: KHX trên màn hình tăng sáng | G41: DTDB | H41: TOẢN | I41: =IF(G41="DTDB",420000,IF(G41="TTDB",420000,IF(G41="DT1",187500,IF(G41="TT1",187500,IF(G41="DT2",97500,IF(G41="TT2",97500,IF(G41="DT3",75000,75000))))))) -> 420000 | J41: TUẤN | K41: =IF(G41="DTDB",300000,IF(G41="TTDB",300000,IF(G41="DT1",135000,IF(G41="TT1",135000,IF(G41="DT2",75000,IF(G41="TT2",75000,IF(G41="DT3",45000,45000))))))) -> 300000 | L41: LUẬN | M41: =IF(L41="-",0,IF(G41="DTDB",300000,IF(G41="TTDB",300000,IF(G41="DT1",135000,IF(G41="TT1",135000,IF(G41="DT2",75000,IF(G41="TT2",75000,IF(G41="DT3",45000,45000)))))))) -> 300000 | N41: =I41+K41+M41 -> 1020000
A42: 35 | B42: 17/01/2025 | C42: Đào Văn Sáng | D42: 58 | F42: Lấy nhân đệm | G42: TT1 | H42: GIÀU | I42: =IF(G42="DTDB",420000,IF(G42="TTDB",420000,IF(G42="DT1",187500,IF(G42="TT1",187500,IF(G42="DT2",97500,IF(G42="TT2",97500,IF(G42="DT3",75000,75000))))))) -> 187500 | J42: KHÉN | K42: =IF(G42="DTDB",300000,IF(G42="TTDB",300000,IF(G42="DT1",135000,IF(G42="TT1",135000,IF(G42="DT2",75000,IF(G42="TT2",75000,IF(G42="DT3",45000,45000))))))) -> 135000 | L42: TÙNG | M42: =IF(L42="-",0,IF(G42="DTDB",300000,IF(G42="TTDB",300000,IF(G42="DT1",135000,IF(G42="TT1",135000,IF(G42="DT2",75000,IF(G42="TT2",75000,IF(G42="DT3",45000,45000)))))))) -> 135000 | N42: =I42+K42+M42 -> 457500
...

Sheet lanh tien PT_BHYT
A1: BV TRƯỜNG ĐHYD CẦN THƠ
A2: KHOA NGOẠI CTCH-TK
A3: DANH SÁCH LÃNH TIỀN THÙ LAO THÁNG 1/2025
A4: (BHYT)
A6: STT | B6: HỌ TÊN | C6: CHỨC VỤ | D6: SỐ TÀI KHOẢN | E6: SỐ TIỀN | F6: Thuế 10%
A7: 1 | B7: Phạm Việt Triều | C7: Bác sĩ | D7: 102006610216 | E7: =SUM(SUMIF(phauthuat_BHYT!$H$8:$H$104,"TRIỀU",phauthuat_BHYT!$I$8:$I$104),SUMIF(phauthuat_BHYT!$J$8:$J$104,"TRIỀU",phauthuat_BHYT!$K$8:$K$104),SUMIF(phauthuat_BHYT!$L$8:$L$104,"TRIỀU",phauthuat_BHYT!$M$8:$M$104)) -> 420000
A8: 2 | B8: Nguyễn Thành Tấn | C8: Bác sĩ | D8: 103006610215 | E8: =SUM(SUMIF(phauthuat_BHYT!$H$8:$H$104,"TẤN",phauthuat_BHYT!$I$8:$I$104),SUMIF(phauthuat_BHYT!$J$8:$J$104,"TẤN",phauthuat_BHYT!$K$8:$K$104),SUMIF(phauthuat_BHYT!$L$8:$L$104,"TẤN",phauthuat_BHYT!$M$8:$M$104)) -> 517500
A9: 3 | B9: Nguyễn Lê Hoan | C9: Bác sĩ | D9: 100006610218 | E9: =SUM(SUMIF(phauthuat_BHYT!$H$8:$H$104,"HOAN",phauthuat_BHYT!$I$8:$I$104),SUMIF(phauthuat_BHYT!$J$8:$J$104,"HOAN",phauthuat_BHYT!$K$8:$K$104),SUMIF(phauthuat_BHYT!$L$8:$L$104,"HOAN",phauthuat_BHYT!$M$8:$M$104)) -> 4260000
A10: 4 | B10: Nguyễn Chí Nguyện | C10: Bác sĩ | D10: 105001159195 | E10: =SUM(SUMIF(phauthuat_BHYT!$H$8:$H$104,"NGUYỆN",phauthuat_BHYT!$I$8:$I$104),SUMIF(phauthuat_BHYT!$J$8:$J$104,"NGUYỆN",phauthuat_BHYT!$K$8:$K$104),SUMIF(phauthuat_BHYT!$L$8:$L$104,"NGUYỆN",phauthuat_BHYT!$M$8:$M$104)) -> 6435000
A11: 5 | B11: Hồ Điền | C11: Bác sĩ | D11: 105001225232 | E11: =SUM(SUMIF(phauthuat_BHYT!$H$8:$H$104,"ĐIỀN",phauthuat_BHYT!$I$8:$I$104),SUMIF(phauthuat_BHYT!$J$8:$J$104,"ĐIỀN",phauthuat_BHYT!$K$8:$K$104),SUMIF(phauthuat_BHYT!$L$8:$L$104,"ĐIỀN",phauthuat_BHYT!$M$8:$M$104)) -> 2595000
A12: 6 | B12: Trần Quốc Toản | C12: Bác sĩ | D12: 107868829237 | E12: =SUM(SUMIF(phauthuat_BHYT!$H$8:$H$104,"TOẢN",phauthuat_BHYT!$I$8:$I$104),SUMIF(phauthuat_BHYT!$J$8:$J$104,"TOẢN",phauthuat_BHYT!$K$8:$K$104),SUMIF(phauthuat_BHYT!$L$8:$L$104,"TOẢN",phauthuat_BHYT!$M$8:$M$104)) -> 6105000
A13: 7 | B13: Đặng Phước Giàu | C13: Bác sĩ | D13: 105867664283 | E13: =SUM(SUMIF(phauthuat_BHYT!$H$8:$H$104,"giàu",phauthuat_BHYT!$I$8:$I$104),SUMIF(phauthuat_BHYT!$J$8:$J$104,"giàu",phauthuat_BHYT!$K$8:$K$104),SUMIF(phauthuat_BHYT!$L$8:$L$104,"giàu",phauthuat_BHYT!$M$8:$M$104)) -> 2407500
A14: 8 | B14: Phạm Việt Tân | C14: Bác sĩ | D14: 104000362303 | E14: =SUM(SUMIF(phauthuat_BHYT!$H$8:$H$104,"v.tân",phauthuat_BHYT!$I$8:$I$104),SUMIF(phauthuat_BHYT!$J$8:$J$104,"v.tân",phauthuat_BHYT!$K$8:$K$104),SUMIF(phauthuat_BHYT!$L$8:$L$104,"v.tân",phauthuat_BHYT!$M$8:$M$104)) -> 3097500
A15: 9 | B15: Bùi Công Minh | C15: Bác sĩ | D15: 105003414654 | E15: =SUM(SUMIF(phauthuat_BHYT!$H$8:$H$104,"minh",phauthuat_BHYT!$I$8:$I$104),SUMIF(phauthuat_BHYT!$J$8:$J$104,"minh",phauthuat_BHYT!$K$8:$K$104),SUMIF(phauthuat_BHYT!$L$8:$L$104,"minh",phauthuat_BHYT!$M$8:$M$104)) -> 1005000
A16: 10 | B16: Phan Văn Tuấn | C16: Bác sĩ | E16: =SUM(SUMIF(phauthuat_BHYT!$H$8:$H$104,"TUẤN",phauthuat_BHYT!$I$8:$I$104),SUMIF(phauthuat_BHYT!$J$8:$J$104,"TUẤN",phauthuat_BHYT!$K$8:$K$104),SUMIF(phauthuat_BHYT!$L$8:$L$104,"TUẤN",phauthuat_BHYT!$M$8:$M$104)) -> 7185000
A17: 11 | B17: Huỳnh Quốc Hưng | C17: Bác sĩ (nt) | E17: =SUM(SUMIF(phauthuat_BHYT!$H$8:$H$104,"hưng",phauthuat_BHYT!$I$8:$I$104),SUMIF(phauthuat_BHYT!$J$8:$J$104,"hưng",phauthuat_BHYT!$K$8:$K$104),SUMIF(phauthuat_BHYT!$L$8:$L$104,"hưng",phauthuat_BHYT!$M$8:$M$104)) -> 2535000
A18: 12 | B18: Võ Văn Phúc Toàn | C18: Bác sĩ (nt) | E18: =SUM(SUMIF(phauthuat_BHYT!$H$8:$H$104,"toàn",phauthuat_BHYT!$I$8:$I$104),SUMIF(phauthuat_BHYT!$J$8:$J$104,"toàn",phauthuat_BHYT!$K$8:$K$104),SUMIF(phauthuat_BHYT!$L$8:$L$104,"toàn",phauthuat_BHYT!$M$8:$M$104)) -> 1380000
A19: 13 | B19: Võ Minh Luận | C19: Bác sĩ (nt) | E19: =SUM(SUMIF(phauthuat_BHYT!$H$8:$H$104,"luận",phauthuat_BHYT!$I$8:$I$104),SUMIF(phauthuat_BHYT!$J$8:$J$104,"luận",phauthuat_BHYT!$K$8:$K$104),SUMIF(phauthuat_BHYT!$L$8:$L$104,"luận",phauthuat_BHYT!$M$8:$M$104)) -> 2070000
A20: 14 | B20: Võ Dương Thành Thái | C20: Bác sĩ (nt) | E20: =SUM(SUMIF(phauthuat_BHYT!$H$8:$H$104,"thái",phauthuat_BHYT!$I$8:$I$104),SUMIF(phauthuat_BHYT!$J$8:$J$104,"thái",phauthuat_BHYT!$K$8:$K$104),SUMIF(phauthuat_BHYT!$L$8:$L$104,"thái",phauthuat_BHYT!$M$8:$M$104)) -> 960000
A21: 15 | B21: Lê Đình Tùng | C21: Bác sĩ (nt) | E21: =SUM(SUMIF(phauthuat_BHYT!$H$8:$H$104,"tùng",phauthuat_BHYT!$I$8:$I$104),SUMIF(phauthuat_BHYT!$J$8:$J$104,"tùng",phauthuat_BHYT!$K$8:$K$104),SUMIF(phauthuat_BHYT!$L$8:$L$104,"tùng",phauthuat_BHYT!$M$8:$M$104)) -> 645000
A22: 16 | B22: Văn Minh Khén | C22: Bác sĩ (nt) | E22: =SUM(SUMIF(phauthuat_BHYT!$H$8:$H$104,"khén",phauthuat_BHYT!$I$8:$I$104),SUMIF(phauthuat_BHYT!$J$8:$J$104,"khén",phauthuat_BHYT!$K$8:$K$104),SUMIF(phauthuat_BHYT!$L$8:$L$104,"khén",phauthuat_BHYT!$M$8:$M$104)) -> 1305000
A23: 17 | B23: Phạm Tấn Hưởng | C23: Bác sĩ (nt) | E23: =SUM(SUMIF(phauthuat_BHYT!$H$8:$H$104,"hưởng",phauthuat_BHYT!$I$8:$I$104),SUMIF(phauthuat_BHYT!$J$8:$J$104,"hưởng",phauthuat_BHYT!$K$8:$K$104),SUMIF(phauthuat_BHYT!$L$8:$L$104,"hưởng",phauthuat_BHYT!$M$8:$M$104)) -> 0
A24: 18 | B24: Nguyễn Đông Khang | C24: Bác sĩ (nt) | E24: =SUM(SUMIF(phauthuat_BHYT!$H$8:$H$104,"khang",phauthuat_BHYT!$I$8:$I$104),SUMIF(phauthuat_BHYT!$J$8:$J$104,"khang",phauthuat_BHYT!$K$8:$K$104),SUMIF(phauthuat_BHYT!$L$8:$L$104,"khang",phauthuat_BHYT!$M$8:$M$104)) -> 495000
A25: 19 | B25: Nguyễn Đình Luật | C25: Bác sĩ (nt) | E25: =SUM(SUMIF(phauthuat_BHYT!$H$8:$H$104,"luật",phauthuat_BHYT!$I$8:$I$104),SUMIF(phauthuat_BHYT!$J$8:$J$104,"luật",phauthuat_BHYT!$K$8:$K$104),SUMIF(phauthuat_BHYT!$L$8:$L$104,"luật",phauthuat_BHYT!$M$8:$M$104)) -> 420000
A26: 20 | B26: Võ Long Ẩn | C26: Bác sĩ (nt) | E26: =SUM(SUMIF(phauthuat_BHYT!$H$8:$H$104,"ẩn",phauthuat_BHYT!$I$8:$I$104),SUMIF(phauthuat_BHYT!$J$8:$J$104,"ẩn",phauthuat_BHYT!$K$8:$K$104),SUMIF(phauthuat_BHYT!$L$8:$L$104,"ẩn",phauthuat_BHYT!$M$8:$M$104)) -> 300000
A27: 21 | B27: Nguyễn Xuân Bình | C27: Bác sĩ (nt) | E27: =SUM(SUMIF(phauthuat_BHYT!$H$8:$H$104,"bình",phauthuat_BHYT!$I$8:$I$104),SUMIF(phauthuat_BHYT!$J$8:$J$104,"bình",phauthuat_BHYT!$K$8:$K$104),SUMIF(phauthuat_BHYT!$L$8:$L$104,"bình",phauthuat_BHYT!$M$8:$M$104)) -> 0
A28: 22 | B28: Phạm Doãn Đại Dương | C28: Bác sĩ (nt) | E28: =SUM(SUMIF(phauthuat_BHYT!$H$8:$H$104,"dương",phauthuat_BHYT!$I$8:$I$104),SUMIF(phauthuat_BHYT!$J$8:$J$104,"dương",phauthuat_BHYT!$K$8:$K$104),SUMIF(phauthuat_BHYT!$L$8:$L$104,"dương",phauthuat_BHYT!$M$8:$M$104)) -> 0
A29: 23 | B29: Lê Quốc Khánh | C29: Bác sĩ (nt) | E29: =SUM(SUMIF(phauthuat_BHYT!$H$8:$H$104,"khánh",phauthuat_BHYT!$I$8:$I$104),SUMIF(phauthuat_BHYT!$J$8:$J$104,"khánh",phauthuat_BHYT!$K$8:$K$104),SUMIF(phauthuat_BHYT!$L$8:$L$104,"khánh",phauthuat_BHYT!$M$8:$M$104)) -> 135000
A30: 24 | B30: Lê Cường Thạnh | C30: Bác sĩ (nt) | E30: =SUM(SUMIF(phauthuat_BHYT!$H$8:$H$104,"thạnh",phauthuat_BHYT!$I$8:$I$104),SUMIF(phauthuat_BHYT!$J$8:$J$104,"thạnh",phauthuat_BHYT!$K$8:$K$104),SUMIF(phauthuat_BHYT!$L$8:$L$104,"thạnh",phauthuat_BHYT!$M$8:$M$104)) -> 0
B31: TỔNG CỘNG | E31: =SUM(E7:E30) -> 44272500
D33: Cần Thơ, ngày 18 tháng 12 năm 2024
A34: Người lập bảng | D34: Trưởng khoa
A38: ĐD. Phan Văn Hiếu | D38: ThS.Bs.CKII. Nguyễn Lê Hoan

Sheet Thực lãnh
A1: BV TRƯỜNG ĐHYD CẦN THƠ
A2: KHOA NGOẠI CTCH-TK
A3: DANH SÁCH LÃNH TIỀN THÙ LAO THÁNG 1/2025
A4: (BHYT)
A6: STT | B6: HỌ TÊN | C6: CHỨC VỤ | D6: SỐ TÀI KHOẢN | E6: SỐ TIỀN | F6: SỐ TIỀN | G6: KÝ NHẬN
A7: 1 | B7: Phạm Việt Triều | C7: Bác sĩ | D7: 102006610216 | E7: =SUM(SUMIF(phauthuat_BHYT!$H$8:$H$104,"TRIỀU",phauthuat_BHYT!$I$8:$I$104),SUMIF(phauthuat_BHYT!$J$8:$J$104,"TRIỀU",phauthuat_BHYT!$K$8:$K$104),SUMIF(phauthuat_BHYT!$L$8:$L$104,"TRIỀU",phauthuat_BHYT!$M$8:$M$104)) -> 420000 | F7: =E7 -> 420000
A8: 2 | B8: Nguyễn Thành Tấn | C8: Bác sĩ | D8: 103006610215 | E8: =SUM(SUMIF(phauthuat_BHYT!$H$8:$H$104,"TẤN",phauthuat_BHYT!$I$8:$I$104),SUMIF(phauthuat_BHYT!$J$8:$J$104,"TẤN",phauthuat_BHYT!$K$8:$K$104),SUMIF(phauthuat_BHYT!$L$8:$L$104,"TẤN",phauthuat_BHYT!$M$8:$M$104)) -> 517500 | F8: =E8 -> 517500
