Workbook

Sheet phauthuat
A1: BV TRƯỜNG ĐHYD CẦN THƠ
A2: KHOA NGOẠI CTCH - TK
A3: BẢNG KÊ TIỀN PHẪU THUẬT
A4: (THÁNG 4/2025)
A6: STT | B6: Ngày | C6: Họ Tên | D6: Nam | E6: Nữ | F6: Phương pháp phẫu thuật | G6: Loại PT | H6: Giá Phẫu thuật thực tính | I6: PTV chính | J6: Số tiền | K6: Phụ mổ 1 | L6: Số tiền | M6: Phụ mổ 2 | N6: Số tiền | O6: Phụ mổ 3 | P6: Số tiền | Q6: ĐD + HL | R6: Thực lãnh
A7: 1 | B7: 18/3/2025 | C7: Trương Quốc Sách | D7: 51 | F7: Cắt lọc hoại tử ổ loét mạn tính | G7: TT2 | H7: 2128200 | I7: GIÀU | J7: =R7-L7-N7-P7-Q7 -> 244743 | K7: Đ.KHANG | L7: =IF(K7="-",0,H7*0.03) -> 63846 | M7: NHỊ | N7: =IF(M7="-",0,H7*0.02) -> 42564 | O7: - | P7: =IF(O7="-",0,H7*0.01) -> 0 | Q7: =H7*0.005 -> 10641 | R7: =IF(I7="V.Tân",H7*0.1375,IF(I7="nguyện",H7*0.1375,IF(I7="TOẢN",H7*0.1375,H7*0.17))) -> 361794
A8: 2 | B8: 22/3/2025 | C8: Trương Quốc Sách | D8: 51 | F8: Cắt lọc hoại tử ổ loét mạn tính | G8: TT2 | H8: 2128200 | I8: GIÀU | J8: =R8-L8-N8-P8-Q8 -> 223461 | K8: Đ.KHANG | L8: =IF(K8="-",0,H8*0.03) -> 63846 | M8: TÙNG | N8: =IF(M8="-",0,H8*0.02) -> 42564 | O8: NGHĨA | P8: =IF(O8="-",0,H8*0.01) -> 21282 | Q8: =H8*0.005 -> 10641 | R8: =IF(I8="V.Tân",H8*0.1375,IF(I8="nguyện",H8*0.1375,IF(I8="TOẢN",H8*0.1375,H8*0.17))) -> 361794
A9: 3 | B9: 25/3/2025 | C9: Nguyễn Văn Beo | D9: 72 | F9: PT viêm xương | G9: TT2 | H9: 2760100 | I9: NGUYỆN | J9: =R9-L9-N9-P9-Q9 -> 227708.25 | K9: TUẤN | L9: =IF(K9="-",0,H9*0.03) -> 82803 | M9: THÁI | N9: =IF(M9="-",0,H9*0.02) -> 55202 | O9: - | P9: =IF(O9="-",0,H9*0.01) -> 0 | Q9: =H9*0.005 -> 13800.5 | R9: =IF(I9="V.Tân",H9*0.1375,IF(I9="nguyện",H9*0.1375,IF(I9="TOẢN",H9*0.1375,H9*0.17))) -> 379513.75
A10: 4 | B10: 28/3/2025 | C10: Lê Ngọc Trúc | E10: 60 | F10: KHX trên màn hình tăng sáng | G10: TTDB | H10: 4497500 | I10: TẤN | J10: =R10-L10-N10-P10-Q10 -> 472237.5 | K10: V.TÂN | L10: =IF(K10="-",0,H10*0.03) -> 134925 | M10: ĐẠT | N10: =IF(M10="-",0,H10*0.02) -> 89950 | O10: T.HƯỞNG | P10: =IF(O10="-",0,H10*0.01) -> 44975 | Q10: =H10*0.005 -> 22487.5 | R10: =IF(I10="V.Tân",H10*0.1375,IF(I10="nguyện",H10*0.1375,IF(I10="TOẢN",H10*0.1375,H10*0.17))) -> 764575
A11: 5 | B11: 28/3/2025 | C11: Huỳnh Hữu Trọng | D11: 26 | F11: KHX trên màn hình tăng sáng | G11: TP | H11: 9972000 | I11: TOẢN | J11: =R11-L11-N11-P11-Q11 -> 722970 | K11: ĐẠT | L11: =IF(K11="-",0,H11*0.03) -> 299160 | M11: T.HƯỞNG | N11: =IF(M11="-",0,H11*0.02) -> 199440 | O11: V.HƯỞNG | P11: =IF(O11="-",0,H11*0.01) -> 99720 | Q11: =H11*0.005 -> 49860 | R11: =IF(I11="V.Tân",H11*0.1375,IF(I11="nguyện",H11*0.1375,IF(I11="TOẢN",H11*0.1375,H11*0.17))) -> 1371150
A12: 6 | B12: 28/3/2025 | C12: Huỳnh Hữu Trọng | D12: 26 | F12: KHX bánh chè (50%) | G12: TP | H12: 3000000 | I12: TOẢN | J12: =R12-L12-N12-P12-Q12 -> 217500 | K12: ĐẠT | L12: =IF(K12="-",0,H12*0.03) -> 90000 | M12: T.HƯỞNG | N12: =IF(M12="-",0,H12*0.02) -> 60000 | O12: V.HƯỞNG | P12: =IF(O12="-",0,H12*0.01) -> 30000 | Q12: =H12*0.005 -> 15000 | R12: =IF(I12="V.Tân",H12*0.1375,IF(I12="nguyện",H12*0.1375,IF(I12="TOẢN",H12*0.1375,H12*0.17))) -> 412500
A13: 7 | B13: 31/03/2025 | C13: Dương Hoàng Thiện | D13: 40 | F13: Cắt lọc hoại tử ổ loét vết thương mạn tính | G13: TT2 | H13: 2128200 | I13: TOẢN | J13: =R13-L13-N13-P13-Q13 -> 154294.5 | K13: TUẤN | L13: =IF(K13="-",0,H13*0.03) -> 63846 | M13: Đ.KHANG | N13: =IF(M13="-",0,H13*0.02) -> 42564 | O13: NGHĨA | P13: =IF(O13="-",0,H13*0.01) -> 21282 | Q13: =H13*0.005 -> 10641 | R13: =IF(I13="V.Tân",H13*0.1375,IF(I13="nguyện",H13*0.1375,IF(I13="TOẢN",H13*0.1375,H13*0.17))) -> 292627.5
A14: 8 | B14: 31/03/2025 | C14: Võ Hoàng Quân | D14: 56 | F14: PT KHX trên màn hình tăng sáng | G14: TTDB | H14: 4497500 | I14: ĐIỀN | J14: =R14-L14-N14-P14-Q14 -> 472237.5 | K14: TÙNG | L14: =IF(K14="-",0,H14*0.03) -> 134925 | M14: KHÉN | N14: =IF(M14="-",0,H14*0.02) -> 89950 | O14: V.HƯỞNG | P14: =IF(O14="-",0,H14*0.01) -> 44975 | Q14: =H14*0.005 -> 22487.5 | R14: =IF(I14="V.Tân",H14*0.1375,IF(I14="nguyện",H14*0.1375,IF(I14="TOẢN",H14*0.1375,H14*0.17))) -> 764575
A15: 9 | B15: 31/03/2025 | C15: LÊ TẤN KHANH | D15: 62 | F15: Cắt lọc hoại tử ổ loét vết thương mạn tính | G15: TT2 | H15: 2128200 | I15: V.TÂN | J15: =R15-L15-N15-P15-Q15 -> 175576.5 | K15: KHÉN | L15: =IF(K15="-",0,H15*0.03) -> 63846 | M15: NHỊ | N15: =IF(M15="-",0,H15*0.02) -> 42564 | O15: - | P15: =IF(O15="-",0,H15*0.01) -> 0 | Q15: =H15*0.005 -> 10641 | R15: =IF(I15="V.Tân",H15*0.1375,IF(I15="nguyện",H15*0.1375,IF(I15="TOẢN",H15*0.1375,H15*0.17))) -> 292627.5
A16: 10 | B16: 31/03/2025 | C16: Trương Quốc Sách | D16: 51 | F16: Ghép da | G16: TT2 | H16: 1955100 | I16: GIÀU | J16: =R16-L16-N16-P16-Q16 -> 224836.5 | K16: LUẬT | L16: =IF(K16="-",0,H16*0.03) -> 58653 | M16: V.HƯỞNG | N16: =IF(M16="-",0,H16*0.02) -> 39102 | O16: - | P16: =IF(O16="-",0,H16*0.01) -> 0 | Q16: =H16*0.005 -> 9775.5 | R16: =IF(I16="V.Tân",H16*0.1375,IF(I16="nguyện",H16*0.1375,IF(I16="TOẢN",H16*0.1375,H16*0.17))) -> 332367
A17: 11 | B17: 31/03/2025 | C17: Nguyễn Văn Minh | D17: 59 | F17: PT KHX trên màn hình tăng sáng | G17: TTDB | H17: 4497500 | I17: GIÀU | J17: =R17-L17-N17-P17-Q17 -> 472237.5 | K17: TÙNG | L17: =IF(K17="-",0,H17*0.03) -> 134925 | M17: KHÉN | N17: =IF(M17="-",0,H17*0.02) -> 89950 | O17: LUẬT | P17: =IF(O17="-",0,H17*0.01) -> 44975 | Q17: =H17*0.005 -> 22487.5 | R17: =IF(I17="V.Tân",H17*0.1375,IF(I17="nguyện",H17*0.1375,IF(I17="TOẢN",H17*0.1375,H17*0.17))) -> 764575
A18: 12 | B18: 01/4/2025 | C18: Hồ Minh Tuấn | D18: 38 | F18: PT KHX trên màn hình tăng sáng | G18: TTDB | H18: 4497500 | I18: GIÀU | J18: =R18-L18-N18-P18-Q18 -> 472237.5 | K18: TUẤN | L18: =IF(K18="-",0,H18*0.03) -> 134925 | M18: T.HƯỞNG | N18: =IF(M18="-",0,H18*0.02) -> 89950 | O18: N.KHANG | P18: =IF(O18="-",0,H18*0.01) -> 44975 | Q18: =H18*0.005 -> 22487.5 | R18: =IF(I18="V.Tân",H18*0.1375,IF(I18="nguyện",H18*0.1375,IF(I18="TOẢN",H18*0.1375,H18*0.17))) -> 764575
A19: 13 | B19: 01/4/2025 | C19: Hồ Minh Tuấn | D19: 38 | F19: PT KHX trên màn hình tăng sáng | G19: TTDB | H19: 2248750 | I19: GIÀU | J19: =R19-L19-N19-P19-Q19 -> 258606.25 | K19: TOẢN | L19: =IF(K19="-",0,H19*0.03) -> 67462.5 | M19: LUẬT | N19: =IF(M19="-",0,H19*0.02) -> 44975 | O19: - | P19: =IF(O19="-",0,H19*0.01) -> 0 | Q19: =H19*0.005 -> 11243.75 | R19: =IF(I19="V.Tân",H19*0.1375,IF(I19="nguyện",H19*0.1375,IF(I19="TOẢN",H19*0.1375,H19*0.17))) -> 382287.5
A20: 14 | B20: 01/4/2025 | C20: Nguyễn Trọng Nghĩa | D20: 36 | F20: PT KHX trên màn hình tăng sáng | G20: TP | H20: 9972000 | I20: TẤN | J20: =R20-L20-N20-P20-Q20 -> 1047060 | K20: NGUYỆN | L20: =IF(K20="-",0,H20*0.03) -> 299160 | M20: TOẢN | N20: =IF(M20="-",0,H20*0.02) -> 199440 | O20: KHÉN | P20: =IF(O20="-",0,H20*0.01) -> 99720 | Q20: =H20*0.005 -> 49860 | R20: =IF(I20="V.Tân",H20*0.1375,IF(I20="nguyện",H20*0.1375,IF(I20="TOẢN",H20*0.1375,H20*0.17))) -> 1695240
A21: 15 | B21: 01/4/2025 | C21: Huỳnh Thị Nhung | E21: 73 | F21: PT cắt cụt chi | G21: TT2 | H21: 1947600 | I21: V.TÂN | J21: =R21-L21-N21-P21-Q21 -> 160677 | K21: THÁI | L21: =IF(K21="-",0,H21*0.03) -> 58428 | M21: KHÉN | N21: =IF(M21="-",0,H21*0.02) -> 38952 | O21: - | P21: =IF(O21="-",0,H21*0.01) -> 0 | Q21: =H21*0.005 -> 9738 | R21: =IF(I21="V.Tân",H21*0.1375,IF(I21="nguyện",H21*0.1375,IF(I21="TOẢN",H21*0.1375,H21*0.17))) -> 267795
A22: 16 | B22: 01/4/2025 | C22: Nguyễn Hữu Thọ | D22: 24 | F22: Lấy DC KHX | G22: TT2 | H22: 2559100 | I22: V.TÂN | J22: =R22-L22-N22-P22-Q22 -> 185534.75 | K22: KHÉN | L22: =IF(K22="-",0,H22*0.03) -> 76773 | M22: THÁI | N22: =IF(M22="-",0,H22*0.02) -> 51182 | O22: V.HƯỞNG | P22: =IF(O22="-",0,H22*0.01) -> 25591 | Q22: =H22*0.005 -> 12795.5 | R22: =IF(I22="V.Tân",H22*0.1375,IF(I22="nguyện",H22*0.1375,IF(I22="TOẢN",H22*0.1375,H22*0.17))) -> 351876.25
A23: 17 | B23: 01/4/2025 | C23: Huỳnh Kim Hường | E23: 60 | F23: PT KHX trên màn hình tăng sáng | G23: TP | H23: 9972000 | I23: V.TÂN | J23: =R23-L23-N23-P23-Q23 -> 822690 | K23: TUẤN | L23: =IF(K23="-",0,H23*0.03) -> 299160 | M23: T.HƯỞNG | N23: =IF(M23="-",0,H23*0.02) -> 199440 | O23: - | P23: =IF(O23="-",0,H23*0.01) -> 0 | Q23: =H23*0.005 -> 49860 | R23: =IF(I23="V.Tân",H23*0.1375,IF(I23="nguyện",H23*0.1375,IF(I23="TOẢN",H23*0.1375,H23*0.17))) -> 1371150
A24: 18 | B24: 01/4/2025 | C24: Trần Thị Hồng Gấm | E24: 22 | F24: Lấy DC KHX | G24: TT2 | H24: 2559100 | I24: GIÀU | J24: =R24-L24-N24-P24-Q24 -> 268705.5 | K24: TUẤN | L24: =IF(K24="-",0,H24*0.03) -> 76773 | M24: Đ.KHANG | N24: =IF(M24="-",0,H24*0.02) -> 51182 | O24: V.HƯỞNG | P24: =IF(O24="-",0,H24*0.01) -> 25591 | Q24: =H24*0.005 -> 12795.5 | R24: =IF(I24="V.Tân",H24*0.1375,IF(I24="nguyện",H24*0.1375,IF(I24="TOẢN",H24*0.1375,H24*0.17))) -> 435047
A25: 19 | B25: 01/4/2025 | C25: Nguyễn Thanh Quang | D25: 45 | F25: PT vết thương phần mềm phức tạp | G25: TT1 | H25: 795400 | I25: V.TÂN | J25: =R25-L25-N25-P25-Q25 -> 57666.5 | K25: ĐẠT | L25: =IF(K25="-",0,H25*0.03) -> 23862 | M25: TÙNG | N25: =IF(M25="-",0,H25*0.02) -> 15908 | O25: NHỊ | P25: =IF(O25="-",0,H25*0.01) -> 7954 | Q25: =H25*0.005 -> 3977 | R25: =IF(I25="V.Tân",H25*0.1375,IF(I25="nguyện",H25*0.1375,IF(I25="TOẢN",H25*0.1375,H25*0.17))) -> 109367.5
A26: 20 | B26: 01/4/2025 | C26: Lê Thị Phước | E26: 74 | F26: Cắt lọc hoại tử ổ loét vết thương mạn tính | G26: TT2 | H26: 2127400 | I26: ĐIỀN | J26: =R26-L26-N26-P26-Q26 -> 244651 | K26: KHÉN | L26: =IF(K26="-",0,H26*0.03) -> 63822 | M26: THÁI | N26: =IF(M26="-",0,H26*0.02) -> 42548 | O26: - | P26: =IF(O26="-",0,H26*0.01) -> 0 | Q26: =H26*0.005 -> 10637 | R26: =IF(I26="V.Tân",H26*0.1375,IF(I26="nguyện",H26*0.1375,IF(I26="TOẢN",H26*0.1375,H26*0.17))) -> 361658
A27: 21 | B27: 02/4/2025 | C27: Nguyễn Thị Thia | E27: 67 | F27: PT KHX trên màn hình tăng sáng | G27: TTDB | H27: 4497500 | I27: V.TÂN | J27: =R27-L27-N27-P27-Q27 -> 326068.75 | K27: GIÀU | L27: =IF(K27="-",0,H27*0.03) -> 134925 | M27: TUẤN | N27: =IF(M27="-",0,H27*0.02) -> 89950 | O27: Đ.KHANG | P27: =IF(O27="-",0,H27*0.01) -> 44975 | Q27: =H27*0.005 -> 22487.5 | R27: =IF(I27="V.Tân",H27*0.1375,IF(I27="nguyện",H27*0.1375,IF(I27="TOẢN",H27*0.1375,H27*0.17))) -> 618406.25
A28: 22 | B28: 02/4/2025 | C28: Nguyễn Văn Tùng | D28: 49 | F28: Cắt lọc hoại tử ổ loét vết thương mạn tính | G28: TT2 | H28: 2128200 | I28: TOẢN | J28: =R28-L28-N28-P28-Q28 -> 175576.5 | K28: TUẤN | L28: =IF(K28="-",0,H28*0.03) -> 63846 | M28: KHÉN | N28: =IF(M28="-",0,H28*0.02) -> 42564 | O28: - | P28: =IF(O28="-",0,H28*0.01) -> 0 | Q28: =H28*0.005 -> 10641 | R28: =IF(I28="V.Tân",H28*0.1375,IF(I28="nguyện",H28*0.1375,IF(I28="TOẢN",H28*0.1375,H28*0.17))) -> 292627.5
A29: 23 | B29: 02/4/2025 | C29: Thị Đẹp | E29: 88 | F29: PT KHX trên màn hình tăng sáng | G29: TTDB | H29: 4497500 | I29: ĐIỀN | J29: =R29-L29-N29-P29-Q29 -> 472237.5 | K29: TUẤN | L29: =IF(K29="-",0,H29*0.03) -> 134925 | M29: T.HƯỞNG | N29: =IF(M29="-",0,H29*0.02) -> 89950 | O29: TÙNG | P29: =IF(O29="-",0,H29*0.01) -> 44975 | Q29: =H29*0.005 -> 22487.5 | R29: =IF(I29="V.Tân",H29*0.1375,IF(I29="nguyện",H29*0.1375,IF(I29="TOẢN",H29*0.1375,H29*0.17))) -> 764575
A30: 24 | B30: 02/4/2025 | C30: Lê Hữu Trí | E30: 31 | F30: Rút nẹp, dụng cụ KHX | G30: TT2 | H30: 2559100 | I30: GIÀU | J30: =R30-L30-N30-P30-Q30 -> 268705.5 | K30: TUẤN | L30: =IF(K30="-",0,H30*0.03) -> 76773 | M30: Đ.KHANG | N30: =IF(M30="-",0,H30*0.02) -> 51182 | O30: V.HƯỞNG | P30: =IF(O30="-",0,H30*0.01) -> 25591 | Q30: =H30*0.005 -> 12795.5 | R30: =IF(I30="V.Tân",H30*0.1375,IF(I30="nguyện",H30*0.1375,IF(I30="TOẢN",H30*0.1375,H30*0.17))) -> 435047
A31: 25 | B31: 03/4/2025 | C31: Nguyễn Vũ Ca | D31: 42 | F31: PT KHX trên màn hình tăng sáng | G31: TTDB | H31: 4497500 | I31: GIÀU | J31: =R31-L31-N31-P31-Q31 -> 472237.5 | K31: TUẤN | L31: =IF(K31="-",0,H31*0.03) -> 134925 | M31: TÙNG | N31: =IF(M31="-",0,H31*0.02) -> 89950 | O31: LUẬT | P31: =IF(O31="-",0,H31*0.01) -> 44975 | Q31: =H31*0.005 -> 22487.5 | R31: =IF(I31="V.Tân",H31*0.1375,IF(I31="nguyện",H31*0.1375,IF(I31="TOẢN",H31*0.1375,H31*0.17))) -> 764575
A32: 26 | B32: 03/4/2025 | C32: TRẦN THỊ HỒNG THẮM | E32: 23 | F32: PT KHX gãy mỏm khuỷu | G32: TP | H32: 6000000 | I32: V.TÂN | J32: =R32-L32-N32-P32-Q32 -> 435000 | K32: TUẤN | L32: =IF(K32="-",0,H32*0.03) -> 180000 | M32: ĐẠT | N32: =IF(M32="-",0,H32*0.02) -> 120000 | O32: TÙNG | P32: =IF(O32="-",0,H32*0.01) -> 60000 | Q32: =H32*0.005 -> 30000 | R32: =IF(I32="V.Tân",H32*0.1375,IF(I32="nguyện",H32*0.1375,IF(I32="TOẢN",H32*0.1375,H32*0.17))) -> 825000
A33: 27 | B33: 03/4/2025 | C33: Lý Minh Quyền | D33: 27 | F33: Lấy DC KHX | G33: TT2 | H33: 2559100 | I33: ĐIỀN | J33: =R33-L33-N33-P33-Q33 -> 294296.5 | K33: LUẬT | L33: =IF(K33="-",0,H33*0.03) -> 76773 | M33: NGHĨA | N33: =IF(M33="-",0,H33*0.02) -> 51182 | O33: - | P33: =IF(O33="-",0,H33*0.01) -> 0 | Q33: =H33*0.005 -> 12795.5 | R33: =IF(I33="V.Tân",H33*0.1375,IF(I33="nguyện",H33*0.1375,IF(I33="TOẢN",H33*0.1375,H33*0.17))) -> 435047
A34: 28 | B34: 04/4/2025 | C34: Lê Thị Phước | E34: 74 | F34: Cắt lọc hoại tử ổ loét vết thương mạn tính | G34: TT2 | H34: 2127400 | I34: V.TÂN | J34: =R34-L34-N34-P34-Q34 -> 175510.5 | K34: KHÉN | L34: =IF(K34="-",0,H34*0.03) -> 63822 | M34: Đ.KHANG | N34: =IF(M34="-",0,H34*0.02) -> 42548 | O34: - | P34: =IF(O34="-",0,H34*0.01) -> 0 | Q34: =H34*0.005 -> 10637 | R34: =IF(I34="V.Tân",H34*0.1375,IF(I34="nguyện",H34*0.1375,IF(I34="TOẢN",H34*0.1375,H34*0.17))) -> 292517.5
A35: 29 | B35: 05/04/2025 | C35: Nguyễn Thị Mỹ | E35: 88 | F35: PT thay khớp háng bán phần | G35: TT1 | H35: 3897500 | I35: TẤN | J35: =R35-L35-N35-P35-Q35 -> 409237.5 | K35: NGUYỆN | L35: =IF(K35="-",0,H35*0.03) -> 116925 | M35: TUẤN | N35: =IF(M35="-",0,H35*0.02) -> 77950 | O35: THÁI | P35: =IF(O35="-",0,H35*0.01) -> 38975 | Q35: =H35*0.005 -> 19487.5 | R35: =IF(I35="V.Tân",H35*0.1375,IF(I35="nguyện",H35*0.1375,IF(I35="TOẢN",H35*0.1375,H35*0.17))) -> 662575
A36: 30 | B36: 07/4/2025 | C36: Trương Bích Ngọc | E36: 72 | F36: Cắt u lành phần mềm > 10cm | G36: TT1 | H36: 1859300 | I36: ĐIỀN | J36: =R36-L36-N36-P36-Q36 -> 213819.5 | K36: T.HƯỞNG | L36: =IF(K36="-",0,H36*0.03) -> 55779 | M36: KHÉN | N36: =IF(M36="-",0,H36*0.02) -> 37186 | O36: - | P36: =IF(O36="-",0,H36*0.01) -> 0 | Q36: =H36*0.005 -> 9296.5 | R36: =IF(I36="V.Tân",H36*0.1375,IF(I36="nguyện",H36*0.1375,IF(I36="TOẢN",H36*0.1375,H36*0.17))) -> 316081
A37: 31 | B37: 08/04/2025 | C37: Trần Văn Thu | D37: 97 | F37: PT thay khớp háng bán phần | G37: TT1 | H37: 3897500 | I37: NGUYỆN | J37: =R37-L37-N37-P37-Q37 -> 282568.75 | K37: TÙNG | L37: =IF(K37="-",0,H37*0.03) -> 116925 | M37: Đ.KHANG | N37: =IF(M37="-",0,H37*0.02) -> 77950 | O37: NHỊ | P37: =IF(O37="-",0,H37*0.01) -> 38975 | Q37: =H37*0.005 -> 19487.5 | R37: =IF(I37="V.Tân",H37*0.1375,IF(I37="nguyện",H37*0.1375,IF(I37="TOẢN",H37*0.1375,H37*0.17))) -> 535906.25
A38: 32 | B38: 08/04/2025 | C38: Võ Thị Thúy Kiều | E38: 32 | F38: KHX trên màn hình tăng sáng | G38: TTDB | H38: 4497500 | I38: TOẢN | J38: =R38-L38-N38-P38-Q38 -> 326068.75 | K38: Đ.KHANG | L38: =IF(K38="-",0,H38*0.03) -> 134925 | M38: TÙNG | N38: =IF(M38="-",0,H38*0.02) -> 89950 | O38: NHỊ | P38: =IF(O38="-",0,H38*0.01) -> 44975 | Q38: =H38*0.005 -> 22487.5 | R38: =IF(I38="V.Tân",H38*0.1375,IF(I38="nguyện",H38*0.1375,IF(I38="TOẢN",H38*0.1375,H38*0.17))) -> 618406.25
A39: 33 | B39: 09/04/2025 | C39: Trần Thị Hiến | E39: 73 | F39: Thay toàn bộ khớp gối | G39: TTDB | H39: 3525500 | I39: TẤN | J39: =R39-L39-N39-P39-Q39 -> 370177.5 | K39: TOẢN | L39: =IF(K39="-",0,H39*0.03) -> 105765 | M39: TUẤN | N39: =IF(M39="-",0,H39*0.02) -> 70510 | O39: ĐẠT | P39: =IF(O39="-",0,H39*0.01) -> 35255 | Q39: =H39*0.005 -> 17627.5 | R39: =IF(I39="V.Tân",H39*0.1375,IF(I39="nguyện",H39*0.1375,IF(I39="TOẢN",H39*0.1375,H39*0.17))) -> 599335
A40: 34 | B40: 09/04/2025 | C40: Nguyễn Hoàng Ly | E40: 40 | F40: PT giải ép thần kinh | G40: TT1 | H40: 2301200 | I40: TOẢN | J40: =R40-L40-N40-P40-Q40 -> 189849 | K40: THÁI | L40: =IF(K40="-",0,H40*0.03) -> 69036 | M40: KHÉN | N40: =IF(M40="-",0,H40*0.02) -> 46024 | O40: - | P40: =IF(O40="-",0,H40*0.01) -> 0 | Q40: =H40*0.005 -> 11506 | R40: =IF(I40="V.Tân",H40*0.1375,IF(I40="nguyện",H40*0.1375,IF(I40="TOẢN",H40*0.1375,H40*0.17))) -> 316415
A41: 35 | B41: 09/04/2025 | C41: Hồ Hoàng Anh | D41: 44 | F41: Cắt lọc hoại tử ổ loét vết thương mạn tính | G41: TT2 | H41: 2128200 | I41: V.TÂN | J41: =R41-L41-N41-P41-Q41 -> 175576.5 | K41: Đ.KHANG | L41: =IF(K41="-",0,H41*0.03) -> 63846 | M41: KHÉN | N41: =IF(M41="-",0,H41*0.02) -> 42564 | O41: - | P41: =IF(O41="-",0,H41*0.01) -> 0 | Q41: =H41*0.005 -> 10641 | R41: =IF(I41="V.Tân",H41*0.1375,IF(I41="nguyện",H41*0.1375,IF(I41="TOẢN",H41*0.1375,H41*0.17))) -> 292627.5
...

Sheet lanh tien PT
A1: BV TRƯỜNG ĐHYD CẦN THƠ
A2: KHOA NGOẠI CTCH-TK
B3: DANH SÁCH LÃNH TIỀN THÙ LAO THÁNG 4/2025
C4: (Phẫu thuật)
A6: STT | B6: HỌ TÊN | C6: chức vụ | D6: SỐ TIỀN | E6: KÝ NHẬN
A7: 1 | B7: Phạm Việt Triều | C7: Bác sĩ | D7: =SUM(SUMIF(phauthuat!$I$7:$I$102,"TRIỀU",phauthuat!$J$7:$J$102),SUMIF(phauthuat!$K$7:$K$102,"TRIỀU",phauthuat!$L$7:$L$102),SUMIF(phauthuat!$M$7:$M$102,"TRIỀU",phauthuat!$N$7:$N$102),SUMIF(phauthuat!$O$7:$O$102,"TRIỀU",phauthuat!$P$7:$P$102)) -> 223377
A8: 2 | B8: Nguyễn Thành Tấn | C8: Bác sĩ | D8: =SUM(SUMIF(phauthuat!$I$7:$I$102,"TẤN",phauthuat!$J$7:$J$102),SUMIF(phauthuat!$K$7:$K$102,"TẤN",phauthuat!$L$7:$L$102),SUMIF(phauthuat!$M$7:$M$102,"TẤN",phauthuat!$N$7:$N$102),SUMIF(phauthuat!$O$7:$O$102,"TẤN",phauthuat!$P$7:$P$102)) -> 4152870.8
A9: 3 | B9: Nguyễn Lê Hoan | C9: Bác sĩ | D9: =SUM(SUMIF(phauthuat!$I$7:$I$102,"HOAN",phauthuat!$J$7:$J$102),SUMIF(phauthuat!$K$7:$K$102,"HOAN",phauthuat!$L$7:$L$102),SUMIF(phauthuat!$M$7:$M$102,"HOAN",phauthuat!$N$7:$N$102),SUMIF(phauthuat!$O$7:$O$102,"TẤN",phauthuat!$P$7:$P$102)) -> 0
A10: 4 | B10: Nguyễn Chí Nguyện | C10: Bác sĩ | D10: =SUM(SUMIF(phauthuat!$I$7:$I$102,"NGUYỆN",phauthuat!$J$7:$J$102),SUMIF(phauthuat!$K$7:$K$102,"NGUYỆN",phauthuat!$L$7:$L$102),SUMIF(phauthuat!$M$7:$M$102,"NGUYỆN",phauthuat!$N$7:$N$102),SUMIF(phauthuat!$O$7:$O$102,"NGUYỆN",phauthuat!$P$7:$P$102)) -> 4107517.5
A11: 5 | B11: Đặng Phước Giàu | C11: Bác sĩ | D11: =SUM(SUMIF(phauthuat!$I$7:$I$102,"GIÀU",phauthuat!$J$7:$J$102),SUMIF(phauthuat!$K$7:$K$102,"GIÀU",phauthuat!$L$7:$L$102),SUMIF(phauthuat!$M$7:$M$102,"GIÀU",phauthuat!$N$7:$N$102),SUMIF(phauthuat!$O$7:$O$102,"GIÀU",phauthuat!$P$7:$P$102)) -> 9701269.8
A12: 6 | B12: Hồ Điền | C12: Bác sĩ | D12: =SUM(SUMIF(phauthuat!$I$7:$I$102,"ĐIỀN",phauthuat!$J$7:$J$102),SUMIF(phauthuat!$K$7:$K$102,"ĐIỀN",phauthuat!$L$7:$L$102),SUMIF(phauthuat!$M$7:$M$102,"ĐIỀN",phauthuat!$N$7:$N$102),SUMIF(phauthuat!$O$7:$O$102,"ĐIỀN",phauthuat!$P$7:$P$102)) -> 5410189.5
A13: 7 | B13: Trần Quốc Toản | C13: Bác sĩ | D13: =SUM(SUMIF(phauthuat!$I$7:$I$102,"TOẢN",phauthuat!$J$7:$J$102),SUMIF(phauthuat!$K$7:$K$102,"TOẢN",phauthuat!$L$7:$L$102),SUMIF(phauthuat!$M$7:$M$102,"TOẢN",phauthuat!$N$7:$N$102),SUMIF(phauthuat!$O$7:$O$102,"TOẢN",phauthuat!$P$7:$P$102)) -> 5098173.8
A14: 8 | B14: Phạm Việt Tân | C14: Bác sĩ | D14: =SUM(SUMIF(phauthuat!$I$7:$I$102,"V.TÂN",phauthuat!$J$7:$J$102),SUMIF(phauthuat!$K$7:$K$102,"V.TÂN",phauthuat!$L$7:$L$102),SUMIF(phauthuat!$M$7:$M$102,"V.TÂN",phauthuat!$N$7:$N$102),SUMIF(phauthuat!$O$7:$O$102,"V.TÂN",phauthuat!$P$7:$P$102)) -> 4617144.5
A15: 9 | B15: Bùi Công Minh | C15: Bác sĩ | D15: =SUM(SUMIF(phauthuat!$I$7:$I$102,"MINH",phauthuat!$J$7:$J$102),SUMIF(phauthuat!$K$7:$K$102,"MINH",phauthuat!$L$7:$L$102),SUMIF(phauthuat!$M$7:$M$102,"MINH",phauthuat!$N$7:$N$102),SUMIF(phauthuat!$O$7:$O$102,"MINH",phauthuat!$P$7:$P$102)) -> 0
A16: 10 | B16: Phan Văn Tuấn | C16: Bác sĩ | D16: =SUM(SUMIF(phauthuat!$I$7:$I$102,"TUẤN",phauthuat!$J$7:$J$102),SUMIF(phauthuat!$K$7:$K$102,"TUẤN",phauthuat!$L$7:$L$102),SUMIF(phauthuat!$M$7:$M$102,"TUẤN",phauthuat!$N$7:$N$102),SUMIF(phauthuat!$O$7:$O$102,"TUẤN",phauthuat!$P$7:$P$102)) -> 4184653
A17: 11 | B17: Nguyễn Hữu Đạt | C17: Bác sĩ | D17: =SUM(SUMIF(phauthuat!$I$7:$I$102,"Đạt",phauthuat!$J$7:$J$102),SUMIF(phauthuat!$K$7:$K$102,"Đạt",phauthuat!$L$7:$L$102),SUMIF(phauthuat!$M$7:$M$102,"Đạt",phauthuat!$N$7:$N$102),SUMIF(phauthuat!$O$7:$O$102,"Đạt",phauthuat!$P$7:$P$102)) -> 1410245
A18: 12 | B18: Võ Dương Thành Thái | C18: Bác sĩ (nt) | D18: =SUM(SUMIF(phauthuat!$I$7:$I$102,"thái",phauthuat!$J$7:$J$102),SUMIF(phauthuat!$K$7:$K$102,"thái",phauthuat!$L$7:$L$102),SUMIF(phauthuat!$M$7:$M$102,"thái",phauthuat!$N$7:$N$102),SUMIF(phauthuat!$O$7:$O$102,"thái",phauthuat!$P$7:$P$102)) -> 1356722
A19: 13 | B19: Lê Đình Tùng | C19: Bác sĩ (nt) | D19: =SUM(SUMIF(phauthuat!$I$7:$I$102,"tùng",phauthuat!$J$7:$J$102),SUMIF(phauthuat!$K$7:$K$102,"tùng",phauthuat!$L$7:$L$102),SUMIF(phauthuat!$M$7:$M$102,"tùng",phauthuat!$N$7:$N$102),SUMIF(phauthuat!$O$7:$O$102,"tùng",phauthuat!$P$7:$P$102)) -> 1558429
A20: 14 | B20: Văn Minh Khén | C20: Bác sĩ (nt) | D20: =SUM(SUMIF(phauthuat!$I$7:$I$102,"khén",phauthuat!$J$7:$J$102),SUMIF(phauthuat!$K$7:$K$102,"khén",phauthuat!$L$7:$L$102),SUMIF(phauthuat!$M$7:$M$102,"khén",phauthuat!$N$7:$N$102),SUMIF(phauthuat!$O$7:$O$102,"khén",phauthuat!$P$7:$P$102)) -> 1522623
A21: 15 | B21: Phạm Tấn Hưởng | C21: Bác sĩ (nt) | D21: =SUM(SUMIF(phauthuat!$I$7:$I$102,"t.hưởng",phauthuat!$J$7:$J$102),SUMIF(phauthuat!$K$7:$K$102,"t.hưởng",phauthuat!$L$7:$L$102),SUMIF(phauthuat!$M$7:$M$102,"t.hưởng",phauthuat!$N$7:$N$102),SUMIF(phauthuat!$O$7:$O$102,"t.hưởng",phauthuat!$P$7:$P$102)) -> 1699823
A22: 16 | B22: Nguyễn Đông Khang | C22: Bác sĩ (nt) | D22: =SUM(SUMIF(phauthuat!$I$7:$I$102,"đ.khang",phauthuat!$J$7:$J$102),SUMIF(phauthuat!$K$7:$K$102,"đ.khang",phauthuat!$L$7:$L$102),SUMIF(phauthuat!$M$7:$M$102,"đ.khang",phauthuat!$N$7:$N$102),SUMIF(phauthuat!$O$7:$O$102,"đ.khang",phauthuat!$P$7:$P$102)) -> 1531328.5
A23: 17 | B23: Nguyễn Đình Luật | C23: Bác sĩ (nt) | D23: =SUM(SUMIF(phauthuat!$I$7:$I$102,"luật",phauthuat!$J$7:$J$102),SUMIF(phauthuat!$K$7:$K$102,"luật",phauthuat!$L$7:$L$102),SUMIF(phauthuat!$M$7:$M$102,"luật",phauthuat!$N$7:$N$102),SUMIF(phauthuat!$O$7:$O$102,"luật",phauthuat!$P$7:$P$102)) -> 704481
A24: 18 | B24: Nguyễn Trung Nhị | C24: Bác sĩ (nt) | D24: =SUM(SUMIF(phauthuat!$I$7:$I$102,"nhị",phauthuat!$J$7:$J$102),SUMIF(phauthuat!$K$7:$K$102,"nhị",phauthuat!$L$7:$L$102),SUMIF(phauthuat!$M$7:$M$102,"nhị",phauthuat!$N$7:$N$102),SUMIF(phauthuat!$O$7:$O$102,"nhị",phauthuat!$P$7:$P$102)) -> 239961
A25: 19 | B25: Trần Trung Nghĩa | C25: Bác sĩ (nt) | D25: =SUM(SUMIF(phauthuat!$I$7:$I$102,"nghĩa",phauthuat!$J$7:$J$102),SUMIF(phauthuat!$K$7:$K$102,"nghĩa",phauthuat!$L$7:$L$102),SUMIF(phauthuat!$M$7:$M$102,"nghĩa",phauthuat!$N$7:$N$102),SUMIF(phauthuat!$O$7:$O$102,"nghĩa",phauthuat!$P$7:$P$102)) -> 358409
A26: 20 | B26: Lê Nhỉ Khang | C26: Bác sĩ (nt) | D26: =SUM(SUMIF(phauthuat!$I$7:$I$102,"n.khang",phauthuat!$J$7:$J$102),SUMIF(phauthuat!$K$7:$K$102,"n.khang",phauthuat!$L$7:$L$102),SUMIF(phauthuat!$M$7:$M$102,"n.khang",phauthuat!$N$7:$N$102),SUMIF(phauthuat!$O$7:$O$102,"n.khang",phauthuat!$P$7:$P$102)) -> 337791
A27: 21 | B27: Phạm Văn Hưởng | C27: Bác sĩ (nt) | D27: =SUM(SUMIF(phauthuat!$I$7:$I$102,"v.hưởng",phauthuat!$J$7:$J$102),SUMIF(phauthuat!$K$7:$K$102,"v.hưởng",phauthuat!$L$7:$L$102),SUMIF(phauthuat!$M$7:$M$102,"v.hưởng",phauthuat!$N$7:$N$102),SUMIF(phauthuat!$O$7:$O$102,"v.hưởng",phauthuat!$P$7:$P$102)) -> 388432
A28: 22 | B28: Phan Văn Hiếu | C28: Điều dưỡng | D28: =phauthuat!Q100/8 -> 202721.75
A29: 23 | B29: Võ Thị Yến Nhi | C29: Điều dưỡng | D29: =D28 -> 202721.75
A30: 24 | B30: Võ Phương Duy | C30: Điều dưỡng | D30: =D29 -> 202721.75
A31: 25 | B31: Nguyễn Kim Ngân | C31: Điều dưỡng | D31: =D30 -> 202721.75
A32: 26 | B32: Lê Ngọc Diệu | C32: Điều dưỡng | D32: =D31 -> 202721.75
A33: 27 | B33: Trần Quỳnh Minh Thư | C33: Điều dưỡng | D33: =D32 -> 202721.75
A34: 28 | B34: Lê Thị Tuyết Đoan | C34: Điều dưỡng | D34: =D33 -> 202721.75
A35: 29 | B35: Thạch Thị Thúy Đa | C35: Điều dưỡng | D35: =D34 -> 202721.75
B36: TỔNG CỘNG | D36: =SUM(D7:D35) -> 50225214
D38: Cần Thơ, ngày 21 tháng 5 năm 2025
A39: Người lập bảng | D39: Trưởng khoa

Sheet Bác sĩ điều trị
A1: BV TRƯỜNG ĐHYD CẦN THƠ
A2: KHOA NGOẠI CTCH-TK
A3: DANH SÁCH LÃNH TIỀN THÙ LAO THÁNG 3/2025
A4: (BÁC SĨ ĐIỀU TRỊ)
A6: STT | B6: HỌ TÊN | C6: chức vụ | D6: SỐ TIỀN | E6: KÝ NHẬN
A7: 1 | B7: Phạm Việt Triều | C7: Bác sĩ | D7: -
A8: 2 | B8: Nguyễn Thành Tấn | C8: Bác sĩ | D8: -
A9: 3 | B9: Nguyễn Lê Hoan | C9: Bác sĩ | D9: 0
A10: 4 | B10: Trần Quang Sơn | C10: Bác sĩ | D10: -
A11: 5 | B11: Nguyễn Chí Nguyện | C11: Bác sĩ | D11: =17600000*0.25 -> 4400000
A12: 6 | B12: Bùi Công Minh | C12: Bác sĩ | D12: -
A13: 7 | B13: Hồ Điền | C13: Bác sĩ | D13: =17600000*0.25 -> 4400000
A14: 8 | B14: Phạm Việt Tân | C14: Bác sĩ | D14: =17600000*0.0625 -> 1100000
A15: 9 | B15: Đặng Phước Giàu | C15: Bác sĩ | D15: =17600000*0.125 -> 2200000
A16: 10 | B16: Trần Quốc Toản | C16: Bác sĩ | D16: =17600000*0.0625 -> 1100000
A17: 11 | B17: Nguyễn Hữu Đạt | C17: Bác sĩ | D17: =17600000*0.125 -> 2200000
A18: 12 | B18: Nguyễn Giang Tử | C18: Bác sĩ | D18: =17600000*0.125 -> 2200000
B19: TỔNG CỘNG | D19: =SUM(D7:D18) -> 17600000
D21: Cần Thơ, ngày 22 tháng 02 năm 2024
A22: Người lập bảng | D22: Trưởng khoa

Sheet lanh tien PT1
A1: BV TRƯỜNG ĐHYD CẦN THƠ
A2: KHOA NGOẠI CTCH-TK
B3: DANH SÁCH LÃNH TIỀN THÙ LAO THÁNG 3/2025
C4: (Phẫu thuật)
A6: STT | B6: HỌ TÊN | C6: chức vụ | D6: SỐ TIỀN | E6: KÝ NHẬN
A7: 1 | B7: Phạm Việt Triều | C7: Bác sĩ | D7: -
A8: 2 | B8: Nguyễn Thành Tấn | C8: Bác sĩ | D8: -
A9: 3 | B9: Lê Dũng | C9: Bác sĩ | D9: -
A10: 4 | B10: Nguyễn Lê Hoan | C10: Bác sĩ | D10: -
A11: 5 | B11: Nguyễn Tâm Từ | C11: Bác sĩ | D11: -
A12: 6 | B12: Hoàng Minh Tú | C12: Bác sĩ | D12: -
A13: 7 | B13: Nguyễn Hữu Thuyết | C13: Bác sĩ | D13: -
A14: 8 | B14: Nguyễn Thanh Huy | C14: Bác sĩ | D14: -
A15: 9 | B15: Trần Mạnh Dũng | C15: Bác sĩ | D15: -
A16: 10 | B16: Trần Quang Sơn | C16: Bác sĩ (nt) | D16: -
A17: 11 | B17: Lê Thế Hiển | C17: Bác sĩ (nt) | D17: -
A18: 12 | B18: Lê Minh Dương | C18: Bác sĩ (nt) | D18: -
G19: =274748+3211497+202722+75000 -> 3763967
A20: 1 | B20: Phan Văn Hiếu | C20: Điều dưỡng | D20: =G22+7560 -> 3177216.4 | G20: =G19*8 -> 30111736
A21: 2 | B21: Võ Thị Yến Nhi | C21: Điều dưỡng | D21: =D20 -> 3177216.4 | G21: =G20/19 -> 1584828.2
A22: 3 | B22: Nguyễn Kim Ngân | C22: Điều dưỡng | D22: =D20 -> 3177216.4 | G22: =G21*2 -> 3169656.4
A23: 4 | B23: Võ Phương Duy | C23: Điều dưỡng | D23: =D20 -> 3177216.4
A24: 5 | B24: Lê Ngọc Diệu | C24: Điều dưỡng | D24: =D20 -> 3177216.4
A25: 6 | B25: Trần Quỳnh Minh Thư | C25: Điều dưỡng | D25: =D20 -> 3177216.4
A26: 7 | B26: Lê Thị Tuyết Đoan | C26: Điều dưỡng | D26: =D20 -> 3177216.4
A27: 8 | B27: Thạch Thị Thúy Đa | C27: Điều dưỡng | D27: =D20 -> 3177216.4
A28: 9 | B28: Nguyễn Lê Duy Anh | C28: Điều dưỡng | D28: =G21+7563 -> 1592391.2 | G28: ='TONG LANH'!E44/11 -> 0
A29: 10 | B29: Lê Kim Hoàn | C29: Điều dưỡng | D29: =D28 -> 1592391.2
A30: 11 | B30: Nguyễn Thị Như Ý | C30: Hộ Lí | D30: =D29 -> 1592391.2
B31: TỔNG CỘNG | D31: =SUM(D20:D30) -> 30194905
D34: Cần Thơ, ngày 25 tháng 09 năm 2017
A35: Người lập bảng | D35: Trưởng khoa

Sheet phauthuat_BHYT
A1: BV TRƯỜNG ĐHYD CẦN THƠ
A2: KHOA NGOẠI CTCH-TK
B3: BẢNG KÊ TIỀN PHẪU THUẬT BHYT
A4: (THÁNG 4/2025)
A7: STT | B7: Ngày | C7: Họ và tên | D7: Nam | E7: Nữ | F7: Phương pháp phẫu thuật | G7: loại pt - đối tượng | H7: PTV chính | I7: Số tiền | J7: Phụ mổ 1 | K7: Số tiền | L7: Phụ mổ 2 | M7: Số tiền | N7: Tổng số tiền được lãnh sau trừ khấu hao
A8: 1 | B8: 26/3/2025 | C8: Nguyễn Văn Hoàng | D8: 53 | F8: KHX trên màn hình tăng sáng | G8: DTDB | H8: TOẢN | I8: =IF(G8="DTDB",420000,IF(G8="TTDB",420000,IF(G8="DT1",187500,IF(G8="TT1",187500,IF(G8="DT2",97500,IF(G8="TT2",97500,IF(G8="DT3",75000,75000))))))) -> 420000 | J8: ĐẠT | K8: =IF(G8="DTDB",300000,IF(G8="TTDB",300000,IF(G8="DT1",135000,IF(G8="TT1",135000,IF(G8="DT2",75000,IF(G8="TT2",75000,IF(G8="DT3",45000,45000))))))) -> 300000 | L8: T.HƯỞNG | M8: =IF(L8="-",0,IF(G8="DTDB",300000,IF(G8="TTDB",300000,IF(G8="DT1",135000,IF(G8="TT1",135000,IF(G8="DT2",75000,IF(G8="TT2",75000,IF(G8="DT3",45000,45000)))))))) -> 300000 | N8: =I8+K8+M8 -> 1020000
A9: 2 | B9: 26/3/2025 | C9: Nguyễn Trí Nghiệp | D9: 59 | F9: KHX màn hình tăng sáng | G9: DTDB | H9: TOẢN | I9: =IF(G9="DTDB",420000,IF(G9="TTDB",420000,IF(G9="DT1",187500,IF(G9="TT1",187500,IF(G9="DT2",97500,IF(G9="TT2",97500,IF(G9="DT3",75000,75000))))))) -> 420000 | J9: T.HƯỞNG | K9: =IF(G9="DTDB",300000,IF(G9="TTDB",300000,IF(G9="DT1",135000,IF(G9="TT1",135000,IF(G9="DT2",75000,IF(G9="TT2",75000,IF(G9="DT3",45000,45000))))))) -> 300000 | L9: LUẬT | M9: =IF(L9="-",0,IF(G9="DTDB",300000,IF(G9="TTDB",300000,IF(G9="DT1",135000,IF(G9="TT1",135000,IF(G9="DT2",75000,IF(G9="TT2",75000,IF(G9="DT3",45000,45000)))))))) -> 300000 | N9: =I9+K9+M9 -> 1020000
A10: 3 | B10: 27/3/2025 | C10: Dương Văn Hiệp | D10: 44 | F10: Thay khớp háng toàn phần | G10: DTDB | H10: TẤN | I10: =IF(G10="DTDB",420000,IF(G10="TTDB",420000,IF(G10="DT1",187500,IF(G10="TT1",187500,IF(G10="DT2",97500,IF(G10="TT2",97500,IF(G10="DT3",75000,75000))))))) -> 420000 | J10: NGUYỆN | K10: =IF(G10="DTDB",300000,IF(G10="TTDB",300000,IF(G10="DT1",135000,IF(G10="TT1",135000,IF(G10="DT2",75000,IF(G10="TT2",75000,IF(G10="DT3",45000,45000))))))) -> 300000 | L10: TÙNG | M10: =IF(L10="-",0,IF(G10="DTDB",300000,IF(G10="TTDB",300000,IF(G10="DT1",135000,IF(G10="TT1",135000,IF(G10="DT2",75000,IF(G10="TT2",75000,IF(G10="DT3",45000,45000)))))))) -> 300000 | N10: =I10+K10+M10 -> 1020000
A11: 4 | B11: 28/3/2025 | C11: Nguyễn Văn Hai | D11: 71 | F11: PTNS cắt hoạt mạc viêm khớp gối | G11: DT1 | H11: TOẢN | I11: =IF(G11="DTDB",420000,IF(G11="TTDB",420000,IF(G11="DT1",187500,IF(G11="TT1",187500,IF(G11="DT2",97500,IF(G11="TT2",97500,IF(G11="DT3",75000,75000))))))) -> 187500 | J11: Đ.KHANG | K11: =IF(G11="DTDB",300000,IF(G11="TTDB",300000,IF(G11="DT1",135000,IF(G11="TT1",135000,IF(G11="DT2",75000,IF(G11="TT2",75000,IF(G11="DT3",45000,45000))))))) -> 135000 | L11: N.KHANG | M11: =IF(L11="-",0,IF(G11="DTDB",300000,IF(G11="TTDB",300000,IF(G11="DT1",135000,IF(G11="TT1",135000,IF(G11="DT2",75000,IF(G11="TT2",75000,IF(G11="DT3",45000,45000)))))))) -> 135000 | N11: =I11+K11+M11 -> 457500
A12: 5 | B12: 28/3/2025 | C12: Lê Ngọc Trúc | E12: 60 | F12: KHX trên màn hình tăng sáng | G12: TTDB | H12: TẤN | I12: =IF(G12="DTDB",420000,IF(G12="TTDB",420000,IF(G12="DT1",187500,IF(G12="TT1",187500,IF(G12="DT2",97500,IF(G12="TT2",97500,IF(G12="DT3",75000,75000))))))) -> 420000 | J12: V.TÂN | K12: =IF(G12="DTDB",300000,IF(G12="TTDB",300000,IF(G12="DT1",135000,IF(G12="TT1",135000,IF(G12="DT2",75000,IF(G12="TT2",75000,IF(G12="DT3",45000,45000))))))) -> 300000 | L12: ĐẠT | M12: =IF(L12="-",0,IF(G12="DTDB",300000,IF(G12="TTDB",300000,IF(G12="DT1",135000,IF(G12="TT1",135000,IF(G12="DT2",75000,IF(G12="TT2",75000,IF(G12="DT3",45000,45000)))))))) -> 300000 | N12: =I12+K12+M12 -> 1020000
A13: 6 | B13: 30/3/2025 | C13: Ngô Chí Tân | D13: 66 | F13: PT vết thương phần mềm phức tạp | G13: DT1 | H13: GIÀU | I13: =IF(G13="DTDB",420000,IF(G13="TTDB",420000,IF(G13="DT1",187500,IF(G13="TT1",187500,IF(G13="DT2",97500,IF(G13="TT2",97500,IF(G13="DT3",75000,75000))))))) -> 187500 | J13: ĐẠT | K13: =IF(G13="DTDB",300000,IF(G13="TTDB",300000,IF(G13="DT1",135000,IF(G13="TT1",135000,IF(G13="DT2",75000,IF(G13="TT2",75000,IF(G13="DT3",45000,45000))))))) -> 135000 | L13: T.HƯỞNG | M13: =IF(L13="-",0,IF(G13="DTDB",300000,IF(G13="TTDB",300000,IF(G13="DT1",135000,IF(G13="TT1",135000,IF(G13="DT2",75000,IF(G13="TT2",75000,IF(G13="DT3",45000,45000)))))))) -> 135000 | N13: =I13+K13+M13 -> 457500
A14: 7 | B14: 31/03/2025 | C14: Nguyễn Vũ Ca | D14: 42 | F14: PT vết thương phần mềm phức tạp | G14: DT1 | H14: GIÀU | I14: =IF(G14="DTDB",420000,IF(G14="TTDB",420000,IF(G14="DT1",187500,IF(G14="TT1",187500,IF(G14="DT2",97500,IF(G14="TT2",97500,IF(G14="DT3",75000,75000))))))) -> 187500 | J14: ĐẠT | K14: =IF(G14="DTDB",300000,IF(G14="TTDB",300000,IF(G14="DT1",135000,IF(G14="TT1",135000,IF(G14="DT2",75000,IF(G14="TT2",75000,IF(G14="DT3",45000,45000))))))) -> 135000 | L14: TUẤN | M14: =IF(L14="-",0,IF(G14="DTDB",300000,IF(G14="TTDB",300000,IF(G14="DT1",135000,IF(G14="TT1",135000,IF(G14="DT2",75000,IF(G14="TT2",75000,IF(G14="DT3",45000,45000)))))))) -> 135000 | N14: =I14+K14+M14 -> 457500
A15: 8 | B15: 31/03/2025 | C15: Võ Hoàng Quân | D15: 56 | F15: PT KHX trên màn hình tăng sáng | G15: TTDB | H15: ĐIỀN | I15: =IF(G15="DTDB",420000,IF(G15="TTDB",420000,IF(G15="DT1",187500,IF(G15="TT1",187500,IF(G15="DT2",97500,IF(G15="TT2",97500,IF(G15="DT3",75000,75000))))))) -> 420000 | J15: TÙNG | K15: =IF(G15="DTDB",300000,IF(G15="TTDB",300000,IF(G15="DT1",135000,IF(G15="TT1",135000,IF(G15="DT2",75000,IF(G15="TT2",75000,IF(G15="DT3",45000,45000))))))) -> 300000 | L15: KHÉN | M15: =IF(L15="-",0,IF(G15="DTDB",300000,IF(G15="TTDB",300000,IF(G15="DT1",135000,IF(G15="TT1",135000,IF(G15="DT2",75000,IF(G15="TT2",75000,IF(G15="DT3",45000,45000)))))))) -> 300000 | N15: =I15+K15+M15 -> 1020000
A16: 9 | B16: 31/03/2025 | C16: Nguyễn Văn Minh | D16: 59 | F16: PT KHX trên màn hình tăng sáng | G16: TTDB | H16: GIÀU | I16: =IF(G16="DTDB",420000,IF(G16="TTDB",420000,IF(G16="DT1",187500,IF(G16="TT1",187500,IF(G16="DT2",97500,IF(G16="TT2",97500,IF(G16="DT3",75000,75000))))))) -> 420000 | J16: TÙNG | K16: =IF(G16="DTDB",300000,IF(G16="TTDB",300000,IF(G16="DT1",135000,IF(G16="TT1",135000,IF(G16="DT2",75000,IF(G16="TT2",75000,IF(G16="DT3",45000,45000))))))) -> 300000 | L16: KHÉN | M16: =IF(L16="-",0,IF(G16="DTDB",300000,IF(G16="TTDB",300000,IF(G16="DT1",135000,IF(G16="TT1",135000,IF(G16="DT2",75000,IF(G16="TT2",75000,IF(G16="DT3",45000,45000)))))))) -> 300000 | N16: =I16+K16+M16 -> 1020000
A17: 10 | B17: 01/4/2025 | C17: Hồ Minh Tuấn | D17: 38 | F17: PT KHX trên màn hình tăng sáng | G17: TTDB | H17: GIÀU | I17: =IF(G17="DTDB",420000,IF(G17="TTDB",420000,IF(G17="DT1",187500,IF(G17="TT1",187500,IF(G17="DT2",97500,IF(G17="TT2",97500,IF(G17="DT3",75000,75000))))))) -> 420000 | J17: TUẤN | K17: =IF(G17="DTDB",300000,IF(G17="TTDB",300000,IF(G17="DT1",135000,IF(G17="TT1",135000,IF(G17="DT2",75000,IF(G17="TT2",75000,IF(G17="DT3",45000,45000))))))) -> 300000 | L17: T.HƯỞNG | M17: =IF(L17="-",0,IF(G17="DTDB",300000,IF(G17="TTDB",300000,IF(G17="DT1",135000,IF(G17="TT1",135000,IF(G17="DT2",75000,IF(G17="TT2",75000,IF(G17="DT3",45000,45000)))))))) -> 300000 | N17: =I17+K17+M17 -> 1020000
A18: 11 | B18: 01/4/2025 | C18: Hồ Minh Tuấn | D18: 38 | F18: PT KHX trên màn hình tăng sáng | G18: TTDB | H18: GIÀU | I18: =IF(G18="DTDB",420000,IF(G18="TTDB",420000,IF(G18="DT1",187500,IF(G18="TT1",187500,IF(G18="DT2",97500,IF(G18="TT2",97500,IF(G18="DT3",75000,75000))))))) -> 420000 | J18: TOẢN | K18: =IF(G18="DTDB",300000,IF(G18="TTDB",300000,IF(G18="DT1",135000,IF(G18="TT1",135000,IF(G18="DT2",75000,IF(G18="TT2",75000,IF(G18="DT3",45000,45000))))))) -> 300000 | L18: LUẬT | M18: =IF(L18="-",0,IF(G18="DTDB",300000,IF(G18="TTDB",300000,IF(G18="DT1",135000,IF(G18="TT1",135000,IF(G18="DT2",75000,IF(G18="TT2",75000,IF(G18="DT3",45000,45000)))))))) -> 300000 | N18: =I18+K18+M18 -> 1020000
A19: 12 | B19: 01/4/2025 | C19: Nguyễn Thanh Quang | D19: 45 | F19: PT vết thương phần mềm phức tạp | G19: TT1 | H19: V.TÂN | I19: =IF(G19="DTDB",420000,IF(G19="TTDB",420000,IF(G19="DT1",187500,IF(G19="TT1",187500,IF(G19="DT2",97500,IF(G19="TT2",97500,IF(G19="DT3",75000,75000))))))) -> 187500 | J19: ĐẠT | K19: =IF(G19="DTDB",300000,IF(G19="TTDB",300000,IF(G19="DT1",135000,IF(G19="TT1",135000,IF(G19="DT2",75000,IF(G19="TT2",75000,IF(G19="DT3",45000,45000))))))) -> 135000 | L19: TÙNG | M19: =IF(L19="-",0,IF(G19="DTDB",300000,IF(G19="TTDB",300000,IF(G19="DT1",135000,IF(G19="TT1",135000,IF(G19="DT2",75000,IF(G19="TT2",75000,IF(G19="DT3",45000,45000)))))))) -> 135000 | N19: =I19+K19+M19 -> 457500
A20: 13 | B20: 02/4/2025 | C20: Nguyễn Thị Thia | E20: 67 | F20: PT KHX trên màn hình tăng sáng | G20: TTDB | H20: V.TÂN | I20: =IF(G20="DTDB",420000,IF(G20="TTDB",420000,IF(G20="DT1",187500,IF(G20="TT1",187500,IF(G20="DT2",97500,IF(G20="TT2",97500,IF(G20="DT3",75000,75000))))))) -> 420000 | J20: GIÀU | K20: =IF(G20="DTDB",300000,IF(G20="TTDB",300000,IF(G20="DT1",135000,IF(G20="TT1",135000,IF(G20="DT2",75000,IF(G20="TT2",75000,IF(G20="DT3",45000,45000))))))) -> 300000 | L20: TUẤN | M20: =IF(L20="-",0,IF(G20="DTDB",300000,IF(G20="TTDB",300000,IF(G20="DT1",135000,IF(G20="TT1",135000,IF(G20="DT2",75000,IF(G20="TT2",75000,IF(G20="DT3",45000,45000)))))))) -> 300000 | N20: =I20+K20+M20 -> 1020000
A21: 14 | B21: 02/4/2025 | C21: Thị Đẹp | E21: 88 | F21: PT KHX trên màn hình tăng sáng | G21: TTDB | H21: ĐIỀN | I21: =IF(G21="DTDB",420000,IF(G21="TTDB",420000,IF(G21="DT1",187500,IF(G21="TT1",187500,IF(G21="DT2",97500,IF(G21="TT2",97500,IF(G21="DT3",75000,75000))))))) -> 420000 | J21: TUẤN | K21: =IF(G21="DTDB",300000,IF(G21="TTDB",300000,IF(G21="DT1",135000,IF(G21="TT1",135000,IF(G21="DT2",75000,IF(G21="TT2",75000,IF(G21="DT3",45000,45000))))))) -> 300000 | L21: T.HƯỞNG | M21: =IF(L21="-",0,IF(G21="DTDB",300000,IF(G21="TTDB",300000,IF(G21="DT1",135000,IF(G21="TT1",135000,IF(G21="DT2",75000,IF(G21="TT2",75000,IF(G21="DT3",45000,45000)))))))) -> 300000 | N21: =I21+K21+M21 -> 1020000
A22: 15 | B22: 03/4/2025 | C22: Nguyễn Vũ Ca | D22: 42 | F22: PT KHX trên màn hình tăng sáng | G22: TTDB | H22: GIÀU | I22: =IF(G22="DTDB",420000,IF(G22="TTDB",420000,IF(G22="DT1",187500,IF(G22="TT1",187500,IF(G22="DT2",97500,IF(G22="TT2",97500,IF(G22="DT3",75000,75000))))))) -> 420000 | J22: TUẤN | K22: =IF(G22="DTDB",300000,IF(G22="TTDB",300000,IF(G22="DT1",135000,IF(G22="TT1",135000,IF(G22="DT2",75000,IF(G22="TT2",75000,IF(G22="DT3",45000,45000))))))) -> 300000 | L22: TÙNG | M22: =IF(L22="-",0,IF(G22="DTDB",300000,IF(G22="TTDB",300000,IF(G22="DT1",135000,IF(G22="TT1",135000,IF(G22="DT2",75000,IF(G22="TT2",75000,IF(G22="DT3",45000,45000)))))))) -> 300000 | N22: =I22+K22+M22 -> 1020000
A23: 16 | B23: 03/4/2025 | C23: Nguyễn Văn Minh | D23: 59 | F23: PT KHX trên màn hình tăng sáng | G23: DTDB | H23: GIÀU | I23: =IF(G23="DTDB",420000,IF(G23="TTDB",420000,IF(G23="DT1",187500,IF(G23="TT1",187500,IF(G23="DT2",97500,IF(G23="TT2",97500,IF(G23="DT3",75000,75000))))))) -> 420000 | J23: TUẤN | K23: =IF(G23="DTDB",300000,IF(G23="TTDB",300000,IF(G23="DT1",135000,IF(G23="TT1",135000,IF(G23="DT2",75000,IF(G23="TT2",75000,IF(G23="DT3",45000,45000))))))) -> 300000 | L23: TÙNG | M23: =IF(L23="-",0,IF(G23="DTDB",300000,IF(G23="TTDB",300000,IF(G23="DT1",135000,IF(G23="TT1",135000,IF(G23="DT2",75000,IF(G23="TT2",75000,IF(G23="DT3",45000,45000)))))))) -> 300000 | N23: =I23+K23+M23 -> 1020000
A24: 17 | B24: 03/4/2025 | C24: Nguyễn Hữu Thanh Phong | D24: 46 | F24: PT KHX trên màn hình tăng sáng | G24: DTDB | H24: NGUYỆN | I24: =IF(G24="DTDB",420000,IF(G24="TTDB",420000,IF(G24="DT1",187500,IF(G24="TT1",187500,IF(G24="DT2",97500,IF(G24="TT2",97500,IF(G24="DT3",75000,75000))))))) -> 420000 | J24: TOẢN | K24: =IF(G24="DTDB",300000,IF(G24="TTDB",300000,IF(G24="DT1",135000,IF(G24="TT1",135000,IF(G24="DT2",75000,IF(G24="TT2",75000,IF(G24="DT3",45000,45000))))))) -> 300000 | L24: TUẤN | M24: =IF(L24="-",0,IF(G24="DTDB",300000,IF(G24="TTDB",300000,IF(G24="DT1",135000,IF(G24="TT1",135000,IF(G24="DT2",75000,IF(G24="TT2",75000,IF(G24="DT3",45000,45000)))))))) -> 300000 | N24: =I24+K24+M24 -> 1020000
A25: 18 | B25: 04/4/2025 | C25: Phan Văn Nghĩa | D25: 71 | F25: PT bệnh lý nhiễm trùng bàn tay | G25: DT1 | H25: V.TÂN | I25: =IF(G25="DTDB",420000,IF(G25="TTDB",420000,IF(G25="DT1",187500,IF(G25="TT1",187500,IF(G25="DT2",97500,IF(G25="TT2",97500,IF(G25="DT3",75000,75000))))))) -> 187500 | J25: TUẤN | K25: =IF(G25="DTDB",300000,IF(G25="TTDB",300000,IF(G25="DT1",135000,IF(G25="TT1",135000,IF(G25="DT2",75000,IF(G25="TT2",75000,IF(G25="DT3",45000,45000))))))) -> 135000 | L25: LUẬT | M25: =IF(L25="-",0,IF(G25="DTDB",300000,IF(G25="TTDB",300000,IF(G25="DT1",135000,IF(G25="TT1",135000,IF(G25="DT2",75000,IF(G25="TT2",75000,IF(G25="DT3",45000,45000)))))))) -> 135000 | N25: =I25+K25+M25 -> 457500
A26: 19 | B26: 05/04/2025 | C26: Nguyễn Thị Mỹ | E26: 88 | F26: PT thay khớp háng bán phần | G26: TT1 | H26: TẤN | I26: =IF(G26="DTDB",420000,IF(G26="TTDB",420000,IF(G26="DT1",187500,IF(G26="TT1",187500,IF(G26="DT2",97500,IF(G26="TT2",97500,IF(G26="DT3",75000,75000))))))) -> 187500 | J26: NGUYỆN | K26: =IF(G26="DTDB",300000,IF(G26="TTDB",300000,IF(G26="DT1",135000,IF(G26="TT1",135000,IF(G26="DT2",75000,IF(G26="TT2",75000,IF(G26="DT3",45000,45000))))))) -> 135000 | L26: TUẤN | M26: =IF(L26="-",0,IF(G26="DTDB",300000,IF(G26="TTDB",300000,IF(G26="DT1",135000,IF(G26="TT1",135000,IF(G26="DT2",75000,IF(G26="TT2",75000,IF(G26="DT3",45000,45000)))))))) -> 135000 | N26: =I26+K26+M26 -> 457500
A27: 20 | B27: 07/4/2025 | C27: Trương Bích Ngọc | E27: 72 | F27: Cắt u lành phần mềm > 10cm | G27: TT1 | H27: ĐIỀN | I27: =IF(G27="DTDB",420000,IF(G27="TTDB",420000,IF(G27="DT1",187500,IF(G27="TT1",187500,IF(G27="DT2",97500,IF(G27="TT2",97500,IF(G27="DT3",75000,75000))))))) -> 187500 | J27: T.HƯỞNG | K27: =IF(G27="DTDB",300000,IF(G27="TTDB",300000,IF(G27="DT1",135000,IF(G27="TT1",135000,IF(G27="DT2",75000,IF(G27="TT2",75000,IF(G27="DT3",45000,45000))))))) -> 135000 | L27: KHÉN | M27: =IF(L27="-",0,IF(G27="DTDB",300000,IF(G27="TTDB",300000,IF(G27="DT1",135000,IF(G27="TT1",135000,IF(G27="DT2",75000,IF(G27="TT2",75000,IF(G27="DT3",45000,45000)))))))) -> 135000 | N27: =I27+K27+M27 -> 457500
A28: 21 | B28: 08/04/2025 | C28: Nguyễn Thị Bé Thủy | E28: 57 | F28: Mở cung sau cột sống ngực | G28: DT1 | H28: NGUYỆN | I28: =IF(G28="DTDB",420000,IF(G28="TTDB",420000,IF(G28="DT1",187500,IF(G28="TT1",187500,IF(G28="DT2",97500,IF(G28="TT2",97500,IF(G28="DT3",75000,75000))))))) -> 187500 | J28: THÁI | K28: =IF(G28="DTDB",300000,IF(G28="TTDB",300000,IF(G28="DT1",135000,IF(G28="TT1",135000,IF(G28="DT2",75000,IF(G28="TT2",75000,IF(G28="DT3",45000,45000))))))) -> 135000 | L28: TÙNG | M28: =IF(L28="-",0,IF(G28="DTDB",300000,IF(G28="TTDB",300000,IF(G28="DT1",135000,IF(G28="TT1",135000,IF(G28="DT2",75000,IF(G28="TT2",75000,IF(G28="DT3",45000,45000)))))))) -> 135000 | N28: =I28+K28+M28 -> 457500
A29: 22 | B29: 08/04/2025 | C29: Trần Văn Thu | D29: 97 | F29: PT thay khớp háng bán phần | G29: TT1 | H29: NGUYỆN | I29: =IF(G29="DTDB",420000,IF(G29="TTDB",420000,IF(G29="DT1",187500,IF(G29="TT1",187500,IF(G29="DT2",97500,IF(G29="TT2",97500,IF(G29="DT3",75000,75000))))))) -> 187500 | J29: TÙNG | K29: =IF(G29="DTDB",300000,IF(G29="TTDB",300000,IF(G29="DT1",135000,IF(G29="TT1",135000,IF(G29="DT2",75000,IF(G29="TT2",75000,IF(G29="DT3",45000,45000))))))) -> 135000 | L29: Đ.KHANG | M29: =IF(L29="-",0,IF(G29="DTDB",300000,IF(G29="TTDB",300000,IF(G29="DT1",135000,IF(G29="TT1",135000,IF(G29="DT2",75000,IF(G29="TT2",75000,IF(G29="DT3",45000,45000)))))))) -> 135000 | N29: =I29+K29+M29 -> 457500
A30: 23 | B30: 08/04/2025 | C30: Võ Thị Thúy Kiều | E30: 32 | F30: KHX trên màn hình tăng sáng | G30: TTDB | H30: TOẢN | I30: =IF(G30="DTDB",420000,IF(G30="TTDB",420000,IF(G30="DT1",187500,IF(G30="TT1",187500,IF(G30="DT2",97500,IF(G30="TT2",97500,IF(G30="DT3",75000,75000))))))) -> 420000 | J30: Đ.KHANG | K30: =IF(G30="DTDB",300000,IF(G30="TTDB",300000,IF(G30="DT1",135000,IF(G30="TT1",135000,IF(G30="DT2",75000,IF(G30="TT2",75000,IF(G30="DT3",45000,45000))))))) -> 300000 | L30: TÙNG | M30: =IF(L30="-",0,IF(G30="DTDB",300000,IF(G30="TTDB",300000,IF(G30="DT1",135000,IF(G30="TT1",135000,IF(G30="DT2",75000,IF(G30="TT2",75000,IF(G30="DT3",45000,45000)))))))) -> 300000 | N30: =I30+K30+M30 -> 1020000
A31: 24 | B31: 09/04/2025 | C31: Trần Thị Hiến | E31: 73 | F31: Thay toàn bộ khớp gối | G31: TTDB | H31: TẤN | I31: =IF(G31="DTDB",420000,IF(G31="TTDB",420000,IF(G31="DT1",187500,IF(G31="TT1",187500,IF(G31="DT2",97500,IF(G31="TT2",97500,IF(G31="DT3",75000,75000))))))) -> 420000 | J31: TOẢN | K31: =IF(G31="DTDB",300000,IF(G31="TTDB",300000,IF(G31="DT1",135000,IF(G31="TT1",135000,IF(G31="DT2",75000,IF(G31="TT2",75000,IF(G31="DT3",45000,45000))))))) -> 300000 | L31: TUẤN | M31: =IF(L31="-",0,IF(G31="DTDB",300000,IF(G31="TTDB",300000,IF(G31="DT1",135000,IF(G31="TT1",135000,IF(G31="DT2",75000,IF(G31="TT2",75000,IF(G31="DT3",45000,45000)))))))) -> 300000 | N31: =I31+K31+M31 -> 1020000
A32: 25 | B32: 09/04/2025 | C32: Nguyễn Hoàng Ly | E32: 40 | F32: PT giải ép thần kinh | G32: TT1 | H32: TOẢN | I32: =IF(G32="DTDB",420000,IF(G32="TTDB",420000,IF(G32="DT1",187500,IF(G32="TT1",187500,IF(G32="DT2",97500,IF(G32="TT2",97500,IF(G32="DT3",75000,75000))))))) -> 187500 | J32: THÁI | K32: =IF(G32="DTDB",300000,IF(G32="TTDB",300000,IF(G32="DT1",135000,IF(G32="TT1",135000,IF(G32="DT2",75000,IF(G32="TT2",75000,IF(G32="DT3",45000,45000))))))) -> 135000 | L32: KHÉN | M32: =IF(L32="-",0,IF(G32="DTDB",300000,IF(G32="TTDB",300000,IF(G32="DT1",135000,IF(G32="TT1",135000,IF(G32="DT2",75000,IF(G32="TT2",75000,IF(G32="DT3",45000,45000)))))))) -> 135000 | N32: =I32+K32+M32 -> 457500
A33: 26 | B33: 09/04/2025 | C33: Nguyễn Văn Luôn | D33: 28 | F33: PT lấy nhân đệm CSTL qua da | G33: TT1 | H33: GIÀU | I33: =IF(G33="DTDB",420000,IF(G33="TTDB",420000,IF(G33="DT1",187500,IF(G33="TT1",187500,IF(G33="DT2",97500,IF(G33="TT2",97500,IF(G33="DT3",75000,75000))))))) -> 187500 | J33: TÙNG | K33: =IF(G33="DTDB",300000,IF(G33="TTDB",300000,IF(G33="DT1",135000,IF(G33="TT1",135000,IF(G33="DT2",75000,IF(G33="TT2",75000,IF(G33="DT3",45000,45000))))))) -> 135000 | L33: THÁI | M33: =IF(L33="-",0,IF(G33="DTDB",300000,IF(G33="TTDB",300000,IF(G33="DT1",135000,IF(G33="TT1",135000,IF(G33="DT2",75000,IF(G33="TT2",75000,IF(G33="DT3",45000,45000)))))))) -> 135000 | N33: =I33+K33+M33 -> 457500
A34: 27 | B34: 09/04/2025 | C34: Nguyễn Hoàng Lễ | D34: 54 | F34: KHX trên màn hình tăng sáng | G34: TTDB | H34: V.TÂN | I34: =IF(G34="DTDB",420000,IF(G34="TTDB",420000,IF(G34="DT1",187500,IF(G34="TT1",187500,IF(G34="DT2",97500,IF(G34="TT2",97500,IF(G34="DT3",75000,75000))))))) -> 420000 | J34: TUẤN | K34: =IF(G34="DTDB",300000,IF(G34="TTDB",300000,IF(G34="DT1",135000,IF(G34="TT1",135000,IF(G34="DT2",75000,IF(G34="TT2",75000,IF(G34="DT3",45000,45000))))))) -> 300000 | L34: TÙNG | M34: =IF(L34="-",0,IF(G34="DTDB",300000,IF(G34="TTDB",300000,IF(G34="DT1",135000,IF(G34="TT1",135000,IF(G34="DT2",75000,IF(G34="TT2",75000,IF(G34="DT3",45000,45000)))))))) -> 300000 | N34: =I34+K34+M34 -> 1020000
A35: 28 | B35: 09/04/2025 | C35: Nguyễn Văn Thọ | D35: 71 | F35: KHX trên màn hình tăng sáng | G35: TTDB | H35: NGUYỆN | I35: =IF(G35="DTDB",420000,IF(G35="TTDB",420000,IF(G35="DT1",187500,IF(G35="TT1",187500,IF(G35="DT2",97500,IF(G35="TT2",97500,IF(G35="DT3",75000,75000))))))) -> 420000 | J35: V.TÂN | K35: =IF(G35="DTDB",300000,IF(G35="TTDB",300000,IF(G35="DT1",135000,IF(G35="TT1",135000,IF(G35="DT2",75000,IF(G35="TT2",75000,IF(G35="DT3",45000,45000))))))) -> 300000 | L35: T.HƯỞNG | M35: =IF(L35="-",0,IF(G35="DTDB",300000,IF(G35="TTDB",300000,IF(G35="DT1",135000,IF(G35="TT1",135000,IF(G35="DT2",75000,IF(G35="TT2",75000,IF(G35="DT3",45000,45000)))))))) -> 300000 | N35: =I35+K35+M35 -> 1020000
A36: 29 | B36: 09/04/2025 | C36: Nguyễn Văn Thọ | D36: 71 | F36: KHX trên màn hình tăng sáng (80%) | G36: TTDB | H36: GIÀU | I36: =IF(G36="DTDB",420000,IF(G36="TTDB",420000,IF(G36="DT1",187500,IF(G36="TT1",187500,IF(G36="DT2",97500,IF(G36="TT2",97500,IF(G36="DT3",75000,75000))))))) -> 420000 | J36: TUẤN | K36: =IF(G36="DTDB",300000,IF(G36="TTDB",300000,IF(G36="DT1",135000,IF(G36="TT1",135000,IF(G36="DT2",75000,IF(G36="TT2",75000,IF(G36="DT3",45000,45000))))))) -> 300000 | L36: KHÉN | M36: =IF(L36="-",0,IF(G36="DTDB",300000,IF(G36="TTDB",300000,IF(G36="DT1",135000,IF(G36="TT1",135000,IF(G36="DT2",75000,IF(G36="TT2",75000,IF(G36="DT3",45000,45000)))))))) -> 300000 | N36: =I36+K36+M36 -> 1020000
A37: 30 | B37: 09/04/2025 | C37: Nguyễn Hà My | E37: 19 | F37: KHX trên màn hình tăng sáng | G37: TTDB | H37: GIÀU | I37: =IF(G37="DTDB",420000,IF(G37="TTDB",420000,IF(G37="DT1",187500,IF(G37="TT1",187500,IF(G37="DT2",97500,IF(G37="TT2",97500,IF(G37="DT3",75000,75000))))))) -> 420000 | J37: ĐẠT | K37: =IF(G37="DTDB",300000,IF(G37="TTDB",300000,IF(G37="DT1",135000,IF(G37="TT1",135000,IF(G37="DT2",75000,IF(G37="TT2",75000,IF(G37="DT3",45000,45000))))))) -> 300000 | L37: Đ.KHANG | M37: =IF(L37="-",0,IF(G37="DTDB",300000,IF(G37="TTDB",300000,IF(G37="DT1",135000,IF(G37="TT1",135000,IF(G37="DT2",75000,IF(G37="TT2",75000,IF(G37="DT3",45000,45000)))))))) -> 300000 | N37: =I37+K37+M37 -> 1020000
A38: 31 | B38: 10/04/2025 | C38: Nguyễn Kim Ngân | E38: 36 | F38: PT thay toàn bộ khớp háng | G38: DTDB | H38: NGUYỆN | I38: =IF(G38="DTDB",420000,IF(G38="TTDB",420000,IF(G38="DT1",187500,IF(G38="TT1",187500,IF(G38="DT2",97500,IF(G38="TT2",97500,IF(G38="DT3",75000,75000))))))) -> 420000 | J38: ĐIỀN | K38: =IF(G38="DTDB",300000,IF(G38="TTDB",300000,IF(G38="DT1",135000,IF(G38="TT1",135000,IF(G38="DT2",75000,IF(G38="TT2",75000,IF(G38="DT3",45000,45000))))))) -> 300000 | L38: TUẤN | M38: =IF(L38="-",0,IF(G38="DTDB",300000,IF(G38="TTDB",300000,IF(G38="DT1",135000,IF(G38="TT1",135000,IF(G38="DT2",75000,IF(G38="TT2",75000,IF(G38="DT3",45000,45000)))))))) -> 300000 | N38: =I38+K38+M38 -> 1020000
A39: 32 | B39: 10/04/2025 | C39: Nguyễn Thị Út Mót | E39: 72 | F39: KHX trên màn hình tăng sáng | G39: TTDB | H39: ĐIỀN | I39: =IF(G39="DTDB",420000,IF(G39="TTDB",420000,IF(G39="DT1",187500,IF(G39="TT1",187500,IF(G39="DT2",97500,IF(G39="TT2",97500,IF(G39="DT3",75000,75000))))))) -> 420000 | J39: TUẤN | K39: =IF(G39="DTDB",300000,IF(G39="TTDB",300000,IF(G39="DT1",135000,IF(G39="TT1",135000,IF(G39="DT2",75000,IF(G39="TT2",75000,IF(G39="DT3",45000,45000))))))) -> 300000 | L39: T.HƯỞNG | M39: =IF(L39="-",0,IF(G39="DTDB",300000,IF(G39="TTDB",300000,IF(G39="DT1",135000,IF(G39="TT1",135000,IF(G39="DT2",75000,IF(G39="TT2",75000,IF(G39="DT3",45000,45000)))))))) -> 300000 | N39: =I39+K39+M39 -> 1020000
A40: 33 | B40: 10/04/2025 | C40: Trịnh Văn Phú | D40: 42 | F40: PT vá da diện tích > 10cm2 | G40: DT1 | H40: TOẢN | I40: =IF(G40="DTDB",420000,IF(G40="TTDB",420000,IF(G40="DT1",187500,IF(G40="TT1",187500,IF(G40="DT2",97500,IF(G40="TT2",97500,IF(G40="DT3",75000,75000))))))) -> 187500 | J40: TUẤN | K40: =IF(G40="DTDB",300000,IF(G40="TTDB",300000,IF(G40="DT1",135000,IF(G40="TT1",135000,IF(G40="DT2",75000,IF(G40="TT2",75000,IF(G40="DT3",45000,45000))))))) -> 135000 | L40: T.HƯỞNG | M40: =IF(L40="-",0,IF(G40="DTDB",300000,IF(G40="TTDB",300000,IF(G40="DT1",135000,IF(G40="TT1",135000,IF(G40="DT2",75000,IF(G40="TT2",75000,IF(G40="DT3",45000,45000)))))))) -> 135000 | N40: =I40+K40+M40 -> 457500
A41: 34 | B41: 10/04/2025 | C41: Lê Hồng Khánh | D41: 43 | F41: PT vết thương phần mềm phức tạp | G41: TT1 | H41: TOẢN | I41: =IF(G41="DTDB",420000,IF(G41="TTDB",420000,IF(G41="DT1",187500,IF(G41="TT1",187500,IF(G41="DT2",97500,IF(G41="TT2",97500,IF(G41="DT3",75000,75000))))))) -> 187500 | J41: TÙNG | K41: =IF(G41="DTDB",300000,IF(G41="TTDB",300000,IF(G41="DT1",135000,IF(G41="TT1",135000,IF(G41="DT2",75000,IF(G41="TT2",75000,IF(G41="DT3",45000,45000))))))) -> 135000 | L41: THÁI | M41: =IF(L41="-",0,IF(G41="DTDB",300000,IF(G41="TTDB",300000,IF(G41="DT1",135000,IF(G41="TT1",135000,IF(G41="DT2",75000,IF(G41="TT2",75000,IF(G41="DT3",45000,45000)))))))) -> 135000 | N41: =I41+K41+M41 -> 457500
A42: 35 | B42: 12/4/2025 | C42: Võ Thị Niết | E42: 67 | F42: Thay toàn bộ khớp gối | G42: TTDB | H42: TẤN | I42: =IF(G42="DTDB",420000,IF(G42="TTDB",420000,IF(G42="DT1",187500,IF(G42="TT1",187500,IF(G42="DT2",97500,IF(G42="TT2",97500,IF(G42="DT3",75000,75000))))))) -> 420000 | J42: NGUYỆN | K42: =IF(G42="DTDB",300000,IF(G42="TTDB",300000,IF(G42="DT1",135000,IF(G42="TT1",135000,IF(G42="DT2",75000,IF(G42="TT2",75000,IF(G42="DT3",45000,45000))))))) -> 300000 | L42: Đ.KHANG | M42: =IF(L42="-",0,IF(G42="DTDB",300000,IF(G42="TTDB",300000,IF(G42="DT1",135000,IF(G42="TT1",135000,IF(G42="DT2",75000,IF(G42="TT2",75000,IF(G42="DT3",45000,45000)))))))) -> 300000 | N42: =I42+K42+M42 -> 1020000
...

Sheet lanh tien PT_BHYT
A1: BV TRƯỜNG ĐHYD CẦN THƠ
A2: KHOA NGOẠI CTCH-TK
A3: DANH SÁCH LÃNH TIỀN THÙ LAO THÁNG 4/2025
A4: (BHYT)
A6: STT | B6: HỌ TÊN | C6: CHỨC VỤ | D6: SỐ TÀI KHOẢN | E6: SỐ TIỀN | F6: Thuế 10%
A7: 1 | B7: Phạm Việt Triều | C7: Bác sĩ | D7: 102006610216 | E7: =SUM(SUMIF(phauthuat_BHYT!$H$8:$H$126,"TRIỀU",phauthuat_BHYT!$I$8:$I$126),SUMIF(phauthuat_BHYT!$J$8:$J$126,"TRIỀU",phauthuat_BHYT!$K$8:$K$126),SUMIF(phauthuat_BHYT!$L$8:$L$126,"TRIỀU",phauthuat_BHYT!$M$8:$M$126)) -> 97500
A8: 2 | B8: Nguyễn Thành Tấn | C8: Bác sĩ | D8: 103006610215 | E8: =SUM(SUMIF(phauthuat_BHYT!$H$8:$H$126,"TẤN",phauthuat_BHYT!$I$8:$I$126),SUMIF(phauthuat_BHYT!$J$8:$J$126,"TẤN",phauthuat_BHYT!$K$8:$K$126),SUMIF(phauthuat_BHYT!$L$8:$L$126,"TẤN",phauthuat_BHYT!$M$8:$M$126)) -> 3322500
A9: 3 | B9: Nguyễn Lê Hoan | C9: Bác sĩ | D9: 100006610218 | E9: =SUM(SUMIF(phauthuat_BHYT!$H$8:$H$126,"HOAN",phauthuat_BHYT!$I$8:$I$126),SUMIF(phauthuat_BHYT!$J$8:$J$126,"HOAN",phauthuat_BHYT!$K$8:$K$126),SUMIF(phauthuat_BHYT!$L$8:$L$126,"HOAN",phauthuat_BHYT!$M$8:$M$126)) -> 0
A10: 4 | B10: Nguyễn Chí Nguyện | C10: Bác sĩ | D10: 105001159195 | E10: =SUM(SUMIF(phauthuat_BHYT!$H$8:$H$126,"NGUYỆN",phauthuat_BHYT!$I$8:$I$126),SUMIF(phauthuat_BHYT!$J$8:$J$126,"NGUYỆN",phauthuat_BHYT!$K$8:$K$126),SUMIF(phauthuat_BHYT!$L$8:$L$126,"NGUYỆN",phauthuat_BHYT!$M$8:$M$126)) -> 4905000
A11: 5 | B11: Hồ Điền | C11: Bác sĩ | D11: 105001225232 | E11: =SUM(SUMIF(phauthuat_BHYT!$H$8:$H$126,"ĐIỀN",phauthuat_BHYT!$I$8:$I$126),SUMIF(phauthuat_BHYT!$J$8:$J$126,"ĐIỀN",phauthuat_BHYT!$K$8:$K$126),SUMIF(phauthuat_BHYT!$L$8:$L$126,"ĐIỀN",phauthuat_BHYT!$M$8:$M$126)) -> 3217500
A12: 6 | B12: Trần Quốc Toản | C12: Bác sĩ | D12: 107868829237 | E12: =SUM(SUMIF(phauthuat_BHYT!$H$8:$H$126,"TOẢN",phauthuat_BHYT!$I$8:$I$126),SUMIF(phauthuat_BHYT!$J$8:$J$126,"TOẢN",phauthuat_BHYT!$K$8:$K$126),SUMIF(phauthuat_BHYT!$L$8:$L$126,"TOẢN",phauthuat_BHYT!$M$8:$M$126)) -> 8265000
A13: 7 | B13: Đặng Phước Giàu | C13: Bác sĩ | D13: 105867664283 | E13: =SUM(SUMIF(phauthuat_BHYT!$H$8:$H$126,"giàu",phauthuat_BHYT!$I$8:$I$126),SUMIF(phauthuat_BHYT!$J$8:$J$126,"giàu",phauthuat_BHYT!$K$8:$K$126),SUMIF(phauthuat_BHYT!$L$8:$L$126,"giàu",phauthuat_BHYT!$M$8:$M$126)) -> 7395000
A14: 8 | B14: Phạm Việt Tân | C14: Bác sĩ | D14: 104000362303 | E14: =SUM(SUMIF(phauthuat_BHYT!$H$8:$H$126,"v.tân",phauthuat_BHYT!$I$8:$I$126),SUMIF(phauthuat_BHYT!$J$8:$J$126,"v.tân",phauthuat_BHYT!$K$8:$K$126),SUMIF(phauthuat_BHYT!$L$8:$L$126,"v.tân",phauthuat_BHYT!$M$8:$M$126)) -> 4065000
A15: 9 | B15: Bùi Công Minh | C15: Bác sĩ | D15: 105003414654 | E15: =SUM(SUMIF(phauthuat_BHYT!$H$8:$H$126,"minh",phauthuat_BHYT!$I$8:$I$126),SUMIF(phauthuat_BHYT!$J$8:$J$126,"minh",phauthuat_BHYT!$K$8:$K$126),SUMIF(phauthuat_BHYT!$L$8:$L$126,"minh",phauthuat_BHYT!$M$8:$M$126)) -> 0
A16: 10 | B16: Phan Văn Tuấn | C16: Bác sĩ | D16: 105872433048 | E16: =SUM(SUMIF(phauthuat_BHYT!$H$8:$H$126,"TUẤN",phauthuat_BHYT!$I$8:$I$126),SUMIF(phauthuat_BHYT!$J$8:$J$126,"TUẤN",phauthuat_BHYT!$K$8:$K$126),SUMIF(phauthuat_BHYT!$L$8:$L$126,"TUẤN",phauthuat_BHYT!$M$8:$M$126)) -> 9255000
A17: 11 | B17: Nguyễn Hữu Đạt | C17: Bác sĩ | D17: 103876067585 | E17: =SUM(SUMIF(phauthuat_BHYT!$H$8:$H$126,"đạt",phauthuat_BHYT!$I$8:$I$126),SUMIF(phauthuat_BHYT!$J$8:$J$126,"đạt",phauthuat_BHYT!$K$8:$K$126),SUMIF(phauthuat_BHYT!$L$8:$L$126,"đạt",phauthuat_BHYT!$M$8:$M$126)) -> 3450000
A18: 14 | B18: Võ Dương Thành Thái | C18: Bác sĩ (nt) | E18: =SUM(SUMIF(phauthuat_BHYT!$H$8:$H$126,"thái",phauthuat_BHYT!$I$8:$I$126),SUMIF(phauthuat_BHYT!$J$8:$J$126,"thái",phauthuat_BHYT!$K$8:$K$126),SUMIF(phauthuat_BHYT!$L$8:$L$126,"thái",phauthuat_BHYT!$M$8:$M$126)) -> 1425000
A19: 15 | B19: Lê Đình Tùng | C19: Bác sĩ (nt) | E19: =SUM(SUMIF(phauthuat_BHYT!$H$8:$H$126,"tùng",phauthuat_BHYT!$I$8:$I$126),SUMIF(phauthuat_BHYT!$J$8:$J$126,"tùng",phauthuat_BHYT!$K$8:$K$126),SUMIF(phauthuat_BHYT!$L$8:$L$126,"tùng",phauthuat_BHYT!$M$8:$M$126)) -> 4335000
A20: 16 | B20: Văn Minh Khén | C20: Bác sĩ (nt) | E20: =SUM(SUMIF(phauthuat_BHYT!$H$8:$H$126,"khén",phauthuat_BHYT!$I$8:$I$126),SUMIF(phauthuat_BHYT!$J$8:$J$126,"khén",phauthuat_BHYT!$K$8:$K$126),SUMIF(phauthuat_BHYT!$L$8:$L$126,"khén",phauthuat_BHYT!$M$8:$M$126)) -> 3300000
A21: 17 | B21: Phạm Tấn Hưởng | C21: Bác sĩ (nt) | E21: =SUM(SUMIF(phauthuat_BHYT!$H$8:$H$126,"T.hưởng",phauthuat_BHYT!$I$8:$I$126),SUMIF(phauthuat_BHYT!$J$8:$J$126,"T.hưởng",phauthuat_BHYT!$K$8:$K$126),SUMIF(phauthuat_BHYT!$L$8:$L$126,"T.hưởng",phauthuat_BHYT!$M$8:$M$126)) -> 4065000
A22: 18 | B22: Nguyễn Đông Khang | C22: Bác sĩ (nt) | E22: =SUM(SUMIF(phauthuat_BHYT!$H$8:$H$126,"Đ.khang",phauthuat_BHYT!$I$8:$I$126),SUMIF(phauthuat_BHYT!$J$8:$J$126,"Đ.khang",phauthuat_BHYT!$K$8:$K$126),SUMIF(phauthuat_BHYT!$L$8:$L$126,"Đ.khang",phauthuat_BHYT!$M$8:$M$126)) -> 1845000
A23: 19 | B23: Nguyễn Đình Luật | C23: Bác sĩ (nt) | E23: =SUM(SUMIF(phauthuat_BHYT!$H$8:$H$126,"luật",phauthuat_BHYT!$I$8:$I$126),SUMIF(phauthuat_BHYT!$J$8:$J$126,"luật",phauthuat_BHYT!$K$8:$K$126),SUMIF(phauthuat_BHYT!$L$8:$L$126,"luật",phauthuat_BHYT!$M$8:$M$126)) -> 1710000
A24: 20 | B24: Lê Nhỉ Khang | C24: Bác sĩ (nt) | E24: =SUM(SUMIF(phauthuat_BHYT!$H$8:$H$126,"N.KHANG",phauthuat_BHYT!$I$8:$I$126),SUMIF(phauthuat_BHYT!$J$8:$J$126,"N.KHANG",phauthuat_BHYT!$K$8:$K$126),SUMIF(phauthuat_BHYT!$L$8:$L$126,"N.KHANG",phauthuat_BHYT!$M$8:$M$126)) -> 210000
A25: 21 | B25: Phạm Văn Hưởng | C25: Bác sĩ (nt) | E25: =SUM(SUMIF(phauthuat_BHYT!$H$8:$H$126,"v.hưởng",phauthuat_BHYT!$I$8:$I$126),SUMIF(phauthuat_BHYT!$J$8:$J$126,"v.hưởng",phauthuat_BHYT!$K$8:$K$126),SUMIF(phauthuat_BHYT!$L$8:$L$126,"v.hưởng",phauthuat_BHYT!$M$8:$M$126)) -> 300000
A26: 22 | B26: Trần Trung Nghĩa | C26: Bác sĩ (nt) | E26: =SUM(SUMIF(phauthuat_BHYT!$H$8:$H$126,"nghĩa",phauthuat_BHYT!$I$8:$I$126),SUMIF(phauthuat_BHYT!$J$8:$J$126,"nghĩa",phauthuat_BHYT!$K$8:$K$126),SUMIF(phauthuat_BHYT!$L$8:$L$126,"nghĩa",phauthuat_BHYT!$M$8:$M$126)) -> 135000
B27: TỔNG CỘNG | E27: =SUM(E7:E26) -> 61297500
D29: Cần Thơ, ngày 18 tháng 12 năm 2024
A30: Người lập bảng | D30: Trưởng khoa
A34: ĐD. Phan Văn Hiếu | D34: ThS.Bs.CKII. Nguyễn Lê Hoan

Sheet Thực lãnh
A1: BV TRƯỜNG ĐHYD CẦN THƠ
A2: KHOA NGOẠI CTCH-TK
A3: DANH SÁCH LÃNH TIỀN THÙ LAO THÁNG 4/2025
A4: (BHYT)
A6: STT | B6: HỌ TÊN | C6: CHỨC VỤ | D6: SỐ TÀI KHOẢN | E6: SỐ TIỀN | F6: SỐ TIỀN | G6: KÝ NHẬN
A7: 1 | B7: Phạm Việt Triều | C7: Bác sĩ | D7: 102006610216 | E7: =SUM(SUMIF(phauthuat_BHYT!$H$8:$H$126,"TRIỀU",phauthuat_BHYT!$I$8:$I$126),SUMIF(phauthuat_BHYT!$J$8:$J$126,"TRIỀU",phauthuat_BHYT!$K$8:$K$126),SUMIF(phauthuat_BHYT!$L$8:$L$126,"TRIỀU",phauthuat_BHYT!$M$8:$M$126)) -> 97500 | F7: =E7 -> 97500
A8: 2 | B8: Nguyễn Thành Tấn | C8: Bác sĩ | D8: 103006610215 | E8: =SUM(SUMIF(phauthuat_BHYT!$H$8:$H$126,"TẤN",phauthuat_BHYT!$I$8:$I$126),SUMIF(phauthuat_BHYT!$J$8:$J$126,"TẤN",phauthuat_BHYT!$K$8:$K$126),SUMIF(phauthuat_BHYT!$L$8:$L$126,"TẤN",phauthuat_BHYT!$M$8:$M$126)) -> 3322500 | F8: =E8 -> 3322500
A9: 3 | B9: Nguyễn Lê Hoan | C9: Bác sĩ | D9: 100006610218 | E9: =SUM(SUMIF(phauthuat_BHYT!$H$8:$H$126,"HOAN",phauthuat_BHYT!$I$8:$I$126),SUMIF(phauthuat_BHYT!$J$8:$J$126,"HOAN",phauthuat_BHYT!$K$8:$K$126),SUMIF(phauthuat_BHYT!$L$8:$L$126,"HOAN",phauthuat_BHYT!$M$8:$M$126)) -> 0 | F9: =E9 -> 0
A10: 4 | B10: Nguyễn Chí Nguyện | C10: Bác sĩ | D10: 105001159195 | E10: =SUM(SUMIF(phauthuat_BHYT!$H$8:$H$126,"NGUYỆN",phauthuat_BHYT!$I$8:$I$126),SUMIF(phauthuat_BHYT!$J$8:$J$126,"NGUYỆN",phauthuat_BHYT!$K$8:$K$126),SUMIF(phauthuat_BHYT!$L$8:$L$126,"NGUYỆN",phauthuat_BHYT!$M$8:$M$126)) -> 4905000 | F10: =E10 -> 4905000
A11: 5 | B11: Hồ Điền | C11: Bác sĩ | D11: 105001225232 | E11: =SUM(SUMIF(phauthuat_BHYT!$H$8:$H$126,"ĐIỀN",phauthuat_BHYT!$I$8:$I$126),SUMIF(phauthuat_BHYT!$J$8:$J$126,"ĐIỀN",phauthuat_BHYT!$K$8:$K$126),SUMIF(phauthuat_BHYT!$L$8:$L$126,"ĐIỀN",phauthuat_BHYT!$M$8:$M$126)) -> 3217500 | F11: =E11+I18 -> 12277500
A12: 6 | B12: Trần Quốc Toản | C12: Bác sĩ | D12: 107868829237 | E12: =SUM(SUMIF(phauthuat_BHYT!$H$8:$H$126,"TOẢN",phauthuat_BHYT!$I$8:$I$126),SUMIF(phauthuat_BHYT!$J$8:$J$126,"TOẢN",phauthuat_BHYT!$K$8:$K$126),SUMIF(phauthuat_BHYT!$L$8:$L$126,"TOẢN",phauthuat_BHYT!$M$8:$M$126)) -> 8265000 | F12: =E12 -> 8265000
