Workbook

Sheet phauthuat
A1: BV TRƯỜNG ĐHYD CẦN THƠ
A2: KHOA NGOẠI CTCH - TK
A3: BẢNG KÊ TIỀN PHẪU THUẬT
A4: (THÁNG 11/2025)
A6: STT | B6: Ngày | C6: Họ Tên | D6: Nam | E6: Nữ | F6: Phương pháp phẫu thuật | G6: Loại PT | H6: Giá Phẫu thuật thực tính | I6: PTV chính | J6: Số tiền | K6: Phụ mổ 1 | L6: Số tiền | M6: Phụ mổ 2 | N6: Số tiền | O6: Phụ mổ 3 | P6: Số tiền | Q6: ĐD + HL | R6: Thực lãnh
A7: 1 | B7: 17/10/2025 | C7: Đỗ Văn Dũng | D7: 55 | F7: Cắt lọc hoại tử ổ loét vết thương mãn tính | G7: TT2 | H7: 2128200 | I7: BẢO | J7: =R7-L7-N7-P7-Q7 -> 244743 | K7: ĐỨC | L7: =IF(K7="-",0,H7*0.03) -> 63846 | M7: DUY | N7: =IF(M7="-",0,H7*0.02) -> 42564 | O7: - | P7: =IF(O7="-",0,H7*0.01) -> 0 | Q7: =H7*0.005 -> 10641 | R7: =IF(I7="V.Tân",H7*0.1375,IF(I7="nguyện",H7*0.1375,IF(I7="TOẢN",H7*0.1375,IF(I7="TUẤN",H7*0.1375,H7*0.17)))) -> 361794
A8: 2 | B8: 21/10/2025 | C8: Đỗ Văn Dũng | D8: 55 | F8: Cắt lọc hoại tử ổ loét vết thương mãn tính | G8: TT2 | H8: 2127400 | I8: BẢO | J8: =R8-L8-N8-P8-Q8 -> 244651 | K8: THIỆN | L8: =IF(K8="-",0,H8*0.03) -> 63822 | M8: ĐỨC | N8: =IF(M8="-",0,H8*0.02) -> 42548 | O8: - | P8: =IF(O8="-",0,H8*0.01) -> 0 | Q8: =H8*0.005 -> 10637 | R8: =IF(I8="V.Tân",H8*0.1375,IF(I8="nguyện",H8*0.1375,IF(I8="TOẢN",H8*0.1375,IF(I8="TUẤN",H8*0.1375,H8*0.17)))) -> 361658
A9: 3 | B9: 27/10/2025 | C9: Nguyễn Thị Bê | E9: 87 | F9: PT thay khớp háng bán phần | G9: TT1 | H9: 3897500 | I9: HOAN | J9: =R9-L9-N9-P9-Q9 -> 448212.5 | K9: DUY | L9: =IF(K9="-",0,H9*0.03) -> 116925 | M9: TUẤN | N9: =IF(M9="-",0,H9*0.02) -> 77950 | O9: - | P9: =IF(O9="-",0,H9*0.01) -> 0 | Q9: =H9*0.005 -> 19487.5 | R9: =IF(I9="V.Tân",H9*0.1375,IF(I9="nguyện",H9*0.1375,IF(I9="TOẢN",H9*0.1375,IF(I9="TUẤN",H9*0.1375,H9*0.17)))) -> 662575
A10: 4 | B10: 28/10/2025 | C10: Nguyễn Thị Pha | E10: 59 | F10: PT thay toàn bộ khớp háng | G10: TTDB | H10: 3525500 | I10: HOAN | J10: =R10-L10-N10-P10-Q10 -> 475942.5 | K10: SƠN | L10: =IF(K10="-",0,H10*0.03) -> 105765 | M10: - | N10: =IF(M10="-",0,H10*0.02) -> 0 | O10: - | P10: =IF(O10="-",0,H10*0.01) -> 0 | Q10: =H10*0.005 -> 17627.5 | R10: =IF(I10="V.Tân",H10*0.1375,IF(I10="nguyện",H10*0.1375,IF(I10="TOẢN",H10*0.1375,IF(I10="TUẤN",H10*0.1375,H10*0.17)))) -> 599335
A11: 5 | B11: 28/10/2025 | C11: MÃ HÒA DỂ | D11: 64 | F11: Cắt lọc hoại tử ổ loét vết thương mãn tính | G11: TT2 | H11: 2127400 | I11: BẢO | J11: =R11-L11-N11-P11-Q11 -> 223377 | K11: V.TÂN | L11: =IF(K11="-",0,H11*0.03) -> 63822 | M11: THIỆN | N11: =IF(M11="-",0,H11*0.02) -> 42548 | O11: THẠNH | P11: =IF(O11="-",0,H11*0.01) -> 21274 | Q11: =H11*0.005 -> 10637 | R11: =IF(I11="V.Tân",H11*0.1375,IF(I11="nguyện",H11*0.1375,IF(I11="TOẢN",H11*0.1375,IF(I11="TUẤN",H11*0.1375,H11*0.17)))) -> 361658
A12: 6 | B12: 29/10/2025 | C12: Huỳnh Thị Đẹp | E12: 73 | F12: KHX trên màn hình tăng sáng | G12: TTDB | H12: 4497500 | I12: SƠN | J12: =R12-L12-N12-P12-Q12 -> 472237.5 | K12: LINH | L12: =IF(K12="-",0,H12*0.03) -> 134925 | M12: BÌNH | N12: =IF(M12="-",0,H12*0.02) -> 89950 | O12: THẠNH | P12: =IF(O12="-",0,H12*0.01) -> 44975 | Q12: =H12*0.005 -> 22487.5 | R12: =IF(I12="V.Tân",H12*0.1375,IF(I12="nguyện",H12*0.1375,IF(I12="TOẢN",H12*0.1375,IF(I12="TUẤN",H12*0.1375,H12*0.17)))) -> 764575
A13: 7 | B13: 29/10/2025 | C13: Lý Sển | D13: 68 | F13: PT cắt cụt chi | G13: TT2 | H13: 1947100 | I13: V.TÂN | J13: =R13-L13-N13-P13-Q13 -> 141164.75 | K13: ĐỨC | L13: =IF(K13="-",0,H13*0.03) -> 58413 | M13: KHÁNH | N13: =IF(M13="-",0,H13*0.02) -> 38942 | O13: THẠNH | P13: =IF(O13="-",0,H13*0.01) -> 19471 | Q13: =H13*0.005 -> 9735.5 | R13: =IF(I13="V.Tân",H13*0.1375,IF(I13="nguyện",H13*0.1375,IF(I13="TOẢN",H13*0.1375,IF(I13="TUẤN",H13*0.1375,H13*0.17)))) -> 267726.25
A14: 8 | B14: 30/10/2025 | C14: Lê Thị Mộng Thu | E14: 53 | F14: NS tái tạo dây chằng | G14: TTDB | H14: 3405500 | I14: SƠN | J14: =R14-L14-N14-P14-Q14 -> 357577.5 | K14: BẢO | L14: =IF(K14="-",0,H14*0.03) -> 102165 | M14: LINH | N14: =IF(M14="-",0,H14*0.02) -> 68110 | O14: NGHIÊM | P14: =IF(O14="-",0,H14*0.01) -> 34055 | Q14: =H14*0.005 -> 17027.5 | R14: =IF(I14="V.Tân",H14*0.1375,IF(I14="nguyện",H14*0.1375,IF(I14="TOẢN",H14*0.1375,IF(I14="TUẤN",H14*0.1375,H14*0.17)))) -> 578935
A15: 9 | B15: 30/10/2025 | C15: Lâm Hồng Luyến | D15: 39 | F15: NS tái tạo dây chằng | G15: TTDB | H15: 3405500 | I15: SƠN | J15: =R15-L15-N15-P15-Q15 -> 357577.5 | K15: LINH | L15: =IF(K15="-",0,H15*0.03) -> 102165 | M15: ẨN | N15: =IF(M15="-",0,H15*0.02) -> 68110 | O15: THẠNH | P15: =IF(O15="-",0,H15*0.01) -> 34055 | Q15: =H15*0.005 -> 17027.5 | R15: =IF(I15="V.Tân",H15*0.1375,IF(I15="nguyện",H15*0.1375,IF(I15="TOẢN",H15*0.1375,IF(I15="TUẤN",H15*0.1375,H15*0.17)))) -> 578935
A16: 10 | B16: 30/10/2025 | C16: Đinh Thị Thu Thảo | E16: 30 | F16: PT vết thương phần mềm phức tạp | G16: TP | H16: 5100000 | I16: BẢO | J16: =R16-L16-N16-P16-Q16 -> 535500 | K16: V.TÂN | L16: =IF(K16="-",0,H16*0.03) -> 153000 | M16: KHÁNH | N16: =IF(M16="-",0,H16*0.02) -> 102000 | O16: CÔNG | P16: =IF(O16="-",0,H16*0.01) -> 51000 | Q16: =H16*0.005 -> 25500 | R16: =IF(I16="V.Tân",H16*0.1375,IF(I16="nguyện",H16*0.1375,IF(I16="TOẢN",H16*0.1375,IF(I16="TUẤN",H16*0.1375,H16*0.17)))) -> 867000
A17: 11 | B17: 30/10/2025 | C17: Trần Thị Khéo | E17: 74 | F17: Cố định cột sống | G17: TTDB | H17: 4201900 | I17: NGUYỆN | J17: =R17-L17-N17-P17-Q17 -> 304637.75 | K17: TUẤN | L17: =IF(K17="-",0,H17*0.03) -> 126057 | M17: ĐỨC | N17: =IF(M17="-",0,H17*0.02) -> 84038 | O17: THẠNH | P17: =IF(O17="-",0,H17*0.01) -> 42019 | Q17: =H17*0.005 -> 21009.5 | R17: =IF(I17="V.Tân",H17*0.1375,IF(I17="nguyện",H17*0.1375,IF(I17="TOẢN",H17*0.1375,IF(I17="TUẤN",H17*0.1375,H17*0.17)))) -> 577761.25
A18: 12 | B18: 30/10/2025 | C18: Hồ Thị Ngự | E18: 56 | F18: KHX bánh chè | G18: TP | H18: 5253000 | I18: BẢO | J18: =R18-L18-N18-P18-Q18 -> 551565 | K18: TUẤN | L18: =IF(K18="-",0,H18*0.03) -> 157590 | M18: ĐỨC | N18: =IF(M18="-",0,H18*0.02) -> 105060 | O18: CÔNG | P18: =IF(O18="-",0,H18*0.01) -> 52530 | Q18: =H18*0.005 -> 26265 | R18: =IF(I18="V.Tân",H18*0.1375,IF(I18="nguyện",H18*0.1375,IF(I18="TOẢN",H18*0.1375,IF(I18="TUẤN",H18*0.1375,H18*0.17)))) -> 893010
A19: 13 | B19: 30/10/2025 | C19: Nguyễn Thị Xuân | E19: 85 | F19: PT cắt cụt chi | G19: TT2 | H19: 1947600 | I19: BẢO | J19: =R19-L19-N19-P19-Q19 -> 204498 | K19: TUẤN | L19: =IF(K19="-",0,H19*0.03) -> 58428 | M19: ĐỨC | N19: =IF(M19="-",0,H19*0.02) -> 38952 | O19: CÔNG | P19: =IF(O19="-",0,H19*0.01) -> 19476 | Q19: =H19*0.005 -> 9738 | R19: =IF(I19="V.Tân",H19*0.1375,IF(I19="nguyện",H19*0.1375,IF(I19="TOẢN",H19*0.1375,IF(I19="TUẤN",H19*0.1375,H19*0.17)))) -> 331092
A20: 14 | B20: 31/10/2025 | C20: Diệp Thị Tiến | E20: 71 | F20: Cắt lọc hoại tử ổ loét vết thương mãn tính | G20: TT2 | H20: 2127400 | I20: BẢO | J20: =R20-L20-N20-P20-Q20 -> 244651 | K20: ẨN | L20: =IF(K20="-",0,H20*0.03) -> 63822 | M20: THẠNH | N20: =IF(M20="-",0,H20*0.02) -> 42548 | O20: - | P20: =IF(O20="-",0,H20*0.01) -> 0 | Q20: =H20*0.005 -> 10637 | R20: =IF(I20="V.Tân",H20*0.1375,IF(I20="nguyện",H20*0.1375,IF(I20="TOẢN",H20*0.1375,IF(I20="TUẤN",H20*0.1375,H20*0.17)))) -> 361658
A21: 15 | B21: 31/10/2025 | C21: Phùng Thị Mỹ Dung | E21: 52 | F21: PTNS cắt lọc khớp gối | G21: TT1 | H21: 3397500 | I21: SƠN | J21: =R21-L21-N21-P21-Q21 -> 390712.5 | K21: NGHIÊM | L21: =IF(K21="-",0,H21*0.03) -> 101925 | M21: THẠNH | N21: =IF(M21="-",0,H21*0.02) -> 67950 | O21: - | P21: =IF(O21="-",0,H21*0.01) -> 0 | Q21: =H21*0.005 -> 16987.5 | R21: =IF(I21="V.Tân",H21*0.1375,IF(I21="nguyện",H21*0.1375,IF(I21="TOẢN",H21*0.1375,IF(I21="TUẤN",H21*0.1375,H21*0.17)))) -> 577575
A22: 16 | B22: 31/10/2025 | C22: Lê Thị Kim Tiếp | E22: 61 | F22: Cố định cột sống | G22: TTDB | H22: 4201900 | I22: HOAN | J22: =R22-L22-N22-P22-Q22 -> 441199.5 | K22: NGUYỆN | L22: =IF(K22="-",0,H22*0.03) -> 126057 | M22: TUẤN | N22: =IF(M22="-",0,H22*0.02) -> 84038 | O22: LINH | P22: =IF(O22="-",0,H22*0.01) -> 42019 | Q22: =H22*0.005 -> 21009.5 | R22: =IF(I22="V.Tân",H22*0.1375,IF(I22="nguyện",H22*0.1375,IF(I22="TOẢN",H22*0.1375,IF(I22="TUẤN",H22*0.1375,H22*0.17)))) -> 714323
A23: 17 | B23: 31/10/2025 | C23: Nguyễn Trần Ngọc Hân | E23: 17 | F23: KHX trên màn hình tăng sáng | G23: TTDB | H23: 4497500 | I23: NGUYỆN | J23: =R23-L23-N23-P23-Q23 -> 326068.75 | K23: THIỆN | L23: =IF(K23="-",0,H23*0.03) -> 134925 | M23: BÌNH | N23: =IF(M23="-",0,H23*0.02) -> 89950 | O23: ẨN | P23: =IF(O23="-",0,H23*0.01) -> 44975 | Q23: =H23*0.005 -> 22487.5 | R23: =IF(I23="V.Tân",H23*0.1375,IF(I23="nguyện",H23*0.1375,IF(I23="TOẢN",H23*0.1375,IF(I23="TUẤN",H23*0.1375,H23*0.17)))) -> 618406.25
A24: 18 | B24: 01/11/2025 | C24: Huỳnh Minh Tần | D24: 34 | F24: PT thay khớp háng toàn phần | G24: TTDB | H24: 3525500 | I24: TẤN | J24: =R24-L24-N24-P24-Q24 -> 370177.5 | K24: NGUYỆN | L24: =IF(K24="-",0,H24*0.03) -> 105765 | M24: BẢO | N24: =IF(M24="-",0,H24*0.02) -> 70510 | O24: G.TỬ | P24: =IF(O24="-",0,H24*0.01) -> 35255 | Q24: =H24*0.005 -> 17627.5 | R24: =IF(I24="V.Tân",H24*0.1375,IF(I24="nguyện",H24*0.1375,IF(I24="TOẢN",H24*0.1375,IF(I24="TUẤN",H24*0.1375,H24*0.17)))) -> 599335
A25: 19 | B25: 01/11/2025 | C25: Huỳnh Minh Tần | D25: 34 | F25: PT thay khớp háng toàn phần (50%) | G25: TTDB | H25: 1762750 | I25: TẤN | J25: =R25-L25-N25-P25-Q25 -> 185088.75 | K25: NGUYỆN | L25: =IF(K25="-",0,H25*0.03) -> 52882.5 | M25: BẢO | N25: =IF(M25="-",0,H25*0.02) -> 35255 | O25: G.TỬ | P25: =IF(O25="-",0,H25*0.01) -> 17627.5 | Q25: =H25*0.005 -> 8813.75 | R25: =IF(I25="V.Tân",H25*0.1375,IF(I25="nguyện",H25*0.1375,IF(I25="TOẢN",H25*0.1375,IF(I25="TUẤN",H25*0.1375,H25*0.17)))) -> 299667.5
A26: 20 | B26: 01/11/2025 | C26: Trần Thị Lến | E26: 90 | F26: PT thay khớp háng bán phần | G26: TT1 | H26: 3897500 | I26: HOAN | J26: =R26-L26-N26-P26-Q26 -> 409237.5 | K26: V.TÂN | L26: =IF(K26="-",0,H26*0.03) -> 116925 | M26: TUẤN | N26: =IF(M26="-",0,H26*0.02) -> 77950 | O26: ĐỨC | P26: =IF(O26="-",0,H26*0.01) -> 38975 | Q26: =H26*0.005 -> 19487.5 | R26: =IF(I26="V.Tân",H26*0.1375,IF(I26="nguyện",H26*0.1375,IF(I26="TOẢN",H26*0.1375,IF(I26="TUẤN",H26*0.1375,H26*0.17)))) -> 662575
A27: 21 | B27: 01/11/2025 | C27: Huỳnh Hoàng Sơn | D27: 36 | F27: PT KHX trên màn hình tăng sáng | G27: TP | H27: 9972000 | I27: DUY | J27: =R27-L27-N27-P27-Q27 -> 1146780 | K27: LINH | L27: =IF(K27="-",0,H27*0.03) -> 299160 | M27: ẨN | N27: =IF(M27="-",0,H27*0.02) -> 199440 | O27: - | P27: =IF(O27="-",0,H27*0.01) -> 0 | Q27: =H27*0.005 -> 49860 | R27: =IF(I27="V.Tân",H27*0.1375,IF(I27="nguyện",H27*0.1375,IF(I27="TOẢN",H27*0.1375,IF(I27="TUẤN",H27*0.1375,H27*0.17)))) -> 1695240
A28: 22 | B28: 03/11/2025 | C28: Trần Thị Ngọc | E28: 56 | F28: KHX trên màn hình tăng sáng | G28: TTDB | H28: 4497500 | I28: ĐIỀN | J28: =R28-L28-N28-P28-Q28 -> 517212.5 | K28: TUẤN | L28: =IF(K28="-",0,H28*0.03) -> 134925 | M28: CÔNG | N28: =IF(M28="-",0,H28*0.02) -> 89950 | O28: - | P28: =IF(O28="-",0,H28*0.01) -> 0 | Q28: =H28*0.005 -> 22487.5 | R28: =IF(I28="V.Tân",H28*0.1375,IF(I28="nguyện",H28*0.1375,IF(I28="TOẢN",H28*0.1375,IF(I28="TUẤN",H28*0.1375,H28*0.17)))) -> 764575
A29: 23 | B29: 03/11/2025 | C29: Lê Thị Đẹp | E29: 74 | F29: Cố định cột sống | G29: TTDB | H29: 4201900 | I29: HOAN | J29: =R29-L29-N29-P29-Q29 -> 441199.5 | K29: NGUYỆN | L29: =IF(K29="-",0,H29*0.03) -> 126057 | M29: ĐIỀN | N29: =IF(M29="-",0,H29*0.02) -> 84038 | O29: THIỆN | P29: =IF(O29="-",0,H29*0.01) -> 42019 | Q29: =H29*0.005 -> 21009.5 | R29: =IF(I29="V.Tân",H29*0.1375,IF(I29="nguyện",H29*0.1375,IF(I29="TOẢN",H29*0.1375,IF(I29="TUẤN",H29*0.1375,H29*0.17)))) -> 714323
A30: 24 | B30: 04/11/2025 | C30: Trần Bé Hiệp | D30: 40 | F30: Phẫu thuật vết thương phần mềm phức tạp | G30: TP | H30: 6000000 | I30: SƠN | J30: =R30-L30-N30-P30-Q30 -> 690000 | K30: THIỆN | L30: =IF(K30="-",0,H30*0.03) -> 180000 | M30: DƯƠNG | N30: =IF(M30="-",0,H30*0.02) -> 120000 | O30: - | P30: =IF(O30="-",0,H30*0.01) -> 0 | Q30: =H30*0.005 -> 30000 | R30: =IF(I30="V.Tân",H30*0.1375,IF(I30="nguyện",H30*0.1375,IF(I30="TOẢN",H30*0.1375,IF(I30="TUẤN",H30*0.1375,H30*0.17)))) -> 1020000
A31: 25 | B31: 04/11/2025 | C31: Trần Thị Bích Ngọc | E31: 28 | F31: PTNS khâu chóp xoay | G31: TTDB | H31: 5397500 | I31: SƠN | J31: =R31-L31-N31-P31-Q31 -> 566737.5 | K31: TUẤN | L31: =IF(K31="-",0,H31*0.03) -> 161925 | M31: ĐỨC | N31: =IF(M31="-",0,H31*0.02) -> 107950 | O31: BÌNH | P31: =IF(O31="-",0,H31*0.01) -> 53975 | Q31: =H31*0.005 -> 26987.5 | R31: =IF(I31="V.Tân",H31*0.1375,IF(I31="nguyện",H31*0.1375,IF(I31="TOẢN",H31*0.1375,IF(I31="TUẤN",H31*0.1375,H31*0.17)))) -> 917575
A32: 26 | B32: 04/11/2025 | C32: Đinh Thị Minh Thư | E32: 36 | F32: PT KHX trên màn hình tăng sáng | G32: TP | H32: 9972000 | I32: DUY | J32: =R32-L32-N32-P32-Q32 -> 1047060 | K32: V.TÂN | L32: =IF(K32="-",0,H32*0.03) -> 299160 | M32: LINH | N32: =IF(M32="-",0,H32*0.02) -> 199440 | O32: ẨN | P32: =IF(O32="-",0,H32*0.01) -> 99720 | Q32: =H32*0.005 -> 49860 | R32: =IF(I32="V.Tân",H32*0.1375,IF(I32="nguyện",H32*0.1375,IF(I32="TOẢN",H32*0.1375,IF(I32="TUẤN",H32*0.1375,H32*0.17)))) -> 1695240
A33: 27 | B33: 04/11/2025 | C33: Nguyễn Hiếu Nghĩa | D33: 65 | F33: PTNS khâu chóp xoay | G33: TTDB | H33: 5397500 | I33: SƠN | J33: =R33-L33-N33-P33-Q33 -> 566737.5 | K33: NGHIÊM | L33: =IF(K33="-",0,H33*0.03) -> 161925 | M33: THẠNH | N33: =IF(M33="-",0,H33*0.02) -> 107950 | O33: TUẤN | P33: =IF(O33="-",0,H33*0.01) -> 53975 | Q33: =H33*0.005 -> 26987.5 | R33: =IF(I33="V.Tân",H33*0.1375,IF(I33="nguyện",H33*0.1375,IF(I33="TOẢN",H33*0.1375,IF(I33="TUẤN",H33*0.1375,H33*0.17)))) -> 917575
A34: 28 | B34: 05/11/2025 | C34: Trần Ngọc Vấn | D34: 63 | F34: Cố định cột sống | G34: TTDB | H34: 4201900 | I34: HOAN | J34: =R34-L34-N34-P34-Q34 -> 441199.5 | K34: NGUYỆN | L34: =IF(K34="-",0,H34*0.03) -> 126057 | M34: ĐIỀN | N34: =IF(M34="-",0,H34*0.02) -> 84038 | O34: LINH | P34: =IF(O34="-",0,H34*0.01) -> 42019 | Q34: =H34*0.005 -> 21009.5 | R34: =IF(I34="V.Tân",H34*0.1375,IF(I34="nguyện",H34*0.1375,IF(I34="TOẢN",H34*0.1375,IF(I34="TUẤN",H34*0.1375,H34*0.17)))) -> 714323
A35: 29 | B35: 05/11/2025 | C35: Lê Xuân Hải | D35: 59 | F35: Lấy dụng cụ | G35: TT2 | H35: 2559100 | I35: DUY | J35: =R35-L35-N35-P35-Q35 -> 294296.5 | K35: G.TỬ | L35: =IF(K35="-",0,H35*0.03) -> 76773 | M35: NGHIÊM | N35: =IF(M35="-",0,H35*0.02) -> 51182 | O35: - | P35: =IF(O35="-",0,H35*0.01) -> 0 | Q35: =H35*0.005 -> 12795.5 | R35: =IF(I35="V.Tân",H35*0.1375,IF(I35="nguyện",H35*0.1375,IF(I35="TOẢN",H35*0.1375,IF(I35="TUẤN",H35*0.1375,H35*0.17)))) -> 435047
A36: 30 | B36: 05/11/2025 | C36: Trần Huỳnh Long | D36: 41 | F36: PT KHX trên màn hình tăng sáng | G36: TP | H36: 9972000 | I36: NGUYỆN | J36: =R36-L36-N36-P36-Q36 -> 722970 | K36: ĐIỀN | L36: =IF(K36="-",0,H36*0.03) -> 299160 | M36: THIỆN | N36: =IF(M36="-",0,H36*0.02) -> 199440 | O36: LINH | P36: =IF(O36="-",0,H36*0.01) -> 99720 | Q36: =H36*0.005 -> 49860 | R36: =IF(I36="V.Tân",H36*0.1375,IF(I36="nguyện",H36*0.1375,IF(I36="TOẢN",H36*0.1375,IF(I36="TUẤN",H36*0.1375,H36*0.17)))) -> 1371150
A37: 31 | B37: 05/11/2025 | C37: Đỗ Văn Dũng | D37: 55 | F37: Ghép da | G37: TT2 | H37: 2934400 | I37: V.TÂN | J37: =R37-L37-N37-P37-Q37 -> 212744 | K37: DƯƠNG | L37: =IF(K37="-",0,H37*0.03) -> 88032 | M37: ẨN | N37: =IF(M37="-",0,H37*0.02) -> 58688 | O37: BÌNH | P37: =IF(O37="-",0,H37*0.01) -> 29344 | Q37: =H37*0.005 -> 14672 | R37: =IF(I37="V.Tân",H37*0.1375,IF(I37="nguyện",H37*0.1375,IF(I37="TOẢN",H37*0.1375,IF(I37="TUẤN",H37*0.1375,H37*0.17)))) -> 403480
A38: 32 | B38: 05/11/2025 | C38: Nguyễn Hiếu Cẩn | D38: 37 | F38: Cắt lọc | G38: TP | H38: 4302000 | I38: TUẤN | J38: =R38-L38-N38-P38-Q38 -> 570015 | K38: - | L38: =IF(K38="-",0,H38*0.03) -> 0 | M38: - | N38: =IF(M38="-",0,H38*0.02) -> 0 | O38: - | P38: =IF(O38="-",0,H38*0.01) -> 0 | Q38: =H38*0.005 -> 21510 | R38: =IF(I38="V.Tân",H38*0.1375,IF(I38="nguyện",H38*0.1375,IF(I38="TOẢN",H38*0.1375,IF(I38="TUẤN",H38*0.1375,H38*0.17)))) -> 591525
A39: 33 | B39: 05/11/2025 | C39: Phạm Thị Tuyết Mai | E39: 32 | F39: KHX trên màn hình tăng sáng | G39: TTDB | H39: 4497500 | I39: TUẤN | J39: =R39-L39-N39-P39-Q39 -> 326068.75 | K39: G.TỬ | L39: =IF(K39="-",0,H39*0.03) -> 134925 | M39: THIỆN | N39: =IF(M39="-",0,H39*0.02) -> 89950 | O39: THẠNH | P39: =IF(O39="-",0,H39*0.01) -> 44975 | Q39: =H39*0.005 -> 22487.5 | R39: =IF(I39="V.Tân",H39*0.1375,IF(I39="nguyện",H39*0.1375,IF(I39="TOẢN",H39*0.1375,IF(I39="TUẤN",H39*0.1375,H39*0.17)))) -> 618406.25
A40: 34 | B40: 06/11/2025 | C40: Bùi Thị Lệ Thanh | E40: 47 | F40: KHX trên màn hình tăng sáng | G40: TTDB | H40: 4497500 | I40: TOẢN | J40: =R40-L40-N40-P40-Q40 -> 326068.75 | K40: NGUYỆN | L40: =IF(K40="-",0,H40*0.03) -> 134925 | M40: NGHIÊM | N40: =IF(M40="-",0,H40*0.02) -> 89950 | O40: KHÁNH | P40: =IF(O40="-",0,H40*0.01) -> 44975 | Q40: =H40*0.005 -> 22487.5 | R40: =IF(I40="V.Tân",H40*0.1375,IF(I40="nguyện",H40*0.1375,IF(I40="TOẢN",H40*0.1375,IF(I40="TUẤN",H40*0.1375,H40*0.17)))) -> 618406.25
A41: 35 | B41: 06/11/2025 | C41: Phạm Thị Kim Phượng | E41: 58 | F41: Cắt lọc hoại tử ổ loét | G41: TT2 | H41: 2127400 | I41: ĐIỀN | J41: =R41-L41-N41-P41-Q41 -> 244651 | K41: ĐỨC | L41: =IF(K41="-",0,H41*0.03) -> 63822 | M41: ẨN | N41: =IF(M41="-",0,H41*0.02) -> 42548 | O41: - | P41: =IF(O41="-",0,H41*0.01) -> 0 | Q41: =H41*0.005 -> 10637 | R41: =IF(I41="V.Tân",H41*0.1375,IF(I41="nguyện",H41*0.1375,IF(I41="TOẢN",H41*0.1375,IF(I41="TUẤN",H41*0.1375,H41*0.17)))) -> 361658
...

Sheet lanh tien PT
A1: BV TRƯỜNG ĐHYD CẦN THƠ
A2: KHOA NGOẠI CTCH-TK
B3: DANH SÁCH LÃNH TIỀN THÙ LAO THÁNG 11/2025
C4: (Phẫu thuật)
A6: STT | B6: HỌ TÊN | C6: chức vụ | D6: SỐ TIỀN | E6: KÝ NHẬN
A7: 1 | B7: Nguyễn Thành Tấn | C7: Bác sĩ | D7: =SUM(SUMIF(phauthuat!$I$7:$I$121,"TẤN",phauthuat!$J$7:$J$121),SUMIF(phauthuat!$K$7:$K$121,"TẤN",phauthuat!$L$7:$L$121),SUMIF(phauthuat!$M$7:$M$121,"TẤN",phauthuat!$N$7:$N$121),SUMIF(phauthuat!$O$7:$O$121,"TẤN",phauthuat!$P$7:$P$121)) -> 555266.25
A8: 2 | B8: Nguyễn Lê Hoan | C8: Bác sĩ | D8: =SUM(SUMIF(phauthuat!$I$7:$I$121,"HOAN",phauthuat!$J$7:$J$121),SUMIF(phauthuat!$K$7:$K$121,"HOAN",phauthuat!$L$7:$L$121),SUMIF(phauthuat!$M$7:$M$121,"HOAN",phauthuat!$N$7:$N$121),SUMIF(phauthuat!$O$7:$O$121,"Hoan",phauthuat!$P$7:$P$121)) -> 8513606.5
A9: 3 | B9: Nguyễn Chí Nguyện | C9: Bác sĩ | D9: =SUM(SUMIF(phauthuat!$I$7:$I$121,"NGUYỆN",phauthuat!$J$7:$J$121),SUMIF(phauthuat!$K$7:$K$121,"NGUYỆN",phauthuat!$L$7:$L$121),SUMIF(phauthuat!$M$7:$M$121,"NGUYỆN",phauthuat!$N$7:$N$121),SUMIF(phauthuat!$O$7:$O$121,"NGUYỆN",phauthuat!$P$7:$P$121)) -> 6612558
A10: 4 | B10: Hồ Điền | C10: Bác sĩ | D10: =SUM(SUMIF(phauthuat!$I$7:$I$121,"ĐIỀN",phauthuat!$J$7:$J$121),SUMIF(phauthuat!$K$7:$K$121,"ĐIỀN",phauthuat!$L$7:$L$121),SUMIF(phauthuat!$M$7:$M$121,"ĐIỀN",phauthuat!$N$7:$N$121),SUMIF(phauthuat!$O$7:$O$121,"ĐIỀN",phauthuat!$P$7:$P$121)) -> 4790892
A11: 5 | B11: Trần Quốc Toản | C11: Bác sĩ | D11: =SUM(SUMIF(phauthuat!$I$7:$I$121,"TOẢN",phauthuat!$J$7:$J$121),SUMIF(phauthuat!$K$7:$K$121,"TOẢN",phauthuat!$L$7:$L$121),SUMIF(phauthuat!$M$7:$M$121,"TOẢN",phauthuat!$N$7:$N$121),SUMIF(phauthuat!$O$7:$O$121,"TOẢN",phauthuat!$P$7:$P$121)) -> 3091240.5
A12: 6 | B12: Phạm Việt Tân | C12: Bác sĩ | D12: =SUM(SUMIF(phauthuat!$I$7:$I$121,"V.TÂN",phauthuat!$J$7:$J$121),SUMIF(phauthuat!$K$7:$K$121,"V.TÂN",phauthuat!$L$7:$L$121),SUMIF(phauthuat!$M$7:$M$121,"V.TÂN",phauthuat!$N$7:$N$121),SUMIF(phauthuat!$O$7:$O$121,"V.TÂN",phauthuat!$P$7:$P$121)) -> 2400262.8
A13: 7 | B13: Phan Văn Tuấn | C13: Bác sĩ | D13: =SUM(SUMIF(phauthuat!$I$7:$I$121,"TUẤN",phauthuat!$J$7:$J$121),SUMIF(phauthuat!$K$7:$K$121,"TUẤN",phauthuat!$L$7:$L$121),SUMIF(phauthuat!$M$7:$M$121,"TUẤN",phauthuat!$N$7:$N$121),SUMIF(phauthuat!$O$7:$O$121,"TUẤN",phauthuat!$P$7:$P$121)) -> 6866610.2
A14: 8 | B14: Nguyễn Tư Thái Bảo | C14: Bác sĩ | D14: =SUM(SUMIF(phauthuat!$I$7:$I$121,"BẢO",phauthuat!$J$7:$J$121),SUMIF(phauthuat!$K$7:$K$121,"BẢO",phauthuat!$L$7:$L$121),SUMIF(phauthuat!$M$7:$M$121,"BẢO",phauthuat!$N$7:$N$121),SUMIF(phauthuat!$O$7:$O$121,"BẢO",phauthuat!$P$7:$P$121)) -> 5240183
A15: 9 | B15: Trần Nguyễn Anh Duy | C15: Bác sĩ | D15: =SUM(SUMIF(phauthuat!$I$7:$I$121,"DUY",phauthuat!$J$7:$J$121),SUMIF(phauthuat!$K$7:$K$121,"DUY",phauthuat!$L$7:$L$121),SUMIF(phauthuat!$M$7:$M$121,"DUY",phauthuat!$N$7:$N$121),SUMIF(phauthuat!$O$7:$O$121,"DUY",phauthuat!$P$7:$P$121)) -> 5385728
A16: 10 | B16: Trần Quang Sơn | C16: Bác sĩ | D16: =SUM(SUMIF(phauthuat!$I$7:$I$121,"SƠN",phauthuat!$J$7:$J$121),SUMIF(phauthuat!$K$7:$K$121,"SƠN",phauthuat!$L$7:$L$121),SUMIF(phauthuat!$M$7:$M$121,"SƠN",phauthuat!$N$7:$N$121),SUMIF(phauthuat!$O$7:$O$121,"SƠN",phauthuat!$P$7:$P$121)) -> 5711389
A17: 11 | B17: Nguyễn Giang Tử | C17: Bác sĩ | D17: =SUM(SUMIF(phauthuat!$I$7:$I$121,"G.TỬ",phauthuat!$J$7:$J$121),SUMIF(phauthuat!$K$7:$K$121,"G.TỬ",phauthuat!$L$7:$L$121),SUMIF(phauthuat!$M$7:$M$121,"G.TỬ",phauthuat!$N$7:$N$121),SUMIF(phauthuat!$O$7:$O$121,"G.TỬ",phauthuat!$P$7:$P$121)) -> 2400965.5
A18: 12 | B18: Võ Long Ẩn | C18: Bác sĩ (nt) | D18: =SUM(SUMIF(phauthuat!$I$7:$I$121,"ẨN",phauthuat!$J$7:$J$121),SUMIF(phauthuat!$K$7:$K$121,"ẨN",phauthuat!$L$7:$L$121),SUMIF(phauthuat!$M$7:$M$121,"ẨN",phauthuat!$N$7:$N$121),SUMIF(phauthuat!$O$7:$O$121,"ẨN",phauthuat!$P$7:$P$121)) -> 1037686
A19: 13 | B19: Nguyễn Xuân Bình | C19: Bác sĩ (nt) | D19: =SUM(SUMIF(phauthuat!$I$7:$I$121,"Bình",phauthuat!$J$7:$J$121),SUMIF(phauthuat!$K$7:$K$121,"bình",phauthuat!$L$7:$L$121),SUMIF(phauthuat!$M$7:$M$121,"bình",phauthuat!$N$7:$N$121),SUMIF(phauthuat!$O$7:$O$121,"bình",phauthuat!$P$7:$P$121)) -> 707162
A20: 14 | B20: Phan Doãn Đại Dương | C20: Bác sĩ (nt) | D20: =SUM(SUMIF(phauthuat!$I$7:$I$121,"dương",phauthuat!$J$7:$J$121),SUMIF(phauthuat!$K$7:$K$121,"dương",phauthuat!$L$7:$L$121),SUMIF(phauthuat!$M$7:$M$121,"dương",phauthuat!$N$7:$N$121),SUMIF(phauthuat!$O$7:$O$121,"dương",phauthuat!$P$7:$P$121)) -> 711236
A21: 15 | B21: Lê Quốc Khánh | C21: Bác sĩ (nt) | D21: =SUM(SUMIF(phauthuat!$I$7:$I$121,"khánh",phauthuat!$J$7:$J$121),SUMIF(phauthuat!$K$7:$K$121,"khánh",phauthuat!$L$7:$L$121),SUMIF(phauthuat!$M$7:$M$121,"khánh",phauthuat!$N$7:$N$121),SUMIF(phauthuat!$O$7:$O$121,"khánh",phauthuat!$P$7:$P$121)) -> 591749
A22: 16 | B22: Lê Cường Thạnh | C22: Bác sĩ (nt) | D22: =SUM(SUMIF(phauthuat!$I$7:$I$121,"thạnh",phauthuat!$J$7:$J$121),SUMIF(phauthuat!$K$7:$K$121,"thạnh",phauthuat!$L$7:$L$121),SUMIF(phauthuat!$M$7:$M$121,"thạnh",phauthuat!$N$7:$N$121),SUMIF(phauthuat!$O$7:$O$121,"thạnh",phauthuat!$P$7:$P$121)) -> 1054169
A23: 17 | B23: Nguyễn Văn Nghiêm | C23: Bác sĩ (nt) | D23: =SUM(SUMIF(phauthuat!$I$7:$I$121,"NGHIÊM",phauthuat!$J$7:$J$121),SUMIF(phauthuat!$K$7:$K$121,"NGHIÊM",phauthuat!$L$7:$L$121),SUMIF(phauthuat!$M$7:$M$121,"NGHIÊM",phauthuat!$N$7:$N$121),SUMIF(phauthuat!$O$7:$O$121,"NGHIÊM",phauthuat!$P$7:$P$121)) -> 1093514
A24: 18 | B24: Đỗ Thành Công | C24: Bác sĩ (nt) | D24: =SUM(SUMIF(phauthuat!$I$7:$I$121,"CÔNG",phauthuat!$J$7:$J$121),SUMIF(phauthuat!$K$7:$K$121,"CÔNG",phauthuat!$L$7:$L$121),SUMIF(phauthuat!$M$7:$M$121,"CÔNG",phauthuat!$N$7:$N$121),SUMIF(phauthuat!$O$7:$O$121,"CÔNG",phauthuat!$P$7:$P$121)) -> 1483944
A25: 19 | B25: Võ Ngọc Thiện | C25: Bác sĩ (nt) | D25: =SUM(SUMIF(phauthuat!$I$7:$I$121,"THIỆN",phauthuat!$J$7:$J$121),SUMIF(phauthuat!$K$7:$K$121,"THIỆN",phauthuat!$L$7:$L$121),SUMIF(phauthuat!$M$7:$M$121,"THIỆN",phauthuat!$N$7:$N$121),SUMIF(phauthuat!$O$7:$O$121,"THIỆN",phauthuat!$P$7:$P$121)) -> 2265346
A26: 20 | B26: Nguyễn Hoài Linh | C26: Bác sĩ (nt) | D26: =SUM(SUMIF(phauthuat!$I$7:$I$121,"LINH",phauthuat!$J$7:$J$121),SUMIF(phauthuat!$K$7:$K$121,"LINH",phauthuat!$L$7:$L$121),SUMIF(phauthuat!$M$7:$M$121,"LINH",phauthuat!$N$7:$N$121),SUMIF(phauthuat!$O$7:$O$121,"LINH",phauthuat!$P$7:$P$121)) -> 2062681
A27: 21 | B27: Nguyễn Hoài Đức | C27: Bác sĩ (nt) | D27: =SUM(SUMIF(phauthuat!$I$7:$I$121,"ĐỨC",phauthuat!$J$7:$J$121),SUMIF(phauthuat!$K$7:$K$121,"ĐỨC",phauthuat!$L$7:$L$121),SUMIF(phauthuat!$M$7:$M$121,"ĐỨC",phauthuat!$N$7:$N$121),SUMIF(phauthuat!$O$7:$O$121,"ĐỨC",phauthuat!$P$7:$P$121)) -> 1375488
A28: 22 | B28: Phan Văn Hiếu | C28: Điều dưỡng | D28: =phauthuat!Q119/10 -> 209615.58
A29: 23 | B29: Võ Thị Yến Nhi | C29: Điều dưỡng | D29: =D28 -> 209615.58
A30: 24 | B30: Võ Phương Duy | C30: Điều dưỡng | D30: =D29 -> 209615.58
A31: 25 | B31: Nguyễn Kim Ngân | C31: Điều dưỡng | D31: =D30 -> 209615.58
A32: 26 | B32: Lê Ngọc Diệu | C32: Điều dưỡng | D32: =D31 -> 209615.58
A33: 27 | B33: Trần Quỳnh Minh Thư | C33: Điều dưỡng | D33: =D32 -> 209615.58
A34: 28 | B34: Lê Thị Tuyết Đoan | C34: Điều dưỡng | D34: =D33 -> 209615.58
A35: 29 | B35: Thạch Thị Thúy Đa | C35: Điều dưỡng | D35: =D33 -> 209615.58
A36: 30 | B36: Lê Kim Hoàn | C36: Điều dưỡng | D36: =D35 -> 209615.58
A37: 31 | B37: Nguyễn Lê Duy Anh | C37: Điều dưỡng | D37: =D36 -> 209615.58
B38: TỔNG CỘNG | D38: =SUM(D7:D37) -> 66047833
D40: Cần Thơ, ngày 16 tháng 12 năm 2025
A41: Người lập bảng | D41: Trưởng khoa
D44: =phauthuat!R119-'lanh tien PT'!D38 -> 0

Sheet phauthuat_BHYT
A1: BV TRƯỜNG ĐHYD CẦN THƠ
A2: KHOA NGOẠI CTCH-TK
B3: BẢNG KÊ TIỀN PHẪU THUẬT BHYT
A4: (THÁNG 11/2025)
A7: STT | B7: Ngày | C7: Họ và tên | D7: Nam | E7: Nữ | F7: Phương pháp phẫu thuật | G7: loại pt - đối tượng | H7: PTV chính | I7: Số tiền | J7: Phụ mổ 1 | K7: Số tiền | L7: Phụ mổ 2 | M7: Số tiền | N7: Tổng số tiền được lãnh sau trừ khấu hao
A8: 1 | B8: 24/10/2025 | C8: Nguyễn Long Hồ | D8: 52 | F8: PT thay toàn bộ khớp háng | G8: DTDB | H8: HOAN | I8: =IF(G8="DTDB",420000,IF(G8="TTDB",420000,IF(G8="DT1",187500,IF(G8="TT1",187500,IF(G8="DT2",97500,IF(G8="TT2",97500,IF(G8="DT3",75000,75000))))))) -> 420000 | J8: TUẤN | K8: =IF(G8="DTDB",300000,IF(G8="TTDB",300000,IF(G8="DT1",135000,IF(G8="TT1",135000,IF(G8="DT2",75000,IF(G8="TT2",75000,IF(G8="DT3",45000,45000))))))) -> 300000 | L8: ĐỨC | M8: =IF(L8="-",0,IF(G8="DTDB",300000,IF(G8="TTDB",300000,IF(G8="DT1",135000,IF(G8="TT1",135000,IF(G8="DT2",75000,IF(G8="TT2",75000,IF(G8="DT3",45000,45000)))))))) -> 300000 | N8: =I8+K8+M8 -> 1020000
A9: 2 | B9: 27/10/2025 | C9: Nguyễn Thị Bê | E9: 87 | F9: PT thay khớp háng bán phần | G9: TT1 | H9: HOAN | I9: =IF(G9="DTDB",420000,IF(G9="TTDB",420000,IF(G9="DT1",187500,IF(G9="TT1",187500,IF(G9="DT2",97500,IF(G9="TT2",97500,IF(G9="DT3",75000,75000))))))) -> 187500 | J9: DUY | K9: =IF(G9="DTDB",300000,IF(G9="TTDB",300000,IF(G9="DT1",135000,IF(G9="TT1",135000,IF(G9="DT2",75000,IF(G9="TT2",75000,IF(G9="DT3",45000,45000))))))) -> 135000 | L9: TUẤN | M9: =IF(L9="-",0,IF(G9="DTDB",300000,IF(G9="TTDB",300000,IF(G9="DT1",135000,IF(G9="TT1",135000,IF(G9="DT2",75000,IF(G9="TT2",75000,IF(G9="DT3",45000,45000)))))))) -> 135000 | N9: =I9+K9+M9 -> 457500
A10: 3 | B10: 27/10/2025 | C10: Phan Thúy Chiều | E10: 37 | F10: PT vết thương phần mềm phức tạp | G10: DT1 | H10: V.TÂN | I10: =IF(G10="DTDB",420000,IF(G10="TTDB",420000,IF(G10="DT1",187500,IF(G10="TT1",187500,IF(G10="DT2",97500,IF(G10="TT2",97500,IF(G10="DT3",75000,75000))))))) -> 187500 | J10: BẢO | K10: =IF(G10="DTDB",300000,IF(G10="TTDB",300000,IF(G10="DT1",135000,IF(G10="TT1",135000,IF(G10="DT2",75000,IF(G10="TT2",75000,IF(G10="DT3",45000,45000))))))) -> 135000 | L10: TUẤN | M10: =IF(L10="-",0,IF(G10="DTDB",300000,IF(G10="TTDB",300000,IF(G10="DT1",135000,IF(G10="TT1",135000,IF(G10="DT2",75000,IF(G10="TT2",75000,IF(G10="DT3",45000,45000)))))))) -> 135000 | N10: =I10+K10+M10 -> 457500
A11: 4 | B11: 28/10/2025 | C11: Nguyễn Thị Pha | E11: 59 | F11: PT thay toàn bộ khớp háng | G11: TTDB | H11: HOAN | I11: =IF(G11="DTDB",420000,IF(G11="TTDB",420000,IF(G11="DT1",187500,IF(G11="TT1",187500,IF(G11="DT2",97500,IF(G11="TT2",97500,IF(G11="DT3",75000,75000))))))) -> 420000 | J11: SƠN | K11: =IF(G11="DTDB",300000,IF(G11="TTDB",300000,IF(G11="DT1",135000,IF(G11="TT1",135000,IF(G11="DT2",75000,IF(G11="TT2",75000,IF(G11="DT3",45000,45000))))))) -> 300000 | L11: TUẤN | M11: =IF(L11="-",0,IF(G11="DTDB",300000,IF(G11="TTDB",300000,IF(G11="DT1",135000,IF(G11="TT1",135000,IF(G11="DT2",75000,IF(G11="TT2",75000,IF(G11="DT3",45000,45000)))))))) -> 300000 | N11: =I11+K11+M11 -> 1020000
A12: 5 | B12: 29/10/2025 | C12: Huỳnh Thị Đẹp | E12: 73 | F12: KHX trên màn hình tăng sáng | G12: TTDB | H12: SƠN | I12: =IF(G12="DTDB",420000,IF(G12="TTDB",420000,IF(G12="DT1",187500,IF(G12="TT1",187500,IF(G12="DT2",97500,IF(G12="TT2",97500,IF(G12="DT3",75000,75000))))))) -> 420000 | J12: LINH | K12: =IF(G12="DTDB",300000,IF(G12="TTDB",300000,IF(G12="DT1",135000,IF(G12="TT1",135000,IF(G12="DT2",75000,IF(G12="TT2",75000,IF(G12="DT3",45000,45000))))))) -> 300000 | L12: BÌNH | M12: =IF(L12="-",0,IF(G12="DTDB",300000,IF(G12="TTDB",300000,IF(G12="DT1",135000,IF(G12="TT1",135000,IF(G12="DT2",75000,IF(G12="TT2",75000,IF(G12="DT3",45000,45000)))))))) -> 300000 | N12: =I12+K12+M12 -> 1020000
A13: 6 | B13: 30/10/2025 | C13: Lê Thị Mộng Thu | E13: 53 | F13: NS tái tạo dây chằng | G13: TTDB | H13: SƠN | I13: =IF(G13="DTDB",420000,IF(G13="TTDB",420000,IF(G13="DT1",187500,IF(G13="TT1",187500,IF(G13="DT2",97500,IF(G13="TT2",97500,IF(G13="DT3",75000,75000))))))) -> 420000 | J13: BẢO | K13: =IF(G13="DTDB",300000,IF(G13="TTDB",300000,IF(G13="DT1",135000,IF(G13="TT1",135000,IF(G13="DT2",75000,IF(G13="TT2",75000,IF(G13="DT3",45000,45000))))))) -> 300000 | L13: LINH | M13: =IF(L13="-",0,IF(G13="DTDB",300000,IF(G13="TTDB",300000,IF(G13="DT1",135000,IF(G13="TT1",135000,IF(G13="DT2",75000,IF(G13="TT2",75000,IF(G13="DT3",45000,45000)))))))) -> 300000 | N13: =I13+K13+M13 -> 1020000
A14: 7 | B14: 30/10/2025 | C14: Lâm Hồng Luyến | D14: 39 | F14: NS tái tạo dây chằng | G14: TTDB | H14: SƠN | I14: =IF(G14="DTDB",420000,IF(G14="TTDB",420000,IF(G14="DT1",187500,IF(G14="TT1",187500,IF(G14="DT2",97500,IF(G14="TT2",97500,IF(G14="DT3",75000,75000))))))) -> 420000 | J14: LINH | K14: =IF(G14="DTDB",300000,IF(G14="TTDB",300000,IF(G14="DT1",135000,IF(G14="TT1",135000,IF(G14="DT2",75000,IF(G14="TT2",75000,IF(G14="DT3",45000,45000))))))) -> 300000 | L14: ẨN | M14: =IF(L14="-",0,IF(G14="DTDB",300000,IF(G14="TTDB",300000,IF(G14="DT1",135000,IF(G14="TT1",135000,IF(G14="DT2",75000,IF(G14="TT2",75000,IF(G14="DT3",45000,45000)))))))) -> 300000 | N14: =I14+K14+M14 -> 1020000
A15: 8 | B15: 30/10/2025 | C15: Trần Thị Khéo | E15: 74 | F15: Cố định cột sống | G15: TTDB | H15: NGUYỆN | I15: =IF(G15="DTDB",420000,IF(G15="TTDB",420000,IF(G15="DT1",187500,IF(G15="TT1",187500,IF(G15="DT2",97500,IF(G15="TT2",97500,IF(G15="DT3",75000,75000))))))) -> 420000 | J15: TUẤN | K15: =IF(G15="DTDB",300000,IF(G15="TTDB",300000,IF(G15="DT1",135000,IF(G15="TT1",135000,IF(G15="DT2",75000,IF(G15="TT2",75000,IF(G15="DT3",45000,45000))))))) -> 300000 | L15: ĐỨC | M15: =IF(L15="-",0,IF(G15="DTDB",300000,IF(G15="TTDB",300000,IF(G15="DT1",135000,IF(G15="TT1",135000,IF(G15="DT2",75000,IF(G15="TT2",75000,IF(G15="DT3",45000,45000)))))))) -> 300000 | N15: =I15+K15+M15 -> 1020000
A16: 9 | B16: 31/10/2025 | C16: Phùng Thị Mỹ Dung | E16: 52 | F16: PTNS cắt lọc khớp gối | G16: TT1 | H16: SƠN | I16: =IF(G16="DTDB",420000,IF(G16="TTDB",420000,IF(G16="DT1",187500,IF(G16="TT1",187500,IF(G16="DT2",97500,IF(G16="TT2",97500,IF(G16="DT3",75000,75000))))))) -> 187500 | J16: NGHIÊM | K16: =IF(G16="DTDB",300000,IF(G16="TTDB",300000,IF(G16="DT1",135000,IF(G16="TT1",135000,IF(G16="DT2",75000,IF(G16="TT2",75000,IF(G16="DT3",45000,45000))))))) -> 135000 | L16: THẠNH | M16: =IF(L16="-",0,IF(G16="DTDB",300000,IF(G16="TTDB",300000,IF(G16="DT1",135000,IF(G16="TT1",135000,IF(G16="DT2",75000,IF(G16="TT2",75000,IF(G16="DT3",45000,45000)))))))) -> 135000 | N16: =I16+K16+M16 -> 457500
A17: 10 | B17: 31/10/2025 | C17: Lê Thị Kim Tiếp | E17: 61 | F17: Cố định cột sống | G17: TTDB | H17: HOAN | I17: =IF(G17="DTDB",420000,IF(G17="TTDB",420000,IF(G17="DT1",187500,IF(G17="TT1",187500,IF(G17="DT2",97500,IF(G17="TT2",97500,IF(G17="DT3",75000,75000))))))) -> 420000 | J17: NGUYỆN | K17: =IF(G17="DTDB",300000,IF(G17="TTDB",300000,IF(G17="DT1",135000,IF(G17="TT1",135000,IF(G17="DT2",75000,IF(G17="TT2",75000,IF(G17="DT3",45000,45000))))))) -> 300000 | L17: TUẤN | M17: =IF(L17="-",0,IF(G17="DTDB",300000,IF(G17="TTDB",300000,IF(G17="DT1",135000,IF(G17="TT1",135000,IF(G17="DT2",75000,IF(G17="TT2",75000,IF(G17="DT3",45000,45000)))))))) -> 300000 | N17: =I17+K17+M17 -> 1020000
A18: 11 | B18: 31/10/2025 | C18: Lã Thị Tơ | E18: 70 | F18: PT chuyển vạt che phủ phần mềm cuống mạch liền | G18: DTDB | H18: HOAN | I18: =IF(G18="DTDB",420000,IF(G18="TTDB",420000,IF(G18="DT1",187500,IF(G18="TT1",187500,IF(G18="DT2",97500,IF(G18="TT2",97500,IF(G18="DT3",75000,75000))))))) -> 420000 | J18: TUẤN | K18: =IF(G18="DTDB",300000,IF(G18="TTDB",300000,IF(G18="DT1",135000,IF(G18="TT1",135000,IF(G18="DT2",75000,IF(G18="TT2",75000,IF(G18="DT3",45000,45000))))))) -> 300000 | L18: KHÁNH | M18: =IF(L18="-",0,IF(G18="DTDB",300000,IF(G18="TTDB",300000,IF(G18="DT1",135000,IF(G18="TT1",135000,IF(G18="DT2",75000,IF(G18="TT2",75000,IF(G18="DT3",45000,45000)))))))) -> 300000 | N18: =I18+K18+M18 -> 1020000
A19: 12 | B19: 31/10/2025 | C19: Nguyễn Trần Ngọc Hân | E19: 17 | F19: KHX trên màn hình tăng sáng | G19: TTDB | H19: NGUYỆN | I19: =IF(G19="DTDB",420000,IF(G19="TTDB",420000,IF(G19="DT1",187500,IF(G19="TT1",187500,IF(G19="DT2",97500,IF(G19="TT2",97500,IF(G19="DT3",75000,75000))))))) -> 420000 | J19: THIỆN | K19: =IF(G19="DTDB",300000,IF(G19="TTDB",300000,IF(G19="DT1",135000,IF(G19="TT1",135000,IF(G19="DT2",75000,IF(G19="TT2",75000,IF(G19="DT3",45000,45000))))))) -> 300000 | L19: BÌNH | M19: =IF(L19="-",0,IF(G19="DTDB",300000,IF(G19="TTDB",300000,IF(G19="DT1",135000,IF(G19="TT1",135000,IF(G19="DT2",75000,IF(G19="TT2",75000,IF(G19="DT3",45000,45000)))))))) -> 300000 | N19: =I19+K19+M19 -> 1020000
A20: 13 | B20: 01/11/2025 | C20: Huỳnh Minh Tần | D20: 34 | F20: PT thay khớp háng toàn phần | G20: TTDB | H20: TẤN | I20: =IF(G20="DTDB",420000,IF(G20="TTDB",420000,IF(G20="DT1",187500,IF(G20="TT1",187500,IF(G20="DT2",97500,IF(G20="TT2",97500,IF(G20="DT3",75000,75000))))))) -> 420000 | J20: NGUYỆN | K20: =IF(G20="DTDB",300000,IF(G20="TTDB",300000,IF(G20="DT1",135000,IF(G20="TT1",135000,IF(G20="DT2",75000,IF(G20="TT2",75000,IF(G20="DT3",45000,45000))))))) -> 300000 | L20: BẢO | M20: =IF(L20="-",0,IF(G20="DTDB",300000,IF(G20="TTDB",300000,IF(G20="DT1",135000,IF(G20="TT1",135000,IF(G20="DT2",75000,IF(G20="TT2",75000,IF(G20="DT3",45000,45000)))))))) -> 300000 | N20: =I20+K20+M20 -> 1020000
A21: 14 | B21: 01/11/2025 | C21: Huỳnh Minh Tần | D21: 34 | F21: PT thay khớp háng toàn phần (50%) | G21: TTDB | H21: TẤN | I21: =IF(G21="DTDB",420000,IF(G21="TTDB",420000,IF(G21="DT1",187500,IF(G21="TT1",187500,IF(G21="DT2",97500,IF(G21="TT2",97500,IF(G21="DT3",75000,75000))))))) -> 420000 | J21: NGUYỆN | K21: =IF(G21="DTDB",300000,IF(G21="TTDB",300000,IF(G21="DT1",135000,IF(G21="TT1",135000,IF(G21="DT2",75000,IF(G21="TT2",75000,IF(G21="DT3",45000,45000))))))) -> 300000 | L21: BẢO | M21: =IF(L21="-",0,IF(G21="DTDB",300000,IF(G21="TTDB",300000,IF(G21="DT1",135000,IF(G21="TT1",135000,IF(G21="DT2",75000,IF(G21="TT2",75000,IF(G21="DT3",45000,45000)))))))) -> 300000 | N21: =I21+K21+M21 -> 1020000
A22: 15 | B22: 01/11/2025 | C22: Trần Thị Lến | E22: 90 | F22: PT thay khớp háng bán phần | G22: TT1 | H22: HOAN | I22: =IF(G22="DTDB",420000,IF(G22="TTDB",420000,IF(G22="DT1",187500,IF(G22="TT1",187500,IF(G22="DT2",97500,IF(G22="TT2",97500,IF(G22="DT3",75000,75000))))))) -> 187500 | J22: V.TÂN | K22: =IF(G22="DTDB",300000,IF(G22="TTDB",300000,IF(G22="DT1",135000,IF(G22="TT1",135000,IF(G22="DT2",75000,IF(G22="TT2",75000,IF(G22="DT3",45000,45000))))))) -> 135000 | L22: TUẤN | M22: =IF(L22="-",0,IF(G22="DTDB",300000,IF(G22="TTDB",300000,IF(G22="DT1",135000,IF(G22="TT1",135000,IF(G22="DT2",75000,IF(G22="TT2",75000,IF(G22="DT3",45000,45000)))))))) -> 135000 | N22: =I22+K22+M22 -> 457500
A23: 16 | B23: 03/11/2025 | C23: Trần Thị Ngọc | E23: 56 | F23: KHX trên màn hình tăng sáng | G23: TTDB | H23: ĐIỀN | I23: =IF(G23="DTDB",420000,IF(G23="TTDB",420000,IF(G23="DT1",187500,IF(G23="TT1",187500,IF(G23="DT2",97500,IF(G23="TT2",97500,IF(G23="DT3",75000,75000))))))) -> 420000 | J23: TUẤN | K23: =IF(G23="DTDB",300000,IF(G23="TTDB",300000,IF(G23="DT1",135000,IF(G23="TT1",135000,IF(G23="DT2",75000,IF(G23="TT2",75000,IF(G23="DT3",45000,45000))))))) -> 300000 | L23: CÔNG | M23: =IF(L23="-",0,IF(G23="DTDB",300000,IF(G23="TTDB",300000,IF(G23="DT1",135000,IF(G23="TT1",135000,IF(G23="DT2",75000,IF(G23="TT2",75000,IF(G23="DT3",45000,45000)))))))) -> 300000 | N23: =I23+K23+M23 -> 1020000
A24: 17 | B24: 03/11/2025 | C24: Lê Thị Đẹp | E24: 74 | F24: Cố định cột sống | G24: TTDB | H24: HOAN | I24: =IF(G24="DTDB",420000,IF(G24="TTDB",420000,IF(G24="DT1",187500,IF(G24="TT1",187500,IF(G24="DT2",97500,IF(G24="TT2",97500,IF(G24="DT3",75000,75000))))))) -> 420000 | J24: NGUYỆN | K24: =IF(G24="DTDB",300000,IF(G24="TTDB",300000,IF(G24="DT1",135000,IF(G24="TT1",135000,IF(G24="DT2",75000,IF(G24="TT2",75000,IF(G24="DT3",45000,45000))))))) -> 300000 | L24: ĐIỀN | M24: =IF(L24="-",0,IF(G24="DTDB",300000,IF(G24="TTDB",300000,IF(G24="DT1",135000,IF(G24="TT1",135000,IF(G24="DT2",75000,IF(G24="TT2",75000,IF(G24="DT3",45000,45000)))))))) -> 300000 | N24: =I24+K24+M24 -> 1020000
A25: 18 | B25: 04/11/2025 | C25: Trần Thị Bích Ngọc | E25: 28 | F25: PTNS khâu chóp xoay | G25: TTDB | H25: SƠN | I25: =IF(G25="DTDB",420000,IF(G25="TTDB",420000,IF(G25="DT1",187500,IF(G25="TT1",187500,IF(G25="DT2",97500,IF(G25="TT2",97500,IF(G25="DT3",75000,75000))))))) -> 420000 | J25: TUẤN | K25: =IF(G25="DTDB",300000,IF(G25="TTDB",300000,IF(G25="DT1",135000,IF(G25="TT1",135000,IF(G25="DT2",75000,IF(G25="TT2",75000,IF(G25="DT3",45000,45000))))))) -> 300000 | L25: ĐỨC | M25: =IF(L25="-",0,IF(G25="DTDB",300000,IF(G25="TTDB",300000,IF(G25="DT1",135000,IF(G25="TT1",135000,IF(G25="DT2",75000,IF(G25="TT2",75000,IF(G25="DT3",45000,45000)))))))) -> 300000 | N25: =I25+K25+M25 -> 1020000
A26: 19 | B26: 04/11/2025 | C26: Nguyễn Hiếu Nghĩa | D26: 65 | F26: PTNS khâu chóp xoay | G26: TTDB | H26: SƠN | I26: =IF(G26="DTDB",420000,IF(G26="TTDB",420000,IF(G26="DT1",187500,IF(G26="TT1",187500,IF(G26="DT2",97500,IF(G26="TT2",97500,IF(G26="DT3",75000,75000))))))) -> 420000 | J26: NGHIÊM | K26: =IF(G26="DTDB",300000,IF(G26="TTDB",300000,IF(G26="DT1",135000,IF(G26="TT1",135000,IF(G26="DT2",75000,IF(G26="TT2",75000,IF(G26="DT3",45000,45000))))))) -> 300000 | L26: THẠNH | M26: =IF(L26="-",0,IF(G26="DTDB",300000,IF(G26="TTDB",300000,IF(G26="DT1",135000,IF(G26="TT1",135000,IF(G26="DT2",75000,IF(G26="TT2",75000,IF(G26="DT3",45000,45000)))))))) -> 300000 | N26: =I26+K26+M26 -> 1020000
A27: 20 | B27: 05/11/2025 | C27: Trần Ngọc Vấn | D27: 63 | F27: Cố định cột sống | G27: TTDB | H27: HOAN | I27: =IF(G27="DTDB",420000,IF(G27="TTDB",420000,IF(G27="DT1",187500,IF(G27="TT1",187500,IF(G27="DT2",97500,IF(G27="TT2",97500,IF(G27="DT3",75000,75000))))))) -> 420000 | J27: NGUYỆN | K27: =IF(G27="DTDB",300000,IF(G27="TTDB",300000,IF(G27="DT1",135000,IF(G27="TT1",135000,IF(G27="DT2",75000,IF(G27="TT2",75000,IF(G27="DT3",45000,45000))))))) -> 300000 | L27: ĐIỀN | M27: =IF(L27="-",0,IF(G27="DTDB",300000,IF(G27="TTDB",300000,IF(G27="DT1",135000,IF(G27="TT1",135000,IF(G27="DT2",75000,IF(G27="TT2",75000,IF(G27="DT3",45000,45000)))))))) -> 300000 | N27: =I27+K27+M27 -> 1020000
A28: 21 | B28: 05/11/2025 | C28: Phạm Thị Tuyết Mai | E28: 32 | F28: KHX trên màn hình tăng sáng | G28: TTDB | H28: TUẤN | I28: =IF(G28="DTDB",420000,IF(G28="TTDB",420000,IF(G28="DT1",187500,IF(G28="TT1",187500,IF(G28="DT2",97500,IF(G28="TT2",97500,IF(G28="DT3",75000,75000))))))) -> 420000 | J28: G.TỬ | K28: =IF(G28="DTDB",300000,IF(G28="TTDB",300000,IF(G28="DT1",135000,IF(G28="TT1",135000,IF(G28="DT2",75000,IF(G28="TT2",75000,IF(G28="DT3",45000,45000))))))) -> 300000 | L28: THIỆN | M28: =IF(L28="-",0,IF(G28="DTDB",300000,IF(G28="TTDB",300000,IF(G28="DT1",135000,IF(G28="TT1",135000,IF(G28="DT2",75000,IF(G28="TT2",75000,IF(G28="DT3",45000,45000)))))))) -> 300000 | N28: =I28+K28+M28 -> 1020000
A29: 22 | B29: 06/11/2025 | C29: Lê Thị Kim Đơn | E29: 64 | F29: PT KHX trên màn hình tăng sáng | G29: DTDB | H29: TOẢN | I29: =IF(G29="DTDB",420000,IF(G29="TTDB",420000,IF(G29="DT1",187500,IF(G29="TT1",187500,IF(G29="DT2",97500,IF(G29="TT2",97500,IF(G29="DT3",75000,75000))))))) -> 420000 | J29: NGUYỆN | K29: =IF(G29="DTDB",300000,IF(G29="TTDB",300000,IF(G29="DT1",135000,IF(G29="TT1",135000,IF(G29="DT2",75000,IF(G29="TT2",75000,IF(G29="DT3",45000,45000))))))) -> 300000 | L29: G.TỬ | M29: =IF(L29="-",0,IF(G29="DTDB",300000,IF(G29="TTDB",300000,IF(G29="DT1",135000,IF(G29="TT1",135000,IF(G29="DT2",75000,IF(G29="TT2",75000,IF(G29="DT3",45000,45000)))))))) -> 300000 | N29: =I29+K29+M29 -> 1020000
A30: 23 | B30: 06/11/2025 | C30: Lê Thị Kim Đơn | E30: 64 | F30: PT KHX trên màn hình tăng sáng (50%) | G30: DTDB | H30: TOẢN | I30: =IF(G30="DTDB",420000,IF(G30="TTDB",420000,IF(G30="DT1",187500,IF(G30="TT1",187500,IF(G30="DT2",97500,IF(G30="TT2",97500,IF(G30="DT3",75000,75000))))))) -> 420000 | J30: NGUYỆN | K30: =IF(G30="DTDB",300000,IF(G30="TTDB",300000,IF(G30="DT1",135000,IF(G30="TT1",135000,IF(G30="DT2",75000,IF(G30="TT2",75000,IF(G30="DT3",45000,45000))))))) -> 300000 | L30: G.TỬ | M30: =IF(L30="-",0,IF(G30="DTDB",300000,IF(G30="TTDB",300000,IF(G30="DT1",135000,IF(G30="TT1",135000,IF(G30="DT2",75000,IF(G30="TT2",75000,IF(G30="DT3",45000,45000)))))))) -> 300000 | N30: =I30+K30+M30 -> 1020000
A31: 24 | B31: 06/11/2025 | C31: Bùi Thị Lệ Thanh | E31: 47 | F31: KHX trên màn hình tăng sáng | G31: TTDB | H31: TOẢN | I31: =IF(G31="DTDB",420000,IF(G31="TTDB",420000,IF(G31="DT1",187500,IF(G31="TT1",187500,IF(G31="DT2",97500,IF(G31="TT2",97500,IF(G31="DT3",75000,75000))))))) -> 420000 | J31: NGUYỆN | K31: =IF(G31="DTDB",300000,IF(G31="TTDB",300000,IF(G31="DT1",135000,IF(G31="TT1",135000,IF(G31="DT2",75000,IF(G31="TT2",75000,IF(G31="DT3",45000,45000))))))) -> 300000 | L31: NGHIÊM | M31: =IF(L31="-",0,IF(G31="DTDB",300000,IF(G31="TTDB",300000,IF(G31="DT1",135000,IF(G31="TT1",135000,IF(G31="DT2",75000,IF(G31="TT2",75000,IF(G31="DT3",45000,45000)))))))) -> 300000 | N31: =I31+K31+M31 -> 1020000
A32: 25 | B32: 06/11/2025 | C32: Nguyễn Duy Thịnh | D32: 48 | F32: PT thay toàn bộ khớp háng | G32: DTDB | H32: HOAN | I32: =IF(G32="DTDB",420000,IF(G32="TTDB",420000,IF(G32="DT1",187500,IF(G32="TT1",187500,IF(G32="DT2",97500,IF(G32="TT2",97500,IF(G32="DT3",75000,75000))))))) -> 420000 | J32: V.TÂN | K32: =IF(G32="DTDB",300000,IF(G32="TTDB",300000,IF(G32="DT1",135000,IF(G32="TT1",135000,IF(G32="DT2",75000,IF(G32="TT2",75000,IF(G32="DT3",45000,45000))))))) -> 300000 | L32: TUẤN | M32: =IF(L32="-",0,IF(G32="DTDB",300000,IF(G32="TTDB",300000,IF(G32="DT1",135000,IF(G32="TT1",135000,IF(G32="DT2",75000,IF(G32="TT2",75000,IF(G32="DT3",45000,45000)))))))) -> 300000 | N32: =I32+K32+M32 -> 1020000
A33: 26 | B33: 07/11/2025 | C33: Nguyễn Văn Khánh | D33: 56 | F33: PT KHX trên màn hình tăng sáng | G33: TTDB | H33: NGUYỆN | I33: =IF(G33="DTDB",420000,IF(G33="TTDB",420000,IF(G33="DT1",187500,IF(G33="TT1",187500,IF(G33="DT2",97500,IF(G33="TT2",97500,IF(G33="DT3",75000,75000))))))) -> 420000 | J33: TOẢN | K33: =IF(G33="DTDB",300000,IF(G33="TTDB",300000,IF(G33="DT1",135000,IF(G33="TT1",135000,IF(G33="DT2",75000,IF(G33="TT2",75000,IF(G33="DT3",45000,45000))))))) -> 300000 | L33: TUẤN | M33: =IF(L33="-",0,IF(G33="DTDB",300000,IF(G33="TTDB",300000,IF(G33="DT1",135000,IF(G33="TT1",135000,IF(G33="DT2",75000,IF(G33="TT2",75000,IF(G33="DT3",45000,45000)))))))) -> 300000 | N33: =I33+K33+M33 -> 1020000
A34: 27 | B34: 07/11/2025 | C34: Nguyễn Văn Khánh | D34: 56 | F34: PT KHX trên màn hình tăng sáng (50%) | G34: DTDB | H34: NGUYỆN | I34: =IF(G34="DTDB",420000,IF(G34="TTDB",420000,IF(G34="DT1",187500,IF(G34="TT1",187500,IF(G34="DT2",97500,IF(G34="TT2",97500,IF(G34="DT3",75000,75000))))))) -> 420000 | J34: TOẢN | K34: =IF(G34="DTDB",300000,IF(G34="TTDB",300000,IF(G34="DT1",135000,IF(G34="TT1",135000,IF(G34="DT2",75000,IF(G34="TT2",75000,IF(G34="DT3",45000,45000))))))) -> 300000 | L34: TUẤN | M34: =IF(L34="-",0,IF(G34="DTDB",300000,IF(G34="TTDB",300000,IF(G34="DT1",135000,IF(G34="TT1",135000,IF(G34="DT2",75000,IF(G34="TT2",75000,IF(G34="DT3",45000,45000)))))))) -> 300000 | N34: =I34+K34+M34 -> 1020000
A35: 28 | B35: 07/11/2025 | C35: Diệp Thị Tiến | E35: 72 | F35: PT chuyển vạt da | G35: TTDB | H35: TUẤN | I35: =IF(G35="DTDB",420000,IF(G35="TTDB",420000,IF(G35="DT1",187500,IF(G35="TT1",187500,IF(G35="DT2",97500,IF(G35="TT2",97500,IF(G35="DT3",75000,75000))))))) -> 420000 | J35: THIỆN | K35: =IF(G35="DTDB",300000,IF(G35="TTDB",300000,IF(G35="DT1",135000,IF(G35="TT1",135000,IF(G35="DT2",75000,IF(G35="TT2",75000,IF(G35="DT3",45000,45000))))))) -> 300000 | L35: NGHIÊM | M35: =IF(L35="-",0,IF(G35="DTDB",300000,IF(G35="TTDB",300000,IF(G35="DT1",135000,IF(G35="TT1",135000,IF(G35="DT2",75000,IF(G35="TT2",75000,IF(G35="DT3",45000,45000)))))))) -> 300000 | N35: =I35+K35+M35 -> 1020000
A36: 29 | B36: 10/11/2025 | C36: Lê Võ Thúy Anh | E36: 20 | F36: PT KHX trên màn hình tăng sáng | G36: TTDB | H36: TUẤN | I36: =IF(G36="DTDB",420000,IF(G36="TTDB",420000,IF(G36="DT1",187500,IF(G36="TT1",187500,IF(G36="DT2",97500,IF(G36="TT2",97500,IF(G36="DT3",75000,75000))))))) -> 420000 | J36: G.TỬ | K36: =IF(G36="DTDB",300000,IF(G36="TTDB",300000,IF(G36="DT1",135000,IF(G36="TT1",135000,IF(G36="DT2",75000,IF(G36="TT2",75000,IF(G36="DT3",45000,45000))))))) -> 300000 | L36: ĐỨC | M36: =IF(L36="-",0,IF(G36="DTDB",300000,IF(G36="TTDB",300000,IF(G36="DT1",135000,IF(G36="TT1",135000,IF(G36="DT2",75000,IF(G36="TT2",75000,IF(G36="DT3",45000,45000)))))))) -> 300000 | N36: =I36+K36+M36 -> 1020000
A37: 30 | B37: 10/11/2025 | C37: Nguyễn Văn Tho | D37: 59 | F37: Ghép da | G37: DT1 | H37: HOAN | I37: =IF(G37="DTDB",420000,IF(G37="TTDB",420000,IF(G37="DT1",187500,IF(G37="TT1",187500,IF(G37="DT2",97500,IF(G37="TT2",97500,IF(G37="DT3",75000,75000))))))) -> 187500 | J37: V.TÂN | K37: =IF(G37="DTDB",300000,IF(G37="TTDB",300000,IF(G37="DT1",135000,IF(G37="TT1",135000,IF(G37="DT2",75000,IF(G37="TT2",75000,IF(G37="DT3",45000,45000))))))) -> 135000 | L37: LINH | M37: =IF(L37="-",0,IF(G37="DTDB",300000,IF(G37="TTDB",300000,IF(G37="DT1",135000,IF(G37="TT1",135000,IF(G37="DT2",75000,IF(G37="TT2",75000,IF(G37="DT3",45000,45000)))))))) -> 135000 | N37: =I37+K37+M37 -> 457500
A38: 31 | B38: 10/11/2025 | C38: Huỳnh Tấn Công | D38: 63 | F38: Thay toàn bộ khớp háng | G38: TTDB | H38: HOAN | I38: =IF(G38="DTDB",420000,IF(G38="TTDB",420000,IF(G38="DT1",187500,IF(G38="TT1",187500,IF(G38="DT2",97500,IF(G38="TT2",97500,IF(G38="DT3",75000,75000))))))) -> 420000 | J38: NGUYỆN | K38: =IF(G38="DTDB",300000,IF(G38="TTDB",300000,IF(G38="DT1",135000,IF(G38="TT1",135000,IF(G38="DT2",75000,IF(G38="TT2",75000,IF(G38="DT3",45000,45000))))))) -> 300000 | L38: G.TỬ | M38: =IF(L38="-",0,IF(G38="DTDB",300000,IF(G38="TTDB",300000,IF(G38="DT1",135000,IF(G38="TT1",135000,IF(G38="DT2",75000,IF(G38="TT2",75000,IF(G38="DT3",45000,45000)))))))) -> 300000 | N38: =I38+K38+M38 -> 1020000
A39: 32 | B39: 10/11/2025 | C39: Huỳnh Tấn Công | D39: 63 | F39: PT KHX trên màn hình tăng sáng (50%) | G39: DTDB | H39: HOAN | I39: =IF(G39="DTDB",420000,IF(G39="TTDB",420000,IF(G39="DT1",187500,IF(G39="TT1",187500,IF(G39="DT2",97500,IF(G39="TT2",97500,IF(G39="DT3",75000,75000))))))) -> 420000 | J39: NGUYỆN | K39: =IF(G39="DTDB",300000,IF(G39="TTDB",300000,IF(G39="DT1",135000,IF(G39="TT1",135000,IF(G39="DT2",75000,IF(G39="TT2",75000,IF(G39="DT3",45000,45000))))))) -> 300000 | L39: G.TỬ | M39: =IF(L39="-",0,IF(G39="DTDB",300000,IF(G39="TTDB",300000,IF(G39="DT1",135000,IF(G39="TT1",135000,IF(G39="DT2",75000,IF(G39="TT2",75000,IF(G39="DT3",45000,45000)))))))) -> 300000 | N39: =I39+K39+M39 -> 1020000
A40: 33 | B40: 10/11/2025 | C40: Nguyễn Thị Hồng Thu | E40: 61 | F40: Vá da diện tích > 10cm2 | G40: TT1 | H40: TUẤN | I40: =IF(G40="DTDB",420000,IF(G40="TTDB",420000,IF(G40="DT1",187500,IF(G40="TT1",187500,IF(G40="DT2",97500,IF(G40="TT2",97500,IF(G40="DT3",75000,75000))))))) -> 187500 | J40: LINH | K40: =IF(G40="DTDB",300000,IF(G40="TTDB",300000,IF(G40="DT1",135000,IF(G40="TT1",135000,IF(G40="DT2",75000,IF(G40="TT2",75000,IF(G40="DT3",45000,45000))))))) -> 135000 | L40: ẨN | M40: =IF(L40="-",0,IF(G40="DTDB",300000,IF(G40="TTDB",300000,IF(G40="DT1",135000,IF(G40="TT1",135000,IF(G40="DT2",75000,IF(G40="TT2",75000,IF(G40="DT3",45000,45000)))))))) -> 135000 | N40: =I40+K40+M40 -> 457500
A41: 34 | B41: 10/11/2025 | C41: NGUYỄN HỮU NHI | D41: 43 | F41: PT KHX trên màn hình tăng sáng | G41: DTDB | H41: DUY | I41: =IF(G41="DTDB",420000,IF(G41="TTDB",420000,IF(G41="DT1",187500,IF(G41="TT1",187500,IF(G41="DT2",97500,IF(G41="TT2",97500,IF(G41="DT3",75000,75000))))))) -> 420000 | J41: CÔNG | K41: =IF(G41="DTDB",300000,IF(G41="TTDB",300000,IF(G41="DT1",135000,IF(G41="TT1",135000,IF(G41="DT2",75000,IF(G41="TT2",75000,IF(G41="DT3",45000,45000))))))) -> 300000 | L41: THẠNH | M41: =IF(L41="-",0,IF(G41="DTDB",300000,IF(G41="TTDB",300000,IF(G41="DT1",135000,IF(G41="TT1",135000,IF(G41="DT2",75000,IF(G41="TT2",75000,IF(G41="DT3",45000,45000)))))))) -> 300000 | N41: =I41+K41+M41 -> 1020000
A42: 35 | B42: 11/11/2025 | C42: Nguyễn Thị Thúy Liên | E42: 59 | F42: PT KHX trên màn hình tăng sáng | G42: DTDB | H42: TUẤN | I42: =IF(G42="DTDB",420000,IF(G42="TTDB",420000,IF(G42="DT1",187500,IF(G42="TT1",187500,IF(G42="DT2",97500,IF(G42="TT2",97500,IF(G42="DT3",75000,75000))))))) -> 420000 | J42: G.TỬ | K42: =IF(G42="DTDB",300000,IF(G42="TTDB",300000,IF(G42="DT1",135000,IF(G42="TT1",135000,IF(G42="DT2",75000,IF(G42="TT2",75000,IF(G42="DT3",45000,45000))))))) -> 300000 | L42: KHÁNH | M42: =IF(L42="-",0,IF(G42="DTDB",300000,IF(G42="TTDB",300000,IF(G42="DT1",135000,IF(G42="TT1",135000,IF(G42="DT2",75000,IF(G42="TT2",75000,IF(G42="DT3",45000,45000)))))))) -> 300000 | N42: =I42+K42+M42 -> 1020000
...

Sheet lanh tien PT_BHYT
A1: BV TRƯỜNG ĐHYD CẦN THƠ
A2: KHOA NGOẠI CTCH-TK
A3: DANH SÁCH LÃNH TIỀN THÙ LAO THÁNG 11/2025
A4: (BHYT)
A6: STT | B6: HỌ TÊN | C6: CHỨC VỤ | D6: SỐ TÀI KHOẢN | E6: SỐ TIỀN | F6: Thuế 10%
A7: 1 | B7: Nguyễn Thành Tấn | C7: Bác sĩ | D7: 103006610215 | E7: =SUM(SUMIF(phauthuat_BHYT!$H$8:$H$155,"TẤN",phauthuat_BHYT!$I$8:$I$155),SUMIF(phauthuat_BHYT!$J$8:$J$155,"TẤN",phauthuat_BHYT!$K$8:$K$155),SUMIF(phauthuat_BHYT!$L$8:$L$155,"TẤN",phauthuat_BHYT!$M$8:$M$155)) -> 840000
A8: 2 | B8: Nguyễn Lê Hoan | C8: Bác sĩ | D8: 100006610218 | E8: =SUM(SUMIF(phauthuat_BHYT!$H$8:$H$155,"HOAN",phauthuat_BHYT!$I$8:$I$155),SUMIF(phauthuat_BHYT!$J$8:$J$155,"HOAN",phauthuat_BHYT!$K$8:$K$155),SUMIF(phauthuat_BHYT!$L$8:$L$155,"HOAN",phauthuat_BHYT!$M$8:$M$155)) -> 10147500
A9: 3 | B9: Nguyễn Chí Nguyện | C9: Bác sĩ | D9: 105001159195 | E9: =SUM(SUMIF(phauthuat_BHYT!$H$8:$H$155,"NGUYỆN",phauthuat_BHYT!$I$8:$I$155),SUMIF(phauthuat_BHYT!$J$8:$J$155,"NGUYỆN",phauthuat_BHYT!$K$8:$K$155),SUMIF(phauthuat_BHYT!$L$8:$L$155,"NGUYỆN",phauthuat_BHYT!$M$8:$M$155)) -> 9255000
A10: 4 | B10: Hồ Điền | C10: Bác sĩ | D10: 105001225232 | E10: =SUM(SUMIF(phauthuat_BHYT!$H$8:$H$155,"ĐIỀN",phauthuat_BHYT!$I$8:$I$155),SUMIF(phauthuat_BHYT!$J$8:$J$155,"ĐIỀN",phauthuat_BHYT!$K$8:$K$155),SUMIF(phauthuat_BHYT!$L$8:$L$155,"ĐIỀN",phauthuat_BHYT!$M$8:$M$155)) -> 1995000
A11: 5 | B11: Trần Quốc Toản | C11: Bác sĩ | D11: 107868829237 | E11: =SUM(SUMIF(phauthuat_BHYT!$H$8:$H$155,"TOẢN",phauthuat_BHYT!$I$8:$I$155),SUMIF(phauthuat_BHYT!$J$8:$J$155,"TOẢN",phauthuat_BHYT!$K$8:$K$155),SUMIF(phauthuat_BHYT!$L$8:$L$155,"TOẢN",phauthuat_BHYT!$M$8:$M$155)) -> 5625000
A12: 6 | B12: Phạm Việt Tân | C12: Bác sĩ | D12: 104000362303 | E12: =SUM(SUMIF(phauthuat_BHYT!$H$8:$H$155,"v.tân",phauthuat_BHYT!$I$8:$I$155),SUMIF(phauthuat_BHYT!$J$8:$J$155,"v.tân",phauthuat_BHYT!$K$8:$K$155),SUMIF(phauthuat_BHYT!$L$8:$L$155,"v.tân",phauthuat_BHYT!$M$8:$M$155)) -> 3697500
A13: 7 | B13: Phan Văn Tuấn | C13: Bác sĩ | D13: 105872433048 | E13: =SUM(SUMIF(phauthuat_BHYT!$H$8:$H$155,"TUẤN",phauthuat_BHYT!$I$8:$I$155),SUMIF(phauthuat_BHYT!$J$8:$J$155,"TUẤN",phauthuat_BHYT!$K$8:$K$155),SUMIF(phauthuat_BHYT!$L$8:$L$155,"TUẤN",phauthuat_BHYT!$M$8:$M$155)) -> 13012500
A14: 8 | B14: Trần Quang Sơn | C14: Bác sĩ | D14: 107004193662 | E14: =SUM(SUMIF(phauthuat_BHYT!$H$8:$H$155,"sơn",phauthuat_BHYT!$I$8:$I$155),SUMIF(phauthuat_BHYT!$J$8:$J$155,"sơn",phauthuat_BHYT!$K$8:$K$155),SUMIF(phauthuat_BHYT!$L$8:$L$155,"sơn",phauthuat_BHYT!$M$8:$M$155)) -> 4500000
A15: 9 | B15: Nguyễn Tư Thái Bảo | C15: Bác sĩ | D15: 109871759605 | E15: =SUM(SUMIF(phauthuat_BHYT!$H$8:$H$155,"bảo",phauthuat_BHYT!$I$8:$I$155),SUMIF(phauthuat_BHYT!$J$8:$J$155,"bảo",phauthuat_BHYT!$K$8:$K$155),SUMIF(phauthuat_BHYT!$L$8:$L$155,"bảo",phauthuat_BHYT!$M$8:$M$155)) -> 4440000
A16: 10 | B16: Trần Nguyễn Anh Duy | C16: Bác sĩ | D16: 109867708726 | E16: =SUM(SUMIF(phauthuat_BHYT!$H$8:$H$155,"duy",phauthuat_BHYT!$I$8:$I$155),SUMIF(phauthuat_BHYT!$J$8:$J$155,"duy",phauthuat_BHYT!$K$8:$K$155),SUMIF(phauthuat_BHYT!$L$8:$L$155,"duy",phauthuat_BHYT!$M$8:$M$155)) -> 3375000
A17: 11 | B17: Nguyễn Giang Tử | C17: Bác sĩ | D17: 109875250610 | E17: =SUM(SUMIF(phauthuat_BHYT!$H$8:$H$155,"g.tử",phauthuat_BHYT!$I$8:$I$155),SUMIF(phauthuat_BHYT!$J$8:$J$155,"g.tử",phauthuat_BHYT!$K$8:$K$155),SUMIF(phauthuat_BHYT!$L$8:$L$155,"g.tử",phauthuat_BHYT!$M$8:$M$155)) -> 6540000
A18: 12 | B18: Võ Long Ẩn | C18: Bác sĩ (nt) | E18: =SUM(SUMIF(phauthuat_BHYT!$H$8:$H$155,"ẩn",phauthuat_BHYT!$I$8:$I$155),SUMIF(phauthuat_BHYT!$J$8:$J$155,"ẩn",phauthuat_BHYT!$K$8:$K$155),SUMIF(phauthuat_BHYT!$L$8:$L$155,"ẩn",phauthuat_BHYT!$M$8:$M$155)) -> 1020000
A19: 13 | B19: Nguyễn Xuân Bình | C19: Bác sĩ (nt) | E19: =SUM(SUMIF(phauthuat_BHYT!$H$8:$H$155,"bình",phauthuat_BHYT!$I$8:$I$155),SUMIF(phauthuat_BHYT!$J$8:$J$155,"bình",phauthuat_BHYT!$K$8:$K$155),SUMIF(phauthuat_BHYT!$L$8:$L$155,"bình",phauthuat_BHYT!$M$8:$M$155)) -> 1020000
A20: 14 | B20: Phan Doãn Đại Dương | C20: Bác sĩ (nt) | E20: =SUM(SUMIF(phauthuat_BHYT!$H$8:$H$155,"dương",phauthuat_BHYT!$I$8:$I$155),SUMIF(phauthuat_BHYT!$J$8:$J$155,"dương",phauthuat_BHYT!$K$8:$K$155),SUMIF(phauthuat_BHYT!$L$8:$L$155,"dương",phauthuat_BHYT!$M$8:$M$155)) -> 810000
A21: 15 | B21: Lê Quốc Khánh | C21: Bác sĩ (nt) | E21: =SUM(SUMIF(phauthuat_BHYT!$H$8:$H$155,"khánh",phauthuat_BHYT!$I$8:$I$155),SUMIF(phauthuat_BHYT!$J$8:$J$155,"khánh",phauthuat_BHYT!$K$8:$K$155),SUMIF(phauthuat_BHYT!$L$8:$L$155,"khánh",phauthuat_BHYT!$M$8:$M$155)) -> 870000
A22: 16 | B22: Lê Cường Thạnh | C22: Bác sĩ (nt) | E22: =SUM(SUMIF(phauthuat_BHYT!$H$8:$H$155,"thạnh",phauthuat_BHYT!$I$8:$I$155),SUMIF(phauthuat_BHYT!$J$8:$J$155,"thạnh",phauthuat_BHYT!$K$8:$K$155),SUMIF(phauthuat_BHYT!$L$8:$L$155,"thạnh",phauthuat_BHYT!$M$8:$M$155)) -> 1455000
A23: 17 | B23: Nguyễn Văn Nghiêm | C23: Bác sĩ (nt) | D23: 108883113558 | E23: =SUM(SUMIF(phauthuat_BHYT!$H$8:$H$155,"NGHIÊM",phauthuat_BHYT!$I$8:$I$155),SUMIF(phauthuat_BHYT!$J$8:$J$155,"NGHIÊM",phauthuat_BHYT!$K$8:$K$155),SUMIF(phauthuat_BHYT!$L$8:$L$155,"NGHIÊM",phauthuat_BHYT!$M$8:$M$155)) -> 1695000
A24: 18 | B24: Đỗ Thành Công | C24: Bác sĩ (nt) | D24: 109881609351 | E24: =SUM(SUMIF(phauthuat_BHYT!$H$8:$H$155,"CÔNG",phauthuat_BHYT!$I$8:$I$155),SUMIF(phauthuat_BHYT!$J$8:$J$155,"CÔNG",phauthuat_BHYT!$K$8:$K$155),SUMIF(phauthuat_BHYT!$L$8:$L$155,"CÔNG",phauthuat_BHYT!$M$8:$M$155)) -> 2445000
A25: 19 | B25: Võ Ngọc Thiện | C25: Bác sĩ (nt) | D25: 102885267089 | E25: =SUM(SUMIF(phauthuat_BHYT!$H$8:$H$155,"THIỆN",phauthuat_BHYT!$I$8:$I$155),SUMIF(phauthuat_BHYT!$J$8:$J$155,"THIỆN",phauthuat_BHYT!$K$8:$K$155),SUMIF(phauthuat_BHYT!$L$8:$L$155,"THIỆN",phauthuat_BHYT!$M$8:$M$155)) -> 3435000
A26: 20 | B26: Nguyễn Hoài Linh | C26: Bác sĩ (nt) | E26: =SUM(SUMIF(phauthuat_BHYT!$H$8:$H$155,"LINH",phauthuat_BHYT!$I$8:$I$155),SUMIF(phauthuat_BHYT!$J$8:$J$155,"LINH",phauthuat_BHYT!$K$8:$K$155),SUMIF(phauthuat_BHYT!$L$8:$L$155,"LINH",phauthuat_BHYT!$M$8:$M$155)) -> 3540000
A27: 21 | B27: Nguyễn Hoài Đức | C27: Bác sĩ (nt) | D27: 101883256042 | E27: =SUM(SUMIF(phauthuat_BHYT!$H$8:$H$155,"ĐỨC",phauthuat_BHYT!$I$8:$I$155),SUMIF(phauthuat_BHYT!$J$8:$J$155,"ĐỨC",phauthuat_BHYT!$K$8:$K$155),SUMIF(phauthuat_BHYT!$L$8:$L$155,"ĐỨC",phauthuat_BHYT!$M$8:$M$155)) -> 2745000
B28: TỔNG CỘNG | E28: =SUM(E7:E27) -> 82462500
D30: Cần Thơ, ngày 16 tháng 12 năm 2025
A31: Người lập bảng | D31: Trưởng khoa
A35: ĐD. Phan Văn Hiếu | D35: ThS.Bs.CKII. Nguyễn Lê Hoan

Sheet Thực lãnh
A1: BV TRƯỜNG ĐHYD CẦN THƠ
A2: KHOA NGOẠI CTCH-TK
A3: DANH SÁCH LÃNH TIỀN THÙ LAO THÁNG 11/2025
A4: (BHYT)
A6: STT | B6: HỌ TÊN | C6: CHỨC VỤ | D6: SỐ TÀI KHOẢN | E6: SỐ TIỀN | F6: SỐ TIỀN | G6: KÝ NHẬN
A7: 1 | B7: Nguyễn Thành Tấn | C7: Bác sĩ | D7: 103006610215 | E7: =SUM(SUMIF(phauthuat_BHYT!$H$8:$H$155,"TẤN",phauthuat_BHYT!$I$8:$I$155),SUMIF(phauthuat_BHYT!$J$8:$J$155,"TẤN",phauthuat_BHYT!$K$8:$K$155),SUMIF(phauthuat_BHYT!$L$8:$L$155,"TẤN",phauthuat_BHYT!$M$8:$M$155)) -> 840000 | F7: =E7 -> 840000
A8: 2 | B8: Nguyễn Lê Hoan | C8: Bác sĩ | D8: 100006610218 | E8: =SUM(SUMIF(phauthuat_BHYT!$H$8:$H$155,"HOAN",phauthuat_BHYT!$I$8:$I$155),SUMIF(phauthuat_BHYT!$J$8:$J$155,"HOAN",phauthuat_BHYT!$K$8:$K$155),SUMIF(phauthuat_BHYT!$L$8:$L$155,"HOAN",phauthuat_BHYT!$M$8:$M$155)) -> 10147500 | F8: =E8+I28 -> 20857500
A9: 3 | B9: Nguyễn Chí Nguyện | C9: Bác sĩ | D9: 105001159195 | E9: =SUM(SUMIF(phauthuat_BHYT!$H$8:$H$155,"NGUYỆN",phauthuat_BHYT!$I$8:$I$155),SUMIF(phauthuat_BHYT!$J$8:$J$155,"NGUYỆN",phauthuat_BHYT!$K$8:$K$155),SUMIF(phauthuat_BHYT!$L$8:$L$155,"NGUYỆN",phauthuat_BHYT!$M$8:$M$155)) -> 9255000 | F9: =E9 -> 9255000
A10: 4 | B10: Hồ Điền | C10: Bác sĩ | D10: 105001225232 | E10: =SUM(SUMIF(phauthuat_BHYT!$H$8:$H$155,"ĐIỀN",phauthuat_BHYT!$I$8:$I$155),SUMIF(phauthuat_BHYT!$J$8:$J$155,"ĐIỀN",phauthuat_BHYT!$K$8:$K$155),SUMIF(phauthuat_BHYT!$L$8:$L$155,"ĐIỀN",phauthuat_BHYT!$M$8:$M$155)) -> 1995000 | F10: =E10+I18 -> 4035000
A11: 5 | B11: Trần Quốc Toản | C11: Bác sĩ | D11: 107868829237 | E11: =SUM(SUMIF(phauthuat_BHYT!$H$8:$H$155,"TOẢN",phauthuat_BHYT!$I$8:$I$155),SUMIF(phauthuat_BHYT!$J$8:$J$155,"TOẢN",phauthuat_BHYT!$K$8:$K$155),SUMIF(phauthuat_BHYT!$L$8:$L$155,"TOẢN",phauthuat_BHYT!$M$8:$M$155)) -> 5625000 | F11: =E11 -> 5625000
A12: 6 | B12: Phạm Việt Tân | C12: Bác sĩ | D12: 104000362303 | F12: ='lanh tien PT_BHYT'!E12 -> 3697500
A13: 7 | B13: Phan Văn Tuấn | C13: Bác sĩ | D13: 105872433048 | F13: ='lanh tien PT_BHYT'!E13 -> 13012500
A14: 8 | B14: Nguyễn Tư Thái Bảo | C14: Bác sĩ | D14: 109871759605 | F14: ='lanh tien PT_BHYT'!E15+I31 -> 7185000
A15: 9 | B15: Trần Nguyễn Anh Duy | C15: Bác sĩ | D15: 109867708726 | F15: ='lanh tien PT_BHYT'!E16+I30 -> 6915000
A16: 10 | B16: Trần Quang Sơn | C16: Bác sĩ | D16: 107004193662 | F16: ='lanh tien PT_BHYT'!E14 -> 4500000
A17: 11 | B17: Nguyễn Giang Tử | C17: Bác sĩ | D17: 109875250610 | F17: ='lanh tien PT_BHYT'!E17 -> 6540000
A18: 12 | B18: Võ Dương Thành Thái | C18: Bác sĩ (nt) | H18: BS.ĐIỀN | I18: =SUM('lanh tien PT_BHYT'!E18:E19) -> 2040000
A19: 13 | B19: Văn Minh Khén | C19: Bác sĩ (nt)
A20: 14 | B20: Nguyễn Đông Khang | C20: Bác sĩ (nt)
A21: 15 | B21: Nguyễn Đình Luật | C21: Bác sĩ (nt)
A22: 16 | B22: Lê Nhỉ Khang | C22: Bác sĩ (nt)
A23: 17 | B23: Phạm Văn Hưởng | C23: Bác sĩ (nt)
A24: 18 | B24: Trần Trung Nghĩa | C24: Bác sĩ (nt)
A25: 19 | B25: Nguyễn Trung Nhị | C25: Bác sĩ (nt)
A26: 20 | B26: Nguyễn Trần Khánh Đan | C26: Bác sĩ (nt)
A27: 21 | B27: Phạm Công Hậu | C27: Bác sĩ (nt)
A28: 22 | B28: Trang Gia Vinh | C28: Bác sĩ (nt) | H28: BS.HOAN | I28: =SUM('lanh tien PT_BHYT'!E20:E25) -> 10710000
A29: 23 | B29: Bùi Quan Tấn | C29: Bác sĩ (nt)
A30: 24 | B30: Tào Nhật Hào | C30: Bác sĩ (nt) | H30: BS.Duy | I30: =SUM('lanh tien PT_BHYT'!E26) -> 3540000
A31: 25 | B31: Huỳnh Phúc Nguyên | C31: Bác sĩ (nt) | H31: Bs.Bảo | I31: ='lanh tien PT_BHYT'!E27 -> 2745000
B32: TỔNG CỘNG | E32: =SUM(E7:E13) -> 27862500 | F32: =SUM(F7:F23) -> 82462500
D34: Cần Thơ, ngày 16 tháng 12 năm 2025
A35: Người lập bảng | D35: Trưởng khoa
A39: Phan Văn Hiếu | D39: ThS.Bs.CKII. Nguyễn Lê Hoan

Sheet Bác sĩ điều trị
A1: BV TRƯỜNG ĐHYD CẦN THƠ
A2: KHOA NGOẠI CTCH-TK
A3: DANH SÁCH LÃNH TIỀN THÙ LAO THÁNG 11/2025
A4: (BÁC SĨ ĐIỀU TRỊ)
A6: STT | B6: HỌ TÊN | C6: chức vụ | D6: SỐ TIỀN | E6: KÝ NHẬN
A7: 1 | B7: Phạm Việt Triều | C7: Bác sĩ | D7: -
A8: 2 | B8: Nguyễn Thành Tấn | C8: Bác sĩ | D8: -
A9: 3 | B9: Nguyễn Lê Hoan | C9: Bác sĩ | D9: =16000000*0.25 -> 4000000
A10: 4 | B10: Trần Quang Sơn | C10: Bác sĩ | D10: -
A11: 5 | B11: Nguyễn Chí Nguyện | C11: Bác sĩ | D11: -
A12: 6 | B12: Bùi Công Minh | C12: Bác sĩ | D12: -
