Workbook

Sheet phauthuat
A1: BV TRƯỜNG ĐHYD CẦN THƠ
A2: KHOA NGOẠI CTCH - TK
A3: BẢNG KÊ TIỀN PHẪU THUẬT
A4: (THÁNG 7/2025)
A6: STT | B6: Ngày | C6: Họ Tên | D6: Nam | E6: Nữ | F6: Phương pháp phẫu thuật | G6: Loại PT | H6: Giá Phẫu thuật thực tính | I6: PTV chính | J6: Số tiền | K6: Phụ mổ 1 | L6: Số tiền | M6: Phụ mổ 2 | N6: Số tiền | O6: Phụ mổ 3 | P6: Số tiền | Q6: ĐD + HL | R6: Thực lãnh
A7: 1 | B7: 20/6/2025 | C7: Lâm Chriêu | D7: 86 | F7: PT cắt cụt chi | G7: TT2 | H7: 1947600 | I7: ĐIỀN | J7: =R7-L7-N7-P7-Q7 -> 223974 | K7: ĐẠT | L7: =IF(K7="-",0,H7*0.03) -> 58428 | M7: ĐAN | N7: =IF(M7="-",0,H7*0.02) -> 38952 | O7: - | P7: =IF(O7="-",0,H7*0.01) -> 0 | Q7: =H7*0.005 -> 9738 | R7: =IF(I7="V.Tân",H7*0.1375,IF(I7="nguyện",H7*0.1375,IF(I7="TOẢN",H7*0.1375,H7*0.17))) -> 331092
A8: 2 | B8: 20/6/2025 | C8: Nguyễn Thị Nuôi | E8: 62 | F8: Cố định cột sống | G8: TTDB | H8: 4201900 | I8: HOAN | J8: =R8-L8-N8-P8-Q8 -> 441199.5 | K8: ĐIỀN | L8: =IF(K8="-",0,H8*0.03) -> 126057 | M8: ĐAN | N8: =IF(M8="-",0,H8*0.02) -> 84038 | O8: VINH | P8: =IF(O8="-",0,H8*0.01) -> 42019 | Q8: =H8*0.005 -> 21009.5 | R8: =IF(I8="V.Tân",H8*0.1375,IF(I8="nguyện",H8*0.1375,IF(I8="TOẢN",H8*0.1375,H8*0.17))) -> 714323
A9: 3 | B9: 24/6/2025 | C9: Nguyễn Thanh Hải | D9: 61 | F9: Ghép da tự thân | G9: TT2 | H9: 2934400 | I9: V.TÂN | J9: =R9-L9-N9-P9-Q9 -> 388808 | K9: - | L9: =IF(K9="-",0,H9*0.03) -> 0 | M9: - | N9: =IF(M9="-",0,H9*0.02) -> 0 | O9: - | P9: =IF(O9="-",0,H9*0.01) -> 0 | Q9: =H9*0.005 -> 14672 | R9: =IF(I9="V.Tân",H9*0.1375,IF(I9="nguyện",H9*0.1375,IF(I9="TOẢN",H9*0.1375,H9*0.17))) -> 403480
A10: 4 | B10: 24/6/2025 | C10: Nguyễn Văn Hùng | D10: 55 | F10: PT làm mỏm cụt | G10: TT2 | H10: 1773300 | I10: V.TÂN | J10: =R10-L10-N10-P10-Q10 -> 128564.25 | K10: GIÀU | L10: =IF(K10="-",0,H10*0.03) -> 53199 | M10: ĐAN | N10: =IF(M10="-",0,H10*0.02) -> 35466 | O10: HẬU | P10: =IF(O10="-",0,H10*0.01) -> 17733 | Q10: =H10*0.005 -> 8866.5 | R10: =IF(I10="V.Tân",H10*0.1375,IF(I10="nguyện",H10*0.1375,IF(I10="TOẢN",H10*0.1375,H10*0.17))) -> 243828.75
A11: 5 | B11: 25/6/2025 | C11: Lê Thị Phan | E11: 76 | F11: Cắt lọc | G11: TT2 | H11: 2128200 | I11: V.TÂN | J11: =R11-L11-N11-P11-Q11 -> 281986.5 | K11: - | L11: =IF(K11="-",0,H11*0.03) -> 0 | M11: - | N11: =IF(M11="-",0,H11*0.02) -> 0 | O11: - | P11: =IF(O11="-",0,H11*0.01) -> 0 | Q11: =H11*0.005 -> 10641 | R11: =IF(I11="V.Tân",H11*0.1375,IF(I11="nguyện",H11*0.1375,IF(I11="TOẢN",H11*0.1375,H11*0.17))) -> 292627.5
A12: 6 | B12: 26/6/2025 | C12: Nguyễn Thị Bé Tư | E12: 70 | F12: Bơm cement tạo hình thân sống | G12: TTDB | H12: 4578000 | I12: HOAN | J12: =R12-L12-N12-P12-Q12 -> 480690 | K12: NGHĨA | L12: =IF(K12="-",0,H12*0.03) -> 137340 | M12: ĐAN | N12: =IF(M12="-",0,H12*0.02) -> 91560 | O12: NGUYÊN | P12: =IF(O12="-",0,H12*0.01) -> 45780 | Q12: =H12*0.005 -> 22890 | R12: =IF(I12="V.Tân",H12*0.1375,IF(I12="nguyện",H12*0.1375,IF(I12="TOẢN",H12*0.1375,H12*0.17))) -> 778260
A13: 7 | B13: 26/6/2025 | C13: Bùi Kim Ngoạt | D13: 77 | F13: PT thay toàn bộ khớp gối | G13: TTDB | H13: 3525500 | I13: HOAN | J13: =R13-L13-N13-P13-Q13 -> 370177.5 | K13: V.TÂN | L13: =IF(K13="-",0,H13*0.03) -> 105765 | M13: ĐAN | N13: =IF(M13="-",0,H13*0.02) -> 70510 | O13: NGUYÊN | P13: =IF(O13="-",0,H13*0.01) -> 35255 | Q13: =H13*0.005 -> 17627.5 | R13: =IF(I13="V.Tân",H13*0.1375,IF(I13="nguyện",H13*0.1375,IF(I13="TOẢN",H13*0.1375,H13*0.17))) -> 599335
A14: 8 | B14: 27/06/2025 | C14: Nguyễn Thành Đạt | D14: 35 | F14: Cắt u đường kính >10cm | G14: TT1 | H14: 1859300 | I14: ĐIỀN | J14: =R14-L14-N14-P14-Q14 -> 213819.5 | K14: NGHĨA | L14: =IF(K14="-",0,H14*0.03) -> 55779 | M14: NHỊ | N14: =IF(M14="-",0,H14*0.02) -> 37186 | O14: - | P14: =IF(O14="-",0,H14*0.01) -> 0 | Q14: =H14*0.005 -> 9296.5 | R14: =IF(I14="V.Tân",H14*0.1375,IF(I14="nguyện",H14*0.1375,IF(I14="TOẢN",H14*0.1375,H14*0.17))) -> 316081
A15: 9 | B15: 28/06/2025 | C15: Nguyễn Tấn Thành | D15: 38 | F15: PT điều trị đứt gân Achille | G15: TTDB | H15: 2697300 | I15: V.TÂN | J15: =R15-L15-N15-P15-Q15 -> 195554.25 | K15: NGUYÊN | L15: =IF(K15="-",0,H15*0.03) -> 80919 | M15: NGHĨA | N15: =IF(M15="-",0,H15*0.02) -> 53946 | O15: HẬU | P15: =IF(O15="-",0,H15*0.01) -> 26973 | Q15: =H15*0.005 -> 13486.5 | R15: =IF(I15="V.Tân",H15*0.1375,IF(I15="nguyện",H15*0.1375,IF(I15="TOẢN",H15*0.1375,H15*0.17))) -> 370878.75
A16: 10 | B16: 28/06/2025 | C16: Huỳnh Văn Hoàng | D16: 69 | F16: PT thay toàn bộ khớp gối | G16: TTDB | H16: 3525500 | I16: TẤN | J16: =R16-L16-N16-P16-Q16 -> 370177.5 | K16: TOẢN | L16: =IF(K16="-",0,H16*0.03) -> 105765 | M16: GIÀU | N16: =IF(M16="-",0,H16*0.02) -> 70510 | O16: HÀO | P16: =IF(O16="-",0,H16*0.01) -> 35255 | Q16: =H16*0.005 -> 17627.5 | R16: =IF(I16="V.Tân",H16*0.1375,IF(I16="nguyện",H16*0.1375,IF(I16="TOẢN",H16*0.1375,H16*0.17))) -> 599335
A17: 11 | B17: 28/06/2025 | C17: Phạm Thị Minh Nghĩa | E17: 50 | F17: PT KHX trên màn hình tăng sáng | G17: TTDB | H17: 4497500 | I17: TẤN | J17: =R17-L17-N17-P17-Q17 -> 472237.5 | K17: TOẢN | L17: =IF(K17="-",0,H17*0.03) -> 134925 | M17: GIÀU | N17: =IF(M17="-",0,H17*0.02) -> 89950 | O17: VINH | P17: =IF(O17="-",0,H17*0.01) -> 44975 | Q17: =H17*0.005 -> 22487.5 | R17: =IF(I17="V.Tân",H17*0.1375,IF(I17="nguyện",H17*0.1375,IF(I17="TOẢN",H17*0.1375,H17*0.17))) -> 764575
A18: 12 | B18: 28/06/2025 | C18: Nguyễn Ngọc Hiếu | D18: 20 | F18: PT KHX trên màn hình tăng sáng | G18: TTDB | H18: 4497500 | I18: TOẢN | J18: =R18-L18-N18-P18-Q18 -> 326068.75 | K18: GIÀU | L18: =IF(K18="-",0,H18*0.03) -> 134925 | M18: ĐAN | N18: =IF(M18="-",0,H18*0.02) -> 89950 | O18: HẬU | P18: =IF(O18="-",0,H18*0.01) -> 44975 | Q18: =H18*0.005 -> 22487.5 | R18: =IF(I18="V.Tân",H18*0.1375,IF(I18="nguyện",H18*0.1375,IF(I18="TOẢN",H18*0.1375,H18*0.17))) -> 618406.25
A19: 13 | B19: 28/06/2025 | C19: Tăng Thị Kim Xoàn | E19: 67 | F19: PT KHX trên màn hình tăng sáng | G19: TTDB | H19: 4497500 | I19: GIÀU | J19: =R19-L19-N19-P19-Q19 -> 472237.5 | K19: HÀO | L19: =IF(K19="-",0,H19*0.03) -> 134925 | M19: HẬU | N19: =IF(M19="-",0,H19*0.02) -> 89950 | O19: ĐAN | P19: =IF(O19="-",0,H19*0.01) -> 44975 | Q19: =H19*0.005 -> 22487.5 | R19: =IF(I19="V.Tân",H19*0.1375,IF(I19="nguyện",H19*0.1375,IF(I19="TOẢN",H19*0.1375,H19*0.17))) -> 764575
A20: 14 | B20: 28/06/2025 | C20: NGUYỄN THỊ TRÚC KHOA | E20: 31 | F20: PT lấy đĩa đệm CSTL qua da | G20: TT1 | H20: 3796000 | I20: GIÀU | J20: =R20-L20-N20-P20-Q20 -> 398580 | K20: Q.TẤN | L20: =IF(K20="-",0,H20*0.03) -> 113880 | M20: VINH | N20: =IF(M20="-",0,H20*0.02) -> 75920 | O20: V.HƯỞNG | P20: =IF(O20="-",0,H20*0.01) -> 37960 | Q20: =H20*0.005 -> 18980 | R20: =IF(I20="V.Tân",H20*0.1375,IF(I20="nguyện",H20*0.1375,IF(I20="TOẢN",H20*0.1375,H20*0.17))) -> 645320
A21: 15 | B21: 29/06/2025 | C21: Nguyễn Hoàng Phúc | D21: 27 | F21: PT vết thương phần mềm phức tạp | G21: TP | H21: 5100000 | I21: ĐIỀN | J21: =R21-L21-N21-P21-Q21 -> 535500 | K21: V.HƯỞNG | L21: =IF(K21="-",0,H21*0.03) -> 153000 | M21: Q.TẤN | N21: =IF(M21="-",0,H21*0.02) -> 102000 | O21: ĐAN | P21: =IF(O21="-",0,H21*0.01) -> 51000 | Q21: =H21*0.005 -> 25500 | R21: =IF(I21="V.Tân",H21*0.1375,IF(I21="nguyện",H21*0.1375,IF(I21="TOẢN",H21*0.1375,H21*0.17))) -> 867000
A22: 16 | B22: 30/6/2025 | C22: Nguyễn Văn Thái | D22: 67 | F22: Cắt lọc | G22: TP | H22: 4000000 | I22: HOAN | J22: =R22-L22-N22-P22-Q22 -> 420000 | K22: ĐẠT | L22: =IF(K22="-",0,H22*0.03) -> 120000 | M22: NHỊ | N22: =IF(M22="-",0,H22*0.02) -> 80000 | O22: HÀO | P22: =IF(O22="-",0,H22*0.01) -> 40000 | Q22: =H22*0.005 -> 20000 | R22: =IF(I22="V.Tân",H22*0.1375,IF(I22="nguyện",H22*0.1375,IF(I22="TOẢN",H22*0.1375,H22*0.17))) -> 680000
A23: 17 | B23: 30/6/2025 | C23: Lê Văn Đô | D23: 40 | F23: PT KHX trên màn hình tăng sáng | G23: TTDB | H23: 4497500 | I23: TOẢN | J23: =R23-L23-N23-P23-Q23 -> 326068.75 | K23: VINH | L23: =IF(K23="-",0,H23*0.03) -> 134925 | M23: HẬU | N23: =IF(M23="-",0,H23*0.02) -> 89950 | O23: Q.TẤN | P23: =IF(O23="-",0,H23*0.01) -> 44975 | Q23: =H23*0.005 -> 22487.5 | R23: =IF(I23="V.Tân",H23*0.1375,IF(I23="nguyện",H23*0.1375,IF(I23="TOẢN",H23*0.1375,H23*0.17))) -> 618406.25
A24: 18 | B24: 30/6/2025 | C24: Lâm Kim Ngân | E24: 52 | F24: PT KHX trên màn hình tăng sáng | G24: TTDB | H24: 4497500 | I24: ĐIỀN | J24: =R24-L24-N24-P24-Q24 -> 472237.5 | K24: NGUYÊN | L24: =IF(K24="-",0,H24*0.03) -> 134925 | M24: HẬU | N24: =IF(M24="-",0,H24*0.02) -> 89950 | O24: N.KHANG | P24: =IF(O24="-",0,H24*0.01) -> 44975 | Q24: =H24*0.005 -> 22487.5 | R24: =IF(I24="V.Tân",H24*0.1375,IF(I24="nguyện",H24*0.1375,IF(I24="TOẢN",H24*0.1375,H24*0.17))) -> 764575
A25: 19 | B25: 30/6/2025 | C25: Nguyễn Văn Beo | D25: 72 | F25: Cắt lọc hoại tử ổ loét mãn tính | G25: TT2 | H25: 2128200 | I25: HOAN | J25: =R25-L25-N25-P25-Q25 -> 287307 | K25: TOẢN | L25: =IF(K25="-",0,H25*0.03) -> 63846 | M25: - | N25: =IF(M25="-",0,H25*0.02) -> 0 | O25: - | P25: =IF(O25="-",0,H25*0.01) -> 0 | Q25: =H25*0.005 -> 10641 | R25: =IF(I25="V.Tân",H25*0.1375,IF(I25="nguyện",H25*0.1375,IF(I25="TOẢN",H25*0.1375,H25*0.17))) -> 361794
A26: 20 | B26: 01/7/2025 | C26: Trần Thanh Tuấn | D26: 58 | F26: KHX trên màn hình tăng sáng | G26: TTDB | H26: 4497500 | I26: GIÀU | J26: =R26-L26-N26-P26-Q26 -> 472237.5 | K26: Q.TẤN | L26: =IF(K26="-",0,H26*0.03) -> 134925 | M26: HẬU | N26: =IF(M26="-",0,H26*0.02) -> 89950 | O26: NGHĨA | P26: =IF(O26="-",0,H26*0.01) -> 44975 | Q26: =H26*0.005 -> 22487.5 | R26: =IF(I26="V.Tân",H26*0.1375,IF(I26="nguyện",H26*0.1375,IF(I26="TOẢN",H26*0.1375,H26*0.17))) -> 764575
A27: 21 | B27: 01/7/2025 | C27: Huỳnh Thị Duyên Em | E27: 44 | F27: Lấy dụng cụ | G27: TP | H27: 4417000 | I27: V.TÂN | J27: =R27-L27-N27-P27-Q27 -> 364402.5 | K27: NGHĨA | L27: =IF(K27="-",0,H27*0.03) -> 132510 | M27: HẬU | N27: =IF(M27="-",0,H27*0.02) -> 88340 | O27: - | P27: =IF(O27="-",0,H27*0.01) -> 0 | Q27: =H27*0.005 -> 22085 | R27: =IF(I27="V.Tân",H27*0.1375,IF(I27="nguyện",H27*0.1375,IF(I27="TOẢN",H27*0.1375,H27*0.17))) -> 607337.5
A28: 22 | B28: 01/7/2025 | C28: Nguyễn Ngọc Niệm | D28: 73 | F28: KHX trên màn hình tăng sáng | G28: TTDB | H28: 4497500 | I28: GIÀU | J28: =R28-L28-N28-P28-Q28 -> 472237.5 | K28: HẬU | L28: =IF(K28="-",0,H28*0.03) -> 134925 | M28: Q.TẤN | N28: =IF(M28="-",0,H28*0.02) -> 89950 | O28: V.HƯỞNG | P28: =IF(O28="-",0,H28*0.01) -> 44975 | Q28: =H28*0.005 -> 22487.5 | R28: =IF(I28="V.Tân",H28*0.1375,IF(I28="nguyện",H28*0.1375,IF(I28="TOẢN",H28*0.1375,H28*0.17))) -> 764575
A29: 23 | B29: 01/7/2025 | C29: Lê VĂn Danh | D29: 38 | F29: Thay toàn bộ khớp háng | G29: TTDB | H29: 3525500 | I29: HOAN | J29: =R29-L29-N29-P29-Q29 -> 370177.5 | K29: TOẢN | L29: =IF(K29="-",0,H29*0.03) -> 105765 | M29: ĐAN | N29: =IF(M29="-",0,H29*0.02) -> 70510 | O29: NGUYÊN | P29: =IF(O29="-",0,H29*0.01) -> 35255 | Q29: =H29*0.005 -> 17627.5 | R29: =IF(I29="V.Tân",H29*0.1375,IF(I29="nguyện",H29*0.1375,IF(I29="TOẢN",H29*0.1375,H29*0.17))) -> 599335
A30: 24 | B30: 01/7/2025 | C30: Lý Thị Nga | E30: 74 | F30: Thay khớp háng bán phần | G30: TT1 | H30: 3897500 | I30: HOAN | J30: =R30-L30-N30-P30-Q30 -> 409237.5 | K30: TOẢN | L30: =IF(K30="-",0,H30*0.03) -> 116925 | M30: Q.TẤN | N30: =IF(M30="-",0,H30*0.02) -> 77950 | O30: HẬU | P30: =IF(O30="-",0,H30*0.01) -> 38975 | Q30: =H30*0.005 -> 19487.5 | R30: =IF(I30="V.Tân",H30*0.1375,IF(I30="nguyện",H30*0.1375,IF(I30="TOẢN",H30*0.1375,H30*0.17))) -> 662575
A31: 25 | B31: 01/7/2025 | C31: Nguyễn Thành Đạt | D31: 23 | F31: Lấy dụng cụ | G31: TT2 | H31: 2559100 | I31: ĐIỀN | J31: =R31-L31-N31-P31-Q31 -> 294296.5 | K31: ĐAN | L31: =IF(K31="-",0,H31*0.03) -> 76773 | M31: NGUYÊN | N31: =IF(M31="-",0,H31*0.02) -> 51182 | O31: - | P31: =IF(O31="-",0,H31*0.01) -> 0 | Q31: =H31*0.005 -> 12795.5 | R31: =IF(I31="V.Tân",H31*0.1375,IF(I31="nguyện",H31*0.1375,IF(I31="TOẢN",H31*0.1375,H31*0.17))) -> 435047
A32: 26 | B32: 01/7/2025 | C32: Nguyễn Khắc Luân | D32: 82 | F32: KHX trên màn hình tăng sáng | G32: TTDB | H32: 4497500 | I32: HOAN | J32: =R32-L32-N32-P32-Q32 -> 472237.5 | K32: ĐAN | L32: =IF(K32="-",0,H32*0.03) -> 134925 | M32: NGUYÊN | N32: =IF(M32="-",0,H32*0.02) -> 89950 | O32: V.HƯỞNG | P32: =IF(O32="-",0,H32*0.01) -> 44975 | Q32: =H32*0.005 -> 22487.5 | R32: =IF(I32="V.Tân",H32*0.1375,IF(I32="nguyện",H32*0.1375,IF(I32="TOẢN",H32*0.1375,H32*0.17))) -> 764575
A33: 27 | B33: 02/07/2025 | C33: Trần Thị Hồng | E33: 57 | F33: PTNS khớp gối | G33: TT1 | H33: 3397500 | I33: GIÀU | J33: =R33-L33-N33-P33-Q33 -> 356737.5 | K33: Q.TẤN | L33: =IF(K33="-",0,H33*0.03) -> 101925 | M33: NHỊ | N33: =IF(M33="-",0,H33*0.02) -> 67950 | O33: V.HƯỞNG | P33: =IF(O33="-",0,H33*0.01) -> 33975 | Q33: =H33*0.005 -> 16987.5 | R33: =IF(I33="V.Tân",H33*0.1375,IF(I33="nguyện",H33*0.1375,IF(I33="TOẢN",H33*0.1375,H33*0.17))) -> 577575
A34: 28 | B34: 02/07/2025 | C34: Nguyễn Thị Năm | E34: 64 | F34: Cố định cột sống thắt lưng | G34: TTDB | H34: 4201900 | I34: HOAN | J34: =R34-L34-N34-P34-Q34 -> 441199.5 | K34: Q.TẤN | L34: =IF(K34="-",0,H34*0.03) -> 126057 | M34: HÀO | N34: =IF(M34="-",0,H34*0.02) -> 84038 | O34: V.HƯỞNG | P34: =IF(O34="-",0,H34*0.01) -> 42019 | Q34: =H34*0.005 -> 21009.5 | R34: =IF(I34="V.Tân",H34*0.1375,IF(I34="nguyện",H34*0.1375,IF(I34="TOẢN",H34*0.1375,H34*0.17))) -> 714323
A35: 29 | B35: 02/07/2025 | C35: Nguyễn Thị Thủy | E35: 71 | F35: Cố định cột sống thắt lưng | G35: TTDB | H35: 4201900 | I35: HOAN | J35: =R35-L35-N35-P35-Q35 -> 441199.5 | K35: GIÀU | L35: =IF(K35="-",0,H35*0.03) -> 126057 | M35: HÀO | N35: =IF(M35="-",0,H35*0.02) -> 84038 | O35: ĐAN | P35: =IF(O35="-",0,H35*0.01) -> 42019 | Q35: =H35*0.005 -> 21009.5 | R35: =IF(I35="V.Tân",H35*0.1375,IF(I35="nguyện",H35*0.1375,IF(I35="TOẢN",H35*0.1375,H35*0.17))) -> 714323
A36: 30 | B36: 02/07/2025 | C36: Nguyễn Thị Thủy | E36: 71 | F36: Bơm cement (80%) | G36: TTDB | H36: 3662400 | I36: GIÀU | J36: =R36-L36-N36-P36-Q36 -> 384552 | K36: HOAN | L36: =IF(K36="-",0,H36*0.03) -> 109872 | M36: V.HƯỞNG | N36: =IF(M36="-",0,H36*0.02) -> 73248 | O36: NHỊ | P36: =IF(O36="-",0,H36*0.01) -> 36624 | Q36: =H36*0.005 -> 18312 | R36: =IF(I36="V.Tân",H36*0.1375,IF(I36="nguyện",H36*0.1375,IF(I36="TOẢN",H36*0.1375,H36*0.17))) -> 622608
A37: 31 | B37: 02/07/2025 | C37: Nguyễn Quốc Thủ | D37: 43 | F37: Lấy dụng cụ KHX | G37: TT1 | H37: 2301200 | I37: V.TÂN | J37: =R37-L37-N37-P37-Q37 -> 166837 | K37: ĐẠT | L37: =IF(K37="-",0,H37*0.03) -> 69036 | M37: ĐAN | N37: =IF(M37="-",0,H37*0.02) -> 46024 | O37: NHỊ | P37: =IF(O37="-",0,H37*0.01) -> 23012 | Q37: =H37*0.005 -> 11506 | R37: =IF(I37="V.Tân",H37*0.1375,IF(I37="nguyện",H37*0.1375,IF(I37="TOẢN",H37*0.1375,H37*0.17))) -> 316415
A38: 32 | B38: 02/07/2025 | C38: Phạm Văn Sự | E38: 63 | F38: PT viêm xương | G38: TT2 | H38: 2760300 | I38: GIÀU | J38: =R38-L38-N38-P38-Q38 -> 289831.5 | K38: ĐAN | L38: =IF(K38="-",0,H38*0.03) -> 82809 | M38: NHỊ | N38: =IF(M38="-",0,H38*0.02) -> 55206 | O38: V.HƯỞNG | P38: =IF(O38="-",0,H38*0.01) -> 27603 | Q38: =H38*0.005 -> 13801.5 | R38: =IF(I38="V.Tân",H38*0.1375,IF(I38="nguyện",H38*0.1375,IF(I38="TOẢN",H38*0.1375,H38*0.17))) -> 469251
A39: 33 | B39: 02/07/2025 | C39: Nguyễn Thị Nuôi | E39: 62 | F39: Cắt lọc hoại tử hoại tử ổ loét vết thương mạn tính | G39: TT2 | H39: 2127400 | I39: HOAN | J39: =R39-L39-N39-P39-Q39 -> 223377 | K39: GIÀU | L39: =IF(K39="-",0,H39*0.03) -> 63822 | M39: HÀO | N39: =IF(M39="-",0,H39*0.02) -> 42548 | O39: V.HƯỞNG | P39: =IF(O39="-",0,H39*0.01) -> 21274 | Q39: =H39*0.005 -> 10637 | R39: =IF(I39="V.Tân",H39*0.1375,IF(I39="nguyện",H39*0.1375,IF(I39="TOẢN",H39*0.1375,H39*0.17))) -> 361658
A40: 34 | B40: 03/07/2025 | C40: Nguyễn Văn Tuấn | D40: 49 | F40: Cắt lọc hoại tử hoại tử ổ loét vết thương mạn tính | G40: TP | H40: 4221000 | I40: ĐIỀN | J40: =R40-L40-N40-P40-Q40 -> 443205 | K40: ĐAN | L40: =IF(K40="-",0,H40*0.03) -> 126630 | M40: Q.TẤN | N40: =IF(M40="-",0,H40*0.02) -> 84420 | O40: V.HƯỞNG | P40: =IF(O40="-",0,H40*0.01) -> 42210 | Q40: =H40*0.005 -> 21105 | R40: =IF(I40="V.Tân",H40*0.1375,IF(I40="nguyện",H40*0.1375,IF(I40="TOẢN",H40*0.1375,H40*0.17))) -> 717570
A41: 35 | B41: 03/07/2025 | C41: Lê Gia Khiêm | D41: 20 | F41: KHX trên màn hình tăng sáng | G41: TP | H41: 9972000 | I41: ĐIỀN | J41: =R41-L41-N41-P41-Q41 -> 1047060 | K41: ĐAN | L41: =IF(K41="-",0,H41*0.03) -> 299160 | M41: Q.TẤN | N41: =IF(M41="-",0,H41*0.02) -> 199440 | O41: V.HƯỞNG | P41: =IF(O41="-",0,H41*0.01) -> 99720 | Q41: =H41*0.005 -> 49860 | R41: =IF(I41="V.Tân",H41*0.1375,IF(I41="nguyện",H41*0.1375,IF(I41="TOẢN",H41*0.1375,H41*0.17))) -> 1695240
...

Sheet lanh tien PT
A1: BV TRƯỜNG ĐHYD CẦN THƠ
A2: KHOA NGOẠI CTCH-TK
B3: DANH SÁCH LÃNH TIỀN THÙ LAO THÁNG 7/2025
C4: (Phẫu thuật)
A6: STT | B6: HỌ TÊN | C6: chức vụ | D6: SỐ TIỀN | E6: KÝ NHẬN
A7: 1 | B7: Phạm Việt Triều | C7: Bác sĩ | D7: =SUM(SUMIF(phauthuat!$I$7:$I$170,"TRIỀU",phauthuat!$J$7:$J$170),SUMIF(phauthuat!$K$7:$K$170,"TRIỀU",phauthuat!$L$7:$L$170),SUMIF(phauthuat!$M$7:$M$170,"TRIỀU",phauthuat!$N$7:$N$170),SUMIF(phauthuat!$O$7:$O$170,"TRIỀU",phauthuat!$P$7:$P$170))+1 -> 1915148.5
A8: 2 | B8: Nguyễn Thành Tấn | C8: Bác sĩ | D8: =SUM(SUMIF(phauthuat!$I$7:$I$170,"TẤN",phauthuat!$J$7:$J$170),SUMIF(phauthuat!$K$7:$K$170,"TẤN",phauthuat!$L$7:$L$170),SUMIF(phauthuat!$M$7:$M$170,"TẤN",phauthuat!$N$7:$N$170),SUMIF(phauthuat!$O$7:$O$170,"TẤN",phauthuat!$P$7:$P$170)) -> 2058712.5
A9: 3 | B9: Nguyễn Lê Hoan | C9: Bác sĩ | D9: =SUM(SUMIF(phauthuat!$I$7:$I$170,"HOAN",phauthuat!$J$7:$J$170),SUMIF(phauthuat!$K$7:$K$170,"HOAN",phauthuat!$L$7:$L$170),SUMIF(phauthuat!$M$7:$M$170,"HOAN",phauthuat!$N$7:$N$170),SUMIF(phauthuat!$O$7:$O$170,"Hoan",phauthuat!$P$7:$P$170)) -> 16389932
A10: 4 | B10: Nguyễn Chí Nguyện | C10: Bác sĩ | D10: =SUM(SUMIF(phauthuat!$I$7:$I$170,"NGUYỆN",phauthuat!$J$7:$J$170),SUMIF(phauthuat!$K$7:$K$170,"NGUYỆN",phauthuat!$L$7:$L$170),SUMIF(phauthuat!$M$7:$M$170,"NGUYỆN",phauthuat!$N$7:$N$170),SUMIF(phauthuat!$O$7:$O$170,"NGUYỆN",phauthuat!$P$7:$P$170)) -> 0
A11: 5 | B11: Đặng Phước Giàu | C11: Bác sĩ | D11: =SUM(SUMIF(phauthuat!$I$7:$I$170,"GIÀU",phauthuat!$J$7:$J$170),SUMIF(phauthuat!$K$7:$K$170,"GIÀU",phauthuat!$L$7:$L$170),SUMIF(phauthuat!$M$7:$M$170,"GIÀU",phauthuat!$N$7:$N$170),SUMIF(phauthuat!$O$7:$O$170,"GIÀU",phauthuat!$P$7:$P$170)) -> 19357086
A12: 6 | B12: Hồ Điền | C12: Bác sĩ | D12: =SUM(SUMIF(phauthuat!$I$7:$I$170,"ĐIỀN",phauthuat!$J$7:$J$170),SUMIF(phauthuat!$K$7:$K$170,"ĐIỀN",phauthuat!$L$7:$L$170),SUMIF(phauthuat!$M$7:$M$170,"ĐIỀN",phauthuat!$N$7:$N$170),SUMIF(phauthuat!$O$7:$O$170,"ĐIỀN",phauthuat!$P$7:$P$170)) -> 9595140
A13: 7 | B13: Trần Quốc Toản | C13: Bác sĩ | D13: =SUM(SUMIF(phauthuat!$I$7:$I$170,"TOẢN",phauthuat!$J$7:$J$170),SUMIF(phauthuat!$K$7:$K$170,"TOẢN",phauthuat!$L$7:$L$170),SUMIF(phauthuat!$M$7:$M$170,"TOẢN",phauthuat!$N$7:$N$170),SUMIF(phauthuat!$O$7:$O$170,"TOẢN",phauthuat!$P$7:$P$170)) -> 4744376.5
A14: 8 | B14: Phạm Việt Tân | C14: Bác sĩ | D14: =SUM(SUMIF(phauthuat!$I$7:$I$170,"V.TÂN",phauthuat!$J$7:$J$170),SUMIF(phauthuat!$K$7:$K$170,"V.TÂN",phauthuat!$L$7:$L$170),SUMIF(phauthuat!$M$7:$M$170,"V.TÂN",phauthuat!$N$7:$N$170),SUMIF(phauthuat!$O$7:$O$170,"V.TÂN",phauthuat!$P$7:$P$170)) -> 7444276.9
A15: 9 | B15: Bùi Công Minh | C15: Bác sĩ | D15: =SUM(SUMIF(phauthuat!$I$7:$I$170,"MINH",phauthuat!$J$7:$J$170),SUMIF(phauthuat!$K$7:$K$170,"MINH",phauthuat!$L$7:$L$170),SUMIF(phauthuat!$M$7:$M$170,"MINH",phauthuat!$N$7:$N$170),SUMIF(phauthuat!$O$7:$O$170,"MINH",phauthuat!$P$7:$P$170)) -> 5064677.5
A16: 10 | B16: Phan Văn Tuấn | C16: Bác sĩ | D16: =SUM(SUMIF(phauthuat!$I$7:$I$170,"TUẤN",phauthuat!$J$7:$J$170),SUMIF(phauthuat!$K$7:$K$170,"TUẤN",phauthuat!$L$7:$L$170),SUMIF(phauthuat!$M$7:$M$170,"TUẤN",phauthuat!$N$7:$N$170),SUMIF(phauthuat!$O$7:$O$170,"TUẤN",phauthuat!$P$7:$P$170)) -> 0
A17: 11 | B17: Nguyễn Hữu Đạt | C17: Bác sĩ | D17: =SUM(SUMIF(phauthuat!$I$7:$I$170,"Đạt",phauthuat!$J$7:$J$170),SUMIF(phauthuat!$K$7:$K$170,"Đạt",phauthuat!$L$7:$L$170),SUMIF(phauthuat!$M$7:$M$170,"Đạt",phauthuat!$N$7:$N$170),SUMIF(phauthuat!$O$7:$O$170,"Đạt",phauthuat!$P$7:$P$170)) -> 1795113
A18: 12 | B18: Trần Quang Sơn | C18: Bác sĩ | D18: =SUM(SUMIF(phauthuat!$I$7:$I$170,"sơn",phauthuat!$J$7:$J$170),SUMIF(phauthuat!$K$7:$K$170,"sơn",phauthuat!$L$7:$L$170),SUMIF(phauthuat!$M$7:$M$170,"sơn",phauthuat!$N$7:$N$170),SUMIF(phauthuat!$O$7:$O$170,"sơn",phauthuat!$P$7:$P$170)) -> 884032.5
A19: 13 | B19: Điều Tấn Kiệt | C19: Bác sĩ (nt) | D19: =SUM(SUMIF(phauthuat!$I$7:$I$170,"kiệt",phauthuat!$J$7:$J$170),SUMIF(phauthuat!$K$7:$K$170,"kiệt",phauthuat!$L$7:$L$170),SUMIF(phauthuat!$M$7:$M$170,"kiệt",phauthuat!$N$7:$N$170),SUMIF(phauthuat!$O$7:$O$170,"kiệt",phauthuat!$P$7:$P$170)) -> 912891
A20: 14 | B20: Nguyễn Lê Duy Phong | C20: Bác sĩ (nt) | D20: =SUM(SUMIF(phauthuat!$I$7:$I$170,"phong",phauthuat!$J$7:$J$170),SUMIF(phauthuat!$K$7:$K$170,"phong",phauthuat!$L$7:$L$170),SUMIF(phauthuat!$M$7:$M$170,"phong",phauthuat!$N$7:$N$170),SUMIF(phauthuat!$O$7:$O$170,"phong",phauthuat!$P$7:$P$170)) -> 571089
A21: 15 | B21: Trương Đại Lợi | C21: Bác sĩ (nt) | D21: =SUM(SUMIF(phauthuat!$I$7:$I$170,"lợi",phauthuat!$J$7:$J$170),SUMIF(phauthuat!$K$7:$K$170,"lợi",phauthuat!$L$7:$L$170),SUMIF(phauthuat!$M$7:$M$170,"lợi",phauthuat!$N$7:$N$170),SUMIF(phauthuat!$O$7:$O$170,"lợi",phauthuat!$P$7:$P$170)) -> 477401
A22: 16 | B22: Nguyễn Chí Thanh | C22: Bác sĩ (nt) | D22: =SUM(SUMIF(phauthuat!$I$7:$I$170,"thanh",phauthuat!$J$7:$J$170),SUMIF(phauthuat!$K$7:$K$170,"thanh",phauthuat!$L$7:$L$170),SUMIF(phauthuat!$M$7:$M$170,"thanh",phauthuat!$N$7:$N$170),SUMIF(phauthuat!$O$7:$O$170,"thanh",phauthuat!$P$7:$P$170)) -> 490228
A23: 17 | B23: Nguyễn Trung Nhị | C23: Bác sĩ (nt) | D23: =SUM(SUMIF(phauthuat!$I$7:$I$170,"nhị",phauthuat!$J$7:$J$170),SUMIF(phauthuat!$K$7:$K$170,"nhị",phauthuat!$L$7:$L$170),SUMIF(phauthuat!$M$7:$M$170,"nhị",phauthuat!$N$7:$N$170),SUMIF(phauthuat!$O$7:$O$170,"nhị",phauthuat!$P$7:$P$170)) -> 989496.5
A24: 18 | B24: Trần Trung Nghĩa | C24: Bác sĩ (nt) | D24: =SUM(SUMIF(phauthuat!$I$7:$I$170,"nghĩa",phauthuat!$J$7:$J$170),SUMIF(phauthuat!$K$7:$K$170,"nghĩa",phauthuat!$L$7:$L$170),SUMIF(phauthuat!$M$7:$M$170,"nghĩa",phauthuat!$N$7:$N$170),SUMIF(phauthuat!$O$7:$O$170,"nghĩa",phauthuat!$P$7:$P$170)) -> 616467
A25: 19 | B25: Lê Nhỉ Khang | C25: Bác sĩ (nt) | D25: =SUM(SUMIF(phauthuat!$I$7:$I$170,"n.khang",phauthuat!$J$7:$J$170),SUMIF(phauthuat!$K$7:$K$170,"n.khang",phauthuat!$L$7:$L$170),SUMIF(phauthuat!$M$7:$M$170,"n.khang",phauthuat!$N$7:$N$170),SUMIF(phauthuat!$O$7:$O$170,"n.khang",phauthuat!$P$7:$P$170)) -> 767486
A26: 20 | B26: Phạm Văn Hưởng | C26: Bác sĩ (nt) | D26: =SUM(SUMIF(phauthuat!$I$7:$I$170,"v.hưởng",phauthuat!$J$7:$J$170),SUMIF(phauthuat!$K$7:$K$170,"v.hưởng",phauthuat!$L$7:$L$170),SUMIF(phauthuat!$M$7:$M$170,"v.hưởng",phauthuat!$N$7:$N$170),SUMIF(phauthuat!$O$7:$O$170,"v.hưởng",phauthuat!$P$7:$P$170)) -> 767445
A27: 21 | B27: Nguyễn Trần Khánh Đan | C27: Bác sĩ (nt) | D27: =SUM(SUMIF(phauthuat!$I$7:$I$170,"ĐAN",phauthuat!$J$7:$J$170),SUMIF(phauthuat!$K$7:$K$170,"ĐAN",phauthuat!$L$7:$L$170),SUMIF(phauthuat!$M$7:$M$170,"ĐAN",phauthuat!$N$7:$N$170),SUMIF(phauthuat!$O$7:$O$170,"ĐAN",phauthuat!$P$7:$P$170)) -> 3265800.5
A28: 22 | B28: Phạm Công Hậu | C28: Bác sĩ (nt) | D28: =SUM(SUMIF(phauthuat!$I$7:$I$170,"HẬU",phauthuat!$J$7:$J$170),SUMIF(phauthuat!$K$7:$K$170,"HẬU",phauthuat!$L$7:$L$170),SUMIF(phauthuat!$M$7:$M$170,"HẬU",phauthuat!$N$7:$N$170),SUMIF(phauthuat!$O$7:$O$170,"HẬU",phauthuat!$P$7:$P$170)) -> 3062417
A29: 23 | B29: Trang Gia Vinh | C29: Bác sĩ (nt) | D29: =SUM(SUMIF(phauthuat!$I$7:$I$170,"VINH",phauthuat!$J$7:$J$170),SUMIF(phauthuat!$K$7:$K$170,"VINH",phauthuat!$L$7:$L$170),SUMIF(phauthuat!$M$7:$M$170,"VINH",phauthuat!$N$7:$N$170),SUMIF(phauthuat!$O$7:$O$170,"VINH",phauthuat!$P$7:$P$170)) -> 2571218
A30: 24 | B30: Bùi Quan Tấn | C30: Bác sĩ (nt) | D30: =SUM(SUMIF(phauthuat!$I$7:$I$170,"Q.TẤN",phauthuat!$J$7:$J$170),SUMIF(phauthuat!$K$7:$K$170,"Q.TẤN",phauthuat!$L$7:$L$170),SUMIF(phauthuat!$M$7:$M$170,"Q.TẤN",phauthuat!$N$7:$N$170),SUMIF(phauthuat!$O$7:$O$170,"Q.TẤN",phauthuat!$P$7:$P$170)) -> 5843198.1
A31: 25 | B31: Tào Nhật Hào | C31: Bác sĩ (nt) | D31: =SUM(SUMIF(phauthuat!$I$7:$I$170,"HÀO",phauthuat!$J$7:$J$170),SUMIF(phauthuat!$K$7:$K$170,"HÀO",phauthuat!$L$7:$L$170),SUMIF(phauthuat!$M$7:$M$170,"HÀO",phauthuat!$N$7:$N$170),SUMIF(phauthuat!$O$7:$O$170,"HÀO",phauthuat!$P$7:$P$170)) -> 2212316
A32: 26 | B32: Huỳnh Phúc Nguyên | C32: Bác sĩ (nt) | D32: =SUM(SUMIF(phauthuat!$I$7:$I$170,"NGUYÊN",phauthuat!$J$7:$J$170),SUMIF(phauthuat!$K$7:$K$170,"NGUYÊN",phauthuat!$L$7:$L$170),SUMIF(phauthuat!$M$7:$M$170,"NGUYÊN",phauthuat!$N$7:$N$170),SUMIF(phauthuat!$O$7:$O$170,"NGUYÊN",phauthuat!$P$7:$P$170)) -> 2295123.8
A33: 27 | B33: Phan Văn Hiếu | C33: Điều dưỡng | D33: =phauthuat!Q168/9 -> 330485.43
A34: 28 | B34: Võ Thị Yến Nhi | C34: Điều dưỡng | D34: =D33 -> 330485.43
A35: 29 | B35: Võ Phương Duy | C35: Điều dưỡng | D35: =D34 -> 330485.43
A36: 30 | B36: Nguyễn Kim Ngân | C36: Điều dưỡng | D36: =D35 -> 330485.43
A37: 31 | B37: Lê Ngọc Diệu | C37: Điều dưỡng | D37: =D36 -> 330485.43
A38: 32 | B38: Trần Quỳnh Minh Thư | C38: Điều dưỡng | D38: =D37 -> 330485.43
A39: 33 | B39: Lê Thị Tuyết Đoan | C39: Điều dưỡng | D39: -
A40: 34 | B40: Thạch Thị Thúy Đa | C40: Điều dưỡng | D40: =D38 -> 330485.43
A41: 35 | B41: Lê Kim Hoàn | C41: Điều dưỡng | D41: =D40 -> 330485.43
...

Sheet phauthuat_BHYT
A1: BV TRƯỜNG ĐHYD CẦN THƠ
A2: KHOA NGOẠI CTCH-TK
B3: BẢNG KÊ TIỀN PHẪU THUẬT BHYT
A4: (THÁNG 7/2025)
A7: STT | B7: Ngày | C7: Họ và tên | D7: Nam | E7: Nữ | F7: Phương pháp phẫu thuật | G7: loại pt - đối tượng | H7: PTV chính | I7: Số tiền | J7: Phụ mổ 1 | K7: Số tiền | L7: Phụ mổ 2 | M7: Số tiền | N7: Tổng số tiền được lãnh sau trừ khấu hao
A8: 1 | B8: 20/6/2025 | C8: Nguyễn Thị Nuôi | E8: 62 | F8: Cố định cột sống | G8: TTDB | H8: HOAN | I8: =IF(G8="DTDB",420000,IF(G8="TTDB",420000,IF(G8="DT1",187500,IF(G8="TT1",187500,IF(G8="DT2",97500,IF(G8="TT2",97500,IF(G8="DT3",75000,75000))))))) -> 420000 | J8: ĐIỀN | K8: =IF(G8="DTDB",300000,IF(G8="TTDB",300000,IF(G8="DT1",135000,IF(G8="TT1",135000,IF(G8="DT2",75000,IF(G8="TT2",75000,IF(G8="DT3",45000,45000))))))) -> 300000 | L8: ĐAN | M8: =IF(L8="-",0,IF(G8="DTDB",300000,IF(G8="TTDB",300000,IF(G8="DT1",135000,IF(G8="TT1",135000,IF(G8="DT2",75000,IF(G8="TT2",75000,IF(G8="DT3",45000,45000)))))))) -> 300000 | N8: =I8+K8+M8 -> 1020000
A9: 2 | B9: 24/6/2025 | C9: Lê Văn Bé Tám | D9: 56 | F9: PTNS cắt hoạt mạc viêm khớp gối | G9: DT1 | H9: TOẢN | I9: =IF(G9="DTDB",420000,IF(G9="TTDB",420000,IF(G9="DT1",187500,IF(G9="TT1",187500,IF(G9="DT2",97500,IF(G9="TT2",97500,IF(G9="DT3",75000,75000))))))) -> 187500 | J9: V.TÂN | K9: =IF(G9="DTDB",300000,IF(G9="TTDB",300000,IF(G9="DT1",135000,IF(G9="TT1",135000,IF(G9="DT2",75000,IF(G9="TT2",75000,IF(G9="DT3",45000,45000))))))) -> 135000 | L9: - | M9: =IF(L9="-",0,IF(G9="DTDB",300000,IF(G9="TTDB",300000,IF(G9="DT1",135000,IF(G9="TT1",135000,IF(G9="DT2",75000,IF(G9="TT2",75000,IF(G9="DT3",45000,45000)))))))) -> 0 | N9: =I9+K9+M9 -> 322500
A10: 3 | B10: 26/6/2025 | C10: Nguyễn Thị Bé Tư | E10: 70 | F10: Bơm cement tạo hình thân sống | G10: TTDB | H10: HOAN | I10: =IF(G10="DTDB",420000,IF(G10="TTDB",420000,IF(G10="DT1",187500,IF(G10="TT1",187500,IF(G10="DT2",97500,IF(G10="TT2",97500,IF(G10="DT3",75000,75000))))))) -> 420000 | J10: NGHĨA | K10: =IF(G10="DTDB",300000,IF(G10="TTDB",300000,IF(G10="DT1",135000,IF(G10="TT1",135000,IF(G10="DT2",75000,IF(G10="TT2",75000,IF(G10="DT3",45000,45000))))))) -> 300000 | L10: ĐAN | M10: =IF(L10="-",0,IF(G10="DTDB",300000,IF(G10="TTDB",300000,IF(G10="DT1",135000,IF(G10="TT1",135000,IF(G10="DT2",75000,IF(G10="TT2",75000,IF(G10="DT3",45000,45000)))))))) -> 300000 | N10: =I10+K10+M10 -> 1020000
A11: 4 | B11: 26/6/2025 | C11: Cao Văn Phụ | D11: 55 | F11: PTNS khâu chóp xoay | G11: DTDB | H11: TOẢN | I11: =IF(G11="DTDB",420000,IF(G11="TTDB",420000,IF(G11="DT1",187500,IF(G11="TT1",187500,IF(G11="DT2",97500,IF(G11="TT2",97500,IF(G11="DT3",75000,75000))))))) -> 420000 | J11: NGUYÊN | K11: =IF(G11="DTDB",300000,IF(G11="TTDB",300000,IF(G11="DT1",135000,IF(G11="TT1",135000,IF(G11="DT2",75000,IF(G11="TT2",75000,IF(G11="DT3",45000,45000))))))) -> 300000 | L11: NHỊ | M11: =IF(L11="-",0,IF(G11="DTDB",300000,IF(G11="TTDB",300000,IF(G11="DT1",135000,IF(G11="TT1",135000,IF(G11="DT2",75000,IF(G11="TT2",75000,IF(G11="DT3",45000,45000)))))))) -> 300000 | N11: =I11+K11+M11 -> 1020000
A12: 5 | B12: 26/6/2025 | C12: Bùi Kim Ngoạt | D12: 77 | F12: PT thay toàn bộ khớp gối | G12: TTDB | H12: HOAN | I12: =IF(G12="DTDB",420000,IF(G12="TTDB",420000,IF(G12="DT1",187500,IF(G12="TT1",187500,IF(G12="DT2",97500,IF(G12="TT2",97500,IF(G12="DT3",75000,75000))))))) -> 420000 | J12: V.TÂN | K12: =IF(G12="DTDB",300000,IF(G12="TTDB",300000,IF(G12="DT1",135000,IF(G12="TT1",135000,IF(G12="DT2",75000,IF(G12="TT2",75000,IF(G12="DT3",45000,45000))))))) -> 300000 | L12: ĐAN | M12: =IF(L12="-",0,IF(G12="DTDB",300000,IF(G12="TTDB",300000,IF(G12="DT1",135000,IF(G12="TT1",135000,IF(G12="DT2",75000,IF(G12="TT2",75000,IF(G12="DT3",45000,45000)))))))) -> 300000 | N12: =I12+K12+M12 -> 1020000
A13: 6 | B13: 27/06/2025 | C13: Nguyễn Thành Đạt | D13: 35 | F13: Cắt u đường kính >10cm | G13: TT1 | H13: ĐIỀN | I13: =IF(G13="DTDB",420000,IF(G13="TTDB",420000,IF(G13="DT1",187500,IF(G13="TT1",187500,IF(G13="DT2",97500,IF(G13="TT2",97500,IF(G13="DT3",75000,75000))))))) -> 187500 | J13: NGHĨA | K13: =IF(G13="DTDB",300000,IF(G13="TTDB",300000,IF(G13="DT1",135000,IF(G13="TT1",135000,IF(G13="DT2",75000,IF(G13="TT2",75000,IF(G13="DT3",45000,45000))))))) -> 135000 | L13: NHỊ | M13: =IF(L13="-",0,IF(G13="DTDB",300000,IF(G13="TTDB",300000,IF(G13="DT1",135000,IF(G13="TT1",135000,IF(G13="DT2",75000,IF(G13="TT2",75000,IF(G13="DT3",45000,45000)))))))) -> 135000 | N13: =I13+K13+M13 -> 457500
A14: 7 | B14: 28/06/2025 | C14: Nguyễn Tấn Thành | D14: 38 | F14: PT điều trị đứt gân Achille | G14: TTDB | H14: V.TÂN | I14: =IF(G14="DTDB",420000,IF(G14="TTDB",420000,IF(G14="DT1",187500,IF(G14="TT1",187500,IF(G14="DT2",97500,IF(G14="TT2",97500,IF(G14="DT3",75000,75000))))))) -> 420000 | J14: NGUYÊN | K14: =IF(G14="DTDB",300000,IF(G14="TTDB",300000,IF(G14="DT1",135000,IF(G14="TT1",135000,IF(G14="DT2",75000,IF(G14="TT2",75000,IF(G14="DT3",45000,45000))))))) -> 300000 | L14: NGHĨA | M14: =IF(L14="-",0,IF(G14="DTDB",300000,IF(G14="TTDB",300000,IF(G14="DT1",135000,IF(G14="TT1",135000,IF(G14="DT2",75000,IF(G14="TT2",75000,IF(G14="DT3",45000,45000)))))))) -> 300000 | N14: =I14+K14+M14 -> 1020000
A15: 8 | B15: 28/06/2025 | C15: Huỳnh Văn Hoàng | D15: 69 | F15: PT thay toàn bộ khớp gối | G15: TTDB | H15: TẤN | I15: =IF(G15="DTDB",420000,IF(G15="TTDB",420000,IF(G15="DT1",187500,IF(G15="TT1",187500,IF(G15="DT2",97500,IF(G15="TT2",97500,IF(G15="DT3",75000,75000))))))) -> 420000 | J15: TOẢN | K15: =IF(G15="DTDB",300000,IF(G15="TTDB",300000,IF(G15="DT1",135000,IF(G15="TT1",135000,IF(G15="DT2",75000,IF(G15="TT2",75000,IF(G15="DT3",45000,45000))))))) -> 300000 | L15: GIÀU | M15: =IF(L15="-",0,IF(G15="DTDB",300000,IF(G15="TTDB",300000,IF(G15="DT1",135000,IF(G15="TT1",135000,IF(G15="DT2",75000,IF(G15="TT2",75000,IF(G15="DT3",45000,45000)))))))) -> 300000 | N15: =I15+K15+M15 -> 1020000
A16: 9 | B16: 28/06/2025 | C16: Phạm Thị Minh Nghĩa | E16: 50 | F16: PT KHX trên màn hình tăng sáng | G16: TTDB | H16: TẤN | I16: =IF(G16="DTDB",420000,IF(G16="TTDB",420000,IF(G16="DT1",187500,IF(G16="TT1",187500,IF(G16="DT2",97500,IF(G16="TT2",97500,IF(G16="DT3",75000,75000))))))) -> 420000 | J16: TOẢN | K16: =IF(G16="DTDB",300000,IF(G16="TTDB",300000,IF(G16="DT1",135000,IF(G16="TT1",135000,IF(G16="DT2",75000,IF(G16="TT2",75000,IF(G16="DT3",45000,45000))))))) -> 300000 | L16: GIÀU | M16: =IF(L16="-",0,IF(G16="DTDB",300000,IF(G16="TTDB",300000,IF(G16="DT1",135000,IF(G16="TT1",135000,IF(G16="DT2",75000,IF(G16="TT2",75000,IF(G16="DT3",45000,45000)))))))) -> 300000 | N16: =I16+K16+M16 -> 1020000
A17: 10 | B17: 28/06/2025 | C17: Nguyễn Ngọc Hiếu | D17: 20 | F17: PT KHX trên màn hình tăng sáng | G17: TTDB | H17: TOẢN | I17: =IF(G17="DTDB",420000,IF(G17="TTDB",420000,IF(G17="DT1",187500,IF(G17="TT1",187500,IF(G17="DT2",97500,IF(G17="TT2",97500,IF(G17="DT3",75000,75000))))))) -> 420000 | J17: GIÀU | K17: =IF(G17="DTDB",300000,IF(G17="TTDB",300000,IF(G17="DT1",135000,IF(G17="TT1",135000,IF(G17="DT2",75000,IF(G17="TT2",75000,IF(G17="DT3",45000,45000))))))) -> 300000 | L17: ĐAN | M17: =IF(L17="-",0,IF(G17="DTDB",300000,IF(G17="TTDB",300000,IF(G17="DT1",135000,IF(G17="TT1",135000,IF(G17="DT2",75000,IF(G17="TT2",75000,IF(G17="DT3",45000,45000)))))))) -> 300000 | N17: =I17+K17+M17 -> 1020000
A18: 11 | B18: 28/06/2025 | C18: Tăng Thị Kim Xoàn | E18: 67 | F18: PT KHX trên màn hình tăng sáng | G18: TTDB | H18: GIÀU | I18: =IF(G18="DTDB",420000,IF(G18="TTDB",420000,IF(G18="DT1",187500,IF(G18="TT1",187500,IF(G18="DT2",97500,IF(G18="TT2",97500,IF(G18="DT3",75000,75000))))))) -> 420000 | J18: HÀO | K18: =IF(G18="DTDB",300000,IF(G18="TTDB",300000,IF(G18="DT1",135000,IF(G18="TT1",135000,IF(G18="DT2",75000,IF(G18="TT2",75000,IF(G18="DT3",45000,45000))))))) -> 300000 | L18: HẬU | M18: =IF(L18="-",0,IF(G18="DTDB",300000,IF(G18="TTDB",300000,IF(G18="DT1",135000,IF(G18="TT1",135000,IF(G18="DT2",75000,IF(G18="TT2",75000,IF(G18="DT3",45000,45000)))))))) -> 300000 | N18: =I18+K18+M18 -> 1020000
A19: 12 | B19: 28/06/2025 | C19: NGUYỄN THỊ TRÚC KHOA | E19: 31 | F19: PT lấy đĩa đệm CSTL qua da | G19: TT1 | H19: GIÀU | I19: =IF(G19="DTDB",420000,IF(G19="TTDB",420000,IF(G19="DT1",187500,IF(G19="TT1",187500,IF(G19="DT2",97500,IF(G19="TT2",97500,IF(G19="DT3",75000,75000))))))) -> 187500 | J19: Q.TẤN | K19: =IF(G19="DTDB",300000,IF(G19="TTDB",300000,IF(G19="DT1",135000,IF(G19="TT1",135000,IF(G19="DT2",75000,IF(G19="TT2",75000,IF(G19="DT3",45000,45000))))))) -> 135000 | L19: VINH | M19: =IF(L19="-",0,IF(G19="DTDB",300000,IF(G19="TTDB",300000,IF(G19="DT1",135000,IF(G19="TT1",135000,IF(G19="DT2",75000,IF(G19="TT2",75000,IF(G19="DT3",45000,45000)))))))) -> 135000 | N19: =I19+K19+M19 -> 457500
A20: 13 | B20: 30/6/2025 | C20: Lê Văn Đô | D20: 40 | F20: PT KHX trên màn hình tăng sáng | G20: TTDB | H20: TOẢN | I20: =IF(G20="DTDB",420000,IF(G20="TTDB",420000,IF(G20="DT1",187500,IF(G20="TT1",187500,IF(G20="DT2",97500,IF(G20="TT2",97500,IF(G20="DT3",75000,75000))))))) -> 420000 | J20: VINH | K20: =IF(G20="DTDB",300000,IF(G20="TTDB",300000,IF(G20="DT1",135000,IF(G20="TT1",135000,IF(G20="DT2",75000,IF(G20="TT2",75000,IF(G20="DT3",45000,45000))))))) -> 300000 | L20: HẬU | M20: =IF(L20="-",0,IF(G20="DTDB",300000,IF(G20="TTDB",300000,IF(G20="DT1",135000,IF(G20="TT1",135000,IF(G20="DT2",75000,IF(G20="TT2",75000,IF(G20="DT3",45000,45000)))))))) -> 300000 | N20: =I20+K20+M20 -> 1020000
A21: 14 | B21: 30/6/2025 | C21: Lâm Kim Ngân | E21: 52 | F21: PT KHX trên màn hình tăng sáng | G21: TTDB | H21: ĐIỀN | I21: =IF(G21="DTDB",420000,IF(G21="TTDB",420000,IF(G21="DT1",187500,IF(G21="TT1",187500,IF(G21="DT2",97500,IF(G21="TT2",97500,IF(G21="DT3",75000,75000))))))) -> 420000 | J21: NGUYÊN | K21: =IF(G21="DTDB",300000,IF(G21="TTDB",300000,IF(G21="DT1",135000,IF(G21="TT1",135000,IF(G21="DT2",75000,IF(G21="TT2",75000,IF(G21="DT3",45000,45000))))))) -> 300000 | L21: HẬU | M21: =IF(L21="-",0,IF(G21="DTDB",300000,IF(G21="TTDB",300000,IF(G21="DT1",135000,IF(G21="TT1",135000,IF(G21="DT2",75000,IF(G21="TT2",75000,IF(G21="DT3",45000,45000)))))))) -> 300000 | N21: =I21+K21+M21 -> 1020000
A22: 15 | B22: 30/6/2025 | C22: Nguyễn Thị Nhung | E22: 53 | F22: PT KHX trên màn hình tăng sáng | G22: DTDB | H22: HOAN | I22: =IF(G22="DTDB",420000,IF(G22="TTDB",420000,IF(G22="DT1",187500,IF(G22="TT1",187500,IF(G22="DT2",97500,IF(G22="TT2",97500,IF(G22="DT3",75000,75000))))))) -> 420000 | J22: TOẢN | K22: =IF(G22="DTDB",300000,IF(G22="TTDB",300000,IF(G22="DT1",135000,IF(G22="TT1",135000,IF(G22="DT2",75000,IF(G22="TT2",75000,IF(G22="DT3",45000,45000))))))) -> 300000 | L22: VINH | M22: =IF(L22="-",0,IF(G22="DTDB",300000,IF(G22="TTDB",300000,IF(G22="DT1",135000,IF(G22="TT1",135000,IF(G22="DT2",75000,IF(G22="TT2",75000,IF(G22="DT3",45000,45000)))))))) -> 300000 | N22: =I22+K22+M22 -> 1020000
A23: 16 | B23: 01/7/2025 | C23: Bùi Thanh Thuận | D23: 20 | F23: Khâu tổn thương gân gấp bàn tay vùng II | G23: DTDB | H23: V.TÂN | I23: =IF(G23="DTDB",420000,IF(G23="TTDB",420000,IF(G23="DT1",187500,IF(G23="TT1",187500,IF(G23="DT2",97500,IF(G23="TT2",97500,IF(G23="DT3",75000,75000))))))) -> 420000 | J23: ĐẠT | K23: =IF(G23="DTDB",300000,IF(G23="TTDB",300000,IF(G23="DT1",135000,IF(G23="TT1",135000,IF(G23="DT2",75000,IF(G23="TT2",75000,IF(G23="DT3",45000,45000))))))) -> 300000 | L23: NGHĨA | M23: =IF(L23="-",0,IF(G23="DTDB",300000,IF(G23="TTDB",300000,IF(G23="DT1",135000,IF(G23="TT1",135000,IF(G23="DT2",75000,IF(G23="TT2",75000,IF(G23="DT3",45000,45000)))))))) -> 300000 | N23: =I23+K23+M23 -> 1020000
A24: 17 | B24: 01/7/2025 | C24: Trần Thanh Tuấn | D24: 58 | F24: KHX trên màn hình tăng sáng | G24: TTDB | H24: GIÀU | I24: =IF(G24="DTDB",420000,IF(G24="TTDB",420000,IF(G24="DT1",187500,IF(G24="TT1",187500,IF(G24="DT2",97500,IF(G24="TT2",97500,IF(G24="DT3",75000,75000))))))) -> 420000 | J24: Q.TẤN | K24: =IF(G24="DTDB",300000,IF(G24="TTDB",300000,IF(G24="DT1",135000,IF(G24="TT1",135000,IF(G24="DT2",75000,IF(G24="TT2",75000,IF(G24="DT3",45000,45000))))))) -> 300000 | L24: HẬU | M24: =IF(L24="-",0,IF(G24="DTDB",300000,IF(G24="TTDB",300000,IF(G24="DT1",135000,IF(G24="TT1",135000,IF(G24="DT2",75000,IF(G24="TT2",75000,IF(G24="DT3",45000,45000)))))))) -> 300000 | N24: =I24+K24+M24 -> 1020000
A25: 18 | B25: 01/7/2025 | C25: Nguyễn Ngọc Niệm | D25: 73 | F25: KHX trên màn hình tăng sáng | G25: TTDB | H25: GIÀU | I25: =IF(G25="DTDB",420000,IF(G25="TTDB",420000,IF(G25="DT1",187500,IF(G25="TT1",187500,IF(G25="DT2",97500,IF(G25="TT2",97500,IF(G25="DT3",75000,75000))))))) -> 420000 | J25: HẬU | K25: =IF(G25="DTDB",300000,IF(G25="TTDB",300000,IF(G25="DT1",135000,IF(G25="TT1",135000,IF(G25="DT2",75000,IF(G25="TT2",75000,IF(G25="DT3",45000,45000))))))) -> 300000 | L25: Q.TẤN | M25: =IF(L25="-",0,IF(G25="DTDB",300000,IF(G25="TTDB",300000,IF(G25="DT1",135000,IF(G25="TT1",135000,IF(G25="DT2",75000,IF(G25="TT2",75000,IF(G25="DT3",45000,45000)))))))) -> 300000 | N25: =I25+K25+M25 -> 1020000
A26: 19 | B26: 01/7/2025 | C26: Lê VĂn Danh | D26: 38 | F26: Thay toàn bộ khớp háng | G26: TTDB | H26: HOAN | I26: =IF(G26="DTDB",420000,IF(G26="TTDB",420000,IF(G26="DT1",187500,IF(G26="TT1",187500,IF(G26="DT2",97500,IF(G26="TT2",97500,IF(G26="DT3",75000,75000))))))) -> 420000 | J26: TOẢN | K26: =IF(G26="DTDB",300000,IF(G26="TTDB",300000,IF(G26="DT1",135000,IF(G26="TT1",135000,IF(G26="DT2",75000,IF(G26="TT2",75000,IF(G26="DT3",45000,45000))))))) -> 300000 | L26: ĐAN | M26: =IF(L26="-",0,IF(G26="DTDB",300000,IF(G26="TTDB",300000,IF(G26="DT1",135000,IF(G26="TT1",135000,IF(G26="DT2",75000,IF(G26="TT2",75000,IF(G26="DT3",45000,45000)))))))) -> 300000 | N26: =I26+K26+M26 -> 1020000
A27: 20 | B27: 01/7/2025 | C27: Lý Thị Nga | E27: 74 | F27: Thay khớp háng bán phần | G27: TT1 | H27: HOAN | I27: =IF(G27="DTDB",420000,IF(G27="TTDB",420000,IF(G27="DT1",187500,IF(G27="TT1",187500,IF(G27="DT2",97500,IF(G27="TT2",97500,IF(G27="DT3",75000,75000))))))) -> 187500 | J27: TOẢN | K27: =IF(G27="DTDB",300000,IF(G27="TTDB",300000,IF(G27="DT1",135000,IF(G27="TT1",135000,IF(G27="DT2",75000,IF(G27="TT2",75000,IF(G27="DT3",45000,45000))))))) -> 135000 | L27: Q.TẤN | M27: =IF(L27="-",0,IF(G27="DTDB",300000,IF(G27="TTDB",300000,IF(G27="DT1",135000,IF(G27="TT1",135000,IF(G27="DT2",75000,IF(G27="TT2",75000,IF(G27="DT3",45000,45000)))))))) -> 135000 | N27: =I27+K27+M27 -> 457500
A28: 21 | B28: 01/7/2025 | C28: Nguyễn Khắc Luân | D28: 82 | F28: KHX trên màn hình tăng sáng | G28: TTDB | H28: HOAN | I28: =IF(G28="DTDB",420000,IF(G28="TTDB",420000,IF(G28="DT1",187500,IF(G28="TT1",187500,IF(G28="DT2",97500,IF(G28="TT2",97500,IF(G28="DT3",75000,75000))))))) -> 420000 | J28: ĐAN | K28: =IF(G28="DTDB",300000,IF(G28="TTDB",300000,IF(G28="DT1",135000,IF(G28="TT1",135000,IF(G28="DT2",75000,IF(G28="TT2",75000,IF(G28="DT3",45000,45000))))))) -> 300000 | L28: NGUYÊN | M28: =IF(L28="-",0,IF(G28="DTDB",300000,IF(G28="TTDB",300000,IF(G28="DT1",135000,IF(G28="TT1",135000,IF(G28="DT2",75000,IF(G28="TT2",75000,IF(G28="DT3",45000,45000)))))))) -> 300000 | N28: =I28+K28+M28 -> 1020000
A29: 22 | B29: 02/07/2025 | C29: Trần Thị Hồng | E29: 57 | F29: PTNS khớp gối | G29: TT1 | H29: GIÀU | I29: =IF(G29="DTDB",420000,IF(G29="TTDB",420000,IF(G29="DT1",187500,IF(G29="TT1",187500,IF(G29="DT2",97500,IF(G29="TT2",97500,IF(G29="DT3",75000,75000))))))) -> 187500 | J29: Q.TẤN | K29: =IF(G29="DTDB",300000,IF(G29="TTDB",300000,IF(G29="DT1",135000,IF(G29="TT1",135000,IF(G29="DT2",75000,IF(G29="TT2",75000,IF(G29="DT3",45000,45000))))))) -> 135000 | L29: NHỊ | M29: =IF(L29="-",0,IF(G29="DTDB",300000,IF(G29="TTDB",300000,IF(G29="DT1",135000,IF(G29="TT1",135000,IF(G29="DT2",75000,IF(G29="TT2",75000,IF(G29="DT3",45000,45000)))))))) -> 135000 | N29: =I29+K29+M29 -> 457500
A30: 23 | B30: 02/07/2025 | C30: Nguyễn Thị Năm | E30: 64 | F30: Cố định cột sống thắt lưng | G30: TTDB | H30: HOAN | I30: =IF(G30="DTDB",420000,IF(G30="TTDB",420000,IF(G30="DT1",187500,IF(G30="TT1",187500,IF(G30="DT2",97500,IF(G30="TT2",97500,IF(G30="DT3",75000,75000))))))) -> 420000 | J30: Q.TẤN | K30: =IF(G30="DTDB",300000,IF(G30="TTDB",300000,IF(G30="DT1",135000,IF(G30="TT1",135000,IF(G30="DT2",75000,IF(G30="TT2",75000,IF(G30="DT3",45000,45000))))))) -> 300000 | L30: HÀO | M30: =IF(L30="-",0,IF(G30="DTDB",300000,IF(G30="TTDB",300000,IF(G30="DT1",135000,IF(G30="TT1",135000,IF(G30="DT2",75000,IF(G30="TT2",75000,IF(G30="DT3",45000,45000)))))))) -> 300000 | N30: =I30+K30+M30 -> 1020000
A31: 24 | B31: 02/07/2025 | C31: Nguyễn Thị Thủy | E31: 71 | F31: Cố định cột sống thắt lưng | G31: TTDB | H31: HOAN | I31: =IF(G31="DTDB",420000,IF(G31="TTDB",420000,IF(G31="DT1",187500,IF(G31="TT1",187500,IF(G31="DT2",97500,IF(G31="TT2",97500,IF(G31="DT3",75000,75000))))))) -> 420000 | J31: GIÀU | K31: =IF(G31="DTDB",300000,IF(G31="TTDB",300000,IF(G31="DT1",135000,IF(G31="TT1",135000,IF(G31="DT2",75000,IF(G31="TT2",75000,IF(G31="DT3",45000,45000))))))) -> 300000 | L31: HÀO | M31: =IF(L31="-",0,IF(G31="DTDB",300000,IF(G31="TTDB",300000,IF(G31="DT1",135000,IF(G31="TT1",135000,IF(G31="DT2",75000,IF(G31="TT2",75000,IF(G31="DT3",45000,45000)))))))) -> 300000 | N31: =I31+K31+M31 -> 1020000
A32: 25 | B32: 02/07/2025 | C32: Nguyễn Thị Thủy | E32: 71 | F32: Bơm cement (80%) | G32: TTDB | H32: GIÀU | I32: =IF(G32="DTDB",420000,IF(G32="TTDB",420000,IF(G32="DT1",187500,IF(G32="TT1",187500,IF(G32="DT2",97500,IF(G32="TT2",97500,IF(G32="DT3",75000,75000))))))) -> 420000 | J32: HOAN | K32: =IF(G32="DTDB",300000,IF(G32="TTDB",300000,IF(G32="DT1",135000,IF(G32="TT1",135000,IF(G32="DT2",75000,IF(G32="TT2",75000,IF(G32="DT3",45000,45000))))))) -> 300000 | L32: V.HƯỞNG | M32: =IF(L32="-",0,IF(G32="DTDB",300000,IF(G32="TTDB",300000,IF(G32="DT1",135000,IF(G32="TT1",135000,IF(G32="DT2",75000,IF(G32="TT2",75000,IF(G32="DT3",45000,45000)))))))) -> 300000 | N32: =I32+K32+M32 -> 1020000
A33: 26 | B33: 02/07/2025 | C33: Nguyễn Quốc Thủ | D33: 43 | F33: Lấy dụng cụ KHX | G33: TT1 | H33: V.TÂN | I33: =IF(G33="DTDB",420000,IF(G33="TTDB",420000,IF(G33="DT1",187500,IF(G33="TT1",187500,IF(G33="DT2",97500,IF(G33="TT2",97500,IF(G33="DT3",75000,75000))))))) -> 187500 | J33: ĐẠT | K33: =IF(G33="DTDB",300000,IF(G33="TTDB",300000,IF(G33="DT1",135000,IF(G33="TT1",135000,IF(G33="DT2",75000,IF(G33="TT2",75000,IF(G33="DT3",45000,45000))))))) -> 135000 | L33: ĐAN | M33: =IF(L33="-",0,IF(G33="DTDB",300000,IF(G33="TTDB",300000,IF(G33="DT1",135000,IF(G33="TT1",135000,IF(G33="DT2",75000,IF(G33="TT2",75000,IF(G33="DT3",45000,45000)))))))) -> 135000 | N33: =I33+K33+M33 -> 457500
A34: 27 | B34: 03/07/2025 | C34: Huỳnh Thúy Nga | E34: 59 | F34: Cố định cột sống thắt lưng | G34: TTDB | H34: HOAN | I34: =IF(G34="DTDB",420000,IF(G34="TTDB",420000,IF(G34="DT1",187500,IF(G34="TT1",187500,IF(G34="DT2",97500,IF(G34="TT2",97500,IF(G34="DT3",75000,75000))))))) -> 420000 | J34: GIÀU | K34: =IF(G34="DTDB",300000,IF(G34="TTDB",300000,IF(G34="DT1",135000,IF(G34="TT1",135000,IF(G34="DT2",75000,IF(G34="TT2",75000,IF(G34="DT3",45000,45000))))))) -> 300000 | L34: VINH | M34: =IF(L34="-",0,IF(G34="DTDB",300000,IF(G34="TTDB",300000,IF(G34="DT1",135000,IF(G34="TT1",135000,IF(G34="DT2",75000,IF(G34="TT2",75000,IF(G34="DT3",45000,45000)))))))) -> 300000 | N34: =I34+K34+M34 -> 1020000
A35: 28 | B35: 03/07/2025 | C35: Đỗ Văn Dương | D35: 28 | F35: PTNS tái tạo dây chằng | G35: TTDB | H35: TOẢN | I35: =IF(G35="DTDB",420000,IF(G35="TTDB",420000,IF(G35="DT1",187500,IF(G35="TT1",187500,IF(G35="DT2",97500,IF(G35="TT2",97500,IF(G35="DT3",75000,75000))))))) -> 420000 | J35: SƠN | K35: =IF(G35="DTDB",300000,IF(G35="TTDB",300000,IF(G35="DT1",135000,IF(G35="TT1",135000,IF(G35="DT2",75000,IF(G35="TT2",75000,IF(G35="DT3",45000,45000))))))) -> 300000 | L35: VINH | M35: =IF(L35="-",0,IF(G35="DTDB",300000,IF(G35="TTDB",300000,IF(G35="DT1",135000,IF(G35="TT1",135000,IF(G35="DT2",75000,IF(G35="TT2",75000,IF(G35="DT3",45000,45000)))))))) -> 300000 | N35: =I35+K35+M35 -> 1020000
A36: 29 | B36: 04/07/2025 | C36: Huỳnh Thị Lụa | E36: 62 | F36: PT u thần kinh | G36: TT1 | H36: HOAN | I36: =IF(G36="DTDB",420000,IF(G36="TTDB",420000,IF(G36="DT1",187500,IF(G36="TT1",187500,IF(G36="DT2",97500,IF(G36="TT2",97500,IF(G36="DT3",75000,75000))))))) -> 187500 | J36: ĐIỀN | K36: =IF(G36="DTDB",300000,IF(G36="TTDB",300000,IF(G36="DT1",135000,IF(G36="TT1",135000,IF(G36="DT2",75000,IF(G36="TT2",75000,IF(G36="DT3",45000,45000))))))) -> 135000 | L36: - | M36: =IF(L36="-",0,IF(G36="DTDB",300000,IF(G36="TTDB",300000,IF(G36="DT1",135000,IF(G36="TT1",135000,IF(G36="DT2",75000,IF(G36="TT2",75000,IF(G36="DT3",45000,45000)))))))) -> 0 | N36: =I36+K36+M36 -> 322500
A37: 30 | B37: 04/07/2025 | C37: Huỳnh Thị Tôi | E37: 62 | F37: Cố định cột sống thắt lưng | G37: TTDB | H37: HOAN | I37: =IF(G37="DTDB",420000,IF(G37="TTDB",420000,IF(G37="DT1",187500,IF(G37="TT1",187500,IF(G37="DT2",97500,IF(G37="TT2",97500,IF(G37="DT3",75000,75000))))))) -> 420000 | J37: ĐIỀN | K37: =IF(G37="DTDB",300000,IF(G37="TTDB",300000,IF(G37="DT1",135000,IF(G37="TT1",135000,IF(G37="DT2",75000,IF(G37="TT2",75000,IF(G37="DT3",45000,45000))))))) -> 300000 | L37: NGUYÊN | M37: =IF(L37="-",0,IF(G37="DTDB",300000,IF(G37="TTDB",300000,IF(G37="DT1",135000,IF(G37="TT1",135000,IF(G37="DT2",75000,IF(G37="TT2",75000,IF(G37="DT3",45000,45000)))))))) -> 300000 | N37: =I37+K37+M37 -> 1020000
A38: 31 | B38: 05/7/2025 | C38: Võ Thị Hai | E38: 77 | F38: KHX trên màn hình tăng sáng | G38: DTDB | H38: GIÀU | I38: =IF(G38="DTDB",420000,IF(G38="TTDB",420000,IF(G38="DT1",187500,IF(G38="TT1",187500,IF(G38="DT2",97500,IF(G38="TT2",97500,IF(G38="DT3",75000,75000))))))) -> 420000 | J38: HẬU | K38: =IF(G38="DTDB",300000,IF(G38="TTDB",300000,IF(G38="DT1",135000,IF(G38="TT1",135000,IF(G38="DT2",75000,IF(G38="TT2",75000,IF(G38="DT3",45000,45000))))))) -> 300000 | L38: Q.TẤN | M38: =IF(L38="-",0,IF(G38="DTDB",300000,IF(G38="TTDB",300000,IF(G38="DT1",135000,IF(G38="TT1",135000,IF(G38="DT2",75000,IF(G38="TT2",75000,IF(G38="DT3",45000,45000)))))))) -> 300000 | N38: =I38+K38+M38 -> 1020000
A39: 32 | B39: 05/7/2025 | C39: Trần Minh Nguyệt | E39: 63 | F39: KHX trên màn hình tăng sáng | G39: DTDB | H39: GIÀU | I39: =IF(G39="DTDB",420000,IF(G39="TTDB",420000,IF(G39="DT1",187500,IF(G39="TT1",187500,IF(G39="DT2",97500,IF(G39="TT2",97500,IF(G39="DT3",75000,75000))))))) -> 420000 | J39: Q.TẤN | K39: =IF(G39="DTDB",300000,IF(G39="TTDB",300000,IF(G39="DT1",135000,IF(G39="TT1",135000,IF(G39="DT2",75000,IF(G39="TT2",75000,IF(G39="DT3",45000,45000))))))) -> 300000 | L39: HẬU | M39: =IF(L39="-",0,IF(G39="DTDB",300000,IF(G39="TTDB",300000,IF(G39="DT1",135000,IF(G39="TT1",135000,IF(G39="DT2",75000,IF(G39="TT2",75000,IF(G39="DT3",45000,45000)))))))) -> 300000 | N39: =I39+K39+M39 -> 1020000
A40: 33 | B40: 05/7/2025 | C40: Lê Thị Lợi | E40: 67 | F40: Cố định cột sống thắt lưng | G40: DTDB | H40: HOAN | I40: =IF(G40="DTDB",420000,IF(G40="TTDB",420000,IF(G40="DT1",187500,IF(G40="TT1",187500,IF(G40="DT2",97500,IF(G40="TT2",97500,IF(G40="DT3",75000,75000))))))) -> 420000 | J40: GIÀU | K40: =IF(G40="DTDB",300000,IF(G40="TTDB",300000,IF(G40="DT1",135000,IF(G40="TT1",135000,IF(G40="DT2",75000,IF(G40="TT2",75000,IF(G40="DT3",45000,45000))))))) -> 300000 | L40: ĐIỀN | M40: =IF(L40="-",0,IF(G40="DTDB",300000,IF(G40="TTDB",300000,IF(G40="DT1",135000,IF(G40="TT1",135000,IF(G40="DT2",75000,IF(G40="TT2",75000,IF(G40="DT3",45000,45000)))))))) -> 300000 | N40: =I40+K40+M40 -> 1020000
A41: 34 | B41: 05/7/2025 | C41: TRỊNH VĂN TÚ | D41: 37 | F41: Lấy nhân đệm qua da | G41: TT1 | H41: GIÀU | I41: =IF(G41="DTDB",420000,IF(G41="TTDB",420000,IF(G41="DT1",187500,IF(G41="TT1",187500,IF(G41="DT2",97500,IF(G41="TT2",97500,IF(G41="DT3",75000,75000))))))) -> 187500 | J41: Q.TẤN | K41: =IF(G41="DTDB",300000,IF(G41="TTDB",300000,IF(G41="DT1",135000,IF(G41="TT1",135000,IF(G41="DT2",75000,IF(G41="TT2",75000,IF(G41="DT3",45000,45000))))))) -> 135000 | L41: V.HƯỞNG | M41: =IF(L41="-",0,IF(G41="DTDB",300000,IF(G41="TTDB",300000,IF(G41="DT1",135000,IF(G41="TT1",135000,IF(G41="DT2",75000,IF(G41="TT2",75000,IF(G41="DT3",45000,45000)))))))) -> 135000 | N41: =I41+K41+M41 -> 457500
A42: 35 | B42: 06/7/2025 | C42: Nguyễn Văn Chính | D42: 59 | F42: KHX trên màn hình tăng sáng | G42: TTDB | H42: ĐIỀN | I42: =IF(G42="DTDB",420000,IF(G42="TTDB",420000,IF(G42="DT1",187500,IF(G42="TT1",187500,IF(G42="DT2",97500,IF(G42="TT2",97500,IF(G42="DT3",75000,75000))))))) -> 420000 | J42: HẬU | K42: =IF(G42="DTDB",300000,IF(G42="TTDB",300000,IF(G42="DT1",135000,IF(G42="TT1",135000,IF(G42="DT2",75000,IF(G42="TT2",75000,IF(G42="DT3",45000,45000))))))) -> 300000 | L42: NHỊ | M42: =IF(L42="-",0,IF(G42="DTDB",300000,IF(G42="TTDB",300000,IF(G42="DT1",135000,IF(G42="TT1",135000,IF(G42="DT2",75000,IF(G42="TT2",75000,IF(G42="DT3",45000,45000)))))))) -> 300000 | N42: =I42+K42+M42 -> 1020000
...

Sheet lanh tien PT_BHYT
A1: BV TRƯỜNG ĐHYD CẦN THƠ
A2: KHOA NGOẠI CTCH-TK
A3: DANH SÁCH LÃNH TIỀN THÙ LAO THÁNG 7/2025
A4: (BHYT)
A6: STT | B6: HỌ TÊN | C6: CHỨC VỤ | D6: SỐ TÀI KHOẢN | E6: SỐ TIỀN | F6: Thuế 10%
A7: 1 | B7: Phạm Việt Triều | C7: Bác sĩ | D7: 102006610216 | E7: =SUM(SUMIF(phauthuat_BHYT!$H$8:$H$185,"TRIỀU",phauthuat_BHYT!$I$8:$I$185),SUMIF(phauthuat_BHYT!$J$8:$J$185,"TRIỀU",phauthuat_BHYT!$K$8:$K$185),SUMIF(phauthuat_BHYT!$L$8:$L$185,"TRIỀU",phauthuat_BHYT!$M$8:$M$185)) -> 2100000
A8: 2 | B8: Nguyễn Thành Tấn | C8: Bác sĩ | D8: 103006610215 | E8: =SUM(SUMIF(phauthuat_BHYT!$H$8:$H$185,"TẤN",phauthuat_BHYT!$I$8:$I$185),SUMIF(phauthuat_BHYT!$J$8:$J$185,"TẤN",phauthuat_BHYT!$K$8:$K$185),SUMIF(phauthuat_BHYT!$L$8:$L$185,"TẤN",phauthuat_BHYT!$M$8:$M$185)) -> 2100000
A9: 3 | B9: Nguyễn Lê Hoan | C9: Bác sĩ | D9: 100006610218 | E9: =SUM(SUMIF(phauthuat_BHYT!$H$8:$H$185,"HOAN",phauthuat_BHYT!$I$8:$I$185),SUMIF(phauthuat_BHYT!$J$8:$J$185,"HOAN",phauthuat_BHYT!$K$8:$K$185),SUMIF(phauthuat_BHYT!$L$8:$L$185,"HOAN",phauthuat_BHYT!$M$8:$M$185)) -> 14985000
A10: 4 | B10: Nguyễn Chí Nguyện | C10: Bác sĩ | D10: 105001159195 | E10: =SUM(SUMIF(phauthuat_BHYT!$H$8:$H$185,"NGUYỆN",phauthuat_BHYT!$I$8:$I$185),SUMIF(phauthuat_BHYT!$J$8:$J$185,"NGUYỆN",phauthuat_BHYT!$K$8:$K$185),SUMIF(phauthuat_BHYT!$L$8:$L$185,"NGUYỆN",phauthuat_BHYT!$M$8:$M$185)) -> 0
A11: 5 | B11: Hồ Điền | C11: Bác sĩ | D11: 105001225232 | E11: =SUM(SUMIF(phauthuat_BHYT!$H$8:$H$185,"ĐIỀN",phauthuat_BHYT!$I$8:$I$185),SUMIF(phauthuat_BHYT!$J$8:$J$185,"ĐIỀN",phauthuat_BHYT!$K$8:$K$185),SUMIF(phauthuat_BHYT!$L$8:$L$185,"ĐIỀN",phauthuat_BHYT!$M$8:$M$185)) -> 6142500
A12: 6 | B12: Trần Quốc Toản | C12: Bác sĩ | D12: 107868829237 | E12: =SUM(SUMIF(phauthuat_BHYT!$H$8:$H$185,"TOẢN",phauthuat_BHYT!$I$8:$I$185),SUMIF(phauthuat_BHYT!$J$8:$J$185,"TOẢN",phauthuat_BHYT!$K$8:$K$185),SUMIF(phauthuat_BHYT!$L$8:$L$185,"TOẢN",phauthuat_BHYT!$M$8:$M$185)) -> 8062500
A13: 7 | B13: Đặng Phước Giàu | C13: Bác sĩ | D13: 105867664283 | E13: =SUM(SUMIF(phauthuat_BHYT!$H$8:$H$185,"giàu",phauthuat_BHYT!$I$8:$I$185),SUMIF(phauthuat_BHYT!$J$8:$J$185,"giàu",phauthuat_BHYT!$K$8:$K$185),SUMIF(phauthuat_BHYT!$L$8:$L$185,"giàu",phauthuat_BHYT!$M$8:$M$185)) -> 15855000
A14: 8 | B14: Phạm Việt Tân | C14: Bác sĩ | D14: 104000362303 | E14: =SUM(SUMIF(phauthuat_BHYT!$H$8:$H$185,"v.tân",phauthuat_BHYT!$I$8:$I$185),SUMIF(phauthuat_BHYT!$J$8:$J$185,"v.tân",phauthuat_BHYT!$K$8:$K$185),SUMIF(phauthuat_BHYT!$L$8:$L$185,"v.tân",phauthuat_BHYT!$M$8:$M$185)) -> 8520000
A15: 9 | B15: Bùi Công Minh | C15: Bác sĩ | D15: 105003414654 | E15: =SUM(SUMIF(phauthuat_BHYT!$H$8:$H$185,"minh",phauthuat_BHYT!$I$8:$I$185),SUMIF(phauthuat_BHYT!$J$8:$J$185,"minh",phauthuat_BHYT!$K$8:$K$185),SUMIF(phauthuat_BHYT!$L$8:$L$185,"minh",phauthuat_BHYT!$M$8:$M$185)) -> 5415000
A16: 10 | B16: Phan Văn Tuấn | C16: Bác sĩ | D16: 105872433048 | E16: =SUM(SUMIF(phauthuat_BHYT!$H$8:$H$185,"TUẤN",phauthuat_BHYT!$I$8:$I$185),SUMIF(phauthuat_BHYT!$J$8:$J$185,"TUẤN",phauthuat_BHYT!$K$8:$K$185),SUMIF(phauthuat_BHYT!$L$8:$L$185,"TUẤN",phauthuat_BHYT!$M$8:$M$185)) -> 0
A17: 11 | B17: Nguyễn Hữu Đạt | C17: Bác sĩ | D17: 103876067585 | E17: =SUM(SUMIF(phauthuat_BHYT!$H$8:$H$185,"đạt",phauthuat_BHYT!$I$8:$I$185),SUMIF(phauthuat_BHYT!$J$8:$J$185,"đạt",phauthuat_BHYT!$K$8:$K$185),SUMIF(phauthuat_BHYT!$L$8:$L$185,"đạt",phauthuat_BHYT!$M$8:$M$185)) -> 4575000
A18: 12 | B18: Trần Quang Sơn | C18: Bác sĩ | D18: 107004193662 | E18: =SUM(SUMIF(phauthuat_BHYT!$H$8:$H$185,"sơn",phauthuat_BHYT!$I$8:$I$185),SUMIF(phauthuat_BHYT!$J$8:$J$185,"sơn",phauthuat_BHYT!$K$8:$K$185),SUMIF(phauthuat_BHYT!$L$8:$L$185,"sơn",phauthuat_BHYT!$M$8:$M$185)) -> 1620000
A19: 13 | B19: Điều Tấn Kiệt | C19: Bác sĩ (nt) | D19: 105883051352 | E19: =SUM(SUMIF(phauthuat_BHYT!$H$8:$H$185,"kiệt",phauthuat_BHYT!$I$8:$I$185),SUMIF(phauthuat_BHYT!$J$8:$J$185,"kiệt",phauthuat_BHYT!$K$8:$K$185),SUMIF(phauthuat_BHYT!$L$8:$L$185,"kiệt",phauthuat_BHYT!$M$8:$M$185)) -> 735000
A20: 14 | B20: Nguyễn Lê Duy Phong | C20: Bác sĩ (nt) | E20: =SUM(SUMIF(phauthuat_BHYT!$H$8:$H$185,"phong",phauthuat_BHYT!$I$8:$I$185),SUMIF(phauthuat_BHYT!$J$8:$J$185,"phong",phauthuat_BHYT!$K$8:$K$185),SUMIF(phauthuat_BHYT!$L$8:$L$185,"phong",phauthuat_BHYT!$M$8:$M$185)) -> 900000
A21: 15 | B21: Trương Đại Lợi | C21: Bác sĩ (nt) | E21: =SUM(SUMIF(phauthuat_BHYT!$H$8:$H$185,"lợi",phauthuat_BHYT!$I$8:$I$185),SUMIF(phauthuat_BHYT!$J$8:$J$185,"lợi",phauthuat_BHYT!$K$8:$K$185),SUMIF(phauthuat_BHYT!$L$8:$L$185,"lợi",phauthuat_BHYT!$M$8:$M$185)) -> 0
A22: 16 | B22: Nguyễn Chí Thanh | C22: Bác sĩ (nt) | E22: =SUM(SUMIF(phauthuat_BHYT!$H$8:$H$185,"thanh",phauthuat_BHYT!$I$8:$I$185),SUMIF(phauthuat_BHYT!$J$8:$J$185,"thanh",phauthuat_BHYT!$K$8:$K$185),SUMIF(phauthuat_BHYT!$L$8:$L$185,"thanh",phauthuat_BHYT!$M$8:$M$185)) -> 570000
A23: 17 | B23: Lê Nhỉ Khang | C23: Bác sĩ (nt) | E23: =SUM(SUMIF(phauthuat_BHYT!$H$8:$H$185,"N.KHANG",phauthuat_BHYT!$I$8:$I$185),SUMIF(phauthuat_BHYT!$J$8:$J$185,"N.KHANG",phauthuat_BHYT!$K$8:$K$185),SUMIF(phauthuat_BHYT!$L$8:$L$185,"N.KHANG",phauthuat_BHYT!$M$8:$M$185)) -> 0
A24: 18 | B24: Phạm Văn Hưởng | C24: Bác sĩ (nt) | E24: =SUM(SUMIF(phauthuat_BHYT!$H$8:$H$185,"v.hưởng",phauthuat_BHYT!$I$8:$I$185),SUMIF(phauthuat_BHYT!$J$8:$J$185,"v.hưởng",phauthuat_BHYT!$K$8:$K$185),SUMIF(phauthuat_BHYT!$L$8:$L$185,"v.hưởng",phauthuat_BHYT!$M$8:$M$185)) -> 435000
A25: 19 | B25: Trần Trung Nghĩa | C25: Bác sĩ (nt) | E25: =SUM(SUMIF(phauthuat_BHYT!$H$8:$H$185,"nghĩa",phauthuat_BHYT!$I$8:$I$185),SUMIF(phauthuat_BHYT!$J$8:$J$185,"nghĩa",phauthuat_BHYT!$K$8:$K$185),SUMIF(phauthuat_BHYT!$L$8:$L$185,"nghĩa",phauthuat_BHYT!$M$8:$M$185)) -> 1035000
A26: 20 | B26: Nguyễn Trung Nhị | C26: Bác sĩ (nt) | E26: =SUM(SUMIF(phauthuat_BHYT!$H$8:$H$185,"nhị",phauthuat_BHYT!$I$8:$I$185),SUMIF(phauthuat_BHYT!$J$8:$J$185,"nhị",phauthuat_BHYT!$K$8:$K$185),SUMIF(phauthuat_BHYT!$L$8:$L$185,"nhị",phauthuat_BHYT!$M$8:$M$185)) -> 870000
A27: 21 | B27: Nguyễn Trần Khánh Đan | C27: Bác sĩ (nt) | D27: 105880975165 | E27: =SUM(SUMIF(phauthuat_BHYT!$H$8:$H$185,"ĐAN",phauthuat_BHYT!$I$8:$I$185),SUMIF(phauthuat_BHYT!$J$8:$J$185,"ĐAN",phauthuat_BHYT!$K$8:$K$185),SUMIF(phauthuat_BHYT!$L$8:$L$185,"ĐAN",phauthuat_BHYT!$M$8:$M$185)) -> 6855000
A28: 22 | B28: Phạm Công Hậu | C28: Bác sĩ (nt) | D28: 102879258199 | E28: =SUM(SUMIF(phauthuat_BHYT!$H$8:$H$185,"HẬU",phauthuat_BHYT!$I$8:$I$185),SUMIF(phauthuat_BHYT!$J$8:$J$185,"HẬU",phauthuat_BHYT!$K$8:$K$185),SUMIF(phauthuat_BHYT!$L$8:$L$185,"HẬU",phauthuat_BHYT!$M$8:$M$185)) -> 6360000
A29: 23 | B29: Trang Gia Vinh | C29: Bác sĩ (nt) | D29: 109880991105 | E29: =SUM(SUMIF(phauthuat_BHYT!$H$8:$H$185,"VINH",phauthuat_BHYT!$I$8:$I$185),SUMIF(phauthuat_BHYT!$J$8:$J$185,"VINH",phauthuat_BHYT!$K$8:$K$185),SUMIF(phauthuat_BHYT!$L$8:$L$185,"VINH",phauthuat_BHYT!$M$8:$M$185)) -> 5370000
A30: 24 | B30: Bùi Quan Tấn | C30: Bác sĩ (nt) | D30: 109881014321 | E30: =SUM(SUMIF(phauthuat_BHYT!$H$8:$H$185,"Q.TẤN",phauthuat_BHYT!$I$8:$I$185),SUMIF(phauthuat_BHYT!$J$8:$J$185,"Q.TẤN",phauthuat_BHYT!$K$8:$K$185),SUMIF(phauthuat_BHYT!$L$8:$L$185,"Q.TẤN",phauthuat_BHYT!$M$8:$M$185)) -> 8670000
A31: 25 | B31: Tào Nhật Hào | C31: Bác sĩ (nt) | D31: 102880994246 | E31: =SUM(SUMIF(phauthuat_BHYT!$H$8:$H$185,"HÀO",phauthuat_BHYT!$I$8:$I$185),SUMIF(phauthuat_BHYT!$J$8:$J$185,"HÀO",phauthuat_BHYT!$K$8:$K$185),SUMIF(phauthuat_BHYT!$L$8:$L$185,"HÀO",phauthuat_BHYT!$M$8:$M$185)) -> 4200000
A32: 25 | B32: Huỳnh Phúc Nguyên | C32: Bác sĩ (nt) | D32: 100881016109 | E32: =SUM(SUMIF(phauthuat_BHYT!$H$8:$H$185,"NGUYÊN",phauthuat_BHYT!$I$8:$I$185),SUMIF(phauthuat_BHYT!$J$8:$J$185,"NGUYÊN",phauthuat_BHYT!$K$8:$K$185),SUMIF(phauthuat_BHYT!$L$8:$L$185,"NGUYÊN",phauthuat_BHYT!$M$8:$M$185)) -> 4410000
B33: TỔNG CỘNG | E33: =SUM(E7:E32) -> 109785000
D35: Cần Thơ, ngày 25 tháng 8 năm 2025
A36: Người lập bảng | D36: Trưởng khoa
A40: ĐD. Phan Văn Hiếu | D40: ThS.Bs.CKII. Nguyễn Lê Hoan

Sheet Thực lãnh
A1: BV TRƯỜNG ĐHYD CẦN THƠ
A2: KHOA NGOẠI CTCH-TK
A3: DANH SÁCH LÃNH TIỀN THÙ LAO THÁNG 7/2025
A4: (BHYT)
A6: STT | B6: HỌ TÊN | C6: CHỨC VỤ | D6: SỐ TÀI KHOẢN | E6: SỐ TIỀN | F6: SỐ TIỀN | G6: KÝ NHẬN
A7: 1 | B7: Phạm Việt Triều | C7: Bác sĩ | D7: 102006610216 | E7: =SUM(SUMIF(phauthuat_BHYT!$H$8:$H$185,"TRIỀU",phauthuat_BHYT!$I$8:$I$185),SUMIF(phauthuat_BHYT!$J$8:$J$185,"TRIỀU",phauthuat_BHYT!$K$8:$K$185),SUMIF(phauthuat_BHYT!$L$8:$L$185,"TRIỀU",phauthuat_BHYT!$M$8:$M$185)) -> 2100000 | F7: =E7+I32 -> 10710000
A8: 2 | B8: Nguyễn Thành Tấn | C8: Bác sĩ | D8: 103006610215 | E8: =SUM(SUMIF(phauthuat_BHYT!$H$8:$H$185,"TẤN",phauthuat_BHYT!$I$8:$I$185),SUMIF(phauthuat_BHYT!$J$8:$J$185,"TẤN",phauthuat_BHYT!$K$8:$K$185),SUMIF(phauthuat_BHYT!$L$8:$L$185,"TẤN",phauthuat_BHYT!$M$8:$M$185)) -> 2100000 | F8: =E8 -> 2100000
A9: 3 | B9: Nguyễn Lê Hoan | C9: Bác sĩ | D9: 100006610218 | E9: =SUM(SUMIF(phauthuat_BHYT!$H$8:$H$185,"HOAN",phauthuat_BHYT!$I$8:$I$185),SUMIF(phauthuat_BHYT!$J$8:$J$185,"HOAN",phauthuat_BHYT!$K$8:$K$185),SUMIF(phauthuat_BHYT!$L$8:$L$185,"HOAN",phauthuat_BHYT!$M$8:$M$185)) -> 14985000 | F9: =E9+I29 -> 29025000
A10: 4 | B10: Nguyễn Chí Nguyện | C10: Bác sĩ | D10: 105001159195 | E10: =SUM(SUMIF(phauthuat_BHYT!$H$8:$H$185,"NGUYỆN",phauthuat_BHYT!$I$8:$I$185),SUMIF(phauthuat_BHYT!$J$8:$J$185,"NGUYỆN",phauthuat_BHYT!$K$8:$K$185),SUMIF(phauthuat_BHYT!$L$8:$L$185,"NGUYỆN",phauthuat_BHYT!$M$8:$M$185)) -> 0 | F10: =E10 -> 0
A11: 5 | B11: Hồ Điền | C11: Bác sĩ | D11: 105001225232 | E11: =SUM(SUMIF(phauthuat_BHYT!$H$8:$H$185,"ĐIỀN",phauthuat_BHYT!$I$8:$I$185),SUMIF(phauthuat_BHYT!$J$8:$J$185,"ĐIỀN",phauthuat_BHYT!$K$8:$K$185),SUMIF(phauthuat_BHYT!$L$8:$L$185,"ĐIỀN",phauthuat_BHYT!$M$8:$M$185)) -> 6142500 | F11: =E11+I19 -> 8347500
A12: 6 | B12: Trần Quốc Toản | C12: Bác sĩ | D12: 107868829237 | E12: =SUM(SUMIF(phauthuat_BHYT!$H$8:$H$185,"TOẢN",phauthuat_BHYT!$I$8:$I$185),SUMIF(phauthuat_BHYT!$J$8:$J$185,"TOẢN",phauthuat_BHYT!$K$8:$K$185),SUMIF(phauthuat_BHYT!$L$8:$L$185,"TOẢN",phauthuat_BHYT!$M$8:$M$185)) -> 8062500 | F12: =E12 -> 8062500
A13: 7 | B13: Đặng Phước Giàu | C13: Bác sĩ | D13: 105867664283 | E13: =SUM(SUMIF(phauthuat_BHYT!$H$8:$H$185,"giàu",phauthuat_BHYT!$I$8:$I$185),SUMIF(phauthuat_BHYT!$J$8:$J$185,"giàu",phauthuat_BHYT!$K$8:$K$185),SUMIF(phauthuat_BHYT!$L$8:$L$185,"giàu",phauthuat_BHYT!$M$8:$M$185)) -> 15855000 | F13: =E13+I24 -> 31410000
